Workbook

Sheet Tubex_Dashboard
B2: TUBEX — May 2026 Month to Date Report
B3: Report Date (Yesterday's Production): | H3: =TODAY()-1
B5: TUBE — YESTERDAY | D5: TUBE — MTD | G5: TUBE — REJECT % | J5: Dispatch — MTD | M5: Press & Printing Downtime — MTD
B6: =SUMPRODUCT((Production_Log!$A$3:$A$8963=MAX(Production_Log!$A$3:$A$8963))*(LEFT(Production_Log!$B$3:$B$8963,5)="Print")*(ISERROR(SEARCH("(Varnish)",Production_Log!$D$3:$D$8963)))*Production_Log!$H$3:$H$8963) | D6: =SUMIF($B$11:$B$59,"TUBE",$H$11:$H$59) | G6: {=IFERROR(SUMPRODUCT((Production_Log!$F$3:$F$8963<>0)*(LEFT(Production_Log!$B$3:$B$8963,5)="Print")*(ISERROR(SEARCH("(Varnish)",Production_Log!$D$3:$D$8963)))*Production_Log!$I$3:$I$8963)/SUMPRODUCT((Production_Log!$F$3:$F$8963<>0)*(LEFT(Production_Log!$B$3:$B$8963,5)="Print")*(ISERROR(SEARCH("(Varnish)",Production_Log!$D$3:$D$8963)))*(Production_Log!$H$3:$H$8963+Production_Log!$I$3:$I$8963)),"-")} | J6: =SUMIF($B$11:$B$59,"TUBE",$K$11:$K$59) | M6: Category | N6: Hours (MTD) | O6: % Share
B7: PET — YESTERDAY | D7: PET — MTD | G7: PET — REJECT % | J7: Dispatch — MTD | M7: =IFERROR(INDEX($S$9:$S$22,MATCH(LARGE($U$9:$U$22,1),$U$9:$U$22,0)),"") | N7: =(IFERROR(INDEX($T$9:$T$22,MATCH(LARGE($U$9:$U$22,1),$U$9:$U$22,0)),""))/60 | O7: =IFERROR(N7/$N$15,"")
B8: =SUMPRODUCT((Production_Log!$A$3:$A$8963=MAX(Production_Log!$A$3:$A$8963))*(Production_Log!$B$3:$B$8963="PF Machine")*Production_Log!$H$3:$H$8963) | D8: =SUMIF($B$11:$B$59,"PET",$H$11:$H$59) | G8: {=IFERROR(SUMPRODUCT((Production_Log!$B$3:$B$8963="PF Machine")*Production_Log!$I$3:$I$8963)/SUMPRODUCT((Production_Log!$B$3:$B$8963="PF Machine")*(Production_Log!$H$3:$H$8963+Production_Log!$I$3:$I$8963)),0)} | J8: =SUMIF($B$11:$B$59,"PET",$K$11:$K$59) | M8: =IFERROR(INDEX($S$9:$S$22,MATCH(LARGE($U$9:$U$22,2),$U$9:$U$22,0)),"") | N8: =IFERROR(INDEX($T$9:$T$22,MATCH(LARGE($U$9:$U$22,2),$U$9:$U$22,0)),"")/60 | O8: =IFERROR(N8/$N$15,"")
B9: Summary of Production & Dispatch - MTD | M9: =IFERROR(INDEX($S$9:$S$22,MATCH(LARGE($U$9:$U$22,3),$U$9:$U$22,0)),"") | N9: =IFERROR(INDEX($T$9:$T$22,MATCH(LARGE($U$9:$U$22,3),$U$9:$U$22,0)),"")/60 | O9: =IFERROR(N9/$N$15,"") | S9: Mechanical | T9: =SUMPRODUCT((MONTH(Production_Log!$A$3:$A$8963)=MONTH(TODAY()))*(YEAR(Production_Log!$A$3:$A$8963)=YEAR(TODAY()))*Production_Log!$K$3:$K$8963) | U9: =T9+0.00001
B10: Type | C10: Customer | D10: Product Name | E10: Dia | F10: Prod ID | G10: Orders | H10: MTD Produced | I10: Remaining | J10: MTD Compliance | K10: Dispatch | M10: =IFERROR(INDEX($S$9:$S$22,MATCH(LARGE($U$9:$U$22,4),$U$9:$U$22,0)),"") | N10: =IFERROR(INDEX($T$9:$T$22,MATCH(LARGE($U$9:$U$22,4),$U$9:$U$22,0)),"")/60 | O10: =IFERROR(N10/$N$15,"") | S10: Electrical | T10: =SUMPRODUCT((MONTH(Production_Log!$A$3:$A$8963)=MONTH(TODAY()))*(YEAR(Production_Log!$A$3:$A$8963)=YEAR(TODAY()))*Production_Log!$L$3:$L$8963) | U10: =T10+0.00002
B11: TUBE | C11: Brookes Pharma Private Limited | D11: ECZEMUS OINTMENT 0.03% 10G | E11: 16 | F11: 6561 | G11: 25000 | H11: =SUMPRODUCT((Production_Log!$F$3:$F$8963=F11)*(LEFT(Production_Log!$B$3:$B$8963,5)="Print")*(ISERROR(SEARCH("(Varnish)",Production_Log!$D$3:$D$8963)))*Production_Log!$H$3:$H$8963) | I11: =G11-H11 | J11: =IF(G11=0,"-",H11/G11) | M11: =IFERROR(INDEX($S$9:$S$22,MATCH(LARGE($U$9:$U$22,5),$U$9:$U$22,0)),"") | N11: =IFERROR(INDEX($T$9:$T$22,MATCH(LARGE($U$9:$U$22,5),$U$9:$U$22,0)),"")/60 | O11: =IFERROR(N11/$N$15,"") | S11: Workers Shortage | T11: =SUMPRODUCT((MONTH(Production_Log!$A$3:$A$8963)=MONTH(TODAY()))*(YEAR(Production_Log!$A$3:$A$8963)=YEAR(TODAY()))*Production_Log!$R$3:$R$8963) | U11: =T11+0.00003
B12: TUBE | C12: Samsol International Private Limited | D12: S-43 DIA 19MM | E12: 19 | F12: 6623 | G12: 0 | H12: =SUMPRODUCT((Production_Log!$F$3:$F$8963=F12)*(LEFT(Production_Log!$B$3:$B$8963,5)="Print")*(ISERROR(SEARCH("(Varnish)",Production_Log!$D$3:$D$8963)))*Production_Log!$H$3:$H$8963) | I12: =G12-H12 | J12: =IF(G12=0,"-",H12/G12) | K12: 24696 | M12: =IFERROR(INDEX($S$9:$S$22,MATCH(LARGE($U$9:$U$22,8),$U$9:$U$22,0)),"") | N12: =IFERROR(INDEX($T$9:$T$22,MATCH(LARGE($U$9:$U$22,8),$U$9:$U$22,0)),"")/60 | O12: =IFERROR(N12/$N$15,"")
B13: TUBE | C13: Samsol International Private Limited | D13: S-45 DIA 19MM | E13: 19 | F13: 6624 | G13: 10888 | H13: =SUMPRODUCT((Production_Log!$F$3:$F$8963=F13)*(LEFT(Production_Log!$B$3:$B$8963,5)="Print")*(ISERROR(SEARCH("(Varnish)",Production_Log!$D$3:$D$8963)))*Production_Log!$H$3:$H$8963) | I13: =G13-H13 | J13: =IF(G13=0,"-",H13/G13) | K13: 8232 | M13: =IFERROR(INDEX($S$9:$S$22,MATCH(LARGE($U$9:$U$22,6),$U$9:$U$22,0)),"") | N13: =IFERROR(INDEX($T$9:$T$22,MATCH(LARGE($U$9:$U$22,6),$U$9:$U$22,0)),"")/60 | O13: =IFERROR(N13/$N$15,"") | S13: Power Shutdown | T13: =SUMPRODUCT((MONTH(Production_Log!$A$3:$A$8963)=MONTH(TODAY()))*(YEAR(Production_Log!$A$3:$A$8963)=YEAR(TODAY()))*Production_Log!$P$3:$P$8963) | U13: =T13+0.00004
B14: TUBE | C14: Brookes Pharma Private Limited | D14: PHLOGIN GEL 20G | E14: 19 | F14: 6559 | G14: 0 | H14: =SUMPRODUCT((Production_Log!$F$3:$F$8963=F14)*(LEFT(Production_Log!$B$3:$B$8963,5)="Print")*(ISERROR(SEARCH("(Varnish)",Production_Log!$D$3:$D$8963)))*Production_Log!$H$3:$H$8963) | I14: =G14-H14 | J14: =IF(G14=0,"-",H14/G14) | K14: 35280 | M14: =IFERROR(INDEX($S$9:$S$22,MATCH(LARGE($U$9:$U$22,7),$U$9:$U$22,0)),"") | N14: =IFERROR(INDEX($T$9:$T$22,MATCH(LARGE($U$9:$U$22,7),$U$9:$U$22,0)),"")/60 | O14: =IFERROR(N14/$N$15,"")
B15: TUBE | C15: Samsol International Private Limited | D15: S-43 DIA 20.5 | E15: 20.5 | F15: 5699 | G15: 0 | H15: =SUMPRODUCT((Production_Log!$F$3:$F$8963=F15)*(LEFT(Production_Log!$B$3:$B$8963,5)="Print")*(ISERROR(SEARCH("(Varnish)",Production_Log!$D$3:$D$8963)))*Production_Log!$H$3:$H$8963) | I15: =G15-H15 | J15: =IF(G15=0,"-",H15/G15) | K15: 49470 | M15: TOTAL | N15: =SUM($T$9:$T$22)/60 | O15: 100%
B16: TUBE | C16: Mablay Beauty PVT LTD. | D16: VINCE HIS ONLY BEARD & MUSTACHE COLOR CREAM | E16: 20.5 | F16: 6077 | G16: 23970 | H16: =SUMPRODUCT((Production_Log!$F$3:$F$8963=F16)*(LEFT(Production_Log!$B$3:$B$8963,5)="Print")*(ISERROR(SEARCH("(Varnish)",Production_Log!$D$3:$D$8963)))*Production_Log!$H$3:$H$8963) | I16: =G16-H16 | J16: =IF(G16=0,"-",H16/G16) | K16: 23185 | S16: Material Shortage | T16: =SUMPRODUCT((MONTH(Production_Log!$A$3:$A$8963)=MONTH(TODAY()))*(YEAR(Production_Log!$A$3:$A$8963)=YEAR(TODAY()))*Production_Log!$M$3:$M$8963) | U16: =T16+0.00005
B17: TUBE | C17: Samsol International Private Limited | D17: S 43 25MM | E17: 25 | F17: 3447 | G17: 38976 | H17: =SUMPRODUCT((Production_Log!$F$3:$F$8963=F17)*(LEFT(Production_Log!$B$3:$B$8963,5)="Print")*(ISERROR(SEARCH("(Varnish)",Production_Log!$D$3:$D$8963)))*Production_Log!$H$3:$H$8963) | I17: =G17-H17 | J17: =IF(G17=0,"-",H17/G17) | K17: 50064 | S17: Changeover | T17: =SUMPRODUCT((MONTH(Production_Log!$A$3:$A$8963)=MONTH(TODAY()))*(YEAR(Production_Log!$A$3:$A$8963)=YEAR(TODAY()))*Production_Log!$N$3:$N$8963) | U17: =T17+0.00007
B18: TUBE | C18: Mablay Beauty PVT LTD. | D18: HIS ONLY HAIR COLOR CREAM 40GM | E18: 25 | F18: 6228 | G18: 21840 | H18: =SUMPRODUCT((Production_Log!$F$3:$F$8963=F18)*(LEFT(Production_Log!$B$3:$B$8963,5)="Print")*(ISERROR(SEARCH("(Varnish)",Production_Log!$D$3:$D$8963)))*Production_Log!$H$3:$H$8963) | I18: =G18-H18 | J18: =IF(G18=0,"-",H18/G18) | K18: 9744 | S18: Operations | T18: =SUMPRODUCT((MONTH(Production_Log!$A$3:$A$8963)=MONTH(TODAY()))*(YEAR(Production_Log!$A$3:$A$8963)=YEAR(TODAY()))*Production_Log!$O$3:$O$8963) | U18: =T18+0.00008
B19: TUBE | C19: Samsol International Private Limited | D19: TUBES COMMON RED | E19: 25 | F19: 6470 | G19: 0 | H19: =SUMPRODUCT((Production_Log!$F$3:$F$8963=F19)*(LEFT(Production_Log!$B$3:$B$8963,5)="Print")*(ISERROR(SEARCH("(Varnish)",Production_Log!$D$3:$D$8963)))*Production_Log!$H$3:$H$8963) | I19: =G19-H19 | J19: =IF(G19=0,"-",H19/G19)
B20: TUBE | C20: Samsol International Private Limited | D20: TUBES | E20: 25 | F20: 3726 | G20: 0 | H20: =SUMPRODUCT((Production_Log!$F$3:$F$8963=F20)*(LEFT(Production_Log!$B$3:$B$8963,5)="Print")*(ISERROR(SEARCH("(Varnish)",Production_Log!$D$3:$D$8963)))*Production_Log!$H$3:$H$8963) | I20: =G20-H20 | J20: =IF(G20=0,"-",H20/G20) | K20: 78288
B21: TUBE | C21: Mablay Beauty PVT LTD. | D21: VINCE NURTURAL | E21: 30 | F21: 5814 | G21: 23562 | H21: =SUMPRODUCT((Production_Log!$F$3:$F$8963=F21)*(LEFT(Production_Log!$B$3:$B$8963,5)="Print")*(ISERROR(SEARCH("(Varnish)",Production_Log!$D$3:$D$8963)))*Production_Log!$H$3:$H$8963) | I21: =G21-H21 | J21: =IF(G21=0,"-",H21/G21)
B22: TUBE | C22: Golden Pearl Cosmetics (PVT) LTD | D22: HELLO HAIR COLOR | E22: 30 | F22: 6206 | G22: 87108 | H22: =SUMPRODUCT((Production_Log!$F$3:$F$8963=F22)*(LEFT(Production_Log!$B$3:$B$8963,5)="Print")*(ISERROR(SEARCH("(Varnish)",Production_Log!$D$3:$D$8963)))*Production_Log!$H$3:$H$8963) | I22: =G22-H22 | J22: =IF(G22=0,"-",H22/G22) | K22: 152320
B23: TUBE | C23: Seatle (Private) Limited | D23: DOWFEN GEL 50G | E23: 30 | F23: 6595 | G23: 0 | H23: =SUMPRODUCT((Production_Log!$F$3:$F$8963=F23)*(LEFT(Production_Log!$B$3:$B$8963,5)="Print")*(ISERROR(SEARCH("(Varnish)",Production_Log!$D$3:$D$8963)))*Production_Log!$H$3:$H$8963) | I23: =G23-H23 | J23: =IF(G23=0,"-",H23/G23) | K23: 24990
B24: TUBE | C24: Al-Rehman Group | D24: SIGNATURE HAIR COLOR CREAM 60ML | E24: 30 | F24: 6416 | G24: 0 | H24: =SUMPRODUCT((Production_Log!$F$3:$F$8963=F24)*(LEFT(Production_Log!$B$3:$B$8963,5)="Print")*(ISERROR(SEARCH("(Varnish)",Production_Log!$D$3:$D$8963)))*Production_Log!$H$3:$H$8963) | I24: =G24-H24 | J24: =IF(G24=0,"-",H24/G24) | K24: 10045
B25: TUBE | C25: Hola Hair | D25: H.H 100GM | E25: 32 | F25: 6515 | G25: 13104 | H25: =SUMPRODUCT((Production_Log!$F$3:$F$8963=F25)*(LEFT(Production_Log!$B$3:$B$8963,5)="Print")*(ISERROR(SEARCH("(Varnish)",Production_Log!$D$3:$D$8963)))*Production_Log!$H$3:$H$8963) | I25: =G25-H25 | J25: =IF(G25=0,"-",H25/G25)
B26: TUBE | C26: Adore | D26: V- HC BROWN | E26: 35 | F26: 6530 | G26: 34000 | H26: =SUMPRODUCT((Production_Log!$F$3:$F$8963=F26)*(LEFT(Production_Log!$B$3:$B$8963,5)="Print")*(ISERROR(SEARCH("(Varnish)",Production_Log!$D$3:$D$8963)))*Production_Log!$H$3:$H$8963) | I26: =G26-H26 | J26: =IF(G26=0,"-",H26/G26) | K26: 5040
B27: TUBE | C27: Adore | D27: V-HC BLACK | E27: 35 | F27: 6531 | G27: 10620 | H27: =SUMPRODUCT((Production_Log!$F$3:$F$8963=F27)*(LEFT(Production_Log!$B$3:$B$8963,5)="Print")*(ISERROR(SEARCH("(Varnish)",Production_Log!$D$3:$D$8963)))*Production_Log!$H$3:$H$8963) | I27: =G27-H27 | J27: =IF(G27=0,"-",H27/G27)
D28: TOTAL | G28: =SUM(G11:G27) | H28: =SUM(H11:H27) | I28: =SUMIF(I11:I27,">"&0) | K28: =SUM(K11:K27)
B29: PET | C29: Samsol International Private Limited | D29: PET BOTTLE SMALL (120ML) YELLOW | E29: 120 ml | F29: 8005 | G29: 58960 | H29: =SUMPRODUCT((Production_Log!$F$3:$F$8963=F29)*Production_Log!$H$3:$H$8963) | I29: =G29-H29 | J29: =IF(G29=0,"-",H29/G29) | K29: 51720
B30: PET | C30: Alpha Labs PVT LTD | D30: PET BOTTLE SMALL (130ML) TRANSPARENT | E30: 130 ml | F30: 8010 | G30: 5000 | H30: =SUMPRODUCT((Production_Log!$F$3:$F$8963=F30)*Production_Log!$H$3:$H$8963) | I30: =G30-H30 | J30: =IF(G30=0,"-",H30/G30) | K30: 5520
B31: PET | C31: Alpha Labs PVT LTD | D31: TRANSPARENT BOTTLE 150ML | E31: 150 ml | F31: 8001 | G31: 166960 | H31: =SUMPRODUCT((Production_Log!$F$3:$F$8963=F31)*Production_Log!$H$3:$H$8963) | I31: =G31-H31 | J31: =IF(G31=0,"-",H31/G31) | K31: 50600
B32: PET | C32: Samsol International Private Limited | D32: PET BOTTLE LARGE 200ML WHITE | E32: 200 ml | F32: 8007 | G32: 10000 | H32: =SUMPRODUCT((Production_Log!$F$3:$F$8963=F32)*Production_Log!$H$3:$H$8963) | I32: =G32-H32 | J32: =IF(G32=0,"-",H32/G32)
B33: PET | C33: Samsol International Private Limited | D33: BT-200 ML YELLOW | E33: 200 ml | F33: 8006 | G33: 42400 | H33: =SUMPRODUCT((Production_Log!$F$3:$F$8963=F33)*Production_Log!$H$3:$H$8963) | I33: =G33-H33 | J33: =IF(G33=0,"-",H33/G33)
B34: PET | C34: Samsol International Private Limited | D34: BT-200ML MUSTARD OIL (TRANSPARENT) | E34: 200 ml | F34: 8014 | G34: 10000 | H34: =SUMPRODUCT((Production_Log!$F$3:$F$8963=F34)*Production_Log!$H$3:$H$8963) | I34: =G34-H34 | J34: =IF(G34=0,"-",H34/G34)
D35: TOTAL | G35: =SUM(G29:G34) | H35: =SUM(H29:H34) | I35: =SUMIF(I29:I34,">"&0) | K35: =SUM(K29:K34) | S35: Gas Shutdown | T35: =SUMPRODUCT((MONTH(Production_Log!$A$3:$A$8963)=MONTH(TODAY()))*(YEAR(Production_Log!$A$3:$A$8963)=YEAR(TODAY()))*Production_Log!$Q$3:$Q$8963) | U35: =T35+0.00006
B36: TUBE | C36: Bahadur | D36: BAHADUR TUBE 12.5MM | E36: 12.5 | F36: 9004 | G36: 0 | H36: =SUMPRODUCT((Production_Log!$F$3:$F$8963=F36)*(LEFT(Production_Log!$B$3:$B$8963,5)="Print")*(ISERROR(SEARCH("(Varnish)",Production_Log!$D$3:$D$8963)))*Production_Log!$H$3:$H$8963) | I36: =G36-H36 | J36: =IF(G36=0,"-",H36/G36)
B37: TUBE | C37: Brookes Pharma Private Limited | D37: PYODINE GEL 20GM | E37: 19 | F37: 1085 | G37: 0 | H37: =SUMPRODUCT((Production_Log!$F$3:$F$8963=F37)*(LEFT(Production_Log!$B$3:$B$8963,5)="Print")*(ISERROR(SEARCH("(Varnish)",Production_Log!$D$3:$D$8963)))*Production_Log!$H$3:$H$8963) | I37: =G37-H37 | J37: =IF(G37=0,"-",H37/G37)
B38: TUBE | C38: Brookes Pharma Private Limited | D38: CONTRATUBEX GEL 20G | E38: 19 | F38: 6560 | G38: 0 | H38: =SUMPRODUCT((Production_Log!$F$3:$F$8963=F38)*(LEFT(Production_Log!$B$3:$B$8963,5)="Print")*(ISERROR(SEARCH("(Varnish)",Production_Log!$D$3:$D$8963)))*Production_Log!$H$3:$H$8963) | I38: =G38-H38 | J38: =IF(G38=0,"-",H38/G38)
B39: TUBE | C39: Samsol International Private Limited | D39: S-45 DIA 20.5 | E39: 20.5 | F39: 5698 | G39: 0 | H39: =SUMPRODUCT((Production_Log!$F$3:$F$8963=F39)*(LEFT(Production_Log!$B$3:$B$8963,5)="Print")*(ISERROR(SEARCH("(Varnish)",Production_Log!$D$3:$D$8963)))*Production_Log!$H$3:$H$8963) | I39: =G39-H39 | J39: =IF(G39=0,"-",H39/G39)
B40: TUBE | C40: Samsol International Private Limited | D40: SAMSOL HAIR COLOR 45 DIA 20.5 MM | E40: 20.5 | F40: 5731 | G40: 0 | H40: =SUMPRODUCT((Production_Log!$F$3:$F$8963=F40)*(LEFT(Production_Log!$B$3:$B$8963,5)="Print")*(ISERROR(SEARCH("(Varnish)",Production_Log!$D$3:$D$8963)))*Production_Log!$H$3:$H$8963) | I40: =G40-H40 | J40: =IF(G40=0,"-",H40/G40)
B41: TUBE | C41: Samsol International Private Limited | D41: SAMSOL HAIR COLOR 43 DIA 20.5 MM | E41: 20.5 | F41: 5732 | G41: 0 | H41: =SUMPRODUCT((Production_Log!$F$3:$F$8963=F41)*(LEFT(Production_Log!$B$3:$B$8963,5)="Print")*(ISERROR(SEARCH("(Varnish)",Production_Log!$D$3:$D$8963)))*Production_Log!$H$3:$H$8963) | I41: =G41-H41 | J41: =IF(G41=0,"-",H41/G41)
B42: TUBE | C42: Samsol International Private Limited | D42: SAMSOL HAIR COLOR 39 SMALL PURPLE | E42: 20.5 | F42: 6556 | G42: 0 | H42: =SUMPRODUCT((Production_Log!$F$3:$F$8963=F42)*(LEFT(Production_Log!$B$3:$B$8963,5)="Print")*(ISERROR(SEARCH("(Varnish)",Production_Log!$D$3:$D$8963)))*Production_Log!$H$3:$H$8963) | I42: =G42-H42 | J42: =IF(G42=0,"-",H42/G42)
...

Sheet MRP
A1: May 2026 Tube Required Orders | G1: Date: | H1: =TODAY()
A2: Dia | B2: Customer | C2: Product Name | D2: Product ID | E2: Job Order # | F2: Required Qty | G2: Produced | H2: Remaining Balance | J2: Remarks
A3: 16 | B3: Brookes Pharma Private Limited | C3: ECZEMUS OINTMENT 0.03% 10G | D3: 6561 | E3: 6849 | F3: 25000 | G3: =SUMPRODUCT((Production_Log!$F$3:$F$8963=D3)*(LEFT(Production_Log!$B$3:$B$8963,5)="Print")*(ISERROR(SEARCH("(Varnish)",Production_Log!$D$3:$D$8963)))*(MONTH(Production_Log!$A$3:$A$8963)=MONTH(TODAY()))*(YEAR(Production_Log!$A$3:$A$8963)=YEAR(TODAY()))*Production_Log!$H$3:$H$8963) | H3: =F3-G3 | J3: CAPS Not Approved
A4: 19 | B4: Samsol International Private Limited | C4: S-45 DIA 19MM | D4: 6624 | E4: 6880 & 6881 | F4: 10888 | G4: =SUMPRODUCT((Production_Log!$F$3:$F$8963=D4)*(LEFT(Production_Log!$B$3:$B$8963,5)="Print")*(ISERROR(SEARCH("(Varnish)",Production_Log!$D$3:$D$8963)))*(MONTH(Production_Log!$A$3:$A$8963)=MONTH(TODAY()))*(YEAR(Production_Log!$A$3:$A$8963)=YEAR(TODAY()))*Production_Log!$H$3:$H$8963) | H4: =F4-G4 | J4: SLUG in Transit
A5: 20.5 | B5: Mablay Beauty PVT LTD. | C5: VINCE HIS ONLY BEARD & MUSTACHE COLOR CREAM | D5: 6077 | E5: 6886 | F5: 23970 | G5: =SUMPRODUCT((Production_Log!$F$3:$F$8963=D5)*(LEFT(Production_Log!$B$3:$B$8963,5)="Print")*(ISERROR(SEARCH("(Varnish)",Production_Log!$D$3:$D$8963)))*(MONTH(Production_Log!$A$3:$A$8963)=MONTH(TODAY()))*(YEAR(Production_Log!$A$3:$A$8963)=YEAR(TODAY()))*Production_Log!$H$3:$H$8963) | H5: =F5-G5
A6: 25 | B6: Mablay Beauty PVT LTD. | C6: HIS ONLY HAIR COLOR CREAM 40GM | D6: 6228 | E6: 6885 | F6: 21840 | G6: =SUMPRODUCT((Production_Log!$F$3:$F$8963=D6)*(LEFT(Production_Log!$B$3:$B$8963,5)="Print")*(ISERROR(SEARCH("(Varnish)",Production_Log!$D$3:$D$8963)))*(MONTH(Production_Log!$A$3:$A$8963)=MONTH(TODAY()))*(YEAR(Production_Log!$A$3:$A$8963)=YEAR(TODAY()))*Production_Log!$H$3:$H$8963) | H6: =F6-G6
A7: 25 | B7: Samsol International Private Limited | C7: S 43 25MM | D7: 3447 | E7: 6876 | F7: 38976 | G7: =SUMPRODUCT((Production_Log!$F$3:$F$8963=D7)*(LEFT(Production_Log!$B$3:$B$8963,5)="Print")*(ISERROR(SEARCH("(Varnish)",Production_Log!$D$3:$D$8963)))*(MONTH(Production_Log!$A$3:$A$8963)=MONTH(TODAY()))*(YEAR(Production_Log!$A$3:$A$8963)=YEAR(TODAY()))*Production_Log!$H$3:$H$8963) | H7: =F7-G7
A8: 30 | B8: Mablay Beauty PVT LTD. | C8: VINCE NURTURAL | D8: 5814 | E8: 6887 | F8: 23562 | G8: =SUMPRODUCT((Production_Log!$F$3:$F$8963=D8)*(LEFT(Production_Log!$B$3:$B$8963,5)="Print")*(ISERROR(SEARCH("(Varnish)",Production_Log!$D$3:$D$8963)))*(MONTH(Production_Log!$A$3:$A$8963)=MONTH(TODAY()))*(YEAR(Production_Log!$A$3:$A$8963)=YEAR(TODAY()))*Production_Log!$H$3:$H$8963) | H8: =F8-G8
A9: 30 | B9: Golden Pearl Cosmetics (PVT) LTD | C9: HELLO HAIR COLOR | D9: 6206 | E9: 6862 | F9: 87108 | G9: =SUMPRODUCT((Production_Log!$F$3:$F$8963=D9)*(LEFT(Production_Log!$B$3:$B$8963,5)="Print")*(ISERROR(SEARCH("(Varnish)",Production_Log!$D$3:$D$8963)))*(MONTH(Production_Log!$A$3:$A$8963)=MONTH(TODAY()))*(YEAR(Production_Log!$A$3:$A$8963)=YEAR(TODAY()))*Production_Log!$H$3:$H$8963) | H9: =F9-G9
A10: 32 | B10: Hola Hair | C10: H.H 100GM | D10: 6515 | E10: 6839 | F10: 13104 | G10: =SUMPRODUCT((Production_Log!$F$3:$F$8963=D10)*(LEFT(Production_Log!$B$3:$B$8963,5)="Print")*(ISERROR(SEARCH("(Varnish)",Production_Log!$D$3:$D$8963)))*(MONTH(Production_Log!$A$3:$A$8963)=MONTH(TODAY()))*(YEAR(Production_Log!$A$3:$A$8963)=YEAR(TODAY()))*Production_Log!$H$3:$H$8963) | H10: =F10-G10
A11: 35 | B11: Adore | C11: V- HC BROWN | D11: 6530 | E11: 6884 | F11: 34000 | G11: =SUMPRODUCT((Production_Log!$F$3:$F$8963=D11)*(LEFT(Production_Log!$B$3:$B$8963,5)="Print")*(ISERROR(SEARCH("(Varnish)",Production_Log!$D$3:$D$8963)))*(MONTH(Production_Log!$A$3:$A$8963)=MONTH(TODAY()))*(YEAR(Production_Log!$A$3:$A$8963)=YEAR(TODAY()))*Production_Log!$H$3:$H$8963) | H11: =F11-G11 | J11: Hold Due to Payment Issue
A12: 35 | B12: Adore | C12: V-HC BLACK | D12: 6531 | E12: 6883 | F12: 10620 | G12: =SUMPRODUCT((Production_Log!$F$3:$F$8963=D12)*(LEFT(Production_Log!$B$3:$B$8963,5)="Print")*(ISERROR(SEARCH("(Varnish)",Production_Log!$D$3:$D$8963)))*(MONTH(Production_Log!$A$3:$A$8963)=MONTH(TODAY()))*(YEAR(Production_Log!$A$3:$A$8963)=YEAR(TODAY()))*Production_Log!$H$3:$H$8963) | H12: =F12-G12
E13: TOTAL: | F13: =SUM(F3:F12) | G13: =SUM(G3:G12) | H13: =SUMIF(H3:H12, ">0")
A14: MAY TUBES MATERIAL REQUIREMENT PLAN
A15: Item ID | B15: Category | C15: Item Name | D15: UOM | E15: Required Qty | F15: Current Stock (Store + WIP) | G15: Surplus / (Deficit) | H15: Product Name(s) | I15: Job Order #(s) | J15: Status | K15: FG Caps On Hold (pcs) | L15: ORDER QTY
A16: 33 | B16: SLUG | C16: 12.5X4.5X4.8 | D16: kg | E16: =SUMPRODUCT((TableBOM[Item ID]=A16)*TableBOM[Per 1000 Units]*(1+TableBOM[Scrap %])*SUMIF($D$3:$D$12,TableBOM[Product ID],$H$3:$H$12)/1000) | F16: =IFERROR(INDEX(TableInventory[Store Balance],MATCH(A16,TableInventory[Item ID],0)),0)+IFERROR(INDEX(TableInventory[Work In Process],MATCH(A16,TableInventory[Item ID],0)),0) | G16: =F16-E16 | H16: =IF(LEN(IF((COUNTIFS(TableBOM[Product ID],$D$3,TableBOM[Item ID],$A16)>0)*($H$3>0),$C$3&", ","")&IF((COUNTIFS(TableBOM[Product ID],$D$4,TableBOM[Item ID],$A16)>0)*($H$4>0),$C$4&", ","")&IF((COUNTIFS(TableBOM[Product ID],$D$5,TableBOM[Item ID],$A16)>0)*($H$5>0),$C$5&", ","")&IF((COUNTIFS(TableBOM[Product ID],$D$6,TableBOM[Item ID],$A16)>0)*($H$6>0),$C$6&", ","")&IF((COUNTIFS(TableBOM[Product ID],$D$7,TableBOM[Item ID],$A16)>0)*($H$7>0),$C$7&", ","")&IF((COUNTIFS(TableBOM[Product ID],$D$8,TableBOM[Item ID],$A16)>0)*($H$8>0),$C$8&", ","")&IF((COUNTIFS(TableBOM[Product ID],$D$9,TableBOM[Item ID],$A16)>0)*($H$9>0),$C$9&", ","")&IF((COUNTIFS(TableBOM[Product ID],$D$10,TableBOM[Item ID],$A16)>0)*($H$10>0),$C$10&", ","")&IF((COUNTIFS(TableBOM[Product ID],$D$11,TableBOM[Item ID],$A16)>0)*($H$11>0),$C$11&", ","")&IF((COUNTIFS(TableBOM[Product ID],$D$12,TableBOM[Item ID],$A16)>0)*($H$12>0),$C$12&", ",""))>1,LEFT(IF((COUNTIFS(TableBOM[Product ID],$D$3,TableBOM[Item ID],$A16)>0)*($H$3>0),$C$3&", ","")&IF((COUNTIFS(TableBOM[Product ID],$D$4,TableBOM[Item ID],$A16)>0)*($H$4>0),$C$4&", ","")&IF((COUNTIFS(TableBOM[Product ID],$D$5,TableBOM[Item ID],$A16)>0)*($H$5>0),$C$5&", ","")&IF((COUNTIFS(TableBOM[Product ID],$D$6,TableBOM[Item ID],$A16)>0)*($H$6>0),$C$6&", ","")&IF((COUNTIFS(TableBOM[Product ID],$D$7,TableBOM[Item ID],$A16)>0)*($H$7>0),$C$7&", ","")&IF((COUNTIFS(TableBOM[Product ID],$D$8,TableBOM[Item ID],$A16)>0)*($H$8>0),$C$8&", ","")&IF((COUNTIFS(TableBOM[Product ID],$D$9,TableBOM[Item ID],$A16)>0)*($H$9>0),$C$9&", ","")&IF((COUNTIFS(TableBOM[Product ID],$D$10,TableBOM[Item ID],$A16)>0)*($H$10>0),$C$10&", ","")&IF((COUNTIFS(TableBOM[Product ID],$D$11,TableBOM[Item ID],$A16)>0)*($H$11>0),$C$11&", ","")&IF((COUNTIFS(TableBOM[Product ID],$D$12,TableBOM[Item ID],$A16)>0)*($H$12>0),$C$12&", ",""),LEN(IF((COUNTIFS(TableBOM[Product ID],$D$3,TableBOM[Item ID],$A16)>0)*($H$3>0),$C$3&", ","")&IF((COUNTIFS(TableBOM[Product ID],$D$4,TableBOM[Item ID],$A16)>0)*($H$4>0),$C$4&", ","")&IF((COUNTIFS(TableBOM[Product ID],$D$5,TableBOM[Item ID],$A16)>0)*($H$5>0),$C$5&", ","")&IF((COUNTIFS(TableBOM[Product ID],$D$6,TableBOM[Item ID],$A16)>0)*($H$6>0),$C$6&", ","")&IF((COUNTIFS(TableBOM[Product ID],$D$7,TableBOM[Item ID],$A16)>0)*($H$7>0),$C$7&", ","")&IF((COUNTIFS(TableBOM[Product ID],$D$8,TableBOM[Item ID],$A16)>0)*($H$8>0),$C$8&", ","")&IF((COUNTIFS(TableBOM[Product ID],$D$9,TableBOM[Item ID],$A16)>0)*($H$9>0),$C$9&", ","")&IF((COUNTIFS(TableBOM[Product ID],$D$10,TableBOM[Item ID],$A16)>0)*($H$10>0),$C$10&", ","")&IF((COUNTIFS(TableBOM[Product ID],$D$11,TableBOM[Item ID],$A16)>0)*($H$11>0),$C$11&", ","")&IF((COUNTIFS(TableBOM[Product ID],$D$12,TableBOM[Item ID],$A16)>0)*($H$12>0),$C$12&", ",""))-2),"") | I16: =IF(LEN(IF((COUNTIFS(TableBOM[Product ID],$D$3,TableBOM[Item ID],$A16)>0)*($H$3>0),$E$3&", ","")&IF((COUNTIFS(TableBOM[Product ID],$D$4,TableBOM[Item ID],$A16)>0)*($H$4>0),$E$4&", ","")&IF((COUNTIFS(TableBOM[Product ID],$D$5,TableBOM[Item ID],$A16)>0)*($H$5>0),$E$5&", ","")&IF((COUNTIFS(TableBOM[Product ID],$D$6,TableBOM[Item ID],$A16)>0)*($H$6>0),$E$6&", ","")&IF((COUNTIFS(TableBOM[Product ID],$D$7,TableBOM[Item ID],$A16)>0)*($H$7>0),$E$7&", ","")&IF((COUNTIFS(TableBOM[Product ID],$D$8,TableBOM[Item ID],$A16)>0)*($H$8>0),$E$8&", ","")&IF((COUNTIFS(TableBOM[Product ID],$D$9,TableBOM[Item ID],$A16)>0)*($H$9>0),$E$9&", ","")&IF((COUNTIFS(TableBOM[Product ID],$D$10,TableBOM[Item ID],$A16)>0)*($H$10>0),$E$10&", ","")&IF((COUNTIFS(TableBOM[Product ID],$D$11,TableBOM[Item ID],$A16)>0)*($H$11>0),$E$11&", ","")&IF((COUNTIFS(TableBOM[Product ID],$D$12,TableBOM[Item ID],$A16)>0)*($H$12>0),$E$12&", ",""))>1,LEFT(IF((COUNTIFS(TableBOM[Product ID],$D$3,TableBOM[Item ID],$A16)>0)*($H$3>0),$E$3&", ","")&IF((COUNTIFS(TableBOM[Product ID],$D$4,TableBOM[Item ID],$A16)>0)*($H$4>0),$E$4&", ","")&IF((COUNTIFS(TableBOM[Product ID],$D$5,TableBOM[Item ID],$A16)>0)*($H$5>0),$E$5&", ","")&IF((COUNTIFS(TableBOM[Product ID],$D$6,TableBOM[Item ID],$A16)>0)*($H$6>0),$E$6&", ","")&IF((COUNTIFS(TableBOM[Product ID],$D$7,TableBOM[Item ID],$A16)>0)*($H$7>0),$E$7&", ","")&IF((COUNTIFS(TableBOM[Product ID],$D$8,TableBOM[Item ID],$A16)>0)*($H$8>0),$E$8&", ","")&IF((COUNTIFS(TableBOM[Product ID],$D$9,TableBOM[Item ID],$A16)>0)*($H$9>0),$E$9&", ","")&IF((COUNTIFS(TableBOM[Product ID],$D$10,TableBOM[Item ID],$A16)>0)*($H$10>0),$E$10&", ","")&IF((COUNTIFS(TableBOM[Product ID],$D$11,TableBOM[Item ID],$A16)>0)*($H$11>0),$E$11&", ","")&IF((COUNTIFS(TableBOM[Product ID],$D$12,TableBOM[Item ID],$A16)>0)*($H$12>0),$E$12&", ",""),LEN(IF((COUNTIFS(TableBOM[Product ID],$D$3,TableBOM[Item ID],$A16)>0)*($H$3>0),$E$3&", ","")&IF((COUNTIFS(TableBOM[Product ID],$D$4,TableBOM[Item ID],$A16)>0)*($H$4>0),$E$4&", ","")&IF((COUNTIFS(TableBOM[Product ID],$D$5,TableBOM[Item ID],$A16)>0)*($H$5>0),$E$5&", ","")&IF((COUNTIFS(TableBOM[Product ID],$D$6,TableBOM[Item ID],$A16)>0)*($H$6>0),$E$6&", ","")&IF((COUNTIFS(TableBOM[Product ID],$D$7,TableBOM[Item ID],$A16)>0)*($H$7>0),$E$7&", ","")&IF((COUNTIFS(TableBOM[Product ID],$D$8,TableBOM[Item ID],$A16)>0)*($H$8>0),$E$8&", ","")&IF((COUNTIFS(TableBOM[Product ID],$D$9,TableBOM[Item ID],$A16)>0)*($H$9>0),$E$9&", ","")&IF((COUNTIFS(TableBOM[Product ID],$D$10,TableBOM[Item ID],$A16)>0)*($H$10>0),$E$10&", ","")&IF((COUNTIFS(TableBOM[Product ID],$D$11,TableBOM[Item ID],$A16)>0)*($H$11>0),$E$11&", ","")&IF((COUNTIFS(TableBOM[Product ID],$D$12,TableBOM[Item ID],$A16)>0)*($H$12>0),$E$12&", ",""))-2),"") | J16: =IF(E16=0,"Not needed",IF(G16<0,"SHORTAGE",IF(G16<F16*0.1,"LOW","OK"))) | K16: =IF(B16<>"CAP","",SUMPRODUCT((ISNUMBER(SEARCH("Cap Not Available",'FG Stock'!$H$4:$H$100)))*('FG Stock'!$I$4:$I$100=A16)*'FG Stock'!$F$4:$F$100)) | L16: =IF(E16=0,"",MAX(0,E16+IFERROR(K16*1,0)-F16))
A17: 31 | B17: SLUG | C17: 13.5X4.2 | D17: kg | E17: =SUMPRODUCT((TableBOM[Item ID]=A17)*TableBOM[Per 1000 Units]*(1+TableBOM[Scrap %])*SUMIF($D$3:$D$12,TableBOM[Product ID],$H$3:$H$12)/1000) | F17: =IFERROR(INDEX(TableInventory[Store Balance],MATCH(A17,TableInventory[Item ID],0)),0)+IFERROR(INDEX(TableInventory[Work In Process],MATCH(A17,TableInventory[Item ID],0)),0) | G17: =F17-E17 | H17: =IF(LEN(IF((COUNTIFS(TableBOM[Product ID],$D$3,TableBOM[Item ID],$A17)>0)*($H$3>0),$C$3&", ","")&IF((COUNTIFS(TableBOM[Product ID],$D$4,TableBOM[Item ID],$A17)>0)*($H$4>0),$C$4&", ","")&IF((COUNTIFS(TableBOM[Product ID],$D$5,TableBOM[Item ID],$A17)>0)*($H$5>0),$C$5&", ","")&IF((COUNTIFS(TableBOM[Product ID],$D$6,TableBOM[Item ID],$A17)>0)*($H$6>0),$C$6&", ","")&IF((COUNTIFS(TableBOM[Product ID],$D$7,TableBOM[Item ID],$A17)>0)*($H$7>0),$C$7&", ","")&IF((COUNTIFS(TableBOM[Product ID],$D$8,TableBOM[Item ID],$A17)>0)*($H$8>0),$C$8&", ","")&IF((COUNTIFS(TableBOM[Product ID],$D$9,TableBOM[Item ID],$A17)>0)*($H$9>0),$C$9&", ","")&IF((COUNTIFS(TableBOM[Product ID],$D$10,TableBOM[Item ID],$A17)>0)*($H$10>0),$C$10&", ","")&IF((COUNTIFS(TableBOM[Product ID],$D$11,TableBOM[Item ID],$A17)>0)*($H$11>0),$C$11&", ","")&IF((COUNTIFS(TableBOM[Product ID],$D$12,TableBOM[Item ID],$A17)>0)*($H$12>0),$C$12&", ",""))>1,LEFT(IF((COUNTIFS(TableBOM[Product ID],$D$3,TableBOM[Item ID],$A17)>0)*($H$3>0),$C$3&", ","")&IF((COUNTIFS(TableBOM[Product ID],$D$4,TableBOM[Item ID],$A17)>0)*($H$4>0),$C$4&", ","")&IF((COUNTIFS(TableBOM[Product ID],$D$5,TableBOM[Item ID],$A17)>0)*($H$5>0),$C$5&", ","")&IF((COUNTIFS(TableBOM[Product ID],$D$6,TableBOM[Item ID],$A17)>0)*($H$6>0),$C$6&", ","")&IF((COUNTIFS(TableBOM[Product ID],$D$7,TableBOM[Item ID],$A17)>0)*($H$7>0),$C$7&", ","")&IF((COUNTIFS(TableBOM[Product ID],$D$8,TableBOM[Item ID],$A17)>0)*($H$8>0),$C$8&", ","")&IF((COUNTIFS(TableBOM[Product ID],$D$9,TableBOM[Item ID],$A17)>0)*($H$9>0),$C$9&", ","")&IF((COUNTIFS(TableBOM[Product ID],$D$10,TableBOM[Item ID],$A17)>0)*($H$10>0),$C$10&", ","")&IF((COUNTIFS(TableBOM[Product ID],$D$11,TableBOM[Item ID],$A17)>0)*($H$11>0),$C$11&", ","")&IF((COUNTIFS(TableBOM[Product ID],$D$12,TableBOM[Item ID],$A17)>0)*($H$12>0),$C$12&", ",""),LEN(IF((COUNTIFS(TableBOM[Product ID],$D$3,TableBOM[Item ID],$A17)>0)*($H$3>0),$C$3&", ","")&IF((COUNTIFS(TableBOM[Product ID],$D$4,TableBOM[Item ID],$A17)>0)*($H$4>0),$C$4&", ","")&IF((COUNTIFS(TableBOM[Product ID],$D$5,TableBOM[Item ID],$A17)>0)*($H$5>0),$C$5&", ","")&IF((COUNTIFS(TableBOM[Product ID],$D$6,TableBOM[Item ID],$A17)>0)*($H$6>0),$C$6&", ","")&IF((COUNTIFS(TableBOM[Product ID],$D$7,TableBOM[Item ID],$A17)>0)*($H$7>0),$C$7&", ","")&IF((COUNTIFS(TableBOM[Product ID],$D$8,TableBOM[Item ID],$A17)>0)*($H$8>0),$C$8&", ","")&IF((COUNTIFS(TableBOM[Product ID],$D$9,TableBOM[Item ID],$A17)>0)*($H$9>0),$C$9&", ","")&IF((COUNTIFS(TableBOM[Product ID],$D$10,TableBOM[Item ID],$A17)>0)*($H$10>0),$C$10&", ","")&IF((COUNTIFS(TableBOM[Product ID],$D$11,TableBOM[Item ID],$A17)>0)*($H$11>0),$C$11&", ","")&IF((COUNTIFS(TableBOM[Product ID],$D$12,TableBOM[Item ID],$A17)>0)*($H$12>0),$C$12&", ",""))-2),"") | I17: =IF(LEN(IF((COUNTIFS(TableBOM[Product ID],$D$3,TableBOM[Item ID],$A17)>0)*($H$3>0),$E$3&", ","")&IF((COUNTIFS(TableBOM[Product ID],$D$4,TableBOM[Item ID],$A17)>0)*($H$4>0),$E$4&", ","")&IF((COUNTIFS(TableBOM[Product ID],$D$5,TableBOM[Item ID],$A17)>0)*($H$5>0),$E$5&", ","")&IF((COUNTIFS(TableBOM[Product ID],$D$6,TableBOM[Item ID],$A17)>0)*($H$6>0),$E$6&", ","")&IF((COUNTIFS(TableBOM[Product ID],$D$7,TableBOM[Item ID],$A17)>0)*($H$7>0),$E$7&", ","")&IF((COUNTIFS(TableBOM[Product ID],$D$8,TableBOM[Item ID],$A17)>0)*($H$8>0),$E$8&", ","")&IF((COUNTIFS(TableBOM[Product ID],$D$9,TableBOM[Item ID],$A17)>0)*($H$9>0),$E$9&", ","")&IF((COUNTIFS(TableBOM[Product ID],$D$10,TableBOM[Item ID],$A17)>0)*($H$10>0),$E$10&", ","")&IF((COUNTIFS(TableBOM[Product ID],$D$11,TableBOM[Item ID],$A17)>0)*($H$11>0),$E$11&", ","")&IF((COUNTIFS(TableBOM[Product ID],$D$12,TableBOM[Item ID],$A17)>0)*($H$12>0),$E$12&", ",""))>1,LEFT(IF((COUNTIFS(TableBOM[Product ID],$D$3,TableBOM[Item ID],$A17)>0)*($H$3>0),$E$3&", ","")&IF((COUNTIFS(TableBOM[Product ID],$D$4,TableBOM[Item ID],$A17)>0)*($H$4>0),$E$4&", ","")&IF((COUNTIFS(TableBOM[Product ID],$D$5,TableBOM[Item ID],$A17)>0)*($H$5>0),$E$5&", ","")&IF((COUNTIFS(TableBOM[Product ID],$D$6,TableBOM[Item ID],$A17)>0)*($H$6>0),$E$6&", ","")&IF((COUNTIFS(TableBOM[Product ID],$D$7,TableBOM[Item ID],$A17)>0)*($H$7>0),$E$7&", ","")&IF((COUNTIFS(TableBOM[Product ID],$D$8,TableBOM[Item ID],$A17)>0)*($H$8>0),$E$8&", ","")&IF((COUNTIFS(TableBOM[Product ID],$D$9,TableBOM[Item ID],$A17)>0)*($H$9>0),$E$9&", ","")&IF((COUNTIFS(TableBOM[Product ID],$D$10,TableBOM[Item ID],$A17)>0)*($H$10>0),$E$10&", ","")&IF((COUNTIFS(TableBOM[Product ID],$D$11,TableBOM[Item ID],$A17)>0)*($H$11>0),$E$11&", ","")&IF((COUNTIFS(TableBOM[Product ID],$D$12,TableBOM[Item ID],$A17)>0)*($H$12>0),$E$12&", ",""),LEN(IF((COUNTIFS(TableBOM[Product ID],$D$3,TableBOM[Item ID],$A17)>0)*($H$3>0),$E$3&", ","")&IF((COUNTIFS(TableBOM[Product ID],$D$4,TableBOM[Item ID],$A17)>0)*($H$4>0),$E$4&", ","")&IF((COUNTIFS(TableBOM[Product ID],$D$5,TableBOM[Item ID],$A17)>0)*($H$5>0),$E$5&", ","")&IF((COUNTIFS(TableBOM[Product ID],$D$6,TableBOM[Item ID],$A17)>0)*($H$6>0),$E$6&", ","")&IF((COUNTIFS(TableBOM[Product ID],$D$7,TableBOM[Item ID],$A17)>0)*($H$7>0),$E$7&", ","")&IF((COUNTIFS(TableBOM[Product ID],$D$8,TableBOM[Item ID],$A17)>0)*($H$8>0),$E$8&", ","")&IF((COUNTIFS(TableBOM[Product ID],$D$9,TableBOM[Item ID],$A17)>0)*($H$9>0),$E$9&", ","")&IF((COUNTIFS(TableBOM[Product ID],$D$10,TableBOM[Item ID],$A17)>0)*($H$10>0),$E$10&", ","")&IF((COUNTIFS(TableBOM[Product ID],$D$11,TableBOM[Item ID],$A17)>0)*($H$11>0),$E$11&", ","")&IF((COUNTIFS(TableBOM[Product ID],$D$12,TableBOM[Item ID],$A17)>0)*($H$12>0),$E$12&", ",""))-2),"") | J17: =IF(E17=0,"Not needed",IF(G17<0,"SHORTAGE",IF(G17<F17*0.1,"LOW","OK"))) | K17: =IF(B17<>"CAP","",SUMPRODUCT((ISNUMBER(SEARCH("Cap Not Available",'FG Stock'!$H$4:$H$100)))*('FG Stock'!$I$4:$I$100=A17)*'FG Stock'!$F$4:$F$100)) | L17: =IF(E17=0,"",MAX(0,E17+IFERROR(K17*1,0)-F17))
A18: 2799 | B18: SLUG | C18: 16x4.5 | D18: kg | E18: =SUMPRODUCT((TableBOM[Item ID]=A18)*TableBOM[Per 1000 Units]*(1+TableBOM[Scrap %])*SUMIF($D$3:$D$12,TableBOM[Product ID],$H$3:$H$12)/1000) | F18: =IFERROR(INDEX(TableInventory[Store Balance],MATCH(A18,TableInventory[Item ID],0)),0)+IFERROR(INDEX(TableInventory[Work In Process],MATCH(A18,TableInventory[Item ID],0)),0) | G18: =F18-E18 | H18: =IF(LEN(IF((COUNTIFS(TableBOM[Product ID],$D$3,TableBOM[Item ID],$A18)>0)*($H$3>0),$C$3&", ","")&IF((COUNTIFS(TableBOM[Product ID],$D$4,TableBOM[Item ID],$A18)>0)*($H$4>0),$C$4&", ","")&IF((COUNTIFS(TableBOM[Product ID],$D$5,TableBOM[Item ID],$A18)>0)*($H$5>0),$C$5&", ","")&IF((COUNTIFS(TableBOM[Product ID],$D$6,TableBOM[Item ID],$A18)>0)*($H$6>0),$C$6&", ","")&IF((COUNTIFS(TableBOM[Product ID],$D$7,TableBOM[Item ID],$A18)>0)*($H$7>0),$C$7&", ","")&IF((COUNTIFS(TableBOM[Product ID],$D$8,TableBOM[Item ID],$A18)>0)*($H$8>0),$C$8&", ","")&IF((COUNTIFS(TableBOM[Product ID],$D$9,TableBOM[Item ID],$A18)>0)*($H$9>0),$C$9&", ","")&IF((COUNTIFS(TableBOM[Product ID],$D$10,TableBOM[Item ID],$A18)>0)*($H$10>0),$C$10&", ","")&IF((COUNTIFS(TableBOM[Product ID],$D$11,TableBOM[Item ID],$A18)>0)*($H$11>0),$C$11&", ","")&IF((COUNTIFS(TableBOM[Product ID],$D$12,TableBOM[Item ID],$A18)>0)*($H$12>0),$C$12&", ",""))>1,LEFT(IF((COUNTIFS(TableBOM[Product ID],$D$3,TableBOM[Item ID],$A18)>0)*($H$3>0),$C$3&", ","")&IF((COUNTIFS(TableBOM[Product ID],$D$4,TableBOM[Item ID],$A18)>0)*($H$4>0),$C$4&", ","")&IF((COUNTIFS(TableBOM[Product ID],$D$5,TableBOM[Item ID],$A18)>0)*($H$5>0),$C$5&", ","")&IF((COUNTIFS(TableBOM[Product ID],$D$6,TableBOM[Item ID],$A18)>0)*($H$6>0),$C$6&", ","")&IF((COUNTIFS(TableBOM[Product ID],$D$7,TableBOM[Item ID],$A18)>0)*($H$7>0),$C$7&", ","")&IF((COUNTIFS(TableBOM[Product ID],$D$8,TableBOM[Item ID],$A18)>0)*($H$8>0),$C$8&", ","")&IF((COUNTIFS(TableBOM[Product ID],$D$9,TableBOM[Item ID],$A18)>0)*($H$9>0),$C$9&", ","")&IF((COUNTIFS(TableBOM[Product ID],$D$10,TableBOM[Item ID],$A18)>0)*($H$10>0),$C$10&", ","")&IF((COUNTIFS(TableBOM[Product ID],$D$11,TableBOM[Item ID],$A18)>0)*($H$11>0),$C$11&", ","")&IF((COUNTIFS(TableBOM[Product ID],$D$12,TableBOM[Item ID],$A18)>0)*($H$12>0),$C$12&", ",""),LEN(IF((COUNTIFS(TableBOM[Product ID],$D$3,TableBOM[Item ID],$A18)>0)*($H$3>0),$C$3&", ","")&IF((COUNTIFS(TableBOM[Product ID],$D$4,TableBOM[Item ID],$A18)>0)*($H$4>0),$C$4&", ","")&IF((COUNTIFS(TableBOM[Product ID],$D$5,TableBOM[Item ID],$A18)>0)*($H$5>0),$C$5&", ","")&IF((COUNTIFS(TableBOM[Product ID],$D$6,TableBOM[Item ID],$A18)>0)*($H$6>0),$C$6&", ","")&IF((COUNTIFS(TableBOM[Product ID],$D$7,TableBOM[Item ID],$A18)>0)*($H$7>0),$C$7&", ","")&IF((COUNTIFS(TableBOM[Product ID],$D$8,TableBOM[Item ID],$A18)>0)*($H$8>0),$C$8&", ","")&IF((COUNTIFS(TableBOM[Product ID],$D$9,TableBOM[Item ID],$A18)>0)*($H$9>0),$C$9&", ","")&IF((COUNTIFS(TableBOM[Product ID],$D$10,TableBOM[Item ID],$A18)>0)*($H$10>0),$C$10&", ","")&IF((COUNTIFS(TableBOM[Product ID],$D$11,TableBOM[Item ID],$A18)>0)*($H$11>0),$C$11&", ","")&IF((COUNTIFS(TableBOM[Product ID],$D$12,TableBOM[Item ID],$A18)>0)*($H$12>0),$C$12&", ",""))-2),"") | I18: =IF(LEN(IF((COUNTIFS(TableBOM[Product ID],$D$3,TableBOM[Item ID],$A18)>0)*($H$3>0),$E$3&", ","")&IF((COUNTIFS(TableBOM[Product ID],$D$4,TableBOM[Item ID],$A18)>0)*($H$4>0),$E$4&", ","")&IF((COUNTIFS(TableBOM[Product ID],$D$5,TableBOM[Item ID],$A18)>0)*($H$5>0),$E$5&", ","")&IF((COUNTIFS(TableBOM[Product ID],$D$6,TableBOM[Item ID],$A18)>0)*($H$6>0),$E$6&", ","")&IF((COUNTIFS(TableBOM[Product ID],$D$7,TableBOM[Item ID],$A18)>0)*($H$7>0),$E$7&", ","")&IF((COUNTIFS(TableBOM[Product ID],$D$8,TableBOM[Item ID],$A18)>0)*($H$8>0),$E$8&", ","")&IF((COUNTIFS(TableBOM[Product ID],$D$9,TableBOM[Item ID],$A18)>0)*($H$9>0),$E$9&", ","")&IF((COUNTIFS(TableBOM[Product ID],$D$10,TableBOM[Item ID],$A18)>0)*($H$10>0),$E$10&", ","")&IF((COUNTIFS(TableBOM[Product ID],$D$11,TableBOM[Item ID],$A18)>0)*($H$11>0),$E$11&", ","")&IF((COUNTIFS(TableBOM[Product ID],$D$12,TableBOM[Item ID],$A18)>0)*($H$12>0),$E$12&", ",""))>1,LEFT(IF((COUNTIFS(TableBOM[Product ID],$D$3,TableBOM[Item ID],$A18)>0)*($H$3>0),$E$3&", ","")&IF((COUNTIFS(TableBOM[Product ID],$D$4,TableBOM[Item ID],$A18)>0)*($H$4>0),$E$4&", ","")&IF((COUNTIFS(TableBOM[Product ID],$D$5,TableBOM[Item ID],$A18)>0)*($H$5>0),$E$5&", ","")&IF((COUNTIFS(TableBOM[Product ID],$D$6,TableBOM[Item ID],$A18)>0)*($H$6>0),$E$6&", ","")&IF((COUNTIFS(TableBOM[Product ID],$D$7,TableBOM[Item ID],$A18)>0)*($H$7>0),$E$7&", ","")&IF((COUNTIFS(TableBOM[Product ID],$D$8,TableBOM[Item ID],$A18)>0)*($H$8>0),$E$8&", ","")&IF((COUNTIFS(TableBOM[Product ID],$D$9,TableBOM[Item ID],$A18)>0)*($H$9>0),$E$9&", ","")&IF((COUNTIFS(TableBOM[Product ID],$D$10,TableBOM[Item ID],$A18)>0)*($H$10>0),$E$10&", ","")&IF((COUNTIFS(TableBOM[Product ID],$D$11,TableBOM[Item ID],$A18)>0)*($H$11>0),$E$11&", ","")&IF((COUNTIFS(TableBOM[Product ID],$D$12,TableBOM[Item ID],$A18)>0)*($H$12>0),$E$12&", ",""),LEN(IF((COUNTIFS(TableBOM[Product ID],$D$3,TableBOM[Item ID],$A18)>0)*($H$3>0),$E$3&", ","")&IF((COUNTIFS(TableBOM[Product ID],$D$4,TableBOM[Item ID],$A18)>0)*($H$4>0),$E$4&", ","")&IF((COUNTIFS(TableBOM[Product ID],$D$5,TableBOM[Item ID],$A18)>0)*($H$5>0),$E$5&", ","")&IF((COUNTIFS(TableBOM[Product ID],$D$6,TableBOM[Item ID],$A18)>0)*($H$6>0),$E$6&", ","")&IF((COUNTIFS(TableBOM[Product ID],$D$7,TableBOM[Item ID],$A18)>0)*($H$7>0),$E$7&", ","")&IF((COUNTIFS(TableBOM[Product ID],$D$8,TableBOM[Item ID],$A18)>0)*($H$8>0),$E$8&", ","")&IF((COUNTIFS(TableBOM[Product ID],$D$9,TableBOM[Item ID],$A18)>0)*($H$9>0),$E$9&", ","")&IF((COUNTIFS(TableBOM[Product ID],$D$10,TableBOM[Item ID],$A18)>0)*($H$10>0),$E$10&", ","")&IF((COUNTIFS(TableBOM[Product ID],$D$11,TableBOM[Item ID],$A18)>0)*($H$11>0),$E$11&", ","")&IF((COUNTIFS(TableBOM[Product ID],$D$12,TableBOM[Item ID],$A18)>0)*($H$12>0),$E$12&", ",""))-2),"") | J18: =IF(E18=0,"Not needed",IF(G18<0,"SHORTAGE",IF(G18<F18*0.1,"LOW","OK"))) | K18: =IF(B18<>"CAP","",SUMPRODUCT((ISNUMBER(SEARCH("Cap Not Available",'FG Stock'!$H$4:$H$100)))*('FG Stock'!$I$4:$I$100=A18)*'FG Stock'!$F$4:$F$100)) | L18: =IF(E18=0,"",MAX(0,E18+IFERROR(K18*1,0)-F18))
A19: 25 | B19: SLUG | C19: 16X4.8 S/M | D19: kg | E19: =SUMPRODUCT((TableBOM[Item ID]=A19)*TableBOM[Per 1000 Units]*(1+TableBOM[Scrap %])*SUMIF($D$3:$D$12,TableBOM[Product ID],$H$3:$H$12)/1000) | F19: =IFERROR(INDEX(TableInventory[Store Balance],MATCH(A19,TableInventory[Item ID],0)),0)+IFERROR(INDEX(TableInventory[Work In Process],MATCH(A19,TableInventory[Item ID],0)),0) | G19: =F19-E19 | H19: =IF(LEN(IF((COUNTIFS(TableBOM[Product ID],$D$3,TableBOM[Item ID],$A19)>0)*($H$3>0),$C$3&", ","")&IF((COUNTIFS(TableBOM[Product ID],$D$4,TableBOM[Item ID],$A19)>0)*($H$4>0),$C$4&", ","")&IF((COUNTIFS(TableBOM[Product ID],$D$5,TableBOM[Item ID],$A19)>0)*($H$5>0),$C$5&", ","")&IF((COUNTIFS(TableBOM[Product ID],$D$6,TableBOM[Item ID],$A19)>0)*($H$6>0),$C$6&", ","")&IF((COUNTIFS(TableBOM[Product ID],$D$7,TableBOM[Item ID],$A19)>0)*($H$7>0),$C$7&", ","")&IF((COUNTIFS(TableBOM[Product ID],$D$8,TableBOM[Item ID],$A19)>0)*($H$8>0),$C$8&", ","")&IF((COUNTIFS(TableBOM[Product ID],$D$9,TableBOM[Item ID],$A19)>0)*($H$9>0),$C$9&", ","")&IF((COUNTIFS(TableBOM[Product ID],$D$10,TableBOM[Item ID],$A19)>0)*($H$10>0),$C$10&", ","")&IF((COUNTIFS(TableBOM[Product ID],$D$11,TableBOM[Item ID],$A19)>0)*($H$11>0),$C$11&", ","")&IF((COUNTIFS(TableBOM[Product ID],$D$12,TableBOM[Item ID],$A19)>0)*($H$12>0),$C$12&", ",""))>1,LEFT(IF((COUNTIFS(TableBOM[Product ID],$D$3,TableBOM[Item ID],$A19)>0)*($H$3>0),$C$3&", ","")&IF((COUNTIFS(TableBOM[Product ID],$D$4,TableBOM[Item ID],$A19)>0)*($H$4>0),$C$4&", ","")&IF((COUNTIFS(TableBOM[Product ID],$D$5,TableBOM[Item ID],$A19)>0)*($H$5>0),$C$5&", ","")&IF((COUNTIFS(TableBOM[Product ID],$D$6,TableBOM[Item ID],$A19)>0)*($H$6>0),$C$6&", ","")&IF((COUNTIFS(TableBOM[Product ID],$D$7,TableBOM[Item ID],$A19)>0)*($H$7>0),$C$7&", ","")&IF((COUNTIFS(TableBOM[Product ID],$D$8,TableBOM[Item ID],$A19)>0)*($H$8>0),$C$8&", ","")&IF((COUNTIFS(TableBOM[Product ID],$D$9,TableBOM[Item ID],$A19)>0)*($H$9>0),$C$9&", ","")&IF((COUNTIFS(TableBOM[Product ID],$D$10,TableBOM[Item ID],$A19)>0)*($H$10>0),$C$10&", ","")&IF((COUNTIFS(TableBOM[Product ID],$D$11,TableBOM[Item ID],$A19)>0)*($H$11>0),$C$11&", ","")&IF((COUNTIFS(TableBOM[Product ID],$D$12,TableBOM[Item ID],$A19)>0)*($H$12>0),$C$12&", ",""),LEN(IF((COUNTIFS(TableBOM[Product ID],$D$3,TableBOM[Item ID],$A19)>0)*($H$3>0),$C$3&", ","")&IF((COUNTIFS(TableBOM[Product ID],$D$4,TableBOM[Item ID],$A19)>0)*($H$4>0),$C$4&", ","")&IF((COUNTIFS(TableBOM[Product ID],$D$5,TableBOM[Item ID],$A19)>0)*($H$5>0),$C$5&", ","")&IF((COUNTIFS(TableBOM[Product ID],$D$6,TableBOM[Item ID],$A19)>0)*($H$6>0),$C$6&", ","")&IF((COUNTIFS(TableBOM[Product ID],$D$7,TableBOM[Item ID],$A19)>0)*($H$7>0),$C$7&", ","")&IF((COUNTIFS(TableBOM[Product ID],$D$8,TableBOM[Item ID],$A19)>0)*($H$8>0),$C$8&", ","")&IF((COUNTIFS(TableBOM[Product ID],$D$9,TableBOM[Item ID],$A19)>0)*($H$9>0),$C$9&", ","")&IF((COUNTIFS(TableBOM[Product ID],$D$10,TableBOM[Item ID],$A19)>0)*($H$10>0),$C$10&", ","")&IF((COUNTIFS(TableBOM[Product ID],$D$11,TableBOM[Item ID],$A19)>0)*($H$11>0),$C$11&", ","")&IF((COUNTIFS(TableBOM[Product ID],$D$12,TableBOM[Item ID],$A19)>0)*($H$12>0),$C$12&", ",""))-2),"") | I19: =IF(LEN(IF((COUNTIFS(TableBOM[Product ID],$D$3,TableBOM[Item ID],$A19)>0)*($H$3>0),$E$3&", ","")&IF((COUNTIFS(TableBOM[Product ID],$D$4,TableBOM[Item ID],$A19)>0)*($H$4>0),$E$4&", ","")&IF((COUNTIFS(TableBOM[Product ID],$D$5,TableBOM[Item ID],$A19)>0)*($H$5>0),$E$5&", ","")&IF((COUNTIFS(TableBOM[Product ID],$D$6,TableBOM[Item ID],$A19)>0)*($H$6>0),$E$6&", ","")&IF((COUNTIFS(TableBOM[Product ID],$D$7,TableBOM[Item ID],$A19)>0)*($H$7>0),$E$7&", ","")&IF((COUNTIFS(TableBOM[Product ID],$D$8,TableBOM[Item ID],$A19)>0)*($H$8>0),$E$8&", ","")&IF((COUNTIFS(TableBOM[Product ID],$D$9,TableBOM[Item ID],$A19)>0)*($H$9>0),$E$9&", ","")&IF((COUNTIFS(TableBOM[Product ID],$D$10,TableBOM[Item ID],$A19)>0)*($H$10>0),$E$10&", ","")&IF((COUNTIFS(TableBOM[Product ID],$D$11,TableBOM[Item ID],$A19)>0)*($H$11>0),$E$11&", ","")&IF((COUNTIFS(TableBOM[Product ID],$D$12,TableBOM[Item ID],$A19)>0)*($H$12>0),$E$12&", ",""))>1,LEFT(IF((COUNTIFS(TableBOM[Product ID],$D$3,TableBOM[Item ID],$A19)>0)*($H$3>0),$E$3&", ","")&IF((COUNTIFS(TableBOM[Product ID],$D$4,TableBOM[Item ID],$A19)>0)*($H$4>0),$E$4&", ","")&IF((COUNTIFS(TableBOM[Product ID],$D$5,TableBOM[Item ID],$A19)>0)*($H$5>0),$E$5&", ","")&IF((COUNTIFS(TableBOM[Product ID],$D$6,TableBOM[Item ID],$A19)>0)*($H$6>0),$E$6&", ","")&IF((COUNTIFS(TableBOM[Product ID],$D$7,TableBOM[Item ID],$A19)>0)*($H$7>0),$E$7&", ","")&IF((COUNTIFS(TableBOM[Product ID],$D$8,TableBOM[Item ID],$A19)>0)*($H$8>0),$E$8&", ","")&IF((COUNTIFS(TableBOM[Product ID],$D$9,TableBOM[Item ID],$A19)>0)*($H$9>0),$E$9&", ","")&IF((COUNTIFS(TableBOM[Product ID],$D$10,TableBOM[Item ID],$A19)>0)*($H$10>0),$E$10&", ","")&IF((COUNTIFS(TableBOM[Product ID],$D$11,TableBOM[Item ID],$A19)>0)*($H$11>0),$E$11&", ","")&IF((COUNTIFS(TableBOM[Product ID],$D$12,TableBOM[Item ID],$A19)>0)*($H$12>0),$E$12&", ",""),LEN(IF((COUNTIFS(TableBOM[Product ID],$D$3,TableBOM[Item ID],$A19)>0)*($H$3>0),$E$3&", ","")&IF((COUNTIFS(TableBOM[Product ID],$D$4,TableBOM[Item ID],$A19)>0)*($H$4>0),$E$4&", ","")&IF((COUNTIFS(TableBOM[Product ID],$D$5,TableBOM[Item ID],$A19)>0)*($H$5>0),$E$5&", ","")&IF((COUNTIFS(TableBOM[Product ID],$D$6,TableBOM[Item ID],$A19)>0)*($H$6>0),$E$6&", ","")&IF((COUNTIFS(TableBOM[Product ID],$D$7,TableBOM[Item ID],$A19)>0)*($H$7>0),$E$7&", ","")&IF((COUNTIFS(TableBOM[Product ID],$D$8,TableBOM[Item ID],$A19)>0)*($H$8>0),$E$8&", ","")&IF((COUNTIFS(TableBOM[Product ID],$D$9,TableBOM[Item ID],$A19)>0)*($H$9>0),$E$9&", ","")&IF((COUNTIFS(TableBOM[Product ID],$D$10,TableBOM[Item ID],$A19)>0)*($H$10>0),$E$10&", ","")&IF((COUNTIFS(TableBOM[Product ID],$D$11,TableBOM[Item ID],$A19)>0)*($H$11>0),$E$11&", ","")&IF((COUNTIFS(TableBOM[Product ID],$D$12,TableBOM[Item ID],$A19)>0)*($H$12>0),$E$12&", ",""))-2),"") | J19: =IF(E19=0,"Not needed",IF(G19<0,"SHORTAGE",IF(G19<F19*0.1,"LOW","OK"))) | K19: =IF(B19<>"CAP","",SUMPRODUCT((ISNUMBER(SEARCH("Cap Not Available",'FG Stock'!$H$4:$H$100)))*('FG Stock'!$I$4:$I$100=A19)*'FG Stock'!$F$4:$F$100)) | L19: =IF(E19=0,"",MAX(0,E19+IFERROR(K19*1,0)-F19))
A20: 22 | B20: SLUG | C20: 19X4.2 | D20: kg | E20: =SUMPRODUCT((TableBOM[Item ID]=A20)*TableBOM[Per 1000 Units]*(1+TableBOM[Scrap %])*SUMIF($D$3:$D$12,TableBOM[Product ID],$H$3:$H$12)/1000) | F20: =IFERROR(INDEX(TableInventory[Store Balance],MATCH(A20,TableInventory[Item ID],0)),0)+IFERROR(INDEX(TableInventory[Work In Process],MATCH(A20,TableInventory[Item ID],0)),0) | G20: =F20-E20 | H20: =IF(LEN(IF((COUNTIFS(TableBOM[Product ID],$D$3,TableBOM[Item ID],$A20)>0)*($H$3>0),$C$3&", ","")&IF((COUNTIFS(TableBOM[Product ID],$D$4,TableBOM[Item ID],$A20)>0)*($H$4>0),$C$4&", ","")&IF((COUNTIFS(TableBOM[Product ID],$D$5,TableBOM[Item ID],$A20)>0)*($H$5>0),$C$5&", ","")&IF((COUNTIFS(TableBOM[Product ID],$D$6,TableBOM[Item ID],$A20)>0)*($H$6>0),$C$6&", ","")&IF((COUNTIFS(TableBOM[Product ID],$D$7,TableBOM[Item ID],$A20)>0)*($H$7>0),$C$7&", ","")&IF((COUNTIFS(TableBOM[Product ID],$D$8,TableBOM[Item ID],$A20)>0)*($H$8>0),$C$8&", ","")&IF((COUNTIFS(TableBOM[Product ID],$D$9,TableBOM[Item ID],$A20)>0)*($H$9>0),$C$9&", ","")&IF((COUNTIFS(TableBOM[Product ID],$D$10,TableBOM[Item ID],$A20)>0)*($H$10>0),$C$10&", ","")&IF((COUNTIFS(TableBOM[Product ID],$D$11,TableBOM[Item ID],$A20)>0)*($H$11>0),$C$11&", ","")&IF((COUNTIFS(TableBOM[Product ID],$D$12,TableBOM[Item ID],$A20)>0)*($H$12>0),$C$12&", ",""))>1,LEFT(IF((COUNTIFS(TableBOM[Product ID],$D$3,TableBOM[Item ID],$A20)>0)*($H$3>0),$C$3&", ","")&IF((COUNTIFS(TableBOM[Product ID],$D$4,TableBOM[Item ID],$A20)>0)*($H$4>0),$C$4&", ","")&IF((COUNTIFS(TableBOM[Product ID],$D$5,TableBOM[Item ID],$A20)>0)*($H$5>0),$C$5&", ","")&IF((COUNTIFS(TableBOM[Product ID],$D$6,TableBOM[Item ID],$A20)>0)*($H$6>0),$C$6&", ","")&IF((COUNTIFS(TableBOM[Product ID],$D$7,TableBOM[Item ID],$A20)>0)*($H$7>0),$C$7&", ","")&IF((COUNTIFS(TableBOM[Product ID],$D$8,TableBOM[Item ID],$A20)>0)*($H$8>0),$C$8&", ","")&IF((COUNTIFS(TableBOM[Product ID],$D$9,TableBOM[Item ID],$A20)>0)*($H$9>0),$C$9&", ","")&IF((COUNTIFS(TableBOM[Product ID],$D$10,TableBOM[Item ID],$A20)>0)*($H$10>0),$C$10&", ","")&IF((COUNTIFS(TableBOM[Product ID],$D$11,TableBOM[Item ID],$A20)>0)*($H$11>0),$C$11&", ","")&IF((COUNTIFS(TableBOM[Product ID],$D$12,TableBOM[Item ID],$A20)>0)*($H$12>0),$C$12&", ",""),LEN(IF((COUNTIFS(TableBOM[Product ID],$D$3,TableBOM[Item ID],$A20)>0)*($H$3>0),$C$3&", ","")&IF((COUNTIFS(TableBOM[Product ID],$D$4,TableBOM[Item ID],$A20)>0)*($H$4>0),$C$4&", ","")&IF((COUNTIFS(TableBOM[Product ID],$D$5,TableBOM[Item ID],$A20)>0)*($H$5>0),$C$5&", ","")&IF((COUNTIFS(TableBOM[Product ID],$D$6,TableBOM[Item ID],$A20)>0)*($H$6>0),$C$6&", ","")&IF((COUNTIFS(TableBOM[Product ID],$D$7,TableBOM[Item ID],$A20)>0)*($H$7>0),$C$7&", ","")&IF((COUNTIFS(TableBOM[Product ID],$D$8,TableBOM[Item ID],$A20)>0)*($H$8>0),$C$8&", ","")&IF((COUNTIFS(TableBOM[Product ID],$D$9,TableBOM[Item ID],$A20)>0)*($H$9>0),$C$9&", ","")&IF((COUNTIFS(TableBOM[Product ID],$D$10,TableBOM[Item ID],$A20)>0)*($H$10>0),$C$10&", ","")&IF((COUNTIFS(TableBOM[Product ID],$D$11,TableBOM[Item ID],$A20)>0)*($H$11>0),$C$11&", ","")&IF((COUNTIFS(TableBOM[Product ID],$D$12,TableBOM[Item ID],$A20)>0)*($H$12>0),$C$12&", ",""))-2),"") | I20: =IF(LEN(IF((COUNTIFS(TableBOM[Product ID],$D$3,TableBOM[Item ID],$A20)>0)*($H$3>0),$E$3&", ","")&IF((COUNTIFS(TableBOM[Product ID],$D$4,TableBOM[Item ID],$A20)>0)*($H$4>0),$E$4&", ","")&IF((COUNTIFS(TableBOM[Product ID],$D$5,TableBOM[Item ID],$A20)>0)*($H$5>0),$E$5&", ","")&IF((COUNTIFS(TableBOM[Product ID],$D$6,TableBOM[Item ID],$A20)>0)*($H$6>0),$E$6&", ","")&IF((COUNTIFS(TableBOM[Product ID],$D$7,TableBOM[Item ID],$A20)>0)*($H$7>0),$E$7&", ","")&IF((COUNTIFS(TableBOM[Product ID],$D$8,TableBOM[Item ID],$A20)>0)*($H$8>0),$E$8&", ","")&IF((COUNTIFS(TableBOM[Product ID],$D$9,TableBOM[Item ID],$A20)>0)*($H$9>0),$E$9&", ","")&IF((COUNTIFS(TableBOM[Product ID],$D$10,TableBOM[Item ID],$A20)>0)*($H$10>0),$E$10&", ","")&IF((COUNTIFS(TableBOM[Product ID],$D$11,TableBOM[Item ID],$A20)>0)*($H$11>0),$E$11&", ","")&IF((COUNTIFS(TableBOM[Product ID],$D$12,TableBOM[Item ID],$A20)>0)*($H$12>0),$E$12&", ",""))>1,LEFT(IF((COUNTIFS(TableBOM[Product ID],$D$3,TableBOM[Item ID],$A20)>0)*($H$3>0),$E$3&", ","")&IF((COUNTIFS(TableBOM[Product ID],$D$4,TableBOM[Item ID],$A20)>0)*($H$4>0),$E$4&", ","")&IF((COUNTIFS(TableBOM[Product ID],$D$5,TableBOM[Item ID],$A20)>0)*($H$5>0),$E$5&", ","")&IF((COUNTIFS(TableBOM[Product ID],$D$6,TableBOM[Item ID],$A20)>0)*($H$6>0),$E$6&", ","")&IF((COUNTIFS(TableBOM[Product ID],$D$7,TableBOM[Item ID],$A20)>0)*($H$7>0),$E$7&", ","")&IF((COUNTIFS(TableBOM[Product ID],$D$8,TableBOM[Item ID],$A20)>0)*($H$8>0),$E$8&", ","")&IF((COUNTIFS(TableBOM[Product ID],$D$9,TableBOM[Item ID],$A20)>0)*($H$9>0),$E$9&", ","")&IF((COUNTIFS(TableBOM[Product ID],$D$10,TableBOM[Item ID],$A20)>0)*($H$10>0),$E$10&", ","")&IF((COUNTIFS(TableBOM[Product ID],$D$11,TableBOM[Item ID],$A20)>0)*($H$11>0),$E$11&", ","")&IF((COUNTIFS(TableBOM[Product ID],$D$12,TableBOM[Item ID],$A20)>0)*($H$12>0),$E$12&", ",""),LEN(IF((COUNTIFS(TableBOM[Product ID],$D$3,TableBOM[Item ID],$A20)>0)*($H$3>0),$E$3&", ","")&IF((COUNTIFS(TableBOM[Product ID],$D$4,TableBOM[Item ID],$A20)>0)*($H$4>0),$E$4&", ","")&IF((COUNTIFS(TableBOM[Product ID],$D$5,TableBOM[Item ID],$A20)>0)*($H$5>0),$E$5&", ","")&IF((COUNTIFS(TableBOM[Product ID],$D$6,TableBOM[Item ID],$A20)>0)*($H$6>0),$E$6&", ","")&IF((COUNTIFS(TableBOM[Product ID],$D$7,TableBOM[Item ID],$A20)>0)*($H$7>0),$E$7&", ","")&IF((COUNTIFS(TableBOM[Product ID],$D$8,TableBOM[Item ID],$A20)>0)*($H$8>0),$E$8&", ","")&IF((COUNTIFS(TableBOM[Product ID],$D$9,TableBOM[Item ID],$A20)>0)*($H$9>0),$E$9&", ","")&IF((COUNTIFS(TableBOM[Product ID],$D$10,TableBOM[Item ID],$A20)>0)*($H$10>0),$E$10&", ","")&IF((COUNTIFS(TableBOM[Product ID],$D$11,TableBOM[Item ID],$A20)>0)*($H$11>0),$E$11&", ","")&IF((COUNTIFS(TableBOM[Product ID],$D$12,TableBOM[Item ID],$A20)>0)*($H$12>0),$E$12&", ",""))-2),"") | J20: =IF(E20=0,"Not needed",IF(G20<0,"SHORTAGE",IF(G20<F20*0.1,"LOW","OK"))) | K20: =IF(B20<>"CAP","",SUMPRODUCT((ISNUMBER(SEARCH("Cap Not Available",'FG Stock'!$H$4:$H$100)))*('FG Stock'!$I$4:$I$100=A20)*'FG Stock'!$F$4:$F$100)) | L20: =IF(E20=0,"",MAX(0,E20+IFERROR(K20*1,0)-F20))
A21: 19 | B21: SLUG | C21: 19X4.5 S/M | D21: kg | E21: =SUMPRODUCT((TableBOM[Item ID]=A21)*TableBOM[Per 1000 Units]*(1+TableBOM[Scrap %])*SUMIF($D$3:$D$12,TableBOM[Product ID],$H$3:$H$12)/1000) | F21: =IFERROR(INDEX(TableInventory[Store Balance],MATCH(A21,TableInventory[Item ID],0)),0)+IFERROR(INDEX(TableInventory[Work In Process],MATCH(A21,TableInventory[Item ID],0)),0) | G21: =F21-E21 | H21: =IF(LEN(IF((COUNTIFS(TableBOM[Product ID],$D$3,TableBOM[Item ID],$A21)>0)*($H$3>0),$C$3&", ","")&IF((COUNTIFS(TableBOM[Product ID],$D$4,TableBOM[Item ID],$A21)>0)*($H$4>0),$C$4&", ","")&IF((COUNTIFS(TableBOM[Product ID],$D$5,TableBOM[Item ID],$A21)>0)*($H$5>0),$C$5&", ","")&IF((COUNTIFS(TableBOM[Product ID],$D$6,TableBOM[Item ID],$A21)>0)*($H$6>0),$C$6&", ","")&IF((COUNTIFS(TableBOM[Product ID],$D$7,TableBOM[Item ID],$A21)>0)*($H$7>0),$C$7&", ","")&IF((COUNTIFS(TableBOM[Product ID],$D$8,TableBOM[Item ID],$A21)>0)*($H$8>0),$C$8&", ","")&IF((COUNTIFS(TableBOM[Product ID],$D$9,TableBOM[Item ID],$A21)>0)*($H$9>0),$C$9&", ","")&IF((COUNTIFS(TableBOM[Product ID],$D$10,TableBOM[Item ID],$A21)>0)*($H$10>0),$C$10&", ","")&IF((COUNTIFS(TableBOM[Product ID],$D$11,TableBOM[Item ID],$A21)>0)*($H$11>0),$C$11&", ","")&IF((COUNTIFS(TableBOM[Product ID],$D$12,TableBOM[Item ID],$A21)>0)*($H$12>0),$C$12&", ",""))>1,LEFT(IF((COUNTIFS(TableBOM[Product ID],$D$3,TableBOM[Item ID],$A21)>0)*($H$3>0),$C$3&", ","")&IF((COUNTIFS(TableBOM[Product ID],$D$4,TableBOM[Item ID],$A21)>0)*($H$4>0),$C$4&", ","")&IF((COUNTIFS(TableBOM[Product ID],$D$5,TableBOM[Item ID],$A21)>0)*($H$5>0),$C$5&", ","")&IF((COUNTIFS(TableBOM[Product ID],$D$6,TableBOM[Item ID],$A21)>0)*($H$6>0),$C$6&", ","")&IF((COUNTIFS(TableBOM[Product ID],$D$7,TableBOM[Item ID],$A21)>0)*($H$7>0),$C$7&", ","")&IF((COUNTIFS(TableBOM[Product ID],$D$8,TableBOM[Item ID],$A21)>0)*($H$8>0),$C$8&", ","")&IF((COUNTIFS(TableBOM[Product ID],$D$9,TableBOM[Item ID],$A21)>0)*($H$9>0),$C$9&", ","")&IF((COUNTIFS(TableBOM[Product ID],$D$10,TableBOM[Item ID],$A21)>0)*($H$10>0),$C$10&", ","")&IF((COUNTIFS(TableBOM[Product ID],$D$11,TableBOM[Item ID],$A21)>0)*($H$11>0),$C$11&", ","")&IF((COUNTIFS(TableBOM[Product ID],$D$12,TableBOM[Item ID],$A21)>0)*($H$12>0),$C$12&", ",""),LEN(IF((COUNTIFS(TableBOM[Product ID],$D$3,TableBOM[Item ID],$A21)>0)*($H$3>0),$C$3&", ","")&IF((COUNTIFS(TableBOM[Product ID],$D$4,TableBOM[Item ID],$A21)>0)*($H$4>0),$C$4&", ","")&IF((COUNTIFS(TableBOM[Product ID],$D$5,TableBOM[Item ID],$A21)>0)*($H$5>0),$C$5&", ","")&IF((COUNTIFS(TableBOM[Product ID],$D$6,TableBOM[Item ID],$A21)>0)*($H$6>0),$C$6&", ","")&IF((COUNTIFS(TableBOM[Product ID],$D$7,TableBOM[Item ID],$A21)>0)*($H$7>0),$C$7&", ","")&IF((COUNTIFS(TableBOM[Product ID],$D$8,TableBOM[Item ID],$A21)>0)*($H$8>0),$C$8&", ","")&IF((COUNTIFS(TableBOM[Product ID],$D$9,TableBOM[Item ID],$A21)>0)*($H$9>0),$C$9&", ","")&IF((COUNTIFS(TableBOM[Product ID],$D$10,TableBOM[Item ID],$A21)>0)*($H$10>0),$C$10&", ","")&IF((COUNTIFS(TableBOM[Product ID],$D$11,TableBOM[Item ID],$A21)>0)*($H$11>0),$C$11&", ","")&IF((COUNTIFS(TableBOM[Product ID],$D$12,TableBOM[Item ID],$A21)>0)*($H$12>0),$C$12&", ",""))-2),"") | I21: =IF(LEN(IF((COUNTIFS(TableBOM[Product ID],$D$3,TableBOM[Item ID],$A21)>0)*($H$3>0),$E$3&", ","")&IF((COUNTIFS(TableBOM[Product ID],$D$4,TableBOM[Item ID],$A21)>0)*($H$4>0),$E$4&", ","")&IF((COUNTIFS(TableBOM[Product ID],$D$5,TableBOM[Item ID],$A21)>0)*($H$5>0),$E$5&", ","")&IF((COUNTIFS(TableBOM[Product ID],$D$6,TableBOM[Item ID],$A21)>0)*($H$6>0),$E$6&", ","")&IF((COUNTIFS(TableBOM[Product ID],$D$7,TableBOM[Item ID],$A21)>0)*($H$7>0),$E$7&", ","")&IF((COUNTIFS(TableBOM[Product ID],$D$8,TableBOM[Item ID],$A21)>0)*($H$8>0),$E$8&", ","")&IF((COUNTIFS(TableBOM[Product ID],$D$9,TableBOM[Item ID],$A21)>0)*($H$9>0),$E$9&", ","")&IF((COUNTIFS(TableBOM[Product ID],$D$10,TableBOM[Item ID],$A21)>0)*($H$10>0),$E$10&", ","")&IF((COUNTIFS(TableBOM[Product ID],$D$11,TableBOM[Item ID],$A21)>0)*($H$11>0),$E$11&", ","")&IF((COUNTIFS(TableBOM[Product ID],$D$12,TableBOM[Item ID],$A21)>0)*($H$12>0),$E$12&", ",""))>1,LEFT(IF((COUNTIFS(TableBOM[Product ID],$D$3,TableBOM[Item ID],$A21)>0)*($H$3>0),$E$3&", ","")&IF((COUNTIFS(TableBOM[Product ID],$D$4,TableBOM[Item ID],$A21)>0)*($H$4>0),$E$4&", ","")&IF((COUNTIFS(TableBOM[Product ID],$D$5,TableBOM[Item ID],$A21)>0)*($H$5>0),$E$5&", ","")&IF((COUNTIFS(TableBOM[Product ID],$D$6,TableBOM[Item ID],$A21)>0)*($H$6>0),$E$6&", ","")&IF((COUNTIFS(TableBOM[Product ID],$D$7,TableBOM[Item ID],$A21)>0)*($H$7>0),$E$7&", ","")&IF((COUNTIFS(TableBOM[Product ID],$D$8,TableBOM[Item ID],$A21)>0)*($H$8>0),$E$8&", ","")&IF((COUNTIFS(TableBOM[Product ID],$D$9,TableBOM[Item ID],$A21)>0)*($H$9>0),$E$9&", ","")&IF((COUNTIFS(TableBOM[Product ID],$D$10,TableBOM[Item ID],$A21)>0)*($H$10>0),$E$10&", ","")&IF((COUNTIFS(TableBOM[Product ID],$D$11,TableBOM[Item ID],$A21)>0)*($H$11>0),$E$11&", ","")&IF((COUNTIFS(TableBOM[Product ID],$D$12,TableBOM[Item ID],$A21)>0)*($H$12>0),$E$12&", ",""),LEN(IF((COUNTIFS(TableBOM[Product ID],$D$3,TableBOM[Item ID],$A21)>0)*($H$3>0),$E$3&", ","")&IF((COUNTIFS(TableBOM[Product ID],$D$4,TableBOM[Item ID],$A21)>0)*($H$4>0),$E$4&", ","")&IF((COUNTIFS(TableBOM[Product ID],$D$5,TableBOM[Item ID],$A21)>0)*($H$5>0),$E$5&", ","")&IF((COUNTIFS(TableBOM[Product ID],$D$6,TableBOM[Item ID],$A21)>0)*($H$6>0),$E$6&", ","")&IF((COUNTIFS(TableBOM[Product ID],$D$7,TableBOM[Item ID],$A21)>0)*($H$7>0),$E$7&", ","")&IF((COUNTIFS(TableBOM[Product ID],$D$8,TableBOM[Item ID],$A21)>0)*($H$8>0),$E$8&", ","")&IF((COUNTIFS(TableBOM[Product ID],$D$9,TableBOM[Item ID],$A21)>0)*($H$9>0),$E$9&", ","")&IF((COUNTIFS(TableBOM[Product ID],$D$10,TableBOM[Item ID],$A21)>0)*($H$10>0),$E$10&", ","")&IF((COUNTIFS(TableBOM[Product ID],$D$11,TableBOM[Item ID],$A21)>0)*($H$11>0),$E$11&", ","")&IF((COUNTIFS(TableBOM[Product ID],$D$12,TableBOM[Item ID],$A21)>0)*($H$12>0),$E$12&", ",""))-2),"") | J21: SLUG in Transit | K21: =IF(B21<>"CAP","",SUMPRODUCT((ISNUMBER(SEARCH("Cap Not Available",'FG Stock'!$H$4:$H$100)))*('FG Stock'!$I$4:$I$100=A21)*'FG Stock'!$F$4:$F$100)) | L21: =IF(E21=0,"",MAX(0,E21+IFERROR(K21*1,0)-F21))
