Workbook

Sheet Tubex_Dashboard
B2: TUBEX — May 2026 Month to Date Report
B3: Report Date (Yesterday's Production): | H3: =TODAY()-1 -> 46156
B5: TUBE — YESTERDAY | D5: TUBE — MTD | G5: TUBE — REJECT % | J5: Dispatch — MTD | M5: Press & Printing Downtime — MTD
B6: =SUMPRODUCT((Production_Log!$A$3:$A$8963=MAX(Production_Log!$A$3:$A$8963))*(LEFT(Production_Log!$B$3:$B$8963,5)="Print")*(ISERROR(SEARCH("(Varnish)",Production_Log!$D$3:$D$8963)))*Production_Log!$H$3:$H$8963) -> 8640 | D6: =SUMIF($B$11:$B$61,"TUBE",$H$11:$H$61) -> 239880 | G6: {=IFERROR(SUMPRODUCT((Production_Log!$F$3:$F$8963<>0)*(LEFT(Production_Log!$B$3:$B$8963,5)="Print")*(ISERROR(SEARCH("(Varnish)",Production_Log!$D$3:$D$8963)))*Production_Log!$I$3:$I$8963)/SUMPRODUCT((Production_Log!$F$3:$F$8963<>0)*(LEFT(Production_Log!$B$3:$B$8963,5)="Print")*(ISERROR(SEARCH("(Varnish)",Production_Log!$D$3:$D$8963)))*(Production_Log!$H$3:$H$8963+Production_Log!$I$3:$I$8963)),"-")} -> 0.033092829 | J6: =SUMIF($B$11:$B$61,"TUBE",$K$11:$K$61) -> 260603 | M6: Category | N6: Hours (MTD) | O6: % Share
B7: PET — YESTERDAY | D7: PET — MTD | G7: PET — REJECT % | J7: Dispatch — MTD | M7: =IFERROR(INDEX($S$9:$S$25,MATCH(LARGE($U$9:$U$25,1),$U$9:$U$25,0)),"") -> Operations | N7: =(IFERROR(INDEX($T$9:$T$25,MATCH(LARGE($U$9:$U$25,1),$U$9:$U$25,0)),""))/60 -> 79.333333 | O7: =IFERROR(N7/$N$15,"") -> 0.32918396
B8: =SUMPRODUCT((Production_Log!$A$3:$A$8963=MAX(Production_Log!$A$3:$A$8963))*(Production_Log!$B$3:$B$8963="PF Machine")*Production_Log!$H$3:$H$8963) -> 0 | D8: =SUMIF($B$11:$B$61,"PET",$H$11:$H$61) -> 44640 | G8: {=IFERROR(SUMPRODUCT((Production_Log!$B$3:$B$8963="PF Machine")*Production_Log!$I$3:$I$8963)/SUMPRODUCT((Production_Log!$B$3:$B$8963="PF Machine")*(Production_Log!$H$3:$H$8963+Production_Log!$I$3:$I$8963)),0)} -> 0.051826678 | J8: =SUMIF($B$11:$B$61,"PET",$K$11:$K$61) -> 107840 | M8: =IFERROR(INDEX($S$9:$S$25,MATCH(LARGE($U$9:$U$25,2),$U$9:$U$25,0)),"") -> Changeover | N8: =IFERROR(INDEX($T$9:$T$25,MATCH(LARGE($U$9:$U$25,2),$U$9:$U$25,0)),"")/60 -> 75.166667 | O8: =IFERROR(N8/$N$15,"") -> 0.31189488
B9: Summary of Production & Dispatch - MTD | M9: =IFERROR(INDEX($S$9:$S$25,MATCH(LARGE($U$9:$U$25,3),$U$9:$U$25,0)),"") -> Material Shortage | N9: =IFERROR(INDEX($T$9:$T$25,MATCH(LARGE($U$9:$U$25,3),$U$9:$U$25,0)),"")/60 -> 49.5 | O9: =IFERROR(N9/$N$15,"") -> 0.20539419 | S9: Mechanical | T9: =SUMPRODUCT((MONTH(Production_Log!$A$3:$A$8963)=MONTH(TODAY()))*(YEAR(Production_Log!$A$3:$A$8963)=YEAR(TODAY()))*Production_Log!$K$3:$K$8963) -> 1660 | U9: =T9+0.00001 -> 1660
B10: Type | C10: Customer | D10: Product Name | E10: Dia | F10: Prod ID | G10: Orders | H10: MTD Produced | I10: Remaining | J10: MTD Compliance | K10: Dispatch | M10: =IFERROR(INDEX($S$9:$S$25,MATCH(LARGE($U$9:$U$25,4),$U$9:$U$25,0)),"") -> Mechanical | N10: =IFERROR(INDEX($T$9:$T$25,MATCH(LARGE($U$9:$U$25,4),$U$9:$U$25,0)),"")/60 -> 27.666667 | O10: =IFERROR(N10/$N$15,"") -> 0.11479945 | S10: Electrical | T10: =SUMPRODUCT((MONTH(Production_Log!$A$3:$A$8963)=MONTH(TODAY()))*(YEAR(Production_Log!$A$3:$A$8963)=YEAR(TODAY()))*Production_Log!$L$3:$L$8963) -> 30 | U10: =T10+0.00002 -> 30.00002
B11: TUBE | C11: Brookes Pharma Private Limited | D11: ECZEMUS OINTMENT 0.03% 10G | E11: 16 | F11: 6561 | G11: 25000 | H11: =SUMPRODUCT((Production_Log!$F$3:$F$8963=F11)*(LEFT(Production_Log!$B$3:$B$8963,5)="Print")*(ISERROR(SEARCH("(Varnish)",Production_Log!$D$3:$D$8963)))*Production_Log!$H$3:$H$8963) -> 0 | I11: =G11-H11 -> 25000 | J11: =IF(G11=0,"-",H11/G11) -> 0 | M11: =IFERROR(INDEX($S$9:$S$25,MATCH(LARGE($U$9:$U$25,5),$U$9:$U$25,0)),"") -> Power Shutdown | N11: =IFERROR(INDEX($T$9:$T$25,MATCH(LARGE($U$9:$U$25,5),$U$9:$U$25,0)),"")/60 -> 8.8333333 | O11: =IFERROR(N11/$N$15,"") -> 0.036652835 | S11: Workers Shortage | T11: =SUMPRODUCT((MONTH(Production_Log!$A$3:$A$8963)=MONTH(TODAY()))*(YEAR(Production_Log!$A$3:$A$8963)=YEAR(TODAY()))*Production_Log!$R$3:$R$8963) -> 0 | U11: =T11+0.00003 -> 3e-05
B12: TUBE | C12: Samsol International Private Limited | D12: S-43 DIA 19MM | E12: 19 | F12: 6623 | G12: 0 | H12: =SUMPRODUCT((Production_Log!$F$3:$F$8963=F12)*(LEFT(Production_Log!$B$3:$B$8963,5)="Print")*(ISERROR(SEARCH("(Varnish)",Production_Log!$D$3:$D$8963)))*(MONTH(Production_Log!$A$3:$A$8963)=MONTH(TODAY()))*(YEAR(Production_Log!$A$3:$A$8963)=YEAR(TODAY()))*Production_Log!$H$3:$H$8963) -> 0 | I12: =G12-H12 -> 0 | J12: =IF(G12=0,"-",H12/G12) -> - | K12: 24696 | M12: =IFERROR(INDEX($S$9:$S$25,MATCH(LARGE($U$9:$U$25,8),$U$9:$U$25,0)),"") -> Workers Shortage | N12: =IFERROR(INDEX($T$9:$T$25,MATCH(LARGE($U$9:$U$25,8),$U$9:$U$25,0)),"")/60 -> 0 | O12: =IFERROR(N12/$N$15,"") -> 0
B13: TUBE | C13: Samsol International Private Limited | D13: S-45 DIA 19MM | E13: 19 | F13: 6624 | G13: 10888 | H13: =SUMPRODUCT((Production_Log!$F$3:$F$8963=F13)*(LEFT(Production_Log!$B$3:$B$8963,5)="Print")*(ISERROR(SEARCH("(Varnish)",Production_Log!$D$3:$D$8963)))*Production_Log!$H$3:$H$8963) -> 0 | I13: =G13-H13 -> 10888 | J13: =IF(G13=0,"-",H13/G13) -> 0 | K13: 8232 | M13: =IFERROR(INDEX($S$9:$S$25,MATCH(LARGE($U$9:$U$25,6),$U$9:$U$25,0)),"") -> Electrical | N13: =IFERROR(INDEX($T$9:$T$25,MATCH(LARGE($U$9:$U$25,6),$U$9:$U$25,0)),"")/60 -> 0.5 | O13: =IFERROR(N13/$N$15,"") -> 0.0020746888 | S13: Power Shutdown | T13: =SUMPRODUCT((MONTH(Production_Log!$A$3:$A$8963)=MONTH(TODAY()))*(YEAR(Production_Log!$A$3:$A$8963)=YEAR(TODAY()))*Production_Log!$P$3:$P$8963) -> 530 | U13: =T13+0.00004 -> 530.00004
B14: TUBE | C14: Brookes Pharma Private Limited | D14: PHLOGIN GEL 20G | E14: 19 | F14: 6559 | G14: 0 | H14: =SUMPRODUCT((Production_Log!$F$3:$F$8963=F14)*(LEFT(Production_Log!$B$3:$B$8963,5)="Print")*(ISERROR(SEARCH("(Varnish)",Production_Log!$D$3:$D$8963)))*(MONTH(Production_Log!$A$3:$A$8963)=MONTH(TODAY()))*(YEAR(Production_Log!$A$3:$A$8963)=YEAR(TODAY()))*Production_Log!$H$3:$H$8963) -> 0 | I14: =G14-H14 -> 0 | J14: =IF(G14=0,"-",H14/G14) -> - | K14: 35280 | M14: =IFERROR(INDEX($S$9:$S$25,MATCH(LARGE($U$9:$U$25,7),$U$9:$U$25,0)),"") -> Gas Shutdown | N14: =IFERROR(INDEX($T$9:$T$25,MATCH(LARGE($U$9:$U$25,7),$U$9:$U$25,0)),"")/60 -> 0 | O14: =IFERROR(N14/$N$15,"") -> 0
B15: TUBE | C15: Mablay Beauty PVT LTD. | D15: VINCE HIS BEARD & MUSTACHE COLOR | E15: 20.5 | F15: 6077 | G15: 23970 | H15: =SUMPRODUCT((Production_Log!$F$3:$F$8963=F15)*(LEFT(Production_Log!$B$3:$B$8963,5)="Print")*(ISERROR(SEARCH("(Varnish)",Production_Log!$D$3:$D$8963)))*Production_Log!$H$3:$H$8963) -> 23970 | I15: =G15-H15 -> 0 | J15: =IF(G15=0,"-",H15/G15) -> 1 | M15: TOTAL | N15: =SUM($T$9:$T$25)/60 -> 241 | O15: 100% | S15: Material Shortage | T15: =SUMPRODUCT((MONTH(Production_Log!$A$3:$A$8963)=MONTH(TODAY()))*(YEAR(Production_Log!$A$3:$A$8963)=YEAR(TODAY()))*Production_Log!$M$3:$M$8963) -> 2970 | U15: =T15+0.00005 -> 2970.0001
B16: TUBE | C16: Mablay Beauty PVT LTD. | D16: HIS ONLY HAIR COLOR CREAM 40GM | E16: 25 | F16: 6228 | G16: 21840 | H16: =SUMPRODUCT((Production_Log!$F$3:$F$8963=F16)*(LEFT(Production_Log!$B$3:$B$8963,5)="Print")*(ISERROR(SEARCH("(Varnish)",Production_Log!$D$3:$D$8963)))*Production_Log!$H$3:$H$8963) -> 21840 | I16: =G16-H16 -> 0 | J16: =IF(G16=0,"-",H16/G16) -> 1 | S16: Gas Shutdown | T16: =SUMPRODUCT((MONTH(Production_Log!$A$3:$A$8963)=MONTH(TODAY()))*(YEAR(Production_Log!$A$3:$A$8963)=YEAR(TODAY()))*Production_Log!$Q$3:$Q$8963) -> 0 | U16: =T16+0.00006 -> 6e-05
B17: TUBE | C17: Samsol International Private Limited | D17: S 43 25MM | E17: 25 | F17: 3447 | G17: 38976 | H17: =SUMPRODUCT((Production_Log!$F$3:$F$8963=F17)*(LEFT(Production_Log!$B$3:$B$8963,5)="Print")*(ISERROR(SEARCH("(Varnish)",Production_Log!$D$3:$D$8963)))*Production_Log!$H$3:$H$8963) -> 38976 | I17: =G17-H17 -> 0 | J17: =IF(G17=0,"-",H17/G17) -> 1 | S17: Changeover | T17: =SUMPRODUCT((MONTH(Production_Log!$A$3:$A$8963)=MONTH(TODAY()))*(YEAR(Production_Log!$A$3:$A$8963)=YEAR(TODAY()))*Production_Log!$N$3:$N$8963) -> 4510 | U17: =T17+0.00007 -> 4510.0001
B18: TUBE | C18: Mablay Beauty PVT LTD. | D18: VINCE NURTURAL | E18: 30 | F18: 5814 | G18: 23562 | H18: =SUMPRODUCT((Production_Log!$F$3:$F$8963=F18)*(LEFT(Production_Log!$B$3:$B$8963,5)="Print")*(ISERROR(SEARCH("(Varnish)",Production_Log!$D$3:$D$8963)))*Production_Log!$H$3:$H$8963) -> 23562 | I18: =G18-H18 -> 0 | J18: =IF(G18=0,"-",H18/G18) -> 1 | S18: Operations | T18: =SUMPRODUCT((MONTH(Production_Log!$A$3:$A$8963)=MONTH(TODAY()))*(YEAR(Production_Log!$A$3:$A$8963)=YEAR(TODAY()))*Production_Log!$O$3:$O$8963) -> 4760 | U18: =T18+0.00008 -> 4760.0001
B19: TUBE | C19: Golden Pearl Cosmetics (PVT) LTD | D19: HELLO HAIR COLOR | E19: 30 | F19: 6206 | G19: 87108 | H19: =SUMPRODUCT((Production_Log!$F$3:$F$8963=F19)*(LEFT(Production_Log!$B$3:$B$8963,5)="Print")*(ISERROR(SEARCH("(Varnish)",Production_Log!$D$3:$D$8963)))*Production_Log!$H$3:$H$8963) -> 87108 | I19: =G19-H19 -> 0 | J19: =IF(G19=0,"-",H19/G19) -> 1 | K19: 152320
B20: TUBE | C20: Seatle (Private) Limited | D20: DOWFEN GEL 50G | E20: 30 | F20: 6595 | G20: 0 | H20: =SUMPRODUCT((Production_Log!$F$3:$F$8963=F20)*(LEFT(Production_Log!$B$3:$B$8963,5)="Print")*(ISERROR(SEARCH("(Varnish)",Production_Log!$D$3:$D$8963)))*(MONTH(Production_Log!$A$3:$A$8963)=MONTH(TODAY()))*(YEAR(Production_Log!$A$3:$A$8963)=YEAR(TODAY()))*Production_Log!$H$3:$H$8963) -> 0 | I20: =G20-H20 -> 0 | J20: =IF(G20=0,"-",H20/G20) -> - | K20: 24990
B21: TUBE | C21: Al-Rehman Group | D21: SIGNATURE HAIR COLOR CREAM 60ML | E21: 30 | F21: 6416 | G21: 0 | H21: =SUMPRODUCT((Production_Log!$F$3:$F$8963=F50)*(LEFT(Production_Log!$B$3:$B$8963,5)="Print")*(ISERROR(SEARCH("(Varnish)",Production_Log!$D$3:$D$8963)))*(MONTH(Production_Log!$A$3:$A$8963)=MONTH(TODAY()))*(YEAR(Production_Log!$A$3:$A$8963)=YEAR(TODAY()))*Production_Log!$H$3:$H$8963) -> 0 | I21: =G50-H50 -> 0 | J21: =IF(G50=0,"-",H50/G50) -> - | K21: 10045
B22: TUBE | C22: Hola Hair | D22: H.H 100GM | E22: 32 | F22: 6515 | G22: 13104 | H22: =SUMPRODUCT((Production_Log!$F$3:$F$8963=F22)*(LEFT(Production_Log!$B$3:$B$8963,5)="Print")*(ISERROR(SEARCH("(Varnish)",Production_Log!$D$3:$D$8963)))*Production_Log!$H$3:$H$8963) -> 13104 | I22: =G22-H22 -> 0 | J22: =IF(G22=0,"-",H22/G22) -> 1
B23: TUBE | C23: Adore | D23: V- HC BROWN | E23: 35 | F23: 6530 | G23: 34000 | H23: =SUMPRODUCT((Production_Log!$F$3:$F$8963=F23)*(LEFT(Production_Log!$B$3:$B$8963,5)="Print")*(ISERROR(SEARCH("(Varnish)",Production_Log!$D$3:$D$8963)))*(MONTH(Production_Log!$A$3:$A$8963)=MONTH(TODAY()))*(YEAR(Production_Log!$A$3:$A$8963)=YEAR(TODAY()))*Production_Log!$H$3:$H$8963) -> 20700 | I23: =G23-H23 -> 13300 | J23: =IF(G23=0,"-",H23/G23) -> 0.60882353 | K23: 5040
B24: TUBE | C24: Adore | D24: V-HC BLACK | E24: 35 | F24: 6531 | G24: 10620 | H24: =SUMPRODUCT((Production_Log!$F$3:$F$8963=F24)*(LEFT(Production_Log!$B$3:$B$8963,5)="Print")*(ISERROR(SEARCH("(Varnish)",Production_Log!$D$3:$D$8963)))*(MONTH(Production_Log!$A$3:$A$8963)=MONTH(TODAY()))*(YEAR(Production_Log!$A$3:$A$8963)=YEAR(TODAY()))*Production_Log!$H$3:$H$8963) -> 10620 | I24: =G24-H24 -> 0 | J24: =IF(G24=0,"-",H24/G24) -> 1
D25: TOTAL | G25: =SUM(G11:G24) -> 289068 | H25: =SUM(H11:H24) -> 239880 | I25: =SUMIF(I11:I24, ">0") -> 49188 | K25: =SUM(K11:K24) -> 260603
B27: PET | C27: Samsol International Private Limited | D27: PET BOTTLE SMALL (120ML) YELLOW | E27: 120 ml | F27: 8005 | G27: 58960 | H27: =SUMPRODUCT((Production_Log!$F$3:$F$8963=F27)*(MONTH(Production_Log!$A$3:$A$8963)=MONTH(TODAY()))*(YEAR(Production_Log!$A$3:$A$8963)=YEAR(TODAY()))*Production_Log!$H$3:$H$8963) -> 39120 | I27: =G27-H27 -> 19840 | J27: =IF(G27=0,"-",H27/G27) -> 0.66350068 | K27: 51720
B28: PET | C28: Alpha Labs PVT LTD | D28: PET BOTTLE SMALL (130ML) TRANSPARENT | E28: 130 ml | F28: 8010 | G28: 5000 | H28: =SUMPRODUCT((Production_Log!$F$3:$F$8963=F28)*(MONTH(Production_Log!$A$3:$A$8963)=MONTH(TODAY()))*(YEAR(Production_Log!$A$3:$A$8963)=YEAR(TODAY()))*Production_Log!$H$3:$H$8963) -> 5520 | I28: =G28-H28 -> -520 | J28: =IF(G28=0,"-",H28/G28) -> 1.104 | K28: 5520
B29: PET | C29: Alpha Labs PVT LTD | D29: TRANSPARENT BOTTLE 150ML | E29: 150 ml | F29: 8001 | G29: 166960 | H29: =SUMPRODUCT((Production_Log!$F$3:$F$8963=F29)*(MONTH(Production_Log!$A$3:$A$8963)=MONTH(TODAY()))*(YEAR(Production_Log!$A$3:$A$8963)=YEAR(TODAY()))*Production_Log!$H$3:$H$8963) -> 0 | I29: =G29-H29 -> 166960 | J29: =IF(G29=0,"-",H29/G29) -> 0 | K29: 50600
B30: PET | C30: Samsol International Private Limited | D30: PET BOTTLE LARGE 200ML WHITE | E30: 200 ml | F30: 8007 | G30: 10000 | H30: =SUMPRODUCT((Production_Log!$F$3:$F$8963=F30)*(MONTH(Production_Log!$A$3:$A$8963)=MONTH(TODAY()))*(YEAR(Production_Log!$A$3:$A$8963)=YEAR(TODAY()))*Production_Log!$H$3:$H$8963) -> 0 | I30: =G30-H30 -> 10000 | J30: =IF(G30=0,"-",H30/G30) -> 0
B31: PET | C31: Samsol International Private Limited | D31: BT-200 ML YELLOW | E31: 200 ml | F31: 8006 | G31: 42400 | H31: =SUMPRODUCT((Production_Log!$F$3:$F$8963=F31)*(MONTH(Production_Log!$A$3:$A$8963)=MONTH(TODAY()))*(YEAR(Production_Log!$A$3:$A$8963)=YEAR(TODAY()))*Production_Log!$H$3:$H$8963) -> 0 | I31: =G31-H31 -> 42400 | J31: =IF(G31=0,"-",H31/G31) -> 0
B32: PET | C32: Samsol International Private Limited | D32: BT-200ML MUSTARD OIL (TRANSPARENT) | E32: 200 ml | F32: 8014 | G32: 10000 | H32: =SUMPRODUCT((Production_Log!$F$3:$F$8963=F32)*(MONTH(Production_Log!$A$3:$A$8963)=MONTH(TODAY()))*(YEAR(Production_Log!$A$3:$A$8963)=YEAR(TODAY()))*Production_Log!$H$3:$H$8963) -> 0 | I32: =G32-H32 -> 10000 | J32: =IF(G32=0,"-",H32/G32) -> 0
D33: TOTAL | G33: =SUM(G27:G32) -> 293320 | H33: =SUM(H27:H32) -> 44640 | I33: =SUMIF(I27:I32, ">0") -> 249200 | K33: =SUM(K27:K32) -> 107840
B35: TUBE | C35: Bahadur | D35: BAHADUR TUBE 12.5MM | E35: 12.5 | F35: 9004 | G35: 0 | H35: =SUMPRODUCT((Production_Log!$F$3:$F$8963=F35)*(LEFT(Production_Log!$B$3:$B$8963,5)="Print")*(ISERROR(SEARCH("(Varnish)",Production_Log!$D$3:$D$8963)))*(MONTH(Production_Log!$A$3:$A$8963)=MONTH(TODAY()))*(YEAR(Production_Log!$A$3:$A$8963)=YEAR(TODAY()))*Production_Log!$H$3:$H$8963) -> 0 | I35: =G35-H35 -> 0 | J35: =IF(G35=0,"-",H35/G35) -> -
B36: TUBE | C36: Brookes Pharma Private Limited | D36: PYODINE GEL 20GM | E36: 19 | F36: 1085 | G36: 0 | H36: =SUMPRODUCT((Production_Log!$F$3:$F$8963=F36)*(LEFT(Production_Log!$B$3:$B$8963,5)="Print")*(ISERROR(SEARCH("(Varnish)",Production_Log!$D$3:$D$8963)))*(MONTH(Production_Log!$A$3:$A$8963)=MONTH(TODAY()))*(YEAR(Production_Log!$A$3:$A$8963)=YEAR(TODAY()))*Production_Log!$H$3:$H$8963) -> 0 | I36: =G36-H36 -> 0 | J36: =IF(G36=0,"-",H36/G36) -> -
B37: TUBE | C37: Brookes Pharma Private Limited | D37: CONTRATUBEX GEL 20G | E37: 19 | F37: 6560 | G37: 0 | H37: =SUMPRODUCT((Production_Log!$F$3:$F$8963=F37)*(LEFT(Production_Log!$B$3:$B$8963,5)="Print")*(ISERROR(SEARCH("(Varnish)",Production_Log!$D$3:$D$8963)))*(MONTH(Production_Log!$A$3:$A$8963)=MONTH(TODAY()))*(YEAR(Production_Log!$A$3:$A$8963)=YEAR(TODAY()))*Production_Log!$H$3:$H$8963) -> 0 | I37: =G37-H37 -> 0 | J37: =IF(G37=0,"-",H37/G37) -> -
B38: TUBE | C38: Samsol International Private Limited | D38: S-45 DIA 20.5 | E38: 20.5 | F38: 5698 | G38: 0 | H38: =SUMPRODUCT((Production_Log!$F$3:$F$8963=F12)*(LEFT(Production_Log!$B$3:$B$8963,5)="Print")*(ISERROR(SEARCH("(Varnish)",Production_Log!$D$3:$D$8963)))*(MONTH(Production_Log!$A$3:$A$8963)=MONTH(TODAY()))*(YEAR(Production_Log!$A$3:$A$8963)=YEAR(TODAY()))*Production_Log!$H$3:$H$8963) -> 0 | I38: =G12-H12 -> 0 | J38: =IF(G12=0,"-",H12/G12) -> -
B39: TUBE | C39: Samsol International Private Limited | D39: S-43 DIA 20.5 | E39: 20.5 | F39: 5699 | G39: 0 | H39: =SUMPRODUCT((Production_Log!$F$3:$F$8963=F38)*(LEFT(Production_Log!$B$3:$B$8963,5)="Print")*(ISERROR(SEARCH("(Varnish)",Production_Log!$D$3:$D$8963)))*(MONTH(Production_Log!$A$3:$A$8963)=MONTH(TODAY()))*(YEAR(Production_Log!$A$3:$A$8963)=YEAR(TODAY()))*Production_Log!$H$3:$H$8963) -> 0 | I39: =G38-H38 -> 0 | J39: =IF(G38=0,"-",H38/G38) -> -
B40: TUBE | C40: Samsol International Private Limited | D40: SAMSOL HAIR COLOR 45 DIA 20.5 MM | E40: 20.5 | F40: 5731 | G40: 0 | H40: =SUMPRODUCT((Production_Log!$F$3:$F$8963=F39)*(LEFT(Production_Log!$B$3:$B$8963,5)="Print")*(ISERROR(SEARCH("(Varnish)",Production_Log!$D$3:$D$8963)))*(MONTH(Production_Log!$A$3:$A$8963)=MONTH(TODAY()))*(YEAR(Production_Log!$A$3:$A$8963)=YEAR(TODAY()))*Production_Log!$H$3:$H$8963) -> 0 | I40: =G39-H39 -> 0 | J40: =IF(G39=0,"-",H39/G39) -> -
B41: TUBE | C41: Samsol International Private Limited | D41: SAMSOL HAIR COLOR 43 DIA 20.5 MM | E41: 20.5 | F41: 5732 | G41: 0 | H41: =SUMPRODUCT((Production_Log!$F$3:$F$8963=F40)*(LEFT(Production_Log!$B$3:$B$8963,5)="Print")*(ISERROR(SEARCH("(Varnish)",Production_Log!$D$3:$D$8963)))*(MONTH(Production_Log!$A$3:$A$8963)=MONTH(TODAY()))*(YEAR(Production_Log!$A$3:$A$8963)=YEAR(TODAY()))*Production_Log!$H$3:$H$8963) -> 0 | I41: =G40-H40 -> 0 | J41: =IF(G40=0,"-",H40/G40) -> -
B42: TUBE | C42: Samsol International Private Limited | D42: SAMSOL HAIR COLOR 39 SMALL PURPLE | E42: 20.5 | F42: 6556 | G42: 0 | H42: =SUMPRODUCT((Production_Log!$F$3:$F$8963=F41)*(LEFT(Production_Log!$B$3:$B$8963,5)="Print")*(ISERROR(SEARCH("(Varnish)",Production_Log!$D$3:$D$8963)))*(MONTH(Production_Log!$A$3:$A$8963)=MONTH(TODAY()))*(YEAR(Production_Log!$A$3:$A$8963)=YEAR(TODAY()))*Production_Log!$H$3:$H$8963) -> 0 | I42: =G41-H41 -> 0 | J42: =IF(G41=0,"-",H41/G41) -> -
B43: TUBE | C43: Samsol International Private Limited | D43: SAMSOL HAIR COLOR 41 SMALL PURPLE | E43: 20.5 | F43: 6557 | G43: 0 | H43: =SUMPRODUCT((Production_Log!$F$3:$F$8963=F42)*(LEFT(Production_Log!$B$3:$B$8963,5)="Print")*(ISERROR(SEARCH("(Varnish)",Production_Log!$D$3:$D$8963)))*(MONTH(Production_Log!$A$3:$A$8963)=MONTH(TODAY()))*(YEAR(Production_Log!$A$3:$A$8963)=YEAR(TODAY()))*Production_Log!$H$3:$H$8963) -> 0 | I43: =G42-H42 -> 0 | J43: =IF(G42=0,"-",H42/G42) -> -
B44: TUBE | C44: DTM | D44: DTM DIA 25MM | E44: 25 | F44: 6338 | G44: 0 | H44: =SUMPRODUCT((Production_Log!$F$3:$F$8963=F43)*(LEFT(Production_Log!$B$3:$B$8963,5)="Print")*(ISERROR(SEARCH("(Varnish)",Production_Log!$D$3:$D$8963)))*(MONTH(Production_Log!$A$3:$A$8963)=MONTH(TODAY()))*(YEAR(Production_Log!$A$3:$A$8963)=YEAR(TODAY()))*Production_Log!$H$3:$H$8963) -> 0 | I44: =G43-H43 -> 0 | J44: =IF(G43=0,"-",H43/G43) -> -
...

Sheet MRP
A1: May 2026 Tube Required Orders | G1: Date: | H1: =TODAY() -> 46157
A2: Dia | B2: Customer | C2: Product Name | D2: Product ID | E2: Job Order # | F2: Required Qty | G2: Produced | H2: Remaining Balance | J2: Remarks
A3: 16 | B3: Brookes Pharma Private Limited | C3: ECZEMUS OINTMENT 0.03% 10G | D3: 6561 | E3: 6849 | F3: 25000 | G3: =SUMPRODUCT((Production_Log!$F$3:$F$8963=D3)*(LEFT(Production_Log!$B$3:$B$8963,5)="Print")*(ISERROR(SEARCH("(Varnish)",Production_Log!$D$3:$D$8963)))*(MONTH(Production_Log!$A$3:$A$8963)=MONTH(TODAY()))*(YEAR(Production_Log!$A$3:$A$8963)=YEAR(TODAY()))*Production_Log!$H$3:$H$8963) -> 0 | H3: =F3-G3 -> 25000 | J3: CAPS Not Approved
A4: 19 | B4: Samsol International Private Limited | C4: S-45 DIA 19MM | D4: 6624 | E4: 6880 & 6881 | F4: 10888 | G4: =SUMPRODUCT((Production_Log!$F$3:$F$8963=D4)*(LEFT(Production_Log!$B$3:$B$8963,5)="Print")*(ISERROR(SEARCH("(Varnish)",Production_Log!$D$3:$D$8963)))*(MONTH(Production_Log!$A$3:$A$8963)=MONTH(TODAY()))*(YEAR(Production_Log!$A$3:$A$8963)=YEAR(TODAY()))*Production_Log!$H$3:$H$8963) -> 0 | H4: =F4-G4 -> 10888 | J4: SLUG in Transit
A5: 20.5 | B5: Mablay Beauty PVT LTD. | C5: VINCE HIS BEARD & MUSTACHE COLOR | D5: 6077 | E5: 6886 | F5: 23970 | G5: =SUMPRODUCT((Production_Log!$F$3:$F$8963=D5)*(LEFT(Production_Log!$B$3:$B$8963,5)="Print")*(ISERROR(SEARCH("(Varnish)",Production_Log!$D$3:$D$8963)))*(MONTH(Production_Log!$A$3:$A$8963)=MONTH(TODAY()))*(YEAR(Production_Log!$A$3:$A$8963)=YEAR(TODAY()))*Production_Log!$H$3:$H$8963) -> 23970 | H5: =F5-G5 -> 0
A6: 25 | B6: Mablay Beauty PVT LTD. | C6: HIS ONLY HAIR COLOR CREAM 40GM | D6: 6228 | E6: 6885 | F6: 21840 | G6: =SUMPRODUCT((Production_Log!$F$3:$F$8963=D6)*(LEFT(Production_Log!$B$3:$B$8963,5)="Print")*(ISERROR(SEARCH("(Varnish)",Production_Log!$D$3:$D$8963)))*(MONTH(Production_Log!$A$3:$A$8963)=MONTH(TODAY()))*(YEAR(Production_Log!$A$3:$A$8963)=YEAR(TODAY()))*Production_Log!$H$3:$H$8963) -> 21840 | H6: =F6-G6 -> 0
A7: 25 | B7: Samsol International Private Limited | C7: S 43 25MM | D7: 3447 | E7: 6876 | F7: 38976 | G7: =SUMPRODUCT((Production_Log!$F$3:$F$8963=D7)*(LEFT(Production_Log!$B$3:$B$8963,5)="Print")*(ISERROR(SEARCH("(Varnish)",Production_Log!$D$3:$D$8963)))*(MONTH(Production_Log!$A$3:$A$8963)=MONTH(TODAY()))*(YEAR(Production_Log!$A$3:$A$8963)=YEAR(TODAY()))*Production_Log!$H$3:$H$8963) -> 38976 | H7: =F7-G7 -> 0
A8: 30 | B8: Mablay Beauty PVT LTD. | C8: VINCE NURTURAL | D8: 5814 | E8: 6887 | F8: 23562 | G8: =SUMPRODUCT((Production_Log!$F$3:$F$8963=D8)*(LEFT(Production_Log!$B$3:$B$8963,5)="Print")*(ISERROR(SEARCH("(Varnish)",Production_Log!$D$3:$D$8963)))*(MONTH(Production_Log!$A$3:$A$8963)=MONTH(TODAY()))*(YEAR(Production_Log!$A$3:$A$8963)=YEAR(TODAY()))*Production_Log!$H$3:$H$8963) -> 23562 | H8: =F8-G8 -> 0
A9: 30 | B9: Golden Pearl Cosmetics (PVT) LTD | C9: HELLO HAIR COLOR | D9: 6206 | E9: 6862 | F9: 87108 | G9: =SUMPRODUCT((Production_Log!$F$3:$F$8963=D9)*(LEFT(Production_Log!$B$3:$B$8963,5)="Print")*(ISERROR(SEARCH("(Varnish)",Production_Log!$D$3:$D$8963)))*(MONTH(Production_Log!$A$3:$A$8963)=MONTH(TODAY()))*(YEAR(Production_Log!$A$3:$A$8963)=YEAR(TODAY()))*Production_Log!$H$3:$H$8963) -> 87108 | H9: =F9-G9 -> 0
A10: 32 | B10: Hola Hair | C10: H.H 100GM | D10: 6515 | E10: 6839 | F10: 13104 | G10: =SUMPRODUCT((Production_Log!$F$3:$F$8963=D10)*(LEFT(Production_Log!$B$3:$B$8963,5)="Print")*(ISERROR(SEARCH("(Varnish)",Production_Log!$D$3:$D$8963)))*(MONTH(Production_Log!$A$3:$A$8963)=MONTH(TODAY()))*(YEAR(Production_Log!$A$3:$A$8963)=YEAR(TODAY()))*Production_Log!$H$3:$H$8963) -> 13104 | H10: =F10-G10 -> 0
A11: 35 | B11: Adore | C11: V- HC BROWN | D11: 6530 | E11: 6884 | F11: 34000 | G11: =SUMPRODUCT((Production_Log!$F$3:$F$8963=D11)*(LEFT(Production_Log!$B$3:$B$8963,5)="Print")*(ISERROR(SEARCH("(Varnish)",Production_Log!$D$3:$D$8963)))*(MONTH(Production_Log!$A$3:$A$8963)=MONTH(TODAY()))*(YEAR(Production_Log!$A$3:$A$8963)=YEAR(TODAY()))*Production_Log!$H$3:$H$8963) -> 20700 | H11: =F11-G11 -> 13300 | J11: Hold Due to Payment Issue
A12: 35 | B12: Adore | C12: V-HC BLACK | D12: 6531 | E12: 6883 | F12: 10620 | G12: =SUMPRODUCT((Production_Log!$F$3:$F$8963=D12)*(LEFT(Production_Log!$B$3:$B$8963,5)="Print")*(ISERROR(SEARCH("(Varnish)",Production_Log!$D$3:$D$8963)))*(MONTH(Production_Log!$A$3:$A$8963)=MONTH(TODAY()))*(YEAR(Production_Log!$A$3:$A$8963)=YEAR(TODAY()))*Production_Log!$H$3:$H$8963) -> 10620 | H12: =F12-G12 -> 0
E13: TOTAL: | F13: =SUM(F3:F12) -> 289068 | G13: =SUM(G3:G12) -> 239880 | H13: =SUMIF(H3:H12, ">0") -> 49188
A14: MAY TUBES MATERIAL REQUIREMENT PLAN
A15: Item ID | B15: Category | C15: Item Name | D15: UOM | E15: Required Qty | F15: Current Stock (Store + WIP) | G15: Surplus / (Deficit) | H15: Product Name(s) | I15: Job Order #(s) | J15: Status | K15: FG Caps On Hold (pcs) | L15: ORDER QTY
A16: 33 | B16: SLUG | C16: 12.5X4.5X4.8 | D16: kg | E16: =SUMPRODUCT((TableBOM[Item ID]=A16)*TableBOM[Per 1000 Units]*(1+TableBOM[Scrap %])*SUMIF($D$3:$D$12,TableBOM[Product ID],$H$3:$H$12)/1000) -> 0 | F16: =IFERROR(INDEX(TableInventory[Store Balance],MATCH(A16,TableInventory[Item ID],0)),0)+IFERROR(INDEX(TableInventory[Work In Process],MATCH(A16,TableInventory[Item ID],0)),0) -> 0 | G16: =F16-E16 -> 0 | H16: =IF(LEN(IF((COUNTIFS(TableBOM[Product ID],$D$3,TableBOM[Item ID],$A16)>0)*($H$3>0),$C$3&", ","")&IF((COUNTIFS(TableBOM[Product ID],$D$4,TableBOM[Item ID],$A16)>0)*($H$4>0),$C$4&", ","")&IF((COUNTIFS(TableBOM[Product ID],$D$5,TableBOM[Item ID],$A16)>0)*($H$5>0),$C$5&", ","")&IF((COUNTIFS(TableBOM[Product ID],$D$6,TableBOM[Item ID],$A16)>0)*($H$6>0),$C$6&", ","")&IF((COUNTIFS(TableBOM[Product ID],$D$7,TableBOM[Item ID],$A16)>0)*($H$7>0),$C$7&", ","")&IF((COUNTIFS(TableBOM[Product ID],$D$8,TableBOM[Item ID],$A16)>0)*($H$8>0),$C$8&", ","")&IF((COUNTIFS(TableBOM[Product ID],$D$9,TableBOM[Item ID],$A16)>0)*($H$9>0),$C$9&", ","")&IF((COUNTIFS(TableBOM[Product ID],$D$10,TableBOM[Item ID],$A16)>0)*($H$10>0),$C$10&", ","")&IF((COUNTIFS(TableBOM[Product ID],$D$12,TableBOM[Item ID],$A16)>0)*($H$12>0),$C$12&", ",""))>1,LEFT(IF((COUNTIFS(TableBOM[Product ID],$D$3,TableBOM[Item ID],$A16)>0)*($H$3>0),$C$3&", ","")&IF((COUNTIFS(TableBOM[Product ID],$D$4,TableBOM[Item ID],$A16)>0)*($H$4>0),$C$4&", ","")&IF((COUNTIFS(TableBOM[Product ID],$D$5,TableBOM[Item ID],$A16)>0)*($H$5>0),$C$5&", ","")&IF((COUNTIFS(TableBOM[Product ID],$D$6,TableBOM[Item ID],$A16)>0)*($H$6>0),$C$6&", ","")&IF((COUNTIFS(TableBOM[Product ID],$D$7,TableBOM[Item ID],$A16)>0)*($H$7>0),$C$7&", ","")&IF((COUNTIFS(TableBOM[Product ID],$D$8,TableBOM[Item ID],$A16)>0)*($H$8>0),$C$8&", ","")&IF((COUNTIFS(TableBOM[Product ID],$D$9,TableBOM[Item ID],$A16)>0)*($H$9>0),$C$9&", ","")&IF((COUNTIFS(TableBOM[Product ID],$D$10,TableBOM[Item ID],$A16)>0)*($H$10>0),$C$10&", ","")&IF((COUNTIFS(TableBOM[Product ID],$D$12,TableBOM[Item ID],$A16)>0)*($H$12>0),$C$12&", ",""),LEN(IF((COUNTIFS(TableBOM[Product ID],$D$3,TableBOM[Item ID],$A16)>0)*($H$3>0),$C$3&", ","")&IF((COUNTIFS(TableBOM[Product ID],$D$4,TableBOM[Item ID],$A16)>0)*($H$4>0),$C$4&", ","")&IF((COUNTIFS(TableBOM[Product ID],$D$5,TableBOM[Item ID],$A16)>0)*($H$5>0),$C$5&", ","")&IF((COUNTIFS(TableBOM[Product ID],$D$6,TableBOM[Item ID],$A16)>0)*($H$6>0),$C$6&", ","")&IF((COUNTIFS(TableBOM[Product ID],$D$7,TableBOM[Item ID],$A16)>0)*($H$7>0),$C$7&", ","")&IF((COUNTIFS(TableBOM[Product ID],$D$8,TableBOM[Item ID],$A16)>0)*($H$8>0),$C$8&", ","")&IF((COUNTIFS(TableBOM[Product ID],$D$9,TableBOM[Item ID],$A16)>0)*($H$9>0),$C$9&", ","")&IF((COUNTIFS(TableBOM[Product ID],$D$10,TableBOM[Item ID],$A16)>0)*($H$10>0),$C$10&", ","")&IF((COUNTIFS(TableBOM[Product ID],$D$12,TableBOM[Item ID],$A16)>0)*($H$12>0),$C$12&", ",""))-2),"") | I16: =IF(LEN(IF((COUNTIFS(TableBOM[Product ID],$D$3,TableBOM[Item ID],$A16)>0)*($H$3>0),$E$3&", ","")&IF((COUNTIFS(TableBOM[Product ID],$D$4,TableBOM[Item ID],$A16)>0)*($H$4>0),$E$4&", ","")&IF((COUNTIFS(TableBOM[Product ID],$D$5,TableBOM[Item ID],$A16)>0)*($H$5>0),$E$5&", ","")&IF((COUNTIFS(TableBOM[Product ID],$D$6,TableBOM[Item ID],$A16)>0)*($H$6>0),$E$6&", ","")&IF((COUNTIFS(TableBOM[Product ID],$D$7,TableBOM[Item ID],$A16)>0)*($H$7>0),$E$7&", ","")&IF((COUNTIFS(TableBOM[Product ID],$D$8,TableBOM[Item ID],$A16)>0)*($H$8>0),$E$8&", ","")&IF((COUNTIFS(TableBOM[Product ID],$D$9,TableBOM[Item ID],$A16)>0)*($H$9>0),$E$9&", ","")&IF((COUNTIFS(TableBOM[Product ID],$D$10,TableBOM[Item ID],$A16)>0)*($H$10>0),$E$10&", ","")&IF((COUNTIFS(TableBOM[Product ID],$D$12,TableBOM[Item ID],$A16)>0)*($H$12>0),$E$12&", ",""))>1,LEFT(IF((COUNTIFS(TableBOM[Product ID],$D$3,TableBOM[Item ID],$A16)>0)*($H$3>0),$E$3&", ","")&IF((COUNTIFS(TableBOM[Product ID],$D$4,TableBOM[Item ID],$A16)>0)*($H$4>0),$E$4&", ","")&IF((COUNTIFS(TableBOM[Product ID],$D$5,TableBOM[Item ID],$A16)>0)*($H$5>0),$E$5&", ","")&IF((COUNTIFS(TableBOM[Product ID],$D$6,TableBOM[Item ID],$A16)>0)*($H$6>0),$E$6&", ","")&IF((COUNTIFS(TableBOM[Product ID],$D$7,TableBOM[Item ID],$A16)>0)*($H$7>0),$E$7&", ","")&IF((COUNTIFS(TableBOM[Product ID],$D$8,TableBOM[Item ID],$A16)>0)*($H$8>0),$E$8&", ","")&IF((COUNTIFS(TableBOM[Product ID],$D$9,TableBOM[Item ID],$A16)>0)*($H$9>0),$E$9&", ","")&IF((COUNTIFS(TableBOM[Product ID],$D$10,TableBOM[Item ID],$A16)>0)*($H$10>0),$E$10&", ","")&IF((COUNTIFS(TableBOM[Product ID],$D$12,TableBOM[Item ID],$A16)>0)*($H$12>0),$E$12&", ",""),LEN(IF((COUNTIFS(TableBOM[Product ID],$D$3,TableBOM[Item ID],$A16)>0)*($H$3>0),$E$3&", ","")&IF((COUNTIFS(TableBOM[Product ID],$D$4,TableBOM[Item ID],$A16)>0)*($H$4>0),$E$4&", ","")&IF((COUNTIFS(TableBOM[Product ID],$D$5,TableBOM[Item ID],$A16)>0)*($H$5>0),$E$5&", ","")&IF((COUNTIFS(TableBOM[Product ID],$D$6,TableBOM[Item ID],$A16)>0)*($H$6>0),$E$6&", ","")&IF((COUNTIFS(TableBOM[Product ID],$D$7,TableBOM[Item ID],$A16)>0)*($H$7>0),$E$7&", ","")&IF((COUNTIFS(TableBOM[Product ID],$D$8,TableBOM[Item ID],$A16)>0)*($H$8>0),$E$8&", ","")&IF((COUNTIFS(TableBOM[Product ID],$D$9,TableBOM[Item ID],$A16)>0)*($H$9>0),$E$9&", ","")&IF((COUNTIFS(TableBOM[Product ID],$D$10,TableBOM[Item ID],$A16)>0)*($H$10>0),$E$10&", ","")&IF((COUNTIFS(TableBOM[Product ID],$D$12,TableBOM[Item ID],$A16)>0)*($H$12>0),$E$12&", ",""))-2),"") | J16: =IF(E16=0,"Not needed",IF(G16<0,"SHORTAGE",IF(G16<F16*0.1,"LOW","OK"))) -> Not needed | K16: =IF(B16<>"CAP","",SUMPRODUCT((ISNUMBER(SEARCH("Cap Not Available",'FG Stock'!$H$4:$H$100)))*('FG Stock'!$I$4:$I$100=A16)*'FG Stock'!$F$4:$F$100)) | L16: =IF(E16=0,"",MAX(0,E16+IFERROR(K16*1,0)-F16))
A17: 31 | B17: SLUG | C17: 13.5X4.2 | D17: kg | E17: =SUMPRODUCT((TableBOM[Item ID]=A17)*TableBOM[Per 1000 Units]*(1+TableBOM[Scrap %])*SUMIF($D$3:$D$12,TableBOM[Product ID],$H$3:$H$12)/1000) -> 0 | F17: =IFERROR(INDEX(TableInventory[Store Balance],MATCH(A17,TableInventory[Item ID],0)),0)+IFERROR(INDEX(TableInventory[Work In Process],MATCH(A17,TableInventory[Item ID],0)),0) -> 71.5 | G17: =F17-E17 -> 71.5 | H17: =IF(LEN(IF((COUNTIFS(TableBOM[Product ID],$D$3,TableBOM[Item ID],$A17)>0)*($H$3>0),$C$3&", ","")&IF((COUNTIFS(TableBOM[Product ID],$D$4,TableBOM[Item ID],$A17)>0)*($H$4>0),$C$4&", ","")&IF((COUNTIFS(TableBOM[Product ID],$D$5,TableBOM[Item ID],$A17)>0)*($H$5>0),$C$5&", ","")&IF((COUNTIFS(TableBOM[Product ID],$D$6,TableBOM[Item ID],$A17)>0)*($H$6>0),$C$6&", ","")&IF((COUNTIFS(TableBOM[Product ID],$D$7,TableBOM[Item ID],$A17)>0)*($H$7>0),$C$7&", ","")&IF((COUNTIFS(TableBOM[Product ID],$D$8,TableBOM[Item ID],$A17)>0)*($H$8>0),$C$8&", ","")&IF((COUNTIFS(TableBOM[Product ID],$D$9,TableBOM[Item ID],$A17)>0)*($H$9>0),$C$9&", ","")&IF((COUNTIFS(TableBOM[Product ID],$D$10,TableBOM[Item ID],$A17)>0)*($H$10>0),$C$10&", ","")&IF((COUNTIFS(TableBOM[Product ID],$D$12,TableBOM[Item ID],$A17)>0)*($H$12>0),$C$12&", ",""))>1,LEFT(IF((COUNTIFS(TableBOM[Product ID],$D$3,TableBOM[Item ID],$A17)>0)*($H$3>0),$C$3&", ","")&IF((COUNTIFS(TableBOM[Product ID],$D$4,TableBOM[Item ID],$A17)>0)*($H$4>0),$C$4&", ","")&IF((COUNTIFS(TableBOM[Product ID],$D$5,TableBOM[Item ID],$A17)>0)*($H$5>0),$C$5&", ","")&IF((COUNTIFS(TableBOM[Product ID],$D$6,TableBOM[Item ID],$A17)>0)*($H$6>0),$C$6&", ","")&IF((COUNTIFS(TableBOM[Product ID],$D$7,TableBOM[Item ID],$A17)>0)*($H$7>0),$C$7&", ","")&IF((COUNTIFS(TableBOM[Product ID],$D$8,TableBOM[Item ID],$A17)>0)*($H$8>0),$C$8&", ","")&IF((COUNTIFS(TableBOM[Product ID],$D$9,TableBOM[Item ID],$A17)>0)*($H$9>0),$C$9&", ","")&IF((COUNTIFS(TableBOM[Product ID],$D$10,TableBOM[Item ID],$A17)>0)*($H$10>0),$C$10&", ","")&IF((COUNTIFS(TableBOM[Product ID],$D$12,TableBOM[Item ID],$A17)>0)*($H$12>0),$C$12&", ",""),LEN(IF((COUNTIFS(TableBOM[Product ID],$D$3,TableBOM[Item ID],$A17)>0)*($H$3>0),$C$3&", ","")&IF((COUNTIFS(TableBOM[Product ID],$D$4,TableBOM[Item ID],$A17)>0)*($H$4>0),$C$4&", ","")&IF((COUNTIFS(TableBOM[Product ID],$D$5,TableBOM[Item ID],$A17)>0)*($H$5>0),$C$5&", ","")&IF((COUNTIFS(TableBOM[Product ID],$D$6,TableBOM[Item ID],$A17)>0)*($H$6>0),$C$6&", ","")&IF((COUNTIFS(TableBOM[Product ID],$D$7,TableBOM[Item ID],$A17)>0)*($H$7>0),$C$7&", ","")&IF((COUNTIFS(TableBOM[Product ID],$D$8,TableBOM[Item ID],$A17)>0)*($H$8>0),$C$8&", ","")&IF((COUNTIFS(TableBOM[Product ID],$D$9,TableBOM[Item ID],$A17)>0)*($H$9>0),$C$9&", ","")&IF((COUNTIFS(TableBOM[Product ID],$D$10,TableBOM[Item ID],$A17)>0)*($H$10>0),$C$10&", ","")&IF((COUNTIFS(TableBOM[Product ID],$D$12,TableBOM[Item ID],$A17)>0)*($H$12>0),$C$12&", ",""))-2),"") | I17: =IF(LEN(IF((COUNTIFS(TableBOM[Product ID],$D$3,TableBOM[Item ID],$A17)>0)*($H$3>0),$E$3&", ","")&IF((COUNTIFS(TableBOM[Product ID],$D$4,TableBOM[Item ID],$A17)>0)*($H$4>0),$E$4&", ","")&IF((COUNTIFS(TableBOM[Product ID],$D$5,TableBOM[Item ID],$A17)>0)*($H$5>0),$E$5&", ","")&IF((COUNTIFS(TableBOM[Product ID],$D$6,TableBOM[Item ID],$A17)>0)*($H$6>0),$E$6&", ","")&IF((COUNTIFS(TableBOM[Product ID],$D$7,TableBOM[Item ID],$A17)>0)*($H$7>0),$E$7&", ","")&IF((COUNTIFS(TableBOM[Product ID],$D$8,TableBOM[Item ID],$A17)>0)*($H$8>0),$E$8&", ","")&IF((COUNTIFS(TableBOM[Product ID],$D$9,TableBOM[Item ID],$A17)>0)*($H$9>0),$E$9&", ","")&IF((COUNTIFS(TableBOM[Product ID],$D$10,TableBOM[Item ID],$A17)>0)*($H$10>0),$E$10&", ","")&IF((COUNTIFS(TableBOM[Product ID],$D$12,TableBOM[Item ID],$A17)>0)*($H$12>0),$E$12&", ",""))>1,LEFT(IF((COUNTIFS(TableBOM[Product ID],$D$3,TableBOM[Item ID],$A17)>0)*($H$3>0),$E$3&", ","")&IF((COUNTIFS(TableBOM[Product ID],$D$4,TableBOM[Item ID],$A17)>0)*($H$4>0),$E$4&", ","")&IF((COUNTIFS(TableBOM[Product ID],$D$5,TableBOM[Item ID],$A17)>0)*($H$5>0),$E$5&", ","")&IF((COUNTIFS(TableBOM[Product ID],$D$6,TableBOM[Item ID],$A17)>0)*($H$6>0),$E$6&", ","")&IF((COUNTIFS(TableBOM[Product ID],$D$7,TableBOM[Item ID],$A17)>0)*($H$7>0),$E$7&", ","")&IF((COUNTIFS(TableBOM[Product ID],$D$8,TableBOM[Item ID],$A17)>0)*($H$8>0),$E$8&", ","")&IF((COUNTIFS(TableBOM[Product ID],$D$9,TableBOM[Item ID],$A17)>0)*($H$9>0),$E$9&", ","")&IF((COUNTIFS(TableBOM[Product ID],$D$10,TableBOM[Item ID],$A17)>0)*($H$10>0),$E$10&", ","")&IF((COUNTIFS(TableBOM[Product ID],$D$12,TableBOM[Item ID],$A17)>0)*($H$12>0),$E$12&", ",""),LEN(IF((COUNTIFS(TableBOM[Product ID],$D$3,TableBOM[Item ID],$A17)>0)*($H$3>0),$E$3&", ","")&IF((COUNTIFS(TableBOM[Product ID],$D$4,TableBOM[Item ID],$A17)>0)*($H$4>0),$E$4&", ","")&IF((COUNTIFS(TableBOM[Product ID],$D$5,TableBOM[Item ID],$A17)>0)*($H$5>0),$E$5&", ","")&IF((COUNTIFS(TableBOM[Product ID],$D$6,TableBOM[Item ID],$A17)>0)*($H$6>0),$E$6&", ","")&IF((COUNTIFS(TableBOM[Product ID],$D$7,TableBOM[Item ID],$A17)>0)*($H$7>0),$E$7&", ","")&IF((COUNTIFS(TableBOM[Product ID],$D$8,TableBOM[Item ID],$A17)>0)*($H$8>0),$E$8&", ","")&IF((COUNTIFS(TableBOM[Product ID],$D$9,TableBOM[Item ID],$A17)>0)*($H$9>0),$E$9&", ","")&IF((COUNTIFS(TableBOM[Product ID],$D$10,TableBOM[Item ID],$A17)>0)*($H$10>0),$E$10&", ","")&IF((COUNTIFS(TableBOM[Product ID],$D$12,TableBOM[Item ID],$A17)>0)*($H$12>0),$E$12&", ",""))-2),"") | J17: =IF(E17=0,"Not needed",IF(G17<0,"SHORTAGE",IF(G17<F17*0.1,"LOW","OK"))) -> Not needed | K17: =IF(B17<>"CAP","",SUMPRODUCT((ISNUMBER(SEARCH("Cap Not Available",'FG Stock'!$H$4:$H$100)))*('FG Stock'!$I$4:$I$100=A17)*'FG Stock'!$F$4:$F$100)) | L17: =IF(E17=0,"",MAX(0,E17+IFERROR(K17*1,0)-F17))
A18: 2799 | B18: SLUG | C18: 16x4.5 | D18: kg | E18: =SUMPRODUCT((TableBOM[Item ID]=A18)*TableBOM[Per 1000 Units]*(1+TableBOM[Scrap %])*SUMIF($D$3:$D$12,TableBOM[Product ID],$H$3:$H$12)/1000) -> 69.269475 | F18: =IFERROR(INDEX(TableInventory[Store Balance],MATCH(A18,TableInventory[Item ID],0)),0)+IFERROR(INDEX(TableInventory[Work In Process],MATCH(A18,TableInventory[Item ID],0)),0) -> 88 | G18: =F18-E18 -> 18.730525 | H18: =IF(LEN(IF((COUNTIFS(TableBOM[Product ID],$D$3,TableBOM[Item ID],$A18)>0)*($H$3>0),$C$3&", ","")&IF((COUNTIFS(TableBOM[Product ID],$D$4,TableBOM[Item ID],$A18)>0)*($H$4>0),$C$4&", ","")&IF((COUNTIFS(TableBOM[Product ID],$D$5,TableBOM[Item ID],$A18)>0)*($H$5>0),$C$5&", ","")&IF((COUNTIFS(TableBOM[Product ID],$D$6,TableBOM[Item ID],$A18)>0)*($H$6>0),$C$6&", ","")&IF((COUNTIFS(TableBOM[Product ID],$D$7,TableBOM[Item ID],$A18)>0)*($H$7>0),$C$7&", ","")&IF((COUNTIFS(TableBOM[Product ID],$D$8,TableBOM[Item ID],$A18)>0)*($H$8>0),$C$8&", ","")&IF((COUNTIFS(TableBOM[Product ID],$D$9,TableBOM[Item ID],$A18)>0)*($H$9>0),$C$9&", ","")&IF((COUNTIFS(TableBOM[Product ID],$D$10,TableBOM[Item ID],$A18)>0)*($H$10>0),$C$10&", ","")&IF((COUNTIFS(TableBOM[Product ID],$D$12,TableBOM[Item ID],$A18)>0)*($H$12>0),$C$12&", ",""))>1,LEFT(IF((COUNTIFS(TableBOM[Product ID],$D$3,TableBOM[Item ID],$A18)>0)*($H$3>0),$C$3&", ","")&IF((COUNTIFS(TableBOM[Product ID],$D$4,TableBOM[Item ID],$A18)>0)*($H$4>0),$C$4&", ","")&IF((COUNTIFS(TableBOM[Product ID],$D$5,TableBOM[Item ID],$A18)>0)*($H$5>0),$C$5&", ","")&IF((COUNTIFS(TableBOM[Product ID],$D$6,TableBOM[Item ID],$A18)>0)*($H$6>0),$C$6&", ","")&IF((COUNTIFS(TableBOM[Product ID],$D$7,TableBOM[Item ID],$A18)>0)*($H$7>0),$C$7&", ","")&IF((COUNTIFS(TableBOM[Product ID],$D$8,TableBOM[Item ID],$A18)>0)*($H$8>0),$C$8&", ","")&IF((COUNTIFS(TableBOM[Product ID],$D$9,TableBOM[Item ID],$A18)>0)*($H$9>0),$C$9&", ","")&IF((COUNTIFS(TableBOM[Product ID],$D$10,TableBOM[Item ID],$A18)>0)*($H$10>0),$C$10&", ","")&IF((COUNTIFS(TableBOM[Product ID],$D$12,TableBOM[Item ID],$A18)>0)*($H$12>0),$C$12&", ",""),LEN(IF((COUNTIFS(TableBOM[Product ID],$D$3,TableBOM[Item ID],$A18)>0)*($H$3>0),$C$3&", ","")&IF((COUNTIFS(TableBOM[Product ID],$D$4,TableBOM[Item ID],$A18)>0)*($H$4>0),$C$4&", ","")&IF((COUNTIFS(TableBOM[Product ID],$D$5,TableBOM[Item ID],$A18)>0)*($H$5>0),$C$5&", ","")&IF((COUNTIFS(TableBOM[Product ID],$D$6,TableBOM[Item ID],$A18)>0)*($H$6>0),$C$6&", ","")&IF((COUNTIFS(TableBOM[Product ID],$D$7,TableBOM[Item ID],$A18)>0)*($H$7>0),$C$7&", ","")&IF((COUNTIFS(TableBOM[Product ID],$D$8,TableBOM[Item ID],$A18)>0)*($H$8>0),$C$8&", ","")&IF((COUNTIFS(TableBOM[Product ID],$D$9,TableBOM[Item ID],$A18)>0)*($H$9>0),$C$9&", ","")&IF((COUNTIFS(TableBOM[Product ID],$D$10,TableBOM[Item ID],$A18)>0)*($H$10>0),$C$10&", ","")&IF((COUNTIFS(TableBOM[Product ID],$D$12,TableBOM[Item ID],$A18)>0)*($H$12>0),$C$12&", ",""))-2),"") -> ECZEMUS OINTMENT 0.03% 10G | I18: =IF(LEN(IF((COUNTIFS(TableBOM[Product ID],$D$3,TableBOM[Item ID],$A18)>0)*($H$3>0),$E$3&", ","")&IF((COUNTIFS(TableBOM[Product ID],$D$4,TableBOM[Item ID],$A18)>0)*($H$4>0),$E$4&", ","")&IF((COUNTIFS(TableBOM[Product ID],$D$5,TableBOM[Item ID],$A18)>0)*($H$5>0),$E$5&", ","")&IF((COUNTIFS(TableBOM[Product ID],$D$6,TableBOM[Item ID],$A18)>0)*($H$6>0),$E$6&", ","")&IF((COUNTIFS(TableBOM[Product ID],$D$7,TableBOM[Item ID],$A18)>0)*($H$7>0),$E$7&", ","")&IF((COUNTIFS(TableBOM[Product ID],$D$8,TableBOM[Item ID],$A18)>0)*($H$8>0),$E$8&", ","")&IF((COUNTIFS(TableBOM[Product ID],$D$9,TableBOM[Item ID],$A18)>0)*($H$9>0),$E$9&", ","")&IF((COUNTIFS(TableBOM[Product ID],$D$10,TableBOM[Item ID],$A18)>0)*($H$10>0),$E$10&", ","")&IF((COUNTIFS(TableBOM[Product ID],$D$12,TableBOM[Item ID],$A18)>0)*($H$12>0),$E$12&", ",""))>1,LEFT(IF((COUNTIFS(TableBOM[Product ID],$D$3,TableBOM[Item ID],$A18)>0)*($H$3>0),$E$3&", ","")&IF((COUNTIFS(TableBOM[Product ID],$D$4,TableBOM[Item ID],$A18)>0)*($H$4>0),$E$4&", ","")&IF((COUNTIFS(TableBOM[Product ID],$D$5,TableBOM[Item ID],$A18)>0)*($H$5>0),$E$5&", ","")&IF((COUNTIFS(TableBOM[Product ID],$D$6,TableBOM[Item ID],$A18)>0)*($H$6>0),$E$6&", ","")&IF((COUNTIFS(TableBOM[Product ID],$D$7,TableBOM[Item ID],$A18)>0)*($H$7>0),$E$7&", ","")&IF((COUNTIFS(TableBOM[Product ID],$D$8,TableBOM[Item ID],$A18)>0)*($H$8>0),$E$8&", ","")&IF((COUNTIFS(TableBOM[Product ID],$D$9,TableBOM[Item ID],$A18)>0)*($H$9>0),$E$9&", ","")&IF((COUNTIFS(TableBOM[Product ID],$D$10,TableBOM[Item ID],$A18)>0)*($H$10>0),$E$10&", ","")&IF((COUNTIFS(TableBOM[Product ID],$D$12,TableBOM[Item ID],$A18)>0)*($H$12>0),$E$12&", ",""),LEN(IF((COUNTIFS(TableBOM[Product ID],$D$3,TableBOM[Item ID],$A18)>0)*($H$3>0),$E$3&", ","")&IF((COUNTIFS(TableBOM[Product ID],$D$4,TableBOM[Item ID],$A18)>0)*($H$4>0),$E$4&", ","")&IF((COUNTIFS(TableBOM[Product ID],$D$5,TableBOM[Item ID],$A18)>0)*($H$5>0),$E$5&", ","")&IF((COUNTIFS(TableBOM[Product ID],$D$6,TableBOM[Item ID],$A18)>0)*($H$6>0),$E$6&", ","")&IF((COUNTIFS(TableBOM[Product ID],$D$7,TableBOM[Item ID],$A18)>0)*($H$7>0),$E$7&", ","")&IF((COUNTIFS(TableBOM[Product ID],$D$8,TableBOM[Item ID],$A18)>0)*($H$8>0),$E$8&", ","")&IF((COUNTIFS(TableBOM[Product ID],$D$9,TableBOM[Item ID],$A18)>0)*($H$9>0),$E$9&", ","")&IF((COUNTIFS(TableBOM[Product ID],$D$10,TableBOM[Item ID],$A18)>0)*($H$10>0),$E$10&", ","")&IF((COUNTIFS(TableBOM[Product ID],$D$12,TableBOM[Item ID],$A18)>0)*($H$12>0),$E$12&", ",""))-2),"") -> 6849 | J18: =IF(E18=0,"Not needed",IF(G18<0,"SHORTAGE",IF(G18<F18*0.1,"LOW","OK"))) -> OK | K18: =IF(B18<>"CAP","",SUMPRODUCT((ISNUMBER(SEARCH("Cap Not Available",'FG Stock'!$H$4:$H$100)))*('FG Stock'!$I$4:$I$100=A18)*'FG Stock'!$F$4:$F$100)) | L18: =IF(E18=0,"",MAX(0,E18+IFERROR(K18*1,0)-F18)) -> 0
A19: 25 | B19: SLUG | C19: 16X4.8 S/M | D19: kg | E19: =SUMPRODUCT((TableBOM[Item ID]=A19)*TableBOM[Per 1000 Units]*(1+TableBOM[Scrap %])*SUMIF($D$3:$D$12,TableBOM[Product ID],$H$3:$H$12)/1000) -> 0 | F19: =IFERROR(INDEX(TableInventory[Store Balance],MATCH(A19,TableInventory[Item ID],0)),0)+IFERROR(INDEX(TableInventory[Work In Process],MATCH(A19,TableInventory[Item ID],0)),0) -> 0 | G19: =F19-E19 -> 0 | H19: =IF(LEN(IF((COUNTIFS(TableBOM[Product ID],$D$3,TableBOM[Item ID],$A19)>0)*($H$3>0),$C$3&", ","")&IF((COUNTIFS(TableBOM[Product ID],$D$4,TableBOM[Item ID],$A19)>0)*($H$4>0),$C$4&", ","")&IF((COUNTIFS(TableBOM[Product ID],$D$5,TableBOM[Item ID],$A19)>0)*($H$5>0),$C$5&", ","")&IF((COUNTIFS(TableBOM[Product ID],$D$6,TableBOM[Item ID],$A19)>0)*($H$6>0),$C$6&", ","")&IF((COUNTIFS(TableBOM[Product ID],$D$7,TableBOM[Item ID],$A19)>0)*($H$7>0),$C$7&", ","")&IF((COUNTIFS(TableBOM[Product ID],$D$8,TableBOM[Item ID],$A19)>0)*($H$8>0),$C$8&", ","")&IF((COUNTIFS(TableBOM[Product ID],$D$9,TableBOM[Item ID],$A19)>0)*($H$9>0),$C$9&", ","")&IF((COUNTIFS(TableBOM[Product ID],$D$10,TableBOM[Item ID],$A19)>0)*($H$10>0),$C$10&", ","")&IF((COUNTIFS(TableBOM[Product ID],$D$12,TableBOM[Item ID],$A19)>0)*($H$12>0),$C$12&", ",""))>1,LEFT(IF((COUNTIFS(TableBOM[Product ID],$D$3,TableBOM[Item ID],$A19)>0)*($H$3>0),$C$3&", ","")&IF((COUNTIFS(TableBOM[Product ID],$D$4,TableBOM[Item ID],$A19)>0)*($H$4>0),$C$4&", ","")&IF((COUNTIFS(TableBOM[Product ID],$D$5,TableBOM[Item ID],$A19)>0)*($H$5>0),$C$5&", ","")&IF((COUNTIFS(TableBOM[Product ID],$D$6,TableBOM[Item ID],$A19)>0)*($H$6>0),$C$6&", ","")&IF((COUNTIFS(TableBOM[Product ID],$D$7,TableBOM[Item ID],$A19)>0)*($H$7>0),$C$7&", ","")&IF((COUNTIFS(TableBOM[Product ID],$D$8,TableBOM[Item ID],$A19)>0)*($H$8>0),$C$8&", ","")&IF((COUNTIFS(TableBOM[Product ID],$D$9,TableBOM[Item ID],$A19)>0)*($H$9>0),$C$9&", ","")&IF((COUNTIFS(TableBOM[Product ID],$D$10,TableBOM[Item ID],$A19)>0)*($H$10>0),$C$10&", ","")&IF((COUNTIFS(TableBOM[Product ID],$D$12,TableBOM[Item ID],$A19)>0)*($H$12>0),$C$12&", ",""),LEN(IF((COUNTIFS(TableBOM[Product ID],$D$3,TableBOM[Item ID],$A19)>0)*($H$3>0),$C$3&", ","")&IF((COUNTIFS(TableBOM[Product ID],$D$4,TableBOM[Item ID],$A19)>0)*($H$4>0),$C$4&", ","")&IF((COUNTIFS(TableBOM[Product ID],$D$5,TableBOM[Item ID],$A19)>0)*($H$5>0),$C$5&", ","")&IF((COUNTIFS(TableBOM[Product ID],$D$6,TableBOM[Item ID],$A19)>0)*($H$6>0),$C$6&", ","")&IF((COUNTIFS(TableBOM[Product ID],$D$7,TableBOM[Item ID],$A19)>0)*($H$7>0),$C$7&", ","")&IF((COUNTIFS(TableBOM[Product ID],$D$8,TableBOM[Item ID],$A19)>0)*($H$8>0),$C$8&", ","")&IF((COUNTIFS(TableBOM[Product ID],$D$9,TableBOM[Item ID],$A19)>0)*($H$9>0),$C$9&", ","")&IF((COUNTIFS(TableBOM[Product ID],$D$10,TableBOM[Item ID],$A19)>0)*($H$10>0),$C$10&", ","")&IF((COUNTIFS(TableBOM[Product ID],$D$12,TableBOM[Item ID],$A19)>0)*($H$12>0),$C$12&", ",""))-2),"") | I19: =IF(LEN(IF((COUNTIFS(TableBOM[Product ID],$D$3,TableBOM[Item ID],$A19)>0)*($H$3>0),$E$3&", ","")&IF((COUNTIFS(TableBOM[Product ID],$D$4,TableBOM[Item ID],$A19)>0)*($H$4>0),$E$4&", ","")&IF((COUNTIFS(TableBOM[Product ID],$D$5,TableBOM[Item ID],$A19)>0)*($H$5>0),$E$5&", ","")&IF((COUNTIFS(TableBOM[Product ID],$D$6,TableBOM[Item ID],$A19)>0)*($H$6>0),$E$6&", ","")&IF((COUNTIFS(TableBOM[Product ID],$D$7,TableBOM[Item ID],$A19)>0)*($H$7>0),$E$7&", ","")&IF((COUNTIFS(TableBOM[Product ID],$D$8,TableBOM[Item ID],$A19)>0)*($H$8>0),$E$8&", ","")&IF((COUNTIFS(TableBOM[Product ID],$D$9,TableBOM[Item ID],$A19)>0)*($H$9>0),$E$9&", ","")&IF((COUNTIFS(TableBOM[Product ID],$D$10,TableBOM[Item ID],$A19)>0)*($H$10>0),$E$10&", ","")&IF((COUNTIFS(TableBOM[Product ID],$D$12,TableBOM[Item ID],$A19)>0)*($H$12>0),$E$12&", ",""))>1,LEFT(IF((COUNTIFS(TableBOM[Product ID],$D$3,TableBOM[Item ID],$A19)>0)*($H$3>0),$E$3&", ","")&IF((COUNTIFS(TableBOM[Product ID],$D$4,TableBOM[Item ID],$A19)>0)*($H$4>0),$E$4&", ","")&IF((COUNTIFS(TableBOM[Product ID],$D$5,TableBOM[Item ID],$A19)>0)*($H$5>0),$E$5&", ","")&IF((COUNTIFS(TableBOM[Product ID],$D$6,TableBOM[Item ID],$A19)>0)*($H$6>0),$E$6&", ","")&IF((COUNTIFS(TableBOM[Product ID],$D$7,TableBOM[Item ID],$A19)>0)*($H$7>0),$E$7&", ","")&IF((COUNTIFS(TableBOM[Product ID],$D$8,TableBOM[Item ID],$A19)>0)*($H$8>0),$E$8&", ","")&IF((COUNTIFS(TableBOM[Product ID],$D$9,TableBOM[Item ID],$A19)>0)*($H$9>0),$E$9&", ","")&IF((COUNTIFS(TableBOM[Product ID],$D$10,TableBOM[Item ID],$A19)>0)*($H$10>0),$E$10&", ","")&IF((COUNTIFS(TableBOM[Product ID],$D$12,TableBOM[Item ID],$A19)>0)*($H$12>0),$E$12&", ",""),LEN(IF((COUNTIFS(TableBOM[Product ID],$D$3,TableBOM[Item ID],$A19)>0)*($H$3>0),$E$3&", ","")&IF((COUNTIFS(TableBOM[Product ID],$D$4,TableBOM[Item ID],$A19)>0)*($H$4>0),$E$4&", ","")&IF((COUNTIFS(TableBOM[Product ID],$D$5,TableBOM[Item ID],$A19)>0)*($H$5>0),$E$5&", ","")&IF((COUNTIFS(TableBOM[Product ID],$D$6,TableBOM[Item ID],$A19)>0)*($H$6>0),$E$6&", ","")&IF((COUNTIFS(TableBOM[Product ID],$D$7,TableBOM[Item ID],$A19)>0)*($H$7>0),$E$7&", ","")&IF((COUNTIFS(TableBOM[Product ID],$D$8,TableBOM[Item ID],$A19)>0)*($H$8>0),$E$8&", ","")&IF((COUNTIFS(TableBOM[Product ID],$D$9,TableBOM[Item ID],$A19)>0)*($H$9>0),$E$9&", ","")&IF((COUNTIFS(TableBOM[Product ID],$D$10,TableBOM[Item ID],$A19)>0)*($H$10>0),$E$10&", ","")&IF((COUNTIFS(TableBOM[Product ID],$D$12,TableBOM[Item ID],$A19)>0)*($H$12>0),$E$12&", ",""))-2),"") | J19: =IF(E19=0,"Not needed",IF(G19<0,"SHORTAGE",IF(G19<F19*0.1,"LOW","OK"))) -> Not needed | K19: =IF(B19<>"CAP","",SUMPRODUCT((ISNUMBER(SEARCH("Cap Not Available",'FG Stock'!$H$4:$H$100)))*('FG Stock'!$I$4:$I$100=A19)*'FG Stock'!$F$4:$F$100)) | L19: =IF(E19=0,"",MAX(0,E19+IFERROR(K19*1,0)-F19))
A20: 22 | B20: SLUG | C20: 19X4.2 | D20: kg | E20: =SUMPRODUCT((TableBOM[Item ID]=A20)*TableBOM[Per 1000 Units]*(1+TableBOM[Scrap %])*SUMIF($D$3:$D$12,TableBOM[Product ID],$H$3:$H$12)/1000) -> 0 | F20: =IFERROR(INDEX(TableInventory[Store Balance],MATCH(A20,TableInventory[Item ID],0)),0)+IFERROR(INDEX(TableInventory[Work In Process],MATCH(A20,TableInventory[Item ID],0)),0) -> 0 | G20: =F20-E20 -> 0 | H20: =IF(LEN(IF((COUNTIFS(TableBOM[Product ID],$D$3,TableBOM[Item ID],$A20)>0)*($H$3>0),$C$3&", ","")&IF((COUNTIFS(TableBOM[Product ID],$D$4,TableBOM[Item ID],$A20)>0)*($H$4>0),$C$4&", ","")&IF((COUNTIFS(TableBOM[Product ID],$D$5,TableBOM[Item ID],$A20)>0)*($H$5>0),$C$5&", ","")&IF((COUNTIFS(TableBOM[Product ID],$D$6,TableBOM[Item ID],$A20)>0)*($H$6>0),$C$6&", ","")&IF((COUNTIFS(TableBOM[Product ID],$D$7,TableBOM[Item ID],$A20)>0)*($H$7>0),$C$7&", ","")&IF((COUNTIFS(TableBOM[Product ID],$D$8,TableBOM[Item ID],$A20)>0)*($H$8>0),$C$8&", ","")&IF((COUNTIFS(TableBOM[Product ID],$D$9,TableBOM[Item ID],$A20)>0)*($H$9>0),$C$9&", ","")&IF((COUNTIFS(TableBOM[Product ID],$D$10,TableBOM[Item ID],$A20)>0)*($H$10>0),$C$10&", ","")&IF((COUNTIFS(TableBOM[Product ID],$D$12,TableBOM[Item ID],$A20)>0)*($H$12>0),$C$12&", ",""))>1,LEFT(IF((COUNTIFS(TableBOM[Product ID],$D$3,TableBOM[Item ID],$A20)>0)*($H$3>0),$C$3&", ","")&IF((COUNTIFS(TableBOM[Product ID],$D$4,TableBOM[Item ID],$A20)>0)*($H$4>0),$C$4&", ","")&IF((COUNTIFS(TableBOM[Product ID],$D$5,TableBOM[Item ID],$A20)>0)*($H$5>0),$C$5&", ","")&IF((COUNTIFS(TableBOM[Product ID],$D$6,TableBOM[Item ID],$A20)>0)*($H$6>0),$C$6&", ","")&IF((COUNTIFS(TableBOM[Product ID],$D$7,TableBOM[Item ID],$A20)>0)*($H$7>0),$C$7&", ","")&IF((COUNTIFS(TableBOM[Product ID],$D$8,TableBOM[Item ID],$A20)>0)*($H$8>0),$C$8&", ","")&IF((COUNTIFS(TableBOM[Product ID],$D$9,TableBOM[Item ID],$A20)>0)*($H$9>0),$C$9&", ","")&IF((COUNTIFS(TableBOM[Product ID],$D$10,TableBOM[Item ID],$A20)>0)*($H$10>0),$C$10&", ","")&IF((COUNTIFS(TableBOM[Product ID],$D$12,TableBOM[Item ID],$A20)>0)*($H$12>0),$C$12&", ",""),LEN(IF((COUNTIFS(TableBOM[Product ID],$D$3,TableBOM[Item ID],$A20)>0)*($H$3>0),$C$3&", ","")&IF((COUNTIFS(TableBOM[Product ID],$D$4,TableBOM[Item ID],$A20)>0)*($H$4>0),$C$4&", ","")&IF((COUNTIFS(TableBOM[Product ID],$D$5,TableBOM[Item ID],$A20)>0)*($H$5>0),$C$5&", ","")&IF((COUNTIFS(TableBOM[Product ID],$D$6,TableBOM[Item ID],$A20)>0)*($H$6>0),$C$6&", ","")&IF((COUNTIFS(TableBOM[Product ID],$D$7,TableBOM[Item ID],$A20)>0)*($H$7>0),$C$7&", ","")&IF((COUNTIFS(TableBOM[Product ID],$D$8,TableBOM[Item ID],$A20)>0)*($H$8>0),$C$8&", ","")&IF((COUNTIFS(TableBOM[Product ID],$D$9,TableBOM[Item ID],$A20)>0)*($H$9>0),$C$9&", ","")&IF((COUNTIFS(TableBOM[Product ID],$D$10,TableBOM[Item ID],$A20)>0)*($H$10>0),$C$10&", ","")&IF((COUNTIFS(TableBOM[Product ID],$D$12,TableBOM[Item ID],$A20)>0)*($H$12>0),$C$12&", ",""))-2),"") | I20: =IF(LEN(IF((COUNTIFS(TableBOM[Product ID],$D$3,TableBOM[Item ID],$A20)>0)*($H$3>0),$E$3&", ","")&IF((COUNTIFS(TableBOM[Product ID],$D$4,TableBOM[Item ID],$A20)>0)*($H$4>0),$E$4&", ","")&IF((COUNTIFS(TableBOM[Product ID],$D$5,TableBOM[Item ID],$A20)>0)*($H$5>0),$E$5&", ","")&IF((COUNTIFS(TableBOM[Product ID],$D$6,TableBOM[Item ID],$A20)>0)*($H$6>0),$E$6&", ","")&IF((COUNTIFS(TableBOM[Product ID],$D$7,TableBOM[Item ID],$A20)>0)*($H$7>0),$E$7&", ","")&IF((COUNTIFS(TableBOM[Product ID],$D$8,TableBOM[Item ID],$A20)>0)*($H$8>0),$E$8&", ","")&IF((COUNTIFS(TableBOM[Product ID],$D$9,TableBOM[Item ID],$A20)>0)*($H$9>0),$E$9&", ","")&IF((COUNTIFS(TableBOM[Product ID],$D$10,TableBOM[Item ID],$A20)>0)*($H$10>0),$E$10&", ","")&IF((COUNTIFS(TableBOM[Product ID],$D$12,TableBOM[Item ID],$A20)>0)*($H$12>0),$E$12&", ",""))>1,LEFT(IF((COUNTIFS(TableBOM[Product ID],$D$3,TableBOM[Item ID],$A20)>0)*($H$3>0),$E$3&", ","")&IF((COUNTIFS(TableBOM[Product ID],$D$4,TableBOM[Item ID],$A20)>0)*($H$4>0),$E$4&", ","")&IF((COUNTIFS(TableBOM[Product ID],$D$5,TableBOM[Item ID],$A20)>0)*($H$5>0),$E$5&", ","")&IF((COUNTIFS(TableBOM[Product ID],$D$6,TableBOM[Item ID],$A20)>0)*($H$6>0),$E$6&", ","")&IF((COUNTIFS(TableBOM[Product ID],$D$7,TableBOM[Item ID],$A20)>0)*($H$7>0),$E$7&", ","")&IF((COUNTIFS(TableBOM[Product ID],$D$8,TableBOM[Item ID],$A20)>0)*($H$8>0),$E$8&", ","")&IF((COUNTIFS(TableBOM[Product ID],$D$9,TableBOM[Item ID],$A20)>0)*($H$9>0),$E$9&", ","")&IF((COUNTIFS(TableBOM[Product ID],$D$10,TableBOM[Item ID],$A20)>0)*($H$10>0),$E$10&", ","")&IF((COUNTIFS(TableBOM[Product ID],$D$12,TableBOM[Item ID],$A20)>0)*($H$12>0),$E$12&", ",""),LEN(IF((COUNTIFS(TableBOM[Product ID],$D$3,TableBOM[Item ID],$A20)>0)*($H$3>0),$E$3&", ","")&IF((COUNTIFS(TableBOM[Product ID],$D$4,TableBOM[Item ID],$A20)>0)*($H$4>0),$E$4&", ","")&IF((COUNTIFS(TableBOM[Product ID],$D$5,TableBOM[Item ID],$A20)>0)*($H$5>0),$E$5&", ","")&IF((COUNTIFS(TableBOM[Product ID],$D$6,TableBOM[Item ID],$A20)>0)*($H$6>0),$E$6&", ","")&IF((COUNTIFS(TableBOM[Product ID],$D$7,TableBOM[Item ID],$A20)>0)*($H$7>0),$E$7&", ","")&IF((COUNTIFS(TableBOM[Product ID],$D$8,TableBOM[Item ID],$A20)>0)*($H$8>0),$E$8&", ","")&IF((COUNTIFS(TableBOM[Product ID],$D$9,TableBOM[Item ID],$A20)>0)*($H$9>0),$E$9&", ","")&IF((COUNTIFS(TableBOM[Product ID],$D$10,TableBOM[Item ID],$A20)>0)*($H$10>0),$E$10&", ","")&IF((COUNTIFS(TableBOM[Product ID],$D$12,TableBOM[Item ID],$A20)>0)*($H$12>0),$E$12&", ",""))-2),"") | J20: =IF(E20=0,"Not needed",IF(G20<0,"SHORTAGE",IF(G20<F20*0.1,"LOW","OK"))) -> Not needed | K20: =IF(B20<>"CAP","",SUMPRODUCT((ISNUMBER(SEARCH("Cap Not Available",'FG Stock'!$H$4:$H$100)))*('FG Stock'!$I$4:$I$100=A20)*'FG Stock'!$F$4:$F$100)) | L20: =IF(E20=0,"",MAX(0,E20+IFERROR(K20*1,0)-F20))
A21: 19 | B21: SLUG | C21: 19X4.5 S/M | D21: kg | E21: =SUMPRODUCT((TableBOM[Item ID]=A21)*TableBOM[Per 1000 Units]*(1+TableBOM[Scrap %])*SUMIF($D$3:$D$12,TableBOM[Product ID],$H$3:$H$12)/1000) -> 40.325886 | F21: =IFERROR(INDEX(TableInventory[Store Balance],MATCH(A21,TableInventory[Item ID],0)),0)+IFERROR(INDEX(TableInventory[Work In Process],MATCH(A21,TableInventory[Item ID],0)),0) -> 0 | G21: =F21-E21 -> -40.325886 | H21: =IF(LEN(IF((COUNTIFS(TableBOM[Product ID],$D$3,TableBOM[Item ID],$A21)>0)*($H$3>0),$C$3&", ","")&IF((COUNTIFS(TableBOM[Product ID],$D$4,TableBOM[Item ID],$A21)>0)*($H$4>0),$C$4&", ","")&IF((COUNTIFS(TableBOM[Product ID],$D$5,TableBOM[Item ID],$A21)>0)*($H$5>0),$C$5&", ","")&IF((COUNTIFS(TableBOM[Product ID],$D$6,TableBOM[Item ID],$A21)>0)*($H$6>0),$C$6&", ","")&IF((COUNTIFS(TableBOM[Product ID],$D$7,TableBOM[Item ID],$A21)>0)*($H$7>0),$C$7&", ","")&IF((COUNTIFS(TableBOM[Product ID],$D$8,TableBOM[Item ID],$A21)>0)*($H$8>0),$C$8&", ","")&IF((COUNTIFS(TableBOM[Product ID],$D$9,TableBOM[Item ID],$A21)>0)*($H$9>0),$C$9&", ","")&IF((COUNTIFS(TableBOM[Product ID],$D$10,TableBOM[Item ID],$A21)>0)*($H$10>0),$C$10&", ","")&IF((COUNTIFS(TableBOM[Product ID],$D$12,TableBOM[Item ID],$A21)>0)*($H$12>0),$C$12&", ",""))>1,LEFT(IF((COUNTIFS(TableBOM[Product ID],$D$3,TableBOM[Item ID],$A21)>0)*($H$3>0),$C$3&", ","")&IF((COUNTIFS(TableBOM[Product ID],$D$4,TableBOM[Item ID],$A21)>0)*($H$4>0),$C$4&", ","")&IF((COUNTIFS(TableBOM[Product ID],$D$5,TableBOM[Item ID],$A21)>0)*($H$5>0),$C$5&", ","")&IF((COUNTIFS(TableBOM[Product ID],$D$6,TableBOM[Item ID],$A21)>0)*($H$6>0),$C$6&", ","")&IF((COUNTIFS(TableBOM[Product ID],$D$7,TableBOM[Item ID],$A21)>0)*($H$7>0),$C$7&", ","")&IF((COUNTIFS(TableBOM[Product ID],$D$8,TableBOM[Item ID],$A21)>0)*($H$8>0),$C$8&", ","")&IF((COUNTIFS(TableBOM[Product ID],$D$9,TableBOM[Item ID],$A21)>0)*($H$9>0),$C$9&", ","")&IF((COUNTIFS(TableBOM[Product ID],$D$10,TableBOM[Item ID],$A21)>0)*($H$10>0),$C$10&", ","")&IF((COUNTIFS(TableBOM[Product ID],$D$12,TableBOM[Item ID],$A21)>0)*($H$12>0),$C$12&", ",""),LEN(IF((COUNTIFS(TableBOM[Product ID],$D$3,TableBOM[Item ID],$A21)>0)*($H$3>0),$C$3&", ","")&IF((COUNTIFS(TableBOM[Product ID],$D$4,TableBOM[Item ID],$A21)>0)*($H$4>0),$C$4&", ","")&IF((COUNTIFS(TableBOM[Product ID],$D$5,TableBOM[Item ID],$A21)>0)*($H$5>0),$C$5&", ","")&IF((COUNTIFS(TableBOM[Product ID],$D$6,TableBOM[Item ID],$A21)>0)*($H$6>0),$C$6&", ","")&IF((COUNTIFS(TableBOM[Product ID],$D$7,TableBOM[Item ID],$A21)>0)*($H$7>0),$C$7&", ","")&IF((COUNTIFS(TableBOM[Product ID],$D$8,TableBOM[Item ID],$A21)>0)*($H$8>0),$C$8&", ","")&IF((COUNTIFS(TableBOM[Product ID],$D$9,TableBOM[Item ID],$A21)>0)*($H$9>0),$C$9&", ","")&IF((COUNTIFS(TableBOM[Product ID],$D$10,TableBOM[Item ID],$A21)>0)*($H$10>0),$C$10&", ","")&IF((COUNTIFS(TableBOM[Product ID],$D$12,TableBOM[Item ID],$A21)>0)*($H$12>0),$C$12&", ",""))-2),"") -> S-45 DIA 19MM | I21: =IF(LEN(IF((COUNTIFS(TableBOM[Product ID],$D$3,TableBOM[Item ID],$A21)>0)*($H$3>0),$E$3&", ","")&IF((COUNTIFS(TableBOM[Product ID],$D$4,TableBOM[Item ID],$A21)>0)*($H$4>0),$E$4&", ","")&IF((COUNTIFS(TableBOM[Product ID],$D$5,TableBOM[Item ID],$A21)>0)*($H$5>0),$E$5&", ","")&IF((COUNTIFS(TableBOM[Product ID],$D$6,TableBOM[Item ID],$A21)>0)*($H$6>0),$E$6&", ","")&IF((COUNTIFS(TableBOM[Product ID],$D$7,TableBOM[Item ID],$A21)>0)*($H$7>0),$E$7&", ","")&IF((COUNTIFS(TableBOM[Product ID],$D$8,TableBOM[Item ID],$A21)>0)*($H$8>0),$E$8&", ","")&IF((COUNTIFS(TableBOM[Product ID],$D$9,TableBOM[Item ID],$A21)>0)*($H$9>0),$E$9&", ","")&IF((COUNTIFS(TableBOM[Product ID],$D$10,TableBOM[Item ID],$A21)>0)*($H$10>0),$E$10&", ","")&IF((COUNTIFS(TableBOM[Product ID],$D$12,TableBOM[Item ID],$A21)>0)*($H$12>0),$E$12&", ",""))>1,LEFT(IF((COUNTIFS(TableBOM[Product ID],$D$3,TableBOM[Item ID],$A21)>0)*($H$3>0),$E$3&", ","")&IF((COUNTIFS(TableBOM[Product ID],$D$4,TableBOM[Item ID],$A21)>0)*($H$4>0),$E$4&", ","")&IF((COUNTIFS(TableBOM[Product ID],$D$5,TableBOM[Item ID],$A21)>0)*($H$5>0),$E$5&", ","")&IF((COUNTIFS(TableBOM[Product ID],$D$6,TableBOM[Item ID],$A21)>0)*($H$6>0),$E$6&", ","")&IF((COUNTIFS(TableBOM[Product ID],$D$7,TableBOM[Item ID],$A21)>0)*($H$7>0),$E$7&", ","")&IF((COUNTIFS(TableBOM[Product ID],$D$8,TableBOM[Item ID],$A21)>0)*($H$8>0),$E$8&", ","")&IF((COUNTIFS(TableBOM[Product ID],$D$9,TableBOM[Item ID],$A21)>0)*($H$9>0),$E$9&", ","")&IF((COUNTIFS(TableBOM[Product ID],$D$10,TableBOM[Item ID],$A21)>0)*($H$10>0),$E$10&", ","")&IF((COUNTIFS(TableBOM[Product ID],$D$12,TableBOM[Item ID],$A21)>0)*($H$12>0),$E$12&", ",""),LEN(IF((COUNTIFS(TableBOM[Product ID],$D$3,TableBOM[Item ID],$A21)>0)*($H$3>0),$E$3&", ","")&IF((COUNTIFS(TableBOM[Product ID],$D$4,TableBOM[Item ID],$A21)>0)*($H$4>0),$E$4&", ","")&IF((COUNTIFS(TableBOM[Product ID],$D$5,TableBOM[Item ID],$A21)>0)*($H$5>0),$E$5&", ","")&IF((COUNTIFS(TableBOM[Product ID],$D$6,TableBOM[Item ID],$A21)>0)*($H$6>0),$E$6&", ","")&IF((COUNTIFS(TableBOM[Product ID],$D$7,TableBOM[Item ID],$A21)>0)*($H$7>0),$E$7&", ","")&IF((COUNTIFS(TableBOM[Product ID],$D$8,TableBOM[Item ID],$A21)>0)*($H$8>0),$E$8&", ","")&IF((COUNTIFS(TableBOM[Product ID],$D$9,TableBOM[Item ID],$A21)>0)*($H$9>0),$E$9&", ","")&IF((COUNTIFS(TableBOM[Product ID],$D$10,TableBOM[Item ID],$A21)>0)*($H$10>0),$E$10&", ","")&IF((COUNTIFS(TableBOM[Product ID],$D$12,TableBOM[Item ID],$A21)>0)*($H$12>0),$E$12&", ",""))-2),"") -> 6880 & 6881 | J21: SLUG in Transit | K21: =IF(B21<>"CAP","",SUMPRODUCT((ISNUMBER(SEARCH("Cap Not Available",'FG Stock'!$H$4:$H$100)))*('FG Stock'!$I$4:$I$100=A21)*'FG Stock'!$F$4:$F$100)) | L21: =IF(E21=0,"",MAX(0,E21+IFERROR(K21*1,0)-F21)) -> 40.325886
