Workbook

Sheet Tubex_Dashboard
B2: TUBEX — August 2026 Month to Date Report
B3: Report Date: | H3: =MAX(Production_Log!$A$3:$A$8961) -> 46256
B5: TUBE | C5: =MAX(Production_Log!$A$3:$A$8961) -> 46256 | D5: TUBE — MTD | G5: TUBE — REJECT % | J5: Dispatch — MTD | M5: Press & Printing Downtime – MTD (Tubes)
B6: =SUMPRODUCT((Production_Log!$A$3:$A$8961=MAX(Production_Log!$A$3:$A$8961))*(LEFT(Production_Log!$B$3:$B$8961,5)="Print")*(ISERROR(SEARCH("(Varnish)",Production_Log!$D$3:$D$8961)))*Production_Log!$H$3:$H$8961) -> 22134 | D6: =SUMIF($B$11:$B$66,"TUBE",$H$11:$H$66) -> 266310 | G6: {=IFERROR(SUMPRODUCT((Production_Log!$F$3:$F$8961<>0)*(LEFT(Production_Log!$B$3:$B$8961,5)="Print")*(ISERROR(SEARCH("(Varnish)",Production_Log!$D$3:$D$8961)))*Production_Log!$I$3:$I$8961)/SUMPRODUCT((Production_Log!$F$3:$F$8961<>0)*(LEFT(Production_Log!$B$3:$B$8961,5)="Print")*(ISERROR(SEARCH("(Varnish)",Production_Log!$D$3:$D$8961)))*(Production_Log!$H$3:$H$8961+Production_Log!$I$3:$I$8961)),"-")} -> 0.020162626 | J6: =SUMIF($B$11:$B$66,"TUBE",$K$11:$K$66) -> 224896 | M6: Category | N6: Hours (MTD) | O6: % Share
B7: PET | C7: =MAX(Production_Log!$A$3:$A$8961) -> 46256 | D7: PET — MTD | G7: PET — REJECT % | J7: Dispatch — MTD | M7: Material Shortage | N7: =SUMPRODUCT(((LEFT(Production_Log!$B$3:$B$1063,5)="Press")+(LEFT(Production_Log!$B$3:$B$1063,5)="Print")+(LEFT(Production_Log!$B$3:$B$1063,5)="PLINE"))*Production_Log!$M$3:$M$1063)/60 -> 80.166667 | O7: =IFERROR(N7/$N$11,"") -> 0.81663837
B8: =SUMPRODUCT((Production_Log!$A$3:$A$8961=MAX(Production_Log!$A$3:$A$8961))*(Production_Log!$B$3:$B$8961="PF Machine")*Production_Log!$H$3:$H$8961) -> 0 | D8: =SUMIF($B$11:$B$66,"PET",$H$11:$H$66) -> 90735 | G8: {=IFERROR(SUMPRODUCT((Production_Log!$B$3:$B$8961="PF Machine")*Production_Log!$I$3:$I$8961)/SUMPRODUCT((Production_Log!$B$3:$B$8961="PF Machine")*(Production_Log!$H$3:$H$8961+Production_Log!$I$3:$I$8961)),0)} -> 0.068907132 | J8: =SUMIF($B$11:$B$66,"PET",$K$11:$K$66) -> 92000 | M8: Operations | N8: =SUMPRODUCT(((LEFT(Production_Log!$B$3:$B$1063,5)="Press")+(LEFT(Production_Log!$B$3:$B$1063,5)="Print")+(LEFT(Production_Log!$B$3:$B$1063,5)="PLINE"))*Production_Log!$O$3:$O$1063)/60 -> 12 | O8: =IFERROR(N8/$N$11,"") -> 0.12224109
B9: Summary of Production & Dispatch - MTD | M9: Mechanical | N9: =SUMPRODUCT(((LEFT(Production_Log!$B$3:$B$1063,5)="Press")+(LEFT(Production_Log!$B$3:$B$1063,5)="Print")+(LEFT(Production_Log!$B$3:$B$1063,5)="PLINE"))*Production_Log!$K$3:$K$1063)/60 -> 5 | O9: =IFERROR(N9/$N$11,"") -> 0.050933786
B10: Type | C10: Customer | D10: Product Name | E10: Dia | F10: Prod ID | G10: Orders | H10: MTD Produced | I10: Remaining | J10: Compliance | K10: Dispatch | L10: Remarks | M10: Changeover | N10: =SUMPRODUCT(((LEFT(Production_Log!$B$3:$B$1063,5)="Press")+(LEFT(Production_Log!$B$3:$B$1063,5)="Print")+(LEFT(Production_Log!$B$3:$B$1063,5)="PLINE"))*Production_Log!$N$3:$N$1063)/60 -> 1 | O10: =IFERROR(N10/$N$11,"") -> 0.010186757
B11: TUBE | C11: Samsol International Private Limited | D11: S-45 | E11: 25 | F11: 5389 | G11: =IFERROR(INDEX(MRP!$F$3:$F$150,MATCH(F11,MRP!$D$3:$D$150,0)),0) -> 0 | H11: =SUMPRODUCT((Production_Log!$F$3:$F$1063=F11)*((LEFT(Production_Log!$B$3:$B$1063,5)="Print")+(LEFT(Production_Log!$B$3:$B$1063,5)="PLINE"))*(ISERROR(SEARCH("(Varnish)",Production_Log!$D$3:$D$1063)))*Production_Log!$H$3:$H$1063) -> 60144 | I11: =G11-H11 -> -60144 | J11: =IF(G11=0,"-",H11/G11) -> - | L11: Produced without Orders | M11: TOTAL | N11: =SUM(N7:N10) -> 98.166667 | O11: 100%
B12: TUBE | C12: Golden Pearl Cosmetics (PVT) LTD | D12: HELLO HAIR COLOR | E12: 30 | F12: 6206 | G12: =IFERROR(INDEX(MRP!$F$3:$F$150,MATCH(F12,MRP!$D$3:$D$150,0)),0) -> 259778 | H12: =SUMPRODUCT((Production_Log!$F$3:$F$1063=F12)*((LEFT(Production_Log!$B$3:$B$1063,5)="Print")+(LEFT(Production_Log!$B$3:$B$1063,5)="PLINE"))*(ISERROR(SEARCH("(Varnish)",Production_Log!$D$3:$D$1063)))*Production_Log!$H$3:$H$1063) -> 206166 | I12: =G12-H12 -> 53612 | J12: =IF(G12=0,"-",H12/G12) -> 0.79362379 | K12: 188496
B13: TUBE | C13: Mablay Beauty PVT LTD. | D13: VINCE NURTURAL | E13: 30 | F13: 5814 | G13: =IFERROR(INDEX(MRP!$F$3:$F$150,MATCH(F13,MRP!$D$3:$D$150,0)),0) -> 25000 | H13: =SUMPRODUCT((Production_Log!$F$3:$F$1063=F13)*((LEFT(Production_Log!$B$3:$B$1063,5)="Print")+(LEFT(Production_Log!$B$3:$B$1063,5)="PLINE"))*(ISERROR(SEARCH("(Varnish)",Production_Log!$D$3:$D$1063)))*Production_Log!$H$3:$H$1063) -> 0 | I13: =G13-H13 -> 25000 | J13: =IF(G13=0,"-",H13/G13) -> 0 | M13: PF Machine Downtime – MTD (PET)
B14: TUBE | C14: Hola Hair | D14: H.H 100GM | E14: 32 | F14: 6515 | G14: =IFERROR(INDEX(MRP!$F$3:$F$150,MATCH(F14,MRP!$D$3:$D$150,0)),0) -> 0 | H14: =SUMPRODUCT((Production_Log!$F$3:$F$1063=F14)*((LEFT(Production_Log!$B$3:$B$1063,5)="Print")+(LEFT(Production_Log!$B$3:$B$1063,5)="PLINE"))*(ISERROR(SEARCH("(Varnish)",Production_Log!$D$3:$D$1063)))*Production_Log!$H$3:$H$1063) -> 0 | I14: =G14-H14 -> 0 | J14: =IF(G14=0,"-",H14/G14) -> - | K14: 36400 | M14: Category | N14: Hours (MTD) | O14: % Share
D15: TOTAL | G15: =SUM(G11:G14) -> 284778 | H15: =SUM(H11:H14) -> 266310 | I15: =SUMIF(I11:I14,">"&0) -> 78612 | K15: =SUM(K11:K14) -> 224896 | M15: Mechanical | N15: =SUMPRODUCT(((LEFT(Production_Log!$B$3:$B$1063,2)="PF")+(LEFT(Production_Log!$B$3:$B$1063,3)="PET"))*Production_Log!$K$3:$K$1063)/60 -> 154 | O15: =IFERROR(N15/$N$19,"") -> 0.7883959
B16: PET | C16: Samsol International Private Limited | D16: Samsol Yellow 120ml | E16: 120 ml | F16: 8005 | G16: =SUMIF(MRP!$D$94:$D$99,F16,MRP!$F$94:$F$99) -> 72160 | H16: =SUMPRODUCT((Production_Log!$F$3:$F$1063=F16)*Production_Log!$H$3:$H$1063) -> 0 | I16: =G16-H16 -> 72160 | J16: =IF(G16=0,"-",H16/G16) -> 0 | M16: Electrical | N16: =SUMPRODUCT(((LEFT(Production_Log!$B$3:$B$1063,2)="PF")+(LEFT(Production_Log!$B$3:$B$1063,3)="PET"))*Production_Log!$L$3:$L$1063)/60 -> 32.5 | O16: =IFERROR(N16/$N$19,"") -> 0.16638225
B17: PET | C17: Mablay Beauty PVT LTD. | D17: Mablay 130ml White | E17: 130 ml | F17: 8015 | G17: 15000 | H17: =SUMPRODUCT((Production_Log!$F$3:$F$1063=F17)*Production_Log!$H$3:$H$1063) -> 0 | I17: =G17-H17 -> 15000 | J17: =IF(G17=0,"-",H17/G17) -> 0 | M17: Operations | N17: =SUMPRODUCT(((LEFT(Production_Log!$B$3:$B$1063,2)="PF")+(LEFT(Production_Log!$B$3:$B$1063,3)="PET"))*Production_Log!$O$3:$O$1063)/60 -> 7.5 | O17: =IFERROR(N17/$N$19,"") -> 0.038395904
B18: PET | C18: Mablay Beauty PVT LTD. | D18: Mablay 130ml TRP | E18: 130 ml | F18: 8010 | G18: =IFERROR(INDEX(MRP!$F$3:$F$150,MATCH(F18,MRP!$D$3:$D$150,0)),0) -> 25000 | H18: =SUMPRODUCT((Production_Log!$F$3:$F$1063=F18)*Production_Log!$H$3:$H$1063) -> 0 | I18: =G18-H18 -> 25000 | J18: =IF(G18=0,"-",H18/G18) -> 0 | M18: Power Shutdown | N18: =SUMPRODUCT(((LEFT(Production_Log!$B$3:$B$1063,2)="PF")+(LEFT(Production_Log!$B$3:$B$1063,3)="PET"))*Production_Log!$P$3:$P$1063)/60 -> 1.3333333 | O18: =IFERROR(N18/$N$19,"") -> 0.0068259386
B19: PET | C19: Alpha Labs PVT LTD | D19: Alpha 150ml TRP | E19: 150 ml | F19: 8001 | G19: 701257 | H19: =SUMPRODUCT((Production_Log!$F$3:$F$1063=F19)*Production_Log!$H$3:$H$1063) -> 90735 | I19: =G19-H19 -> 610522 | J19: =IF(G19=0,"-",H19/G19) -> 0.12938908 | K19: 78200 | L19: 15k pieces rejected | M19: TOTAL | N19: =SUM(N15:N18) -> 195.33333 | O19: 100%
B20: PET | C20: Horizon Chem | D20: Horizon 150ml TRP | E20: 150 ml | F20: 8017 | G20: 13960 | H20: =SUMPRODUCT((Production_Log!$F$3:$F$1063=F20)*Production_Log!$H$3:$H$1063) -> 0 | I20: =G20-H20 -> 13960 | J20: =IF(G20=0,"-",H20/G20) -> 0 | K20: 13800
B21: PET | C21: Samsol International Private Limited | D21: Samsol Yellow 200ml | E21: 200 ml | F21: 8006 | G21: =IFERROR(INDEX(MRP!$F$3:$F$150,MATCH(F21,MRP!$D$3:$D$150,0)),0) -> 47000 | H21: =SUMPRODUCT((Production_Log!$F$3:$F$1063=F21)*Production_Log!$H$3:$H$1063) -> 0 | I21: =G21-H21 -> 47000 | J21: =IF(G21=0,"-",H21/G21) -> 0
D22: TOTAL | G22: =SUM(G16:G21) -> 874377 | H22: =SUM(H16:H21) -> 90735 | I22: =SUMIF(I16:I21,">"&0) -> 783642 | K22: =SUM(K16:K21) -> 92000
B23: TUBE | C23: Bahadur | D23: BAHADUR TUBE 12.5MM | E23: 12.5 | F23: 9004 | G23: =IFERROR(INDEX(MRP!$F$3:$F$150,MATCH(F23,MRP!$D$3:$D$150,0)),0) -> 0 | H23: =SUMPRODUCT((Production_Log!$F$3:$F$1063=F23)*((LEFT(Production_Log!$B$3:$B$1063,5)="Print")+(LEFT(Production_Log!$B$3:$B$1063,5)="PLINE"))*(ISERROR(SEARCH("(Varnish)",Production_Log!$D$3:$D$1063)))*Production_Log!$H$3:$H$1063) -> 0 | I23: =G23-H23 -> 0 | J23: =IF(G23=0,"-",H23/G23) -> -
B24: TUBE | C24: Brookes Pharma Private Limited | D24: ECZEMUS OINTMENT 0.03% 10G | E24: 16 | F24: 6561 | G24: =IFERROR(INDEX(MRP!$F$3:$F$150,MATCH(F24,MRP!$D$3:$D$150,0)),0) -> 0 | H24: =SUMPRODUCT((Production_Log!$F$3:$F$1063=F24)*((LEFT(Production_Log!$B$3:$B$1063,5)="Print")+(LEFT(Production_Log!$B$3:$B$1063,5)="PLINE"))*(ISERROR(SEARCH("(Varnish)",Production_Log!$D$3:$D$1063)))*Production_Log!$H$3:$H$1063) -> 0 | I24: =G24-H24 -> 0 | J24: =IF(G24=0,"-",H24/G24) -> -
B25: TUBE | C25: Samsol International Private Limited | D25: S-45 DIA 19MM | E25: 19 | F25: 6624 | G25: =IFERROR(INDEX(MRP!$F$3:$F$150,MATCH(F25,MRP!$D$3:$D$150,0)),0) -> 0 | H25: =SUMPRODUCT((Production_Log!$F$3:$F$1063=F25)*((LEFT(Production_Log!$B$3:$B$1063,5)="Print")+(LEFT(Production_Log!$B$3:$B$1063,5)="PLINE"))*(ISERROR(SEARCH("(Varnish)",Production_Log!$D$3:$D$1063)))*Production_Log!$H$3:$H$1063) -> 0 | I25: =G25-H25 -> 0 | J25: =IF(G25=0,"-",H25/G25) -> -
B26: TUBE | C26: Samsol International Private Limited | D26: S-43 DIA 19MM | E26: 19 | F26: 6623 | G26: =IFERROR(INDEX(MRP!$F$3:$F$150,MATCH(F26,MRP!$D$3:$D$150,0)),0) -> 0 | H26: =SUMPRODUCT((Production_Log!$F$3:$F$1063=F26)*((LEFT(Production_Log!$B$3:$B$1063,5)="Print")+(LEFT(Production_Log!$B$3:$B$1063,5)="PLINE"))*(ISERROR(SEARCH("(Varnish)",Production_Log!$D$3:$D$1063)))*Production_Log!$H$3:$H$1063) -> 0 | I26: =G26-H26 -> 0 | J26: =IF(G26=0,"-",H26/G26) -> -
B27: TUBE | C27: Brookes Pharma Private Limited | D27: S-43 DIA 19MM | E27: 19 | F27: 6559 | G27: =IFERROR(INDEX(MRP!$F$3:$F$150,MATCH(F27,MRP!$D$3:$D$150,0)),0) -> 0 | H27: =SUMPRODUCT((Production_Log!$F$3:$F$1063=F27)*((LEFT(Production_Log!$B$3:$B$1063,5)="Print")+(LEFT(Production_Log!$B$3:$B$1063,5)="PLINE"))*(ISERROR(SEARCH("(Varnish)",Production_Log!$D$3:$D$1063)))*Production_Log!$H$3:$H$1063) -> 0 | I27: =G27-H27 -> 0 | J27: =IF(G27=0,"-",H27/G27) -> -
B28: TUBE | C28: Brookes Pharma Private Limited | D28: PYODINE GEL 20GM | E28: 19 | F28: 1085 | G28: =IFERROR(INDEX(MRP!$F$3:$F$150,MATCH(F28,MRP!$D$3:$D$150,0)),0) -> 0 | H28: =SUMPRODUCT((Production_Log!$F$3:$F$1063=F28)*((LEFT(Production_Log!$B$3:$B$1063,5)="Print")+(LEFT(Production_Log!$B$3:$B$1063,5)="PLINE"))*(ISERROR(SEARCH("(Varnish)",Production_Log!$D$3:$D$1063)))*Production_Log!$H$3:$H$1063) -> 0 | I28: =G28-H28 -> 0 | J28: =IF(G28=0,"-",H28/G28) -> -
B29: TUBE | C29: Brookes Pharma Private Limited | D29: CONTRATUBEX GEL 20G | E29: 19 | F29: 6560 | G29: =IFERROR(INDEX(MRP!$F$3:$F$150,MATCH(F29,MRP!$D$3:$D$150,0)),0) -> 0 | H29: =SUMPRODUCT((Production_Log!$F$3:$F$1063=F29)*((LEFT(Production_Log!$B$3:$B$1063,5)="Print")+(LEFT(Production_Log!$B$3:$B$1063,5)="PLINE"))*(ISERROR(SEARCH("(Varnish)",Production_Log!$D$3:$D$1063)))*Production_Log!$H$3:$H$1063) -> 0 | I29: =G29-H29 -> 0 | J29: =IF(G29=0,"-",H29/G29) -> -
B30: TUBE | C30: Samsol International Private Limited | D30: S-43 DIA 20.5 | E30: 20.5 | F30: 5699 | G30: =IFERROR(INDEX(MRP!$F$3:$F$150,MATCH(F30,MRP!$D$3:$D$150,0)),0) -> 0 | H30: =SUMPRODUCT((Production_Log!$F$3:$F$1063=F30)*((LEFT(Production_Log!$B$3:$B$1063,5)="Print")+(LEFT(Production_Log!$B$3:$B$1063,5)="PLINE"))*(ISERROR(SEARCH("(Varnish)",Production_Log!$D$3:$D$1063)))*Production_Log!$H$3:$H$1063) -> 0 | I30: =G30-H30 -> 0 | J30: =IF(G30=0,"-",H30/G30) -> -
B31: TUBE | C31: Mablay Beauty PVT LTD. | D31: VINCE HIS ONLY BEARD & MUSTACHE COLOR CREAM | E31: 20.5 | F31: 6077 | G31: =IFERROR(INDEX(MRP!$F$3:$F$150,MATCH(F31,MRP!$D$3:$D$150,0)),0) -> 0 | H31: =SUMPRODUCT((Production_Log!$F$3:$F$1063=F31)*((LEFT(Production_Log!$B$3:$B$1063,5)="Print")+(LEFT(Production_Log!$B$3:$B$1063,5)="PLINE"))*(ISERROR(SEARCH("(Varnish)",Production_Log!$D$3:$D$1063)))*Production_Log!$H$3:$H$1063) -> 0 | I31: =G31-H31 -> 0 | J31: =IF(G31=0,"-",H31/G31) -> -
B32: TUBE | C32: Samsol International Private Limited | D32: SAMSOL HAIR COLOR 45 DIA 20.5 MM | E32: 20.5 | F32: 5731 | G32: =IFERROR(INDEX(MRP!$F$3:$F$150,MATCH(F32,MRP!$D$3:$D$150,0)),0) -> 0 | H32: =SUMPRODUCT((Production_Log!$F$3:$F$1063=F32)*((LEFT(Production_Log!$B$3:$B$1063,5)="Print")+(LEFT(Production_Log!$B$3:$B$1063,5)="PLINE"))*(ISERROR(SEARCH("(Varnish)",Production_Log!$D$3:$D$1063)))*Production_Log!$H$3:$H$1063) -> 0 | I32: =G32-H32 -> 0 | J32: =IF(G32=0,"-",H32/G32) -> -
B33: TUBE | C33: Samsol International Private Limited | D33: S-45 DIA 20.5 | E33: 20.5 | F33: 5698 | G33: =IFERROR(INDEX(MRP!$F$3:$F$150,MATCH(F33,MRP!$D$3:$D$150,0)),0) -> 0 | H33: =SUMPRODUCT((Production_Log!$F$3:$F$1063=F33)*((LEFT(Production_Log!$B$3:$B$1063,5)="Print")+(LEFT(Production_Log!$B$3:$B$1063,5)="PLINE"))*(ISERROR(SEARCH("(Varnish)",Production_Log!$D$3:$D$1063)))*Production_Log!$H$3:$H$1063) -> 0 | I33: =G33-H33 -> 0 | J33: =IF(G33=0,"-",H33/G33) -> -
B34: TUBE | C34: Samsol International Private Limited | D34: SAMSOL HAIR COLOR 43 DIA 20.5 MM | E34: 20.5 | F34: 5732 | G34: =IFERROR(INDEX(MRP!$F$3:$F$150,MATCH(F34,MRP!$D$3:$D$150,0)),0) -> 0 | H34: =SUMPRODUCT((Production_Log!$F$3:$F$1063=F34)*((LEFT(Production_Log!$B$3:$B$1063,5)="Print")+(LEFT(Production_Log!$B$3:$B$1063,5)="PLINE"))*(ISERROR(SEARCH("(Varnish)",Production_Log!$D$3:$D$1063)))*Production_Log!$H$3:$H$1063) -> 0 | I34: =G34-H34 -> 0 | J34: =IF(G34=0,"-",H34/G34) -> -
... B58: TUBE | C58: Adore | D58: ANVIL 45 | E58: 35 | F58: 6021 | G58: =IFERROR(INDEX(MRP!$F$3:$F$150,MATCH(F58,MRP!$D$3:$D$150,0)),0) -> 0 | H58: =SUMPRODUCT((Production_Log!$F$3:$F$1063=F58)*((LEFT(Production_Log!$B$3:$B$1063,5)="Print")+(LEFT(Production_Log!$B$3:$B$1063,5)="PLINE"))*(ISERROR(SEARCH("(Varnish)",Production_Log!$D$3:$D$1063)))*Production_Log!$H$3:$H$1063) -> 0 | I58: =G58-H58 -> 0 | J58: =IF(G58=0,"-",H58/G58) -> -
B59: PET | C59: Samsol International Private Limited | D59: Samsol Black 120ml | E59: 120 ml | F59: 8011 | G59: =IFERROR(INDEX(MRP!$F$3:$F$150,MATCH(F59,MRP!$D$3:$D$150,0)),0) -> 0 | H59: =SUMPRODUCT((Production_Log!$F$3:$F$1063=F59)*Production_Log!$H$3:$H$1063) -> 0 | I59: =G59-H59 -> 0 | J59: =IF(G59=0,"-",H59/G59) -> -
B60: PET | C60: Samsol International Private Limited | D60: Samsol White 120ml | E60: 120 ml | F60: 8012 | G60: =IFERROR(INDEX(MRP!$F$3:$F$150,MATCH(F60,MRP!$D$3:$D$150,0)),0) -> 0 | H60: =SUMPRODUCT((Production_Log!$F$3:$F$1063=F60)*Production_Log!$H$3:$H$1063) -> 0 | I60: =G60-H60 -> 0 | J60: =IF(G60=0,"-",H60/G60) -> -
B61: PET | C61: Samsol International Private Limited | D61: Samsol White 200ml | E61: 200 ml | F61: 8007 | G61: =IFERROR(INDEX(MRP!$F$3:$F$150,MATCH(F61,MRP!$D$3:$D$150,0)),0) -> 0 | H61: =SUMPRODUCT((Production_Log!$F$3:$F$1063=F61)*Production_Log!$H$3:$H$1063) -> 0 | I61: =G61-H61 -> 0 | J61: =IF(G61=0,"-",H61/G61) -> -
B62: PET | C62: Samsol International Private Limited | D62: Samsol Mustard Oil 200ml TRP | E62: 200 ml | F62: 8014 | G62: =IFERROR(INDEX(MRP!$F$3:$F$150,MATCH(F62,MRP!$D$3:$D$150,0)),0) -> 0 | H62: =SUMPRODUCT((Production_Log!$F$3:$F$1063=F62)*Production_Log!$H$3:$H$1063) -> 0 | I62: =G62-H62 -> 0 | J62: =IF(G62=0,"-",H62/G62) -> -
B63: PET | C63: Samsol International Private Limited | D63: Samsol Coconut Oil 200ml White | E63: 200 ml | F63: 8016 | G63: =IFERROR(INDEX(MRP!$F$3:$F$150,MATCH(F63,MRP!$D$3:$D$150,0)),0) -> 0 | H63: =SUMPRODUCT((Production_Log!$F$3:$F$1063=F63)*Production_Log!$H$3:$H$1063) -> 0 | I63: =G63-H63 -> 0 | J63: =IF(G63=0,"-",H63/G63) -> -
B64: PET | C64: Samsol International Private Limited | D64: Samsol Black 200ml | E64: 200 ml | F64: 8008 | G64: =IFERROR(INDEX(MRP!$F$3:$F$150,MATCH(F64,MRP!$D$3:$D$150,0)),0) -> 0 | H64: =SUMPRODUCT((Production_Log!$F$3:$F$1063=F64)*Production_Log!$H$3:$H$1063) -> 0 | I64: =G64-H64 -> 0 | J64: =IF(G64=0,"-",H64/G64) -> -
B65: PET | C65: Mablay Beauty PVT LTD. | D65: Mablay 300ml TRP | E65: 300 ml | F65: 8009 | G65: =IFERROR(INDEX(MRP!$F$3:$F$150,MATCH(F65,MRP!$D$3:$D$150,0)),0) -> 0 | H65: =SUMPRODUCT((Production_Log!$F$3:$F$1063=F65)*Production_Log!$H$3:$H$1063) -> 0 | I65: =G65-H65 -> 0 | J65: =IF(G65=0,"-",H65/G65) -> -
...

Sheet MRP
A1: AUGUST 2026 Tube Required Orders | G1: Date: | H1: =TODAY() -> 46258
A2: Dia | B2: Customer | C2: Product Name | D2: Product ID | E2: Job Order # | F2: Required Qty | G2: Produced | H2: Remaining Balance | I2: Remarks
A3: 30 | B3: Golden Pearl Cosmetics (PVT) LTD | C3: HELLO HAIR COLOR | D3: 6206 | E3: 6900 | F3: 259778 | G3: =INDEX(Tubex_Dashboard!$H$11:$H$100,MATCH(MRP!D3,Tubex_Dashboard!$F$11:$F$100,0)) -> 206166 | H3: =F3-G3 -> 53612 | I3: Cap Shortage
A4: 30 | B4: Mablay Beauty PVT LTD. | C4: VINCE NURTURAL | D4: 5814 | E4: 6901 | F4: 25000 | G4: =INDEX(Tubex_Dashboard!$H$11:$H$100,MATCH(MRP!D4,Tubex_Dashboard!$F$11:$F$100,0)) -> 0 | H4: =F4-G4 -> 25000 | I4: Cap Shortage
E5: TOTAL: | F5: =SUM(F3:F4) -> 284778 | G5: =SUM(G3:G4) -> 206166 | H5: =SUMIF(H3:H4, ">0") -> 78612
A6: JULY TUBES MATERIAL REQUIREMENT PLAN
A7: Item ID | B7: Category | C7: Item Name | D7: UOM | E7: Required Qty | F7: Current Stock (Store + WIP) | G7: Surplus / (Deficit) | H7: Current Stock Pieces Can Produce | I7: Status | J7: Product Name(s)
A8: 33 | B8: SLUG | C8: 12.5X4.5X4.8 | D8: kg | E8: =SUMPRODUCT((TableBOM[Item ID]=A8)*TableBOM[Per 1000 Units]*(1+TableBOM[Scrap %])*SUMIF($D$3:$D$4,TableBOM[Product ID],$H$3:$H$4)/1000) -> 0 | F8: =IFERROR(INDEX(TableInventory[Store Balance],MATCH(A8,TableInventory[Item ID],0)),0)+IFERROR(INDEX(TableInventory[Work In Process],MATCH(A8,TableInventory[Item ID],0)),0) -> 0 | G8: =F8-E8 -> 0 | H8: =IFERROR(IF(SUMPRODUCT((TableBOM[Item ID]=A8)*((TableBOM[Product ID]=$D$3)*($H$3>0)+(TableBOM[Product ID]=$D$4)*($H$4>0)))=0,"-",ROUND(F8/((SUMPRODUCT((TableBOM[Item ID]=A8)*TableBOM[Per 1000 Units]*((TableBOM[Product ID]=$D$3)*($H$3>0)+(TableBOM[Product ID]=$D$4)*($H$4>0)))/SUMPRODUCT((TableBOM[Item ID]=A8)*((TableBOM[Product ID]=$D$3)*($H$3>0)+(TableBOM[Product ID]=$D$4)*($H$4>0))))/1000),0)),"-") -> - | I8: =IF(E8=0,"Not needed",IF(G8<0,"SHORTAGE",IF(G8<F8*0.1,"LOW","OK"))) -> Not needed | J8: =IF(LEN(IF((COUNTIFS(TableBOM[Product ID],$D$3,TableBOM[Item ID],$A8)>0)*($H$3>0),$C$3&", ","") & IF((COUNTIFS(TableBOM[Product ID],$D$4,TableBOM[Item ID],$A8)>0)*($H$4>0),$C$4&", ",""))>1,LEFT(IF((COUNTIFS(TableBOM[Product ID],$D$3,TableBOM[Item ID],$A8)>0)*($H$3>0),$C$3&", ","") & IF((COUNTIFS(TableBOM[Product ID],$D$4,TableBOM[Item ID],$A8)>0)*($H$4>0),$C$4&", ",""),LEN(IF((COUNTIFS(TableBOM[Product ID],$D$3,TableBOM[Item ID],$A8)>0)*($H$3>0),$C$3&", ","") & IF((COUNTIFS(TableBOM[Product ID],$D$4,TableBOM[Item ID],$A8)>0)*($H$4>0),$C$4&", ",""))-2),"")
A9: 31 | B9: SLUG | C9: 13.5X4.2 | D9: kg | E9: =SUMPRODUCT((TableBOM[Item ID]=A9)*TableBOM[Per 1000 Units]*(1+TableBOM[Scrap %])*SUMIF($D$3:$D$4,TableBOM[Product ID],$H$3:$H$4)/1000) -> 0 | F9: =IFERROR(INDEX(TableInventory[Store Balance],MATCH(A9,TableInventory[Item ID],0)),0)+IFERROR(INDEX(TableInventory[Work In Process],MATCH(A9,TableInventory[Item ID],0)),0) -> 71.5 | G9: =F9-E9 -> 71.5 | H9: =IFERROR(IF(SUMPRODUCT((TableBOM[Item ID]=A9)*((TableBOM[Product ID]=$D$3)*($H$3>0)+(TableBOM[Product ID]=$D$4)*($H$4>0)))=0,"-",ROUND(F9/((SUMPRODUCT((TableBOM[Item ID]=A9)*TableBOM[Per 1000 Units]*((TableBOM[Product ID]=$D$3)*($H$3>0)+(TableBOM[Product ID]=$D$4)*($H$4>0)))/SUMPRODUCT((TableBOM[Item ID]=A9)*((TableBOM[Product ID]=$D$3)*($H$3>0)+(TableBOM[Product ID]=$D$4)*($H$4>0))))/1000),0)),"-") -> - | I9: =IF(E9=0,"Not needed",IF(G9<0,"SHORTAGE",IF(G9<F9*0.1,"LOW","OK"))) -> Not needed | J9: =IF(LEN(IF((COUNTIFS(TableBOM[Product ID],$D$3,TableBOM[Item ID],$A9)>0)*($H$3>0),$C$3&", ","") & IF((COUNTIFS(TableBOM[Product ID],$D$4,TableBOM[Item ID],$A9)>0)*($H$4>0),$C$4&", ",""))>1,LEFT(IF((COUNTIFS(TableBOM[Product ID],$D$3,TableBOM[Item ID],$A9)>0)*($H$3>0),$C$3&", ","") & IF((COUNTIFS(TableBOM[Product ID],$D$4,TableBOM[Item ID],$A9)>0)*($H$4>0),$C$4&", ",""),LEN(IF((COUNTIFS(TableBOM[Product ID],$D$3,TableBOM[Item ID],$A9)>0)*($H$3>0),$C$3&", ","") & IF((COUNTIFS(TableBOM[Product ID],$D$4,TableBOM[Item ID],$A9)>0)*($H$4>0),$C$4&", ",""))-2),"")
A10: 2799 | B10: SLUG | C10: 16x4.5 | D10: kg | E10: =SUMPRODUCT((TableBOM[Item ID]=A10)*TableBOM[Per 1000 Units]*(1+TableBOM[Scrap %])*SUMIF($D$3:$D$4,TableBOM[Product ID],$H$3:$H$4)/1000) -> 0 | F10: =IFERROR(INDEX(TableInventory[Store Balance],MATCH(A10,TableInventory[Item ID],0)),0)+IFERROR(INDEX(TableInventory[Work In Process],MATCH(A10,TableInventory[Item ID],0)),0) -> 88 | G10: =F10-E10 -> 88 | H10: =IFERROR(IF(SUMPRODUCT((TableBOM[Item ID]=A10)*((TableBOM[Product ID]=$D$3)*($H$3>0)+(TableBOM[Product ID]=$D$4)*($H$4>0)))=0,"-",ROUND(F10/((SUMPRODUCT((TableBOM[Item ID]=A10)*TableBOM[Per 1000 Units]*((TableBOM[Product ID]=$D$3)*($H$3>0)+(TableBOM[Product ID]=$D$4)*($H$4>0)))/SUMPRODUCT((TableBOM[Item ID]=A10)*((TableBOM[Product ID]=$D$3)*($H$3>0)+(TableBOM[Product ID]=$D$4)*($H$4>0))))/1000),0)),"-") -> - | I10: =IF(E10=0,"Not needed",IF(G10<0,"SHORTAGE",IF(G10<F10*0.1,"LOW","OK"))) -> Not needed | J10: =IF(LEN(IF((COUNTIFS(TableBOM[Product ID],$D$3,TableBOM[Item ID],$A10)>0)*($H$3>0),$C$3&", ","") & IF((COUNTIFS(TableBOM[Product ID],$D$4,TableBOM[Item ID],$A10)>0)*($H$4>0),$C$4&", ",""))>1,LEFT(IF((COUNTIFS(TableBOM[Product ID],$D$3,TableBOM[Item ID],$A10)>0)*($H$3>0),$C$3&", ","") & IF((COUNTIFS(TableBOM[Product ID],$D$4,TableBOM[Item ID],$A10)>0)*($H$4>0),$C$4&", ",""),LEN(IF((COUNTIFS(TableBOM[Product ID],$D$3,TableBOM[Item ID],$A10)>0)*($H$3>0),$C$3&", ","") & IF((COUNTIFS(TableBOM[Product ID],$D$4,TableBOM[Item ID],$A10)>0)*($H$4>0),$C$4&", ",""))-2),"")
A11: 25 | B11: SLUG | C11: 16X4.8 S/M | D11: kg | E11: =SUMPRODUCT((TableBOM[Item ID]=A11)*TableBOM[Per 1000 Units]*(1+TableBOM[Scrap %])*SUMIF($D$3:$D$4,TableBOM[Product ID],$H$3:$H$4)/1000) -> 0 | F11: =IFERROR(INDEX(TableInventory[Store Balance],MATCH(A11,TableInventory[Item ID],0)),0)+IFERROR(INDEX(TableInventory[Work In Process],MATCH(A11,TableInventory[Item ID],0)),0) -> 0 | G11: =F11-E11 -> 0 | H11: =IFERROR(IF(SUMPRODUCT((TableBOM[Item ID]=A11)*((TableBOM[Product ID]=$D$3)*($H$3>0)+(TableBOM[Product ID]=$D$4)*($H$4>0)))=0,"-",ROUND(F11/((SUMPRODUCT((TableBOM[Item ID]=A11)*TableBOM[Per 1000 Units]*((TableBOM[Product ID]=$D$3)*($H$3>0)+(TableBOM[Product ID]=$D$4)*($H$4>0)))/SUMPRODUCT((TableBOM[Item ID]=A11)*((TableBOM[Product ID]=$D$3)*($H$3>0)+(TableBOM[Product ID]=$D$4)*($H$4>0))))/1000),0)),"-") -> - | I11: =IF(E11=0,"Not needed",IF(G11<0,"SHORTAGE",IF(G11<F11*0.1,"LOW","OK"))) -> Not needed | J11: =IF(LEN(IF((COUNTIFS(TableBOM[Product ID],$D$3,TableBOM[Item ID],$A11)>0)*($H$3>0),$C$3&", ","") & IF((COUNTIFS(TableBOM[Product ID],$D$4,TableBOM[Item ID],$A11)>0)*($H$4>0),$C$4&", ",""))>1,LEFT(IF((COUNTIFS(TableBOM[Product ID],$D$3,TableBOM[Item ID],$A11)>0)*($H$3>0),$C$3&", ","") & IF((COUNTIFS(TableBOM[Product ID],$D$4,TableBOM[Item ID],$A11)>0)*($H$4>0),$C$4&", ",""),LEN(IF((COUNTIFS(TableBOM[Product ID],$D$3,TableBOM[Item ID],$A11)>0)*($H$3>0),$C$3&", ","") & IF((COUNTIFS(TableBOM[Product ID],$D$4,TableBOM[Item ID],$A11)>0)*($H$4>0),$C$4&", ",""))-2),"")
A12: 22 | B12: SLUG | C12: 19X4.2 | D12: kg | E12: =SUMPRODUCT((TableBOM[Item ID]=A12)*TableBOM[Per 1000 Units]*(1+TableBOM[Scrap %])*SUMIF($D$3:$D$4,TableBOM[Product ID],$H$3:$H$4)/1000) -> 0 | F12: =IFERROR(INDEX(TableInventory[Store Balance],MATCH(A12,TableInventory[Item ID],0)),0)+IFERROR(INDEX(TableInventory[Work In Process],MATCH(A12,TableInventory[Item ID],0)),0) -> 0 | G12: =F12-E12 -> 0 | H12: =IFERROR(IF(SUMPRODUCT((TableBOM[Item ID]=A12)*((TableBOM[Product ID]=$D$3)*($H$3>0)+(TableBOM[Product ID]=$D$4)*($H$4>0)))=0,"-",ROUND(F12/((SUMPRODUCT((TableBOM[Item ID]=A12)*TableBOM[Per 1000 Units]*((TableBOM[Product ID]=$D$3)*($H$3>0)+(TableBOM[Product ID]=$D$4)*($H$4>0)))/SUMPRODUCT((TableBOM[Item ID]=A12)*((TableBOM[Product ID]=$D$3)*($H$3>0)+(TableBOM[Product ID]=$D$4)*($H$4>0))))/1000),0)),"-") -> - | I12: =IF(E12=0,"Not needed",IF(G12<0,"SHORTAGE",IF(G12<F12*0.1,"LOW","OK"))) -> Not needed | J12: =IF(LEN(IF((COUNTIFS(TableBOM[Product ID],$D$3,TableBOM[Item ID],$A12)>0)*($H$3>0),$C$3&", ","") & IF((COUNTIFS(TableBOM[Product ID],$D$4,TableBOM[Item ID],$A12)>0)*($H$4>0),$C$4&", ",""))>1,LEFT(IF((COUNTIFS(TableBOM[Product ID],$D$3,TableBOM[Item ID],$A12)>0)*($H$3>0),$C$3&", ","") & IF((COUNTIFS(TableBOM[Product ID],$D$4,TableBOM[Item ID],$A12)>0)*($H$4>0),$C$4&", ",""),LEN(IF((COUNTIFS(TableBOM[Product ID],$D$3,TableBOM[Item ID],$A12)>0)*($H$3>0),$C$3&", ","") & IF((COUNTIFS(TableBOM[Product ID],$D$4,TableBOM[Item ID],$A12)>0)*($H$4>0),$C$4&", ",""))-2),"")
A13: 19 | B13: SLUG | C13: 19X4.5 S/M | D13: kg | E13: =SUMPRODUCT((TableBOM[Item ID]=A13)*TableBOM[Per 1000 Units]*(1+TableBOM[Scrap %])*SUMIF($D$3:$D$4,TableBOM[Product ID],$H$3:$H$4)/1000) -> 0 | F13: =IFERROR(INDEX(TableInventory[Store Balance],MATCH(A13,TableInventory[Item ID],0)),0)+IFERROR(INDEX(TableInventory[Work In Process],MATCH(A13,TableInventory[Item ID],0)),0) -> 425 | G13: =F13-E13 -> 425 | H13: =IFERROR(IF(SUMPRODUCT((TableBOM[Item ID]=A13)*((TableBOM[Product ID]=$D$3)*($H$3>0)+(TableBOM[Product ID]=$D$4)*($H$4>0)))=0,"-",ROUND(F13/((SUMPRODUCT((TableBOM[Item ID]=A13)*TableBOM[Per 1000 Units]*((TableBOM[Product ID]=$D$3)*($H$3>0)+(TableBOM[Product ID]=$D$4)*($H$4>0)))/SUMPRODUCT((TableBOM[Item ID]=A13)*((TableBOM[Product ID]=$D$3)*($H$3>0)+(TableBOM[Product ID]=$D$4)*($H$4>0))))/1000),0)),"-") -> - | I13: =IF(E13=0,"Not needed",IF(G13<0,"SHORTAGE",IF(G13<F13*0.1,"LOW","OK"))) -> Not needed | J13: =IF(LEN(IF((COUNTIFS(TableBOM[Product ID],$D$3,TableBOM[Item ID],$A13)>0)*($H$3>0),$C$3&", ","") & IF((COUNTIFS(TableBOM[Product ID],$D$4,TableBOM[Item ID],$A13)>0)*($H$4>0),$C$4&", ",""))>1,LEFT(IF((COUNTIFS(TableBOM[Product ID],$D$3,TableBOM[Item ID],$A13)>0)*($H$3>0),$C$3&", ","") & IF((COUNTIFS(TableBOM[Product ID],$D$4,TableBOM[Item ID],$A13)>0)*($H$4>0),$C$4&", ",""),LEN(IF((COUNTIFS(TableBOM[Product ID],$D$3,TableBOM[Item ID],$A13)>0)*($H$3>0),$C$3&", ","") & IF((COUNTIFS(TableBOM[Product ID],$D$4,TableBOM[Item ID],$A13)>0)*($H$4>0),$C$4&", ",""))-2),"")
A14: 4179 | B14: SLUG | C14: 20.5x4.5 | D14: kg | E14: =SUMPRODUCT((TableBOM[Item ID]=A14)*TableBOM[Per 1000 Units]*(1+TableBOM[Scrap %])*SUMIF($D$3:$D$4,TableBOM[Product ID],$H$3:$H$4)/1000) -> 0 | F14: =IFERROR(INDEX(TableInventory[Store Balance],MATCH(A14,TableInventory[Item ID],0)),0)+IFERROR(INDEX(TableInventory[Work In Process],MATCH(A14,TableInventory[Item ID],0)),0) -> 132 | G14: =F14-E14 -> 132 | H14: =IFERROR(IF(SUMPRODUCT((TableBOM[Item ID]=A14)*((TableBOM[Product ID]=$D$3)*($H$3>0)+(TableBOM[Product ID]=$D$4)*($H$4>0)))=0,"-",ROUND(F14/((SUMPRODUCT((TableBOM[Item ID]=A14)*TableBOM[Per 1000 Units]*((TableBOM[Product ID]=$D$3)*($H$3>0)+(TableBOM[Product ID]=$D$4)*($H$4>0)))/SUMPRODUCT((TableBOM[Item ID]=A14)*((TableBOM[Product ID]=$D$3)*($H$3>0)+(TableBOM[Product ID]=$D$4)*($H$4>0))))/1000),0)),"-") -> - | I14: =IF(E14=0,"Not needed",IF(G14<0,"SHORTAGE",IF(G14<F14*0.1,"LOW","OK"))) -> Not needed | J14: =IF(LEN(IF((COUNTIFS(TableBOM[Product ID],$D$3,TableBOM[Item ID],$A14)>0)*($H$3>0),$C$3&", ","") & IF((COUNTIFS(TableBOM[Product ID],$D$4,TableBOM[Item ID],$A14)>0)*($H$4>0),$C$4&", ",""))>1,LEFT(IF((COUNTIFS(TableBOM[Product ID],$D$3,TableBOM[Item ID],$A14)>0)*($H$3>0),$C$3&", ","") & IF((COUNTIFS(TableBOM[Product ID],$D$4,TableBOM[Item ID],$A14)>0)*($H$4>0),$C$4&", ",""),LEN(IF((COUNTIFS(TableBOM[Product ID],$D$3,TableBOM[Item ID],$A14)>0)*($H$3>0),$C$3&", ","") & IF((COUNTIFS(TableBOM[Product ID],$D$4,TableBOM[Item ID],$A14)>0)*($H$4>0),$C$4&", ",""))-2),"")
A15: 6 | B15: SLUG | C15: 25X4.5 S/M | D15: kg | E15: =SUMPRODUCT((TableBOM[Item ID]=A15)*TableBOM[Per 1000 Units]*(1+TableBOM[Scrap %])*SUMIF($D$3:$D$4,TableBOM[Product ID],$H$3:$H$4)/1000) -> 0 | F15: =IFERROR(INDEX(TableInventory[Store Balance],MATCH(A15,TableInventory[Item ID],0)),0)+IFERROR(INDEX(TableInventory[Work In Process],MATCH(A15,TableInventory[Item ID],0)),0) -> 25 | G15: =F15-E15 -> 25 | H15: =IFERROR(IF(SUMPRODUCT((TableBOM[Item ID]=A15)*((TableBOM[Product ID]=$D$3)*($H$3>0)+(TableBOM[Product ID]=$D$4)*($H$4>0)))=0,"-",ROUND(F15/((SUMPRODUCT((TableBOM[Item ID]=A15)*TableBOM[Per 1000 Units]*((TableBOM[Product ID]=$D$3)*($H$3>0)+(TableBOM[Product ID]=$D$4)*($H$4>0)))/SUMPRODUCT((TableBOM[Item ID]=A15)*((TableBOM[Product ID]=$D$3)*($H$3>0)+(TableBOM[Product ID]=$D$4)*($H$4>0))))/1000),0)),"-") -> - | I15: =IF(E15=0,"Not needed",IF(G15<0,"SHORTAGE",IF(G15<F15*0.1,"LOW","OK"))) -> Not needed | J15: =IF(LEN(IF((COUNTIFS(TableBOM[Product ID],$D$3,TableBOM[Item ID],$A15)>0)*($H$3>0),$C$3&", ","") & IF((COUNTIFS(TableBOM[Product ID],$D$4,TableBOM[Item ID],$A15)>0)*($H$4>0),$C$4&", ",""))>1,LEFT(IF((COUNTIFS(TableBOM[Product ID],$D$3,TableBOM[Item ID],$A15)>0)*($H$3>0),$C$3&", ","") & IF((COUNTIFS(TableBOM[Product ID],$D$4,TableBOM[Item ID],$A15)>0)*($H$4>0),$C$4&", ",""),LEN(IF((COUNTIFS(TableBOM[Product ID],$D$3,TableBOM[Item ID],$A15)>0)*($H$3>0),$C$3&", ","") & IF((COUNTIFS(TableBOM[Product ID],$D$4,TableBOM[Item ID],$A15)>0)*($H$4>0),$C$4&", ",""))-2),"")
A16: 10 | B16: SLUG | C16: 25X4.8 S/M | D16: kg | E16: =SUMPRODUCT((TableBOM[Item ID]=A16)*TableBOM[Per 1000 Units]*(1+TableBOM[Scrap %])*SUMIF($D$3:$D$4,TableBOM[Product ID],$H$3:$H$4)/1000) -> 0 | F16: =IFERROR(INDEX(TableInventory[Store Balance],MATCH(A16,TableInventory[Item ID],0)),0)+IFERROR(INDEX(TableInventory[Work In Process],MATCH(A16,TableInventory[Item ID],0)),0) -> 0 | G16: =F16-E16 -> 0 | H16: =IFERROR(IF(SUMPRODUCT((TableBOM[Item ID]=A16)*((TableBOM[Product ID]=$D$3)*($H$3>0)+(TableBOM[Product ID]=$D$4)*($H$4>0)))=0,"-",ROUND(F16/((SUMPRODUCT((TableBOM[Item ID]=A16)*TableBOM[Per 1000 Units]*((TableBOM[Product ID]=$D$3)*($H$3>0)+(TableBOM[Product ID]=$D$4)*($H$4>0)))/SUMPRODUCT((TableBOM[Item ID]=A16)*((TableBOM[Product ID]=$D$3)*($H$3>0)+(TableBOM[Product ID]=$D$4)*($H$4>0))))/1000),0)),"-") -> - | I16: =IF(E16=0,"Not needed",IF(G16<0,"SHORTAGE",IF(G16<F16*0.1,"LOW","OK"))) -> Not needed | J16: =IF(LEN(IF((COUNTIFS(TableBOM[Product ID],$D$3,TableBOM[Item ID],$A16)>0)*($H$3>0),$C$3&", ","") & IF((COUNTIFS(TableBOM[Product ID],$D$4,TableBOM[Item ID],$A16)>0)*($H$4>0),$C$4&", ",""))>1,LEFT(IF((COUNTIFS(TableBOM[Product ID],$D$3,TableBOM[Item ID],$A16)>0)*($H$3>0),$C$3&", ","") & IF((COUNTIFS(TableBOM[Product ID],$D$4,TableBOM[Item ID],$A16)>0)*($H$4>0),$C$4&", ",""),LEN(IF((COUNTIFS(TableBOM[Product ID],$D$3,TableBOM[Item ID],$A16)>0)*($H$3>0),$C$3&", ","") & IF((COUNTIFS(TableBOM[Product ID],$D$4,TableBOM[Item ID],$A16)>0)*($H$4>0),$C$4&", ",""))-2),"")
A17: 2 | B17: SLUG | C17: 30X4.3 | D17: kg | E17: =SUMPRODUCT((TableBOM[Item ID]=A17)*TableBOM[Per 1000 Units]*(1+TableBOM[Scrap %])*SUMIF($D$3:$D$4,TableBOM[Product ID],$H$3:$H$4)/1000) -> 0 | F17: =IFERROR(INDEX(TableInventory[Store Balance],MATCH(A17,TableInventory[Item ID],0)),0)+IFERROR(INDEX(TableInventory[Work In Process],MATCH(A17,TableInventory[Item ID],0)),0) -> 0 | G17: =F17-E17 -> 0 | H17: =IFERROR(IF(SUMPRODUCT((TableBOM[Item ID]=A17)*((TableBOM[Product ID]=$D$3)*($H$3>0)+(TableBOM[Product ID]=$D$4)*($H$4>0)))=0,"-",ROUND(F17/((SUMPRODUCT((TableBOM[Item ID]=A17)*TableBOM[Per 1000 Units]*((TableBOM[Product ID]=$D$3)*($H$3>0)+(TableBOM[Product ID]=$D$4)*($H$4>0)))/SUMPRODUCT((TableBOM[Item ID]=A17)*((TableBOM[Product ID]=$D$3)*($H$3>0)+(TableBOM[Product ID]=$D$4)*($H$4>0))))/1000),0)),"-") -> - | I17: =IF(E17=0,"Not needed",IF(G17<0,"SHORTAGE",IF(G17<F17*0.1,"LOW","OK"))) -> Not needed | J17: =IF(LEN(IF((COUNTIFS(TableBOM[Product ID],$D$3,TableBOM[Item ID],$A17)>0)*($H$3>0),$C$3&", ","") & IF((COUNTIFS(TableBOM[Product ID],$D$4,TableBOM[Item ID],$A17)>0)*($H$4>0),$C$4&", ",""))>1,LEFT(IF((COUNTIFS(TableBOM[Product ID],$D$3,TableBOM[Item ID],$A17)>0)*($H$3>0),$C$3&", ","") & IF((COUNTIFS(TableBOM[Product ID],$D$4,TableBOM[Item ID],$A17)>0)*($H$4>0),$C$4&", ",""),LEN(IF((COUNTIFS(TableBOM[Product ID],$D$3,TableBOM[Item ID],$A17)>0)*($H$3>0),$C$3&", ","") & IF((COUNTIFS(TableBOM[Product ID],$D$4,TableBOM[Item ID],$A17)>0)*($H$4>0),$C$4&", ",""))-2),"")
A18: 406 | B18: SLUG | C18: 30X4.5 S/M | D18: kg | E18: =SUMPRODUCT((TableBOM[Item ID]=A18)*TableBOM[Per 1000 Units]*(1+TableBOM[Scrap %])*SUMIF($D$3:$D$4,TableBOM[Product ID],$H$3:$H$4)/1000) -> 691.7856 | F18: =IFERROR(INDEX(TableInventory[Store Balance],MATCH(A18,TableInventory[Item ID],0)),0)+IFERROR(INDEX(TableInventory[Work In Process],MATCH(A18,TableInventory[Item ID],0)),0) -> 105 | G18: =F18-E18 -> -586.7856 | H18: =IFERROR(IF(SUMPRODUCT((TableBOM[Item ID]=A18)*((TableBOM[Product ID]=$D$3)*($H$3>0)+(TableBOM[Product ID]=$D$4)*($H$4>0)))=0,"-",ROUND(F18/((SUMPRODUCT((TableBOM[Item ID]=A18)*TableBOM[Per 1000 Units]*((TableBOM[Product ID]=$D$3)*($H$3>0)+(TableBOM[Product ID]=$D$4)*($H$4>0)))/SUMPRODUCT((TableBOM[Item ID]=A18)*((TableBOM[Product ID]=$D$3)*($H$3>0)+(TableBOM[Product ID]=$D$4)*($H$4>0))))/1000),0)),"-") -> 13125 | I18: =IF(E18=0,"Not needed",IF(G18<0,"SHORTAGE",IF(G18<F18*0.1,"LOW","OK"))) -> SHORTAGE | J18: =IF(LEN(IF((COUNTIFS(TableBOM[Product ID],$D$3,TableBOM[Item ID],$A18)>0)*($H$3>0),$C$3&", ","") & IF((COUNTIFS(TableBOM[Product ID],$D$4,TableBOM[Item ID],$A18)>0)*($H$4>0),$C$4&", ",""))>1,LEFT(IF((COUNTIFS(TableBOM[Product ID],$D$3,TableBOM[Item ID],$A18)>0)*($H$3>0),$C$3&", ","") & IF((COUNTIFS(TableBOM[Product ID],$D$4,TableBOM[Item ID],$A18)>0)*($H$4>0),$C$4&", ",""),LEN(IF((COUNTIFS(TableBOM[Product ID],$D$3,TableBOM[Item ID],$A18)>0)*($H$3>0),$C$3&", ","") & IF((COUNTIFS(TableBOM[Product ID],$D$4,TableBOM[Item ID],$A18)>0)*($H$4>0),$C$4&", ",""))-2),"") -> HELLO HAIR COLOR, VINCE NURTURAL
A19: 6961 | B19: SLUG | C19: 32X5.2 | D19: kg | E19: =SUMPRODUCT((TableBOM[Item ID]=A19)*TableBOM[Per 1000 Units]*(1+TableBOM[Scrap %])*SUMIF($D$3:$D$4,TableBOM[Product ID],$H$3:$H$4)/1000) -> 0 | F19: =IFERROR(INDEX(TableInventory[Store Balance],MATCH(A19,TableInventory[Item ID],0)),0)+IFERROR(INDEX(TableInventory[Work In Process],MATCH(A19,TableInventory[Item ID],0)),0) -> 0 | G19: =F19-E19 -> 0 | H19: =IFERROR(IF(SUMPRODUCT((TableBOM[Item ID]=A19)*((TableBOM[Product ID]=$D$3)*($H$3>0)+(TableBOM[Product ID]=$D$4)*($H$4>0)))=0,"-",ROUND(F19/((SUMPRODUCT((TableBOM[Item ID]=A19)*TableBOM[Per 1000 Units]*((TableBOM[Product ID]=$D$3)*($H$3>0)+(TableBOM[Product ID]=$D$4)*($H$4>0)))/SUMPRODUCT((TableBOM[Item ID]=A19)*((TableBOM[Product ID]=$D$3)*($H$3>0)+(TableBOM[Product ID]=$D$4)*($H$4>0))))/1000),0)),"-") -> - | I19: =IF(E19=0,"Not needed",IF(G19<0,"SHORTAGE",IF(G19<F19*0.1,"LOW","OK"))) -> Not needed | J19: =IF(LEN(IF((COUNTIFS(TableBOM[Product ID],$D$3,TableBOM[Item ID],$A19)>0)*($H$3>0),$C$3&", ","") & IF((COUNTIFS(TableBOM[Product ID],$D$4,TableBOM[Item ID],$A19)>0)*($H$4>0),$C$4&", ",""))>1,LEFT(IF((COUNTIFS(TableBOM[Product ID],$D$3,TableBOM[Item ID],$A19)>0)*($H$3>0),$C$3&", ","") & IF((COUNTIFS(TableBOM[Product ID],$D$4,TableBOM[Item ID],$A19)>0)*($H$4>0),$C$4&", ",""),LEN(IF((COUNTIFS(TableBOM[Product ID],$D$3,TableBOM[Item ID],$A19)>0)*($H$3>0),$C$3&", ","") & IF((COUNTIFS(TableBOM[Product ID],$D$4,TableBOM[Item ID],$A19)>0)*($H$4>0),$C$4&", ",""))-2),"")
... A89: 3043 | B89: PACKING | C89: PLASTIC DOORI | D89: ROLL | E89: =SUMPRODUCT((TableBOM[Item ID]=A89)*TableBOM[Per 1000 Units]*(1+TableBOM[Scrap %])*SUMIF($D$3:$D$4,TableBOM[Product ID],$H$3:$H$4)/1000) -> 0 | F89: =IFERROR(INDEX(TableInventory[Store Balance],MATCH(A89,TableInventory[Item ID],0)),0)+IFERROR(INDEX(TableInventory[Work In Process],MATCH(A89,TableInventory[Item ID],0)),0) -> 0 | G89: =F89-E89 -> 0 | H89: =IFERROR(IF(SUMPRODUCT((TableBOM[Item ID]=A89)*((TableBOM[Product ID]=$D$3)*($H$3>0)+(TableBOM[Product ID]=$D$4)*($H$4>0)))=0,"-",ROUND(F89/((SUMPRODUCT((TableBOM[Item ID]=A89)*TableBOM[Per 1000 Units]*((TableBOM[Product ID]=$D$3)*($H$3>0)+(TableBOM[Product ID]=$D$4)*($H$4>0)))/SUMPRODUCT((TableBOM[Item ID]=A89)*((TableBOM[Product ID]=$D$3)*($H$3>0)+(TableBOM[Product ID]=$D$4)*($H$4>0))))/1000),0)),"-") -> - | I89: =IF(E89=0,"Not needed",IF(G89<0,"SHORTAGE",IF(G89<F89*0.1,"LOW","OK"))) -> Not needed | J89: =IF(LEN(IF((COUNTIFS(TableBOM[Product ID],$D$3,TableBOM[Item ID],$A89)>0)*($H$3>0),$C$3&", ","") & IF((COUNTIFS(TableBOM[Product ID],$D$4,TableBOM[Item ID],$A89)>0)*($H$4>0),$C$4&", ",""))>1,LEFT(IF((COUNTIFS(TableBOM[Product ID],$D$3,TableBOM[Item ID],$A89)>0)*($H$3>0),$C$3&", ","") & IF((COUNTIFS(TableBOM[Product ID],$D$4,TableBOM[Item ID],$A89)>0)*($H$4>0),$C$4&", ",""),LEN(IF((COUNTIFS(TableBOM[Product ID],$D$3,TableBOM[Item ID],$A89)>0)*($H$3>0),$C$3&", ","") & IF((COUNTIFS(TableBOM[Product ID],$D$4,TableBOM[Item ID],$A89)>0)*($H$4>0),$C$4&", ",""))-2),"")
A92: AUGUST 2026 PET Required Pet Orders
A93: Dia | B93: Customer | C93: Product Name | D93: Product ID | E93: Job Order # | F93: Required Qty | G93: Produced | H93: Remaining Balance | I93: Remarks
A94: 120 ml | B94: Samsol International Private Limited | C94: Samsol Yellow 120ml | D94: 8005 | E94: 337, 345 & 350 | F94: =7160+30000+35000 -> 72160 | G94: =INDEX(Tubex_Dashboard!$H$11:$H$100,MATCH(MRP!D94,Tubex_Dashboard!$F$11:$F$100,0)) -> 0 | H94: =F94-G94 -> 72160
A95: 130 ml | B95: Mablay Beauty PVT LTD. | C95: Mablay 130ml White | D95: 8015 | E95: 344 | F95: 15000 | G95: =INDEX(Tubex_Dashboard!$H$11:$H$100,MATCH(MRP!D95,Tubex_Dashboard!$F$11:$F$100,0)) -> 0 | H95: =F95-G95 -> 15000
A96: 130 ml | B96: Mablay Beauty PVT LTD. | C96: Mablay 130ml TRP | D96: 8010 | E96: 349 | F96: 25000 | G96: =INDEX(Tubex_Dashboard!$H$11:$H$100,MATCH(MRP!D96,Tubex_Dashboard!$F$11:$F$100,0)) -> 0 | H96: =F96-G96 -> 25000
A97: 150 ml | B97: Alpha Labs PVT LTD | C97: Alpha 150ml TRP | D97: 8001 | E97: 341 & 347 | F97: =100000+116667-15410+500000 -> 701257 | G97: =INDEX(Tubex_Dashboard!$H$11:$H$100,MATCH(MRP!D97,Tubex_Dashboard!$F$11:$F$100,0)) -> 90735 | H97: =F97-G97 -> 610522 | I97: 15k Rejected
A98: 150 ml | B98: Horizon Chem | C98: Horizon 150ml TRP | D98: 8017 | E98: 346 | F98: 13960 | G98: =INDEX(Tubex_Dashboard!$H$11:$H$100,MATCH(MRP!D98,Tubex_Dashboard!$F$11:$F$100,0)) -> 0 | H98: =F98-G98 -> 13960
A99: 200 ml | B99: Samsol International Private Limited | C99: Samsol Yellow 200ml | D99: 8006 | E99: 351 | F99: 47000 | G99: =INDEX(Tubex_Dashboard!$H$11:$H$100,MATCH(MRP!D99,Tubex_Dashboard!$F$11:$F$100,0)) -> 0 | H99: =F99-G99 -> 47000
E100: TOTAL: | F100: =SUM(F94:F99) -> 874377 | G100: =SUM(G94:G99) -> 90735 | H100: =SUMIF(H94:H99, ">0") -> 783642
A101: AUGUST PET MATERIAL REQUIREMENT PLAN
A102: Item ID | B102: Category | C102: Item Name | D102: UOM | E102: Required Qty | F102: Current Stock (Store + WIP) | G102: Surplus / (Deficit) | H102: Current Stock Pieces Can Produce | I102: Status | J102: Product Name(s)
A103: 2680 | B103: PET RESIN | C103: PET RESIN A-84 | D103: kg | E103: =SUMPRODUCT((TableBOM[Item ID]=A103)*TableBOM[Per 1000 Units]*(1+TableBOM[Scrap %])*SUMIF($D$94:$D$99,TableBOM[Product ID],$H$94:$H$99)/1000) -> 19314.583 | F103: =IFERROR(INDEX(TableInventory[Store Balance],MATCH(A103,TableInventory[Item ID],0)),0)+IFERROR(INDEX(TableInventory[Work In Process],MATCH(A103,TableInventory[Item ID],0)),0) -> 1500 | G103: =F103-E103 -> -17814.583 | H103: =IFERROR(IF(SUMPRODUCT((TableBOM[Item ID]=A103)*((SUMIF($D$94:$D$99,TableBOM[Product ID],$H$94:$H$99))>0)*(SUMIF($D$94:$D$99,TableBOM[Product ID],$H$94:$H$99))*TableBOM[Per 1000 Units])=0,"-",ROUND(F103*1000*SUMPRODUCT((TableBOM[Item ID]=A103)*((SUMIF($D$94:$D$99,TableBOM[Product ID],$H$94:$H$99))>0)*(SUMIF($D$94:$D$99,TableBOM[Product ID],$H$94:$H$99)))/SUMPRODUCT((TableBOM[Item ID]=A103)*((SUMIF($D$94:$D$99,TableBOM[Product ID],$H$94:$H$99))>0)*(SUMIF($D$94:$D$99,TableBOM[Product ID],$H$94:$H$99))*TableBOM[Per 1000 Units]),0)),"-") -> 69988 | I103: =IF(E103=0,"Not needed",IF(G103<0,"SHORTAGE",IF(G103<F103*0.1,"LOW","OK"))) -> SHORTAGE | J103: =IF(LEN(IF((COUNTIFS(TableBOM[Product ID],$D$94,TableBOM[Item ID],$A103)>0)*($H$94>0),$C$94&", ","") & IF((COUNTIFS(TableBOM[Product ID],$D$95,TableBOM[Item ID],$A103)>0)*($H$95>0),$C$95&", ","") & IF((COUNTIFS(TableBOM[Product ID],$D$96,TableBOM[Item ID],$A103)>0)*($H$96>0),$C$96&", ","") & IF((COUNTIFS(TableBOM[Product ID],$D$97,TableBOM[Item ID],$A103)>0)*($H$97>0),$C$97&", ","") & IF((COUNTIFS(TableBOM[Product ID],$D$98,TableBOM[Item ID],$A103)>0)*($H$98>0),$C$98&", ","") & IF((COUNTIFS(TableBOM[Product ID],$D$99,TableBOM[Item ID],$A103)>0)*($H$99>0),$C$99&", ",""))>1,LEFT(IF((COUNTIFS(TableBOM[Product ID],$D$94,TableBOM[Item ID],$A103)>0)*($H$94>0),$C$94&", ","") & IF((COUNTIFS(TableBOM[Product ID],$D$95,TableBOM[Item ID],$A103)>0)*($H$95>0),$C$95&", ","") & IF((COUNTIFS(TableBOM[Product ID],$D$96,TableBOM[Item ID],$A103)>0)*($H$96>0),$C$96&", ","") & IF((COUNTIFS(TableBOM[Product ID],$D$97,TableBOM[Item ID],$A103)>0)*($H$97>0),$C$97&", ","") & IF((COUNTIFS(TableBOM[Product ID],$D$98,TableBOM[Item ID],$A103)>0)*($H$98>0),$C$98&", ","") & IF((COUNTIFS(TableBOM[Product ID],$D$99,TableBOM[Item ID],$A103)>0)*($H$99>0),$C$99&", ",""),LEN(IF((COUNTIFS(TableBOM[Product ID],$D$94,TableBOM[Item ID],$A103)>0)*($H$94>0),$C$94&", ","") & IF((COUNTIFS(TableBOM[Product ID],$D$95,TableBOM[Item ID],$A103)>0)*($H$95>0),$C$95&", ","") & IF((COUNTIFS(TableBOM[Product ID],$D$96,TableBOM[Item ID],$A103)>0)*($H$96>0),$C$96&", ","") & IF((COUNTIFS(TableBOM[Product ID],$D$97,TableBOM[Item ID],$A103)>0)*($H$97>0),$C$97&", ","") & IF((COUNTIFS(TableBOM[Product ID],$D$98,TableBOM[Item ID],$A103)>0)*($H$98>0),$C$98&", ","") & IF((COUNTIFS(TableBOM[Product ID],$D$99,TableBOM[Item ID],$A103)>0)*($H$99>0),$C$99&", ",""))-2),"") -> Samsol Yellow 120ml, Mablay 130ml White, Mablay 130ml TRP, Alpha 150ml TRP, Horizon 150ml TRP, Samsol Yellow 200ml
A104: 4002 | B104: MASTER BATCH | C104: MASTER BATCH YELLOW CMN# 3087 | D104: kg | E104: =SUMPRODUCT((TableBOM[Item ID]=A104)*TableBOM[Per 1000 Units]*(1+TableBOM[Scrap %])*SUMIF($D$94:$D$99,TableBOM[Product ID],$H$94:$H$99)/1000) -> 142.2481 | F104: =IFERROR(INDEX(TableInventory[Store Balance],MATCH(A104,TableInventory[Item ID],0)),0)+IFERROR(INDEX(TableInventory[Work In Process],MATCH(A104,TableInventory[Item ID],0)),0) -> 125 | G104: =F104-E104 -> -17.2481 | H104: =IFERROR(IF(SUMPRODUCT((TableBOM[Item ID]=A104)*((SUMIF($D$94:$D$99,TableBOM[Product ID],$H$94:$H$99))>0)*(SUMIF($D$94:$D$99,TableBOM[Product ID],$H$94:$H$99))*TableBOM[Per 1000 Units])=0,"-",ROUND(F104*1000*SUMPRODUCT((TableBOM[Item ID]=A104)*((SUMIF($D$94:$D$99,TableBOM[Product ID],$H$94:$H$99))>0)*(SUMIF($D$94:$D$99,TableBOM[Product ID],$H$94:$H$99)))/SUMPRODUCT((TableBOM[Item ID]=A104)*((SUMIF($D$94:$D$99,TableBOM[Product ID],$H$94:$H$99))>0)*(SUMIF($D$94:$D$99,TableBOM[Product ID],$H$94:$H$99))*TableBOM[Per 1000 Units]),0)),"-") -> 120418 | I104: =IF(E104=0,"Not needed",IF(G104<0,"SHORTAGE",IF(G104<F104*0.1,"LOW","OK"))) -> SHORTAGE | J104: =IF(LEN(IF((COUNTIFS(TableBOM[Product ID],$D$94,TableBOM[Item ID],$A104)>0)*($H$94>0),$C$94&", ","") & IF((COUNTIFS(TableBOM[Product ID],$D$95,TableBOM[Item ID],$A104)>0)*($H$95>0),$C$95&", ","") & IF((COUNTIFS(TableBOM[Product ID],$D$96,TableBOM[Item ID],$A104)>0)*($H$96>0),$C$96&", ","") & IF((COUNTIFS(TableBOM[Product ID],$D$97,TableBOM[Item ID],$A104)>0)*($H$97>0),$C$97&", ","") & IF((COUNTIFS(TableBOM[Product ID],$D$98,TableBOM[Item ID],$A104)>0)*($H$98>0),$C$98&", ","") & IF((COUNTIFS(TableBOM[Product ID],$D$99,TableBOM[Item ID],$A104)>0)*($H$99>0),$C$99&", ",""))>1,LEFT(IF((COUNTIFS(TableBOM[Product ID],$D$94,TableBOM[Item ID],$A104)>0)*($H$94>0),$C$94&", ","") & IF((COUNTIFS(TableBOM[Product ID],$D$95,TableBOM[Item ID],$A104)>0)*($H$95>0),$C$95&", ","") & IF((COUNTIFS(TableBOM[Product ID],$D$96,TableBOM[Item ID],$A104)>0)*($H$96>0),$C$96&", ","") & IF((COUNTIFS(TableBOM[Product ID],$D$97,TableBOM[Item ID],$A104)>0)*($H$97>0),$C$97&", ","") & IF((COUNTIFS(TableBOM[Product ID],$D$98,TableBOM[Item ID],$A104)>0)*($H$98>0),$C$98&", ","") & IF((COUNTIFS(TableBOM[Product ID],$D$99,TableBOM[Item ID],$A104)>0)*($H$99>0),$C$99&", ",""),LEN(IF((COUNTIFS(TableBOM[Product ID],$D$94,TableBOM[Item ID],$A104)>0)*($H$94>0),$C$94&", ","") & IF((COUNTIFS(TableBOM[Product ID],$D$95,TableBOM[Item ID],$A104)>0)*($H$95>0),$C$95&", ","") & IF((COUNTIFS(TableBOM[Product ID],$D$96,TableBOM[Item ID],$A104)>0)*($H$96>0),$C$96&", ","") & IF((COUNTIFS(TableBOM[Product ID],$D$97,TableBOM[Item ID],$A104)>0)*($H$97>0),$C$97&", ","") & IF((COUNTIFS(TableBOM[Product ID],$D$98,TableBOM[Item ID],$A104)>0)*($H$98>0),$C$98&", ","") & IF((COUNTIFS(TableBOM[Product ID],$D$99,TableBOM[Item ID],$A104)>0)*($H$99>0),$C$99&", ",""))-2),"") -> Samsol Yellow 120ml, Samsol Yellow 200ml
A105: 5816 | B105: MASTER BATCH | C105: MASTER BATCH WHITE PRC-MC ET02340000 | D105: kg | E105: =SUMPRODUCT((TableBOM[Item ID]=A105)*TableBOM[Per 1000 Units]*(1+TableBOM[Scrap %])*SUMIF($D$94:$D$99,TableBOM[Product ID],$H$94:$H$99)/1000) -> 15.525 | F105: =IFERROR(INDEX(TableInventory[Store Balance],MATCH(A105,TableInventory[Item ID],0)),0)+IFERROR(INDEX(TableInventory[Work In Process],MATCH(A105,TableInventory[Item ID],0)),0) -> 25 | G105: =F105-E105 -> 9.475 | H105: =IFERROR(IF(SUMPRODUCT((TableBOM[Item ID]=A105)*((SUMIF($D$94:$D$99,TableBOM[Product ID],$H$94:$H$99))>0)*(SUMIF($D$94:$D$99,TableBOM[Product ID],$H$94:$H$99))*TableBOM[Per 1000 Units])=0,"-",ROUND(F105*1000*SUMPRODUCT((TableBOM[Item ID]=A105)*((SUMIF($D$94:$D$99,TableBOM[Product ID],$H$94:$H$99))>0)*(SUMIF($D$94:$D$99,TableBOM[Product ID],$H$94:$H$99)))/SUMPRODUCT((TableBOM[Item ID]=A105)*((SUMIF($D$94:$D$99,TableBOM[Product ID],$H$94:$H$99))>0)*(SUMIF($D$94:$D$99,TableBOM[Product ID],$H$94:$H$99))*TableBOM[Per 1000 Units]),0)),"-") -> 27778 | I105: =IF(E105=0,"Not needed",IF(G105<0,"SHORTAGE",IF(G105<F105*0.1,"LOW","OK"))) -> OK | J105: =IF(LEN(IF((COUNTIFS(TableBOM[Product ID],$D$94,TableBOM[Item ID],$A105)>0)*($H$94>0),$C$94&", ","") & IF((COUNTIFS(TableBOM[Product ID],$D$95,TableBOM[Item ID],$A105)>0)*($H$95>0),$C$95&", ","") & IF((COUNTIFS(TableBOM[Product ID],$D$96,TableBOM[Item ID],$A105)>0)*($H$96>0),$C$96&", ","") & IF((COUNTIFS(TableBOM[Product ID],$D$97,TableBOM[Item ID],$A105)>0)*($H$97>0),$C$97&", ","") & IF((COUNTIFS(TableBOM[Product ID],$D$98,TableBOM[Item ID],$A105)>0)*($H$98>0),$C$98&", ","") & IF((COUNTIFS(TableBOM[Product ID],$D$99,TableBOM[Item ID],$A105)>0)*($H$99>0),$C$99&", ",""))>1,LEFT(IF((COUNTIFS(TableBOM[Product ID],$D$94,TableBOM[Item ID],$A105)>0)*($H$94>0),$C$94&", ","") & IF((COUNTIFS(TableBOM[Product ID],$D$95,TableBOM[Item ID],$A105)>0)*($H$95>0),$C$95&", ","") & IF((COUNTIFS(TableBOM[Product ID],$D$96,TableBOM[Item ID],$A105)>0)*($H$96>0),$C$96&", ","") & IF((COUNTIFS(TableBOM[Product ID],$D$97,TableBOM[Item ID],$A105)>0)*($H$97>0),$C$97&", ","") & IF((COUNTIFS(TableBOM[Product ID],$D$98,TableBOM[Item ID],$A105)>0)*($H$98>0),$C$98&", ","") & IF((COUNTIFS(TableBOM[Product ID],$D$99,TableBOM[Item ID],$A105)>0)*($H$99>0),$C$99&", ",""),LEN(IF((COUNTIFS(TableBOM[Product ID],$D$94,TableBOM[Item ID],$A105)>0)*($H$94>0),$C$94&", ","") & IF((COUNTIFS(TableBOM[Product ID],$D$95,TableBOM[Item ID],$A105)>0)*($H$95>0),$C$95&", ","") & IF((COUNTIFS(TableBOM[Product ID],$D$96,TableBOM[Item ID],$A105)>0)*($H$96>0),$C$96&", ","") & IF((COUNTIFS(TableBOM[Product ID],$D$97,TableBOM[Item ID],$A105)>0)*($H$97>0),$C$97&", ","") & IF((COUNTIFS(TableBOM[Product ID],$D$98,TableBOM[Item ID],$A105)>0)*($H$98>0),$C$98&", ","") & IF((COUNTIFS(TableBOM[Product ID],$D$99,TableBOM[Item ID],$A105)>0)*($H$99>0),$C$99&", ",""))-2),"") -> Mablay 130ml White
A106: 5977 | B106: Carton | C106: MASTER CARTON 38"X24"X15.5" | D106: PCS | E106: =SUMPRODUCT((TableBOM[Item ID]=A106)*TableBOM[Per 1000 Units]*(1+TableBOM[Scrap %])*SUMIF($D$94:$D$99,TableBOM[Product ID],$H$94:$H$99)/1000) -> 857.31572 | F106: =IFERROR(INDEX(TableInventory[Store Balance],MATCH(A106,TableInventory[Item ID],0)),0)+IFERROR(INDEX(TableInventory[Work In Process],MATCH(A106,TableInventory[Item ID],0)),0) -> 212 | G106: =F106-E106 -> -645.31572 | H106: =IFERROR(IF(SUMPRODUCT((TableBOM[Item ID]=A106)*((SUMIF($D$94:$D$99,TableBOM[Product ID],$H$94:$H$99))>0)*(SUMIF($D$94:$D$99,TableBOM[Product ID],$H$94:$H$99))*TableBOM[Per 1000 Units])=0,"-",ROUND(F106*1000*SUMPRODUCT((TableBOM[Item ID]=A106)*((SUMIF($D$94:$D$99,TableBOM[Product ID],$H$94:$H$99))>0)*(SUMIF($D$94:$D$99,TableBOM[Product ID],$H$94:$H$99)))/SUMPRODUCT((TableBOM[Item ID]=A106)*((SUMIF($D$94:$D$99,TableBOM[Product ID],$H$94:$H$99))>0)*(SUMIF($D$94:$D$99,TableBOM[Product ID],$H$94:$H$99))*TableBOM[Per 1000 Units]),0)),"-") -> 188963 | I106: =IF(E106=0,"Not needed",IF(G106<0,"SHORTAGE",IF(G106<F106*0.1,"LOW","OK"))) -> SHORTAGE | J106: =IF(LEN(IF((COUNTIFS(TableBOM[Product ID],$D$94,TableBOM[Item ID],$A106)>0)*($H$94>0),$C$94&", ","") & IF((COUNTIFS(TableBOM[Product ID],$D$95,TableBOM[Item ID],$A106)>0)*($H$95>0),$C$95&", ","") & IF((COUNTIFS(TableBOM[Product ID],$D$96,TableBOM[Item ID],$A106)>0)*($H$96>0),$C$96&", ","") & IF((COUNTIFS(TableBOM[Product ID],$D$97,TableBOM[Item ID],$A106)>0)*($H$97>0),$C$97&", ","") & IF((COUNTIFS(TableBOM[Product ID],$D$98,TableBOM[Item ID],$A106)>0)*($H$98>0),$C$98&", ","") & IF((COUNTIFS(TableBOM[Product ID],$D$99,TableBOM[Item ID],$A106)>0)*($H$99>0),$C$99&", ",""))>1,LEFT(IF((COUNTIFS(TableBOM[Product ID],$D$94,TableBOM[Item ID],$A106)>0)*($H$94>0),$C$94&", ","") & IF((COUNTIFS(TableBOM[Product ID],$D$95,TableBOM[Item ID],$A106)>0)*($H$95>0),$C$95&", ","") & IF((COUNTIFS(TableBOM[Product ID],$D$96,TableBOM[Item ID],$A106)>0)*($H$96>0),$C$96&", ","") & IF((COUNTIFS(TableBOM[Product ID],$D$97,TableBOM[Item ID],$A106)>0)*($H$97>0),$C$97&", ","") & IF((COUNTIFS(TableBOM[Product ID],$D$98,TableBOM[Item ID],$A106)>0)*($H$98>0),$C$98&", ","") & IF((COUNTIFS(TableBOM[Product ID],$D$99,TableBOM[Item ID],$A106)>0)*($H$99>0),$C$99&", ",""),LEN(IF((COUNTIFS(TableBOM[Product ID],$D$94,TableBOM[Item ID],$A106)>0)*($H$94>0),$C$94&", ","") & IF((COUNTIFS(TableBOM[Product ID],$D$95,TableBOM[Item ID],$A106)>0)*($H$95>0),$C$95&", ","") & IF((COUNTIFS(TableBOM[Product ID],$D$96,TableBOM[Item ID],$A106)>0)*($H$96>0),$C$96&", ","") & IF((COUNTIFS(TableBOM[Product ID],$D$97,TableBOM[Item ID],$A106)>0)*($H$97>0),$C$97&", ","") & IF((COUNTIFS(TableBOM[Product ID],$D$98,TableBOM[Item ID],$A106)>0)*($H$98>0),$C$98&", ","") & IF((COUNTIFS(TableBOM[Product ID],$D$99,TableBOM[Item ID],$A106)>0)*($H$99>0),$C$99&", ",""))-2),"") -> Mablay 130ml White, Mablay 130ml TRP, Alpha 150ml TRP, Horizon 150ml TRP
A107: 2267 | B107: Poly Bag | C107: POLY BAG 20X30 (LDPE) | D107: PCS | E107: =SUMPRODUCT((TableBOM[Item ID]=A107)*TableBOM[Per 1000 Units]*(1+TableBOM[Scrap %])*SUMIF($D$94:$D$99,TableBOM[Product ID],$H$94:$H$99)/1000) -> 7396.5755 | F107: =IFERROR(INDEX(TableInventory[Store Balance],MATCH(A107,TableInventory[Item ID],0)),0)+IFERROR(INDEX(TableInventory[Work In Process],MATCH(A107,TableInventory[Item ID],0)),0) -> 182 | G107: =F107-E107 -> -7214.5755 | H107: =IFERROR(IF(SUMPRODUCT((TableBOM[Item ID]=A107)*((SUMIF($D$94:$D$99,TableBOM[Product ID],$H$94:$H$99))>0)*(SUMIF($D$94:$D$99,TableBOM[Product ID],$H$94:$H$99))*TableBOM[Per 1000 Units])=0,"-",ROUND(F107*1000*SUMPRODUCT((TableBOM[Item ID]=A107)*((SUMIF($D$94:$D$99,TableBOM[Product ID],$H$94:$H$99))>0)*(SUMIF($D$94:$D$99,TableBOM[Product ID],$H$94:$H$99)))/SUMPRODUCT((TableBOM[Item ID]=A107)*((SUMIF($D$94:$D$99,TableBOM[Product ID],$H$94:$H$99))>0)*(SUMIF($D$94:$D$99,TableBOM[Product ID],$H$94:$H$99))*TableBOM[Per 1000 Units]),0)),"-") -> 20845 | I107: =IF(E107=0,"Not needed",IF(G107<0,"SHORTAGE",IF(G107<F107*0.1,"LOW","OK"))) -> SHORTAGE | J107: =IF(LEN(IF((COUNTIFS(TableBOM[Product ID],$D$94,TableBOM[Item ID],$A107)>0)*($H$94>0),$C$94&", ","") & IF((COUNTIFS(TableBOM[Product ID],$D$95,TableBOM[Item ID],$A107)>0)*($H$95>0),$C$95&", ","") & IF((COUNTIFS(TableBOM[Product ID],$D$96,TableBOM[Item ID],$A107)>0)*($H$96>0),$C$96&", ","") & IF((COUNTIFS(TableBOM[Product ID],$D$97,TableBOM[Item ID],$A107)>0)*($H$97>0),$C$97&", ","") & IF((COUNTIFS(TableBOM[Product ID],$D$98,TableBOM[Item ID],$A107)>0)*($H$98>0),$C$98&", ","") & IF((COUNTIFS(TableBOM[Product ID],$D$99,TableBOM[Item ID],$A107)>0)*($H$99>0),$C$99&", ",""))>1,LEFT(IF((COUNTIFS(TableBOM[Product ID],$D$94,TableBOM[Item ID],$A107)>0)*($H$94>0),$C$94&", ","") & IF((COUNTIFS(TableBOM[Product ID],$D$95,TableBOM[Item ID],$A107)>0)*($H$95>0),$C$95&", ","") & IF((COUNTIFS(TableBOM[Product ID],$D$96,TableBOM[Item ID],$A107)>0)*($H$96>0),$C$96&", ","") & IF((COUNTIFS(TableBOM[Product ID],$D$97,TableBOM[Item ID],$A107)>0)*($H$97>0),$C$97&", ","") & IF((COUNTIFS(TableBOM[Product ID],$D$98,TableBOM[Item ID],$A107)>0)*($H$98>0),$C$98&", ","") & IF((COUNTIFS(TableBOM[Product ID],$D$99,TableBOM[Item ID],$A107)>0)*($H$99>0),$C$99&", ",""),LEN(IF((COUNTIFS(TableBOM[Product ID],$D$94,TableBOM[Item ID],$A107)>0)*($H$94>0),$C$94&", ","") & IF((COUNTIFS(TableBOM[Product ID],$D$95,TableBOM[Item ID],$A107)>0)*($H$95>0),$C$95&", ","") & IF((COUNTIFS(TableBOM[Product ID],$D$96,TableBOM[Item ID],$A107)>0)*($H$96>0),$C$96&", ","") & IF((COUNTIFS(TableBOM[Product ID],$D$97,TableBOM[Item ID],$A107)>0)*($H$97>0),$C$97&", ","") & IF((COUNTIFS(TableBOM[Product ID],$D$98,TableBOM[Item ID],$A107)>0)*($H$98>0),$C$98&", ","") & IF((COUNTIFS(TableBOM[Product ID],$D$99,TableBOM[Item ID],$A107)>0)*($H$99>0),$C$99&", ",""))-2),"") -> Samsol Yellow 120ml, Mablay 130ml White, Mablay 130ml TRP, Alpha 150ml TRP, Horizon 150ml TRP
A108: 3006 | B108: Poly Bag | C108: POLY BAG 24X36 (LDPE) | D108: PCS | E108: =SUMPRODUCT((TableBOM[Item ID]=A108)*TableBOM[Per 1000 Units]*(1+TableBOM[Scrap %])*SUMIF($D$94:$D$99,TableBOM[Product ID],$H$94:$H$99)/1000) -> 450.39865 | F108: =IFERROR(INDEX(TableInventory[Store Balance],MATCH(A108,TableInventory[Item ID],0)),0)+IFERROR(INDEX(TableInventory[Work In Process],MATCH(A108,TableInventory[Item ID],0)),0) -> 232 | G108: =F108-E108 -> -218.39865 | H108: =IFERROR(IF(SUMPRODUCT((TableBOM[Item ID]=A108)*((SUMIF($D$94:$D$99,TableBOM[Product ID],$H$94:$H$99))>0)*(SUMIF($D$94:$D$99,TableBOM[Product ID],$H$94:$H$99))*TableBOM[Per 1000 Units])=0,"-",ROUND(F108*1000*SUMPRODUCT((TableBOM[Item ID]=A108)*((SUMIF($D$94:$D$99,TableBOM[Product ID],$H$94:$H$99))>0)*(SUMIF($D$94:$D$99,TableBOM[Product ID],$H$94:$H$99)))/SUMPRODUCT((TableBOM[Item ID]=A108)*((SUMIF($D$94:$D$99,TableBOM[Product ID],$H$94:$H$99))>0)*(SUMIF($D$94:$D$99,TableBOM[Product ID],$H$94:$H$99))*TableBOM[Per 1000 Units]),0)),"-") -> 27841 | I108: =IF(E108=0,"Not needed",IF(G108<0,"SHORTAGE",IF(G108<F108*0.1,"LOW","OK"))) -> SHORTAGE | J108: =IF(LEN(IF((COUNTIFS(TableBOM[Product ID],$D$94,TableBOM[Item ID],$A108)>0)*($H$94>0),$C$94&", ","") & IF((COUNTIFS(TableBOM[Product ID],$D$95,TableBOM[Item ID],$A108)>0)*($H$95>0),$C$95&", ","") & IF((COUNTIFS(TableBOM[Product ID],$D$96,TableBOM[Item ID],$A108)>0)*($H$96>0),$C$96&", ","") & IF((COUNTIFS(TableBOM[Product ID],$D$97,TableBOM[Item ID],$A108)>0)*($H$97>0),$C$97&", ","") & IF((COUNTIFS(TableBOM[Product ID],$D$98,TableBOM[Item ID],$A108)>0)*($H$98>0),$C$98&", ","") & IF((COUNTIFS(TableBOM[Product ID],$D$99,TableBOM[Item ID],$A108)>0)*($H$99>0),$C$99&", ",""))>1,LEFT(IF((COUNTIFS(TableBOM[Product ID],$D$94,TableBOM[Item ID],$A108)>0)*($H$94>0),$C$94&", ","") & IF((COUNTIFS(TableBOM[Product ID],$D$95,TableBOM[Item ID],$A108)>0)*($H$95>0),$C$95&", ","") & IF((COUNTIFS(TableBOM[Product ID],$D$96,TableBOM[Item ID],$A108)>0)*($H$96>0),$C$96&", ","") & IF((COUNTIFS(TableBOM[Product ID],$D$97,TableBOM[Item ID],$A108)>0)*($H$97>0),$C$97&", ","") & IF((COUNTIFS(TableBOM[Product ID],$D$98,TableBOM[Item ID],$A108)>0)*($H$98>0),$C$98&", ","") & IF((COUNTIFS(TableBOM[Product ID],$D$99,TableBOM[Item ID],$A108)>0)*($H$99>0),$C$99&", ",""),LEN(IF((COUNTIFS(TableBOM[Product ID],$D$94,TableBOM[Item ID],$A108)>0)*($H$94>0),$C$94&", ","") & IF((COUNTIFS(TableBOM[Product ID],$D$95,TableBOM[Item ID],$A108)>0)*($H$95>0),$C$95&", ","") & IF((COUNTIFS(TableBOM[Product ID],$D$96,TableBOM[Item ID],$A108)>0)*($H$96>0),$C$96&", ","") & IF((COUNTIFS(TableBOM[Product ID],$D$97,TableBOM[Item ID],$A108)>0)*($H$97>0),$C$97&", ","") & IF((COUNTIFS(TableBOM[Product ID],$D$98,TableBOM[Item ID],$A108)>0)*($H$98>0),$C$98&", ","") & IF((COUNTIFS(TableBOM[Product ID],$D$99,TableBOM[Item ID],$A108)>0)*($H$99>0),$C$99&", ",""))-2),"") -> Samsol Yellow 200ml
A109: 3043 | B109: PACKING | C109: PLASTIC DOORI | D109: ROLL | E109: =SUMPRODUCT((TableBOM[Item ID]=A109)*TableBOM[Per 1000 Units]*(1+TableBOM[Scrap %])*SUMIF($D$94:$D$99,TableBOM[Product ID],$H$94:$H$99)/1000) -> 4.5059415 | F109: =IFERROR(INDEX(TableInventory[Store Balance],MATCH(A109,TableInventory[Item ID],0)),0)+IFERROR(INDEX(TableInventory[Work In Process],MATCH(A109,TableInventory[Item ID],0)),0) -> 0 | G109: =F109-E109 -> -4.5059415 | H109: =IFERROR(IF(SUMPRODUCT((TableBOM[Item ID]=A109)*((SUMIF($D$94:$D$99,TableBOM[Product ID],$H$94:$H$99))>0)*(SUMIF($D$94:$D$99,TableBOM[Product ID],$H$94:$H$99))*TableBOM[Per 1000 Units])=0,"-",ROUND(F109*1000*SUMPRODUCT((TableBOM[Item ID]=A109)*((SUMIF($D$94:$D$99,TableBOM[Product ID],$H$94:$H$99))>0)*(SUMIF($D$94:$D$99,TableBOM[Product ID],$H$94:$H$99)))/SUMPRODUCT((TableBOM[Item ID]=A109)*((SUMIF($D$94:$D$99,TableBOM[Product ID],$H$94:$H$99))>0)*(SUMIF($D$94:$D$99,TableBOM[Product ID],$H$94:$H$99))*TableBOM[Per 1000 Units]),0)),"-") -> 0 | I109: =IF(E109=0,"Not needed",IF(G109<0,"SHORTAGE",IF(G109<F109*0.1,"LOW","OK"))) -> SHORTAGE | J109: =IF(LEN(IF((COUNTIFS(TableBOM[Product ID],$D$94,TableBOM[Item ID],$A109)>0)*($H$94>0),$C$94&", ","") & IF((COUNTIFS(TableBOM[Product ID],$D$95,TableBOM[Item ID],$A109)>0)*($H$95>0),$C$95&", ","") & IF((COUNTIFS(TableBOM[Product ID],$D$96,TableBOM[Item ID],$A109)>0)*($H$96>0),$C$96&", ","") & IF((COUNTIFS(TableBOM[Product ID],$D$97,TableBOM[Item ID],$A109)>0)*($H$97>0),$C$97&", ","") & IF((COUNTIFS(TableBOM[Product ID],$D$98,TableBOM[Item ID],$A109)>0)*($H$98>0),$C$98&", ","") & IF((COUNTIFS(TableBOM[Product ID],$D$99,TableBOM[Item ID],$A109)>0)*($H$99>0),$C$99&", ",""))>1,LEFT(IF((COUNTIFS(TableBOM[Product ID],$D$94,TableBOM[Item ID],$A109)>0)*($H$94>0),$C$94&", ","") & IF((COUNTIFS(TableBOM[Product ID],$D$95,TableBOM[Item ID],$A109)>0)*($H$95>0),$C$95&", ","") & IF((COUNTIFS(TableBOM[Product ID],$D$96,TableBOM[Item ID],$A109)>0)*($H$96>0),$C$96&", ","") & IF((COUNTIFS(TableBOM[Product ID],$D$97,TableBOM[Item ID],$A109)>0)*($H$97>0),$C$97&", ","") & IF((COUNTIFS(TableBOM[Product ID],$D$98,TableBOM[Item ID],$A109)>0)*($H$98>0),$C$98&", ","") & IF((COUNTIFS(TableBOM[Product ID],$D$99,TableBOM[Item ID],$A109)>0)*($H$99>0),$C$99&", ",""),LEN(IF((COUNTIFS(TableBOM[Product ID],$D$94,TableBOM[Item ID],$A109)>0)*($H$94>0),$C$94&", ","") & IF((COUNTIFS(TableBOM[Product ID],$D$95,TableBOM[Item ID],$A109)>0)*($H$95>0),$C$95&", ","") & IF((COUNTIFS(TableBOM[Product ID],$D$96,TableBOM[Item ID],$A109)>0)*($H$96>0),$C$96&", ","") & IF((COUNTIFS(TableBOM[Product ID],$D$97,TableBOM[Item ID],$A109)>0)*($H$97>0),$C$97&", ","") & IF((COUNTIFS(TableBOM[Product ID],$D$98,TableBOM[Item ID],$A109)>0)*($H$98>0),$C$98&", ","") & IF((COUNTIFS(TableBOM[Product ID],$D$99,TableBOM[Item ID],$A109)>0)*($H$99>0),$C$99&", ",""))-2),"") -> Samsol Yellow 120ml, Mablay 130ml White, Mablay 130ml TRP, Alpha 150ml TRP, Horizon 150ml TRP, Samsol Yellow 200ml

Sheet Production_Log
A1: PRODUCTION LOG — One row per machine per product per day.
A2: Date | B2: Machine | C2: Customer | D2: Product Name | E2: Dia / Volume | F2: Product ID | G2: Target Quantity | H2: Good Quantity Produced | I2: Reject/Scrap Quantity | J2: Waste% | K2: Mechanical DT | L2: Electrical DT | M2: Material Shortage DT | N2: Changeover DT | O2: Operations DT | P2: Power Shutdown DT | Q2: Gas Shutdown DT | R2: Workers Shortage DT
A3: 46235 | B3: Lacquer-03 | C3: Golden Pearl Cosmetics (PVT) LTD | D3: HELLO HAIR COLOR | E3: 30 | F3: 6206 | G3: 25000 | H3: 24590 | I3: 410 | J3: =IFERROR(I3/(H3+I3),"") -> 0.0164
