Workbook

Sheet Tubex_Dashboard
B2: TUBEX — October 2026 Month to Date Report
B3: Report Date: | H3: =TODAY() -> 46316
B5: TUBE | C5: =MAX(Production_Log!$A$3:$A$8961) -> 46315 | D5: TUBE — MTD | G5: TUBE — REJECT % | J5: Dispatch — MTD | M5: Press & Printing Downtime – MTD (Tubes)
B6: =SUMPRODUCT((Production_Log!$A$3:$A$8961=MAX(Production_Log!$A$3:$A$8961))*(LEFT(Production_Log!$B$3:$B$8961,5)="Print")*(ISERROR(SEARCH("(Varnish)",Production_Log!$D$3:$D$8961)))*Production_Log!$H$3:$H$8961) -> 23086 | D6: =SUMIF($B$11:$B$68,"TUBE",$H$11:$H$68) -> 257602 | G6: {=IFERROR(SUMPRODUCT((Production_Log!$F$3:$F$8961<>0)*(LEFT(Production_Log!$B$3:$B$8961,5)="Print")*(ISERROR(SEARCH("(Varnish)",Production_Log!$D$3:$D$8961)))*Production_Log!$I$3:$I$8961)/SUMPRODUCT((Production_Log!$F$3:$F$8961<>0)*(LEFT(Production_Log!$B$3:$B$8961,5)="Print")*(ISERROR(SEARCH("(Varnish)",Production_Log!$D$3:$D$8961)))*(Production_Log!$H$3:$H$8961+Production_Log!$I$3:$I$8961)),"-")} -> 0.030010694 | J6: =SUMIF($B$11:$B$68,"TUBE",$K$11:$K$68) -> 215199 | M6: Category | N6: Hours (MTD) | O6: % Share
B7: PET | C7: =MAX(Production_Log!$A$3:$A$8961) -> 46315 | D7: PET — MTD | G7: PET — REJECT % | J7: Dispatch — MTD | L7: PET Shifts | M7: Material Shortage | N7: =SUMPRODUCT(((LEFT(Production_Log!$B$3:$B$1000,5)="Press")+(LEFT(Production_Log!$B$3:$B$1000,5)="Print")+(LEFT(Production_Log!$B$3:$B$1000,5)="PLINE"))*Production_Log!$M$3:$M$1000)/60 -> 45.333333 | O7: =IFERROR(N7/$N$10,"") -> 0.55623722
B8: =SUMPRODUCT((Production_Log!$A$3:$A$8961=MAX(Production_Log!$A$3:$A$8961))*(Production_Log!$B$3:$B$8961="PF Machine")*Production_Log!$H$3:$H$8961) -> 5980 | D8: =SUMIF($B$11:$B$68,"PET",$H$11:$H$68) -> 132160 | G8: {=IFERROR(SUMPRODUCT((Production_Log!$B$3:$B$8961="PF Machine")*Production_Log!$I$3:$I$8961)/SUMPRODUCT((Production_Log!$B$3:$B$8961="PF Machine")*(Production_Log!$H$3:$H$8961+Production_Log!$I$3:$I$8961)),0)} -> 0.25665111 | J8: =SUMIF($B$11:$B$68,"PET",$K$11:$K$68) -> 151990 | L8: A+B (8+8) | M8: Mechanical | N8: =SUMPRODUCT(((LEFT(Production_Log!$B$3:$B$1000,5)="Press")+(LEFT(Production_Log!$B$3:$B$1000,5)="Print")+(LEFT(Production_Log!$B$3:$B$1000,5)="PLINE"))*Production_Log!$K$3:$K$1000)/60 -> 28.166667 | O8: =IFERROR(N8/$N$10,"") -> 0.34560327
B9: Summary of Production & Dispatch - MTD | M9: Changeover | N9: =SUMPRODUCT(((LEFT(Production_Log!$B$3:$B$1000,5)="Press")+(LEFT(Production_Log!$B$3:$B$1000,5)="Print")+(LEFT(Production_Log!$B$3:$B$1000,5)="PLINE"))*Production_Log!$N$3:$N$1000)/60 -> 8 | O9: =IFERROR(N9/$N$10,"") -> 0.098159509
B10: Type | C10: Customer | D10: Product Name | E10: Dia | F10: Prod ID | G10: Orders | H10: MTD Produced | I10: Remaining | J10: Compliance | K10: Dispatch | L10: Remarks | M10: TOTAL | N10: =SUM(N7:N9) -> 81.5 | O10: 100%
B11: TUBE | C11: Mablay Beauty PVT LTD. | D11: VINCE HIS ONLY BEARD & MUSTACHE COLOR CREAM | E11: 20.5 | F11: 6077 | G11: =IFERROR(INDEX(MRP!$F$3:$F$150,MATCH(F11,MRP!$D$3:$D$150,0)),0) -> 22000 | H11: =SUMPRODUCT((Production_Log!$F$3:$F$1000=F11)*((LEFT(Production_Log!$B$3:$B$1000,5)="Print")+(LEFT(Production_Log!$B$3:$B$1000,5)="PLINE"))*(ISERROR(SEARCH("(Varnish)",Production_Log!$D$3:$D$1000)))*Production_Log!$H$3:$H$1000) -> 0 | I11: =G11-H11 -> 22000 | J11: =IF(G11=0,"-",H11/G11) -> 0
B12: TUBE | C12: Samsol International Private Limited | D12: TUBES COMMON RED | E12: 25 | F12: 6470 | G12: =IFERROR(INDEX(MRP!$F$3:$F$150,MATCH(F12,MRP!$D$3:$D$150,0)),0) -> 30000 | H12: =SUMPRODUCT((Production_Log!$F$3:$F$1000=F12)*((LEFT(Production_Log!$B$3:$B$1000,5)="Print")+(LEFT(Production_Log!$B$3:$B$1000,5)="PLINE"))*(ISERROR(SEARCH("(Varnish)",Production_Log!$D$3:$D$1000)))*Production_Log!$H$3:$H$1000) -> 0 | I12: =G12-H12 -> 30000 | J12: =IF(G12=0,"-",H12/G12) -> 0 | L12: Order Not Approved | M12: PF Machine Downtime – MTD (PET)
B13: TUBE | C13: Mablay Beauty PVT LTD. | D13: VINCE NURTURAL | E13: 30 | F13: 5814 | G13: =IFERROR(INDEX(MRP!$F$3:$F$150,MATCH(F13,MRP!$D$3:$D$150,0)),0) -> 50000 | H13: =SUMPRODUCT((Production_Log!$F$3:$F$1000=F13)*((LEFT(Production_Log!$B$3:$B$1000,5)="Print")+(LEFT(Production_Log!$B$3:$B$1000,5)="PLINE"))*(ISERROR(SEARCH("(Varnish)",Production_Log!$D$3:$D$1000)))*Production_Log!$H$3:$H$1000) -> 49742 | I13: =G13-H13 -> 258 | J13: =IF(G13=0,"-",H13/G13) -> 0.99484 | K13: 47793 | L13: Order Complete | M13: Category | N13: Hours (MTD) | O13: % Share
B14: TUBE | C14: Golden Pearl Cosmetics (PVT) LTD | D14: HELLO HAIR COLOR | E14: 30 | F14: 6206 | G14: =IFERROR(INDEX(MRP!$F$3:$F$150,MATCH(F14,MRP!$D$3:$D$150,0)),0) -> 389418 | H14: =SUMPRODUCT((Production_Log!$F$3:$F$1000=F14)*((LEFT(Production_Log!$B$3:$B$1000,5)="Print")+(LEFT(Production_Log!$B$3:$B$1000,5)="PLINE"))*(ISERROR(SEARCH("(Varnish)",Production_Log!$D$3:$D$1000)))*Production_Log!$H$3:$H$1000) -> 149188 | I14: =G14-H14 -> 240230 | J14: =IF(G14=0,"-",H14/G14) -> 0.38310504 | K14: 110432 | M14: Compressor Issue | N14: =SUMPRODUCT(((LEFT(Production_Log!$B$3:$B$1000,2)="PF")+(LEFT(Production_Log!$B$3:$B$1000,3)="PET"))*Production_Log!$S$3:$S$1000)/60 -> 38 | O14: =IFERROR(N14/$N$20,"") -> 0.40425532
B15: TUBE | C15: Hola Hair | D15: H.H 100GM | E15: 32 | F15: 6515 | G15: =IFERROR(INDEX(MRP!$F$3:$F$150,MATCH(F15,MRP!$D$3:$D$150,0)),0) -> 172336 | H15: =SUMPRODUCT((Production_Log!$F$3:$F$1000=F15)*((LEFT(Production_Log!$B$3:$B$1000,5)="Print")+(LEFT(Production_Log!$B$3:$B$1000,5)="PLINE"))*(ISERROR(SEARCH("(Varnish)",Production_Log!$D$3:$D$1000)))*Production_Log!$H$3:$H$1000) -> 58672 | I15: =G15-H15 -> 113664 | J15: =IF(G15=0,"-",H15/G15) -> 0.34045121 | K15: 37232 | M15: Operations | N15: =SUMPRODUCT(((LEFT(Production_Log!$B$3:$B$1000,2)="PF")+(LEFT(Production_Log!$B$3:$B$1000,3)="PET"))*Production_Log!$O$3:$O$1000)/60 -> 27.5 | O15: =IFERROR(N15/$N$20,"") -> 0.29255319
B16: TUBE | C16: Adore | D16: V- HC BROWN | E16: 35 | F16: 6530 | G16: =IFERROR(INDEX(MRP!$F$3:$F$150,MATCH(F16,MRP!$D$3:$D$150,0)),0) -> 0 | H16: =SUMPRODUCT((Production_Log!$F$3:$F$1000=F16)*((LEFT(Production_Log!$B$3:$B$1000,5)="Print")+(LEFT(Production_Log!$B$3:$B$1000,5)="PLINE"))*(ISERROR(SEARCH("(Varnish)",Production_Log!$D$3:$D$1000)))*Production_Log!$H$3:$H$1000) -> 0 | I16: =G16-H16 -> 0 | J16: =IF(G16=0,"-",H16/G16) -> - | K16: 15422 | M16: Mechanical | N16: =SUMPRODUCT(((LEFT(Production_Log!$B$3:$B$1000,2)="PF")+(LEFT(Production_Log!$B$3:$B$1000,3)="PET"))*Production_Log!$K$3:$K$1000)/60 -> 10.5 | O16: =IFERROR(N16/$N$20,"") -> 0.11170213
B17: TUBE | C17: Adore | D17: V-HC BLACK | E17: 35 | F17: 6531 | G17: =IFERROR(INDEX(MRP!$F$3:$F$150,MATCH(F17,MRP!$D$3:$D$150,0)),0) -> 0 | H17: =SUMPRODUCT((Production_Log!$F$3:$F$1000=F17)*((LEFT(Production_Log!$B$3:$B$1000,5)="Print")+(LEFT(Production_Log!$B$3:$B$1000,5)="PLINE"))*(ISERROR(SEARCH("(Varnish)",Production_Log!$D$3:$D$1000)))*Production_Log!$H$3:$H$1000) -> 0 | I17: =G17-H17 -> 0 | J17: =IF(G17=0,"-",H17/G17) -> - | K17: 4320 | M17: Changeover | N17: =SUMPRODUCT(((LEFT(Production_Log!$B$3:$B$1000,2)="PF")+(LEFT(Production_Log!$B$3:$B$1000,3)="PET"))*Production_Log!$N$3:$N$1000)/60 -> 8 | O17: =IFERROR(N17/$N$20,"") -> 0.085106383
D18: TOTAL | G18: =SUM(G11:G17) -> 663754 | H18: =SUM(H11:H17) -> 257602 | I18: =SUMIF(I11:I17,">"&0) -> 406152 | J18: =IF(G18=0,"-",H18/G18) -> 0.3880986 | K18: =SUM(K11:K17) -> 215199 | M18: Material Shortage | N18: =SUMPRODUCT(((LEFT(Production_Log!$B$3:$B$1000,2)="PF")+(LEFT(Production_Log!$B$3:$B$1000,3)="PET"))*Production_Log!$M$3:$M$1000)/60 -> 7 | O18: =IFERROR(N18/$N$20,"") -> 0.074468085
B19: PET | C19: Alpha Labs PVT LTD | D19: PET BOTTLE (75ML) TRANSPARENT BODY MIST | E19: 75 ml | F19: 8018 | G19: =IFERROR(INDEX(MRP!$F$3:$F$150,MATCH(F19,MRP!$D$3:$D$150,0)),0) -> 25000 | H19: =SUMPRODUCT((Production_Log!$F$3:$F$1000=F19)*Production_Log!$H$3:$H$1000) -> 0 | I19: =G19-H19 -> 25000 | J19: =IF(G19=0,"-",H19/G19) -> 0 | M19: Electrical | N19: =SUMPRODUCT(((LEFT(Production_Log!$B$3:$B$1000,2)="PF")+(LEFT(Production_Log!$B$3:$B$1000,3)="PET"))*Production_Log!$L$3:$L$1000)/60 -> 3 | O19: =IFERROR(N19/$N$20,"") -> 0.031914894
B20: PET | C20: Samsol International Private Limited | D20: PET BOTTLE SMALL (120ML) YELLOW | E20: 120 ml | F20: 8005 | G20: =IFERROR(INDEX(MRP!$F$3:$F$150,MATCH(F20,MRP!$D$3:$D$150,0)),0) -> 0 | H20: =SUMPRODUCT((Production_Log!$F$3:$F$1000=F20)*Production_Log!$H$3:$H$1000) -> 0 | I20: =G20-H20 -> 0 | J20: =IF(G20=0,"-",H20/G20) -> - | K20: 12840 | M20: TOTAL | N20: =SUM(N14:N19) -> 94 | O20: 100%
B21: PET | C21: Mablay Beauty PVT LTD. | D21: PET BOTTLE 130ML WHITE | E21: 130 ml | F21: 8015 | G21: =IFERROR(INDEX(MRP!$F$3:$F$150,MATCH(F21,MRP!$D$3:$D$150,0)),0) -> 9480 | H21: =SUMPRODUCT((Production_Log!$F$3:$F$1000=F21)*Production_Log!$H$3:$H$1000) -> 0 | I21: =G21-H21 -> 9480 | J21: =IF(G21=0,"-",H21/G21) -> 0
B22: PET | C22: Alpha Labs PVT LTD | D22: PET BOTTLE SMALL (130ML) TRANSPARENT | E22: 130 ml | F22: 8019 | G22: =IFERROR(INDEX(MRP!$F$3:$F$150,MATCH(F22,MRP!$D$3:$D$150,0)),0) -> 5000 | H22: =SUMPRODUCT((Production_Log!$F$3:$F$1000=F22)*Production_Log!$H$3:$H$1000) -> 5000 | I22: =G22-H22 -> 0 | J22: =IF(G22=0,"-",H22/G22) -> 1 | K22: 5060 | L22: Order Complete
B23: PET | C23: Mablay Beauty PVT LTD. | D23: PET BOTTLE SMALL (130ML) TRANSPARENT | E23: 130 ml | F23: 8010 | G23: =IFERROR(INDEX(MRP!$F$3:$F$150,MATCH(F23,MRP!$D$3:$D$150,0)),0) -> 18500 | H23: =SUMPRODUCT((Production_Log!$F$3:$F$1000=F23)*Production_Log!$H$3:$H$1000) -> 18690 | I23: =G23-H23 -> -190 | J23: =IF(G23=0,"-",H23/G23) -> 1.0102703 | K23: 30130 | L23: Order Complete
B24: PET | C24: Alpha Labs PVT LTD | D24: TRANSPARENT BOTTLE 150ML | E24: 150 ml | F24: 8001 | G24: =IFERROR(INDEX(MRP!$F$3:$F$150,MATCH(F24,MRP!$D$3:$D$150,0)),0) -> 549967 | H24: =SUMPRODUCT((Production_Log!$F$3:$F$1000=F24)*Production_Log!$H$3:$H$1000) -> 108470 | I24: =G24-H24 -> 441497 | J24: =IF(G24=0,"-",H24/G24) -> 0.19723002 | K24: 103960
B25: PET | C25: Samsol International Private Limited | D25: PET BOTTLE LARGE (200 ML) YELLOW | E25: 200 ml | F25: 8006 | G25: =IFERROR(INDEX(MRP!$F$3:$F$150,MATCH(F25,MRP!$D$3:$D$150,0)),0) -> 4280 | H25: =SUMPRODUCT((Production_Log!$F$3:$F$1000=F25)*Production_Log!$H$3:$H$1000) -> 0 | I25: =G25-H25 -> 4280 | J25: =IF(G25=0,"-",H25/G25) -> 0
D26: TOTAL | G26: =SUM(G19:G25) -> 612227 | H26: =SUM(H19:H25) -> 132160 | I26: =SUMIF(I19:I25,">"&0) -> 480257 | J26: =IF(G26=0,"-",H26/G26) -> 0.21586764 | K26: =SUM(K19:K25) -> 151990
B27: TUBE | C27: Bahadur | D27: BAHADUR TUBE 12.5MM | E27: 12.5 | F27: 9004 | G27: =IFERROR(INDEX(MRP!$F$3:$F$150,MATCH(F27,MRP!$D$3:$D$150,0)),0) -> 0 | H27: =SUMPRODUCT((Production_Log!$F$3:$F$1000=F27)*((LEFT(Production_Log!$B$3:$B$1000,5)="Print")+(LEFT(Production_Log!$B$3:$B$1000,5)="PLINE"))*(ISERROR(SEARCH("(Varnish)",Production_Log!$D$3:$D$1000)))*Production_Log!$H$3:$H$1000) -> 0 | I27: =G27-H27 -> 0 | J27: =IF(G27=0,"-",H27/G27) -> -
B28: TUBE | C28: Brookes Pharma Private Limited | D28: ECZEMUS OINTMENT 0.03% 10G | E28: 16 | F28: 6561 | G28: =IFERROR(INDEX(MRP!$F$3:$F$150,MATCH(F28,MRP!$D$3:$D$150,0)),0) -> 0 | H28: =SUMPRODUCT((Production_Log!$F$3:$F$1000=F28)*((LEFT(Production_Log!$B$3:$B$1000,5)="Print")+(LEFT(Production_Log!$B$3:$B$1000,5)="PLINE"))*(ISERROR(SEARCH("(Varnish)",Production_Log!$D$3:$D$1000)))*Production_Log!$H$3:$H$1000) -> 0 | I28: =G28-H28 -> 0 | J28: =IF(G28=0,"-",H28/G28) -> -
B29: TUBE | C29: Samsol International Private Limited | D29: S-45 DIA 19MM | E29: 19 | F29: 6624 | G29: =IFERROR(INDEX(MRP!$F$3:$F$150,MATCH(F29,MRP!$D$3:$D$150,0)),0) -> 0 | H29: =SUMPRODUCT((Production_Log!$F$3:$F$1000=F29)*((LEFT(Production_Log!$B$3:$B$1000,5)="Print")+(LEFT(Production_Log!$B$3:$B$1000,5)="PLINE"))*(ISERROR(SEARCH("(Varnish)",Production_Log!$D$3:$D$1000)))*Production_Log!$H$3:$H$1000) -> 0 | I29: =G29-H29 -> 0 | J29: =IF(G29=0,"-",H29/G29) -> -
B30: TUBE | C30: Samsol International Private Limited | D30: S-43 DIA 19MM | E30: 19 | F30: 6623 | G30: =IFERROR(INDEX(MRP!$F$3:$F$150,MATCH(F30,MRP!$D$3:$D$150,0)),0) -> 0 | H30: =SUMPRODUCT((Production_Log!$F$3:$F$1000=F30)*((LEFT(Production_Log!$B$3:$B$1000,5)="Print")+(LEFT(Production_Log!$B$3:$B$1000,5)="PLINE"))*(ISERROR(SEARCH("(Varnish)",Production_Log!$D$3:$D$1000)))*Production_Log!$H$3:$H$1000) -> 0 | I30: =G30-H30 -> 0 | J30: =IF(G30=0,"-",H30/G30) -> -
B31: TUBE | C31: Brookes Pharma Private Limited | D31: S-43 DIA 19MM | E31: 19 | F31: 6559 | G31: =IFERROR(INDEX(MRP!$F$3:$F$150,MATCH(F31,MRP!$D$3:$D$150,0)),0) -> 0 | H31: =SUMPRODUCT((Production_Log!$F$3:$F$1000=F31)*((LEFT(Production_Log!$B$3:$B$1000,5)="Print")+(LEFT(Production_Log!$B$3:$B$1000,5)="PLINE"))*(ISERROR(SEARCH("(Varnish)",Production_Log!$D$3:$D$1000)))*Production_Log!$H$3:$H$1000) -> 0 | I31: =G31-H31 -> 0 | J31: =IF(G31=0,"-",H31/G31) -> -
B32: TUBE | C32: Brookes Pharma Private Limited | D32: PYODINE GEL 20GM | E32: 19 | F32: 1085 | G32: =IFERROR(INDEX(MRP!$F$3:$F$150,MATCH(F32,MRP!$D$3:$D$150,0)),0) -> 0 | H32: =SUMPRODUCT((Production_Log!$F$3:$F$1000=F32)*((LEFT(Production_Log!$B$3:$B$1000,5)="Print")+(LEFT(Production_Log!$B$3:$B$1000,5)="PLINE"))*(ISERROR(SEARCH("(Varnish)",Production_Log!$D$3:$D$1000)))*Production_Log!$H$3:$H$1000) -> 0 | I32: =G32-H32 -> 0 | J32: =IF(G32=0,"-",H32/G32) -> -
B33: TUBE | C33: Brookes Pharma Private Limited | D33: CONTRATUBEX GEL 20G | E33: 19 | F33: 6560 | G33: =IFERROR(INDEX(MRP!$F$3:$F$150,MATCH(F33,MRP!$D$3:$D$150,0)),0) -> 0 | H33: =SUMPRODUCT((Production_Log!$F$3:$F$1000=F33)*((LEFT(Production_Log!$B$3:$B$1000,5)="Print")+(LEFT(Production_Log!$B$3:$B$1000,5)="PLINE"))*(ISERROR(SEARCH("(Varnish)",Production_Log!$D$3:$D$1000)))*Production_Log!$H$3:$H$1000) -> 0 | I33: =G33-H33 -> 0 | J33: =IF(G33=0,"-",H33/G33) -> -
B34: TUBE | C34: Samsol International Private Limited | D34: S-43 DIA 20.5 | E34: 20.5 | F34: 5699 | G34: =IFERROR(INDEX(MRP!$F$3:$F$150,MATCH(F34,MRP!$D$3:$D$150,0)),0) -> 0 | H34: =SUMPRODUCT((Production_Log!$F$3:$F$1000=F34)*((LEFT(Production_Log!$B$3:$B$1000,5)="Print")+(LEFT(Production_Log!$B$3:$B$1000,5)="PLINE"))*(ISERROR(SEARCH("(Varnish)",Production_Log!$D$3:$D$1000)))*Production_Log!$H$3:$H$1000) -> 0 | I34: =G34-H34 -> 0 | J34: =IF(G34=0,"-",H34/G34) -> -
B35: TUBE | C35: Samsol International Private Limited | D35: SAMSOL HAIR COLOR 45 DIA 20.5 MM | E35: 20.5 | F35: 5731 | G35: =IFERROR(INDEX(MRP!$F$3:$F$150,MATCH(F35,MRP!$D$3:$D$150,0)),0) -> 0 | H35: =SUMPRODUCT((Production_Log!$F$3:$F$1000=F35)*((LEFT(Production_Log!$B$3:$B$1000,5)="Print")+(LEFT(Production_Log!$B$3:$B$1000,5)="PLINE"))*(ISERROR(SEARCH("(Varnish)",Production_Log!$D$3:$D$1000)))*Production_Log!$H$3:$H$1000) -> 0 | I35: =G35-H35 -> 0 | J35: =IF(G35=0,"-",H35/G35) -> -
B36: TUBE | C36: Samsol International Private Limited | D36: S-45 DIA 20.5 | E36: 20.5 | F36: 5698 | G36: =IFERROR(INDEX(MRP!$F$3:$F$150,MATCH(F36,MRP!$D$3:$D$150,0)),0) -> 0 | H36: =SUMPRODUCT((Production_Log!$F$3:$F$1000=F36)*((LEFT(Production_Log!$B$3:$B$1000,5)="Print")+(LEFT(Production_Log!$B$3:$B$1000,5)="PLINE"))*(ISERROR(SEARCH("(Varnish)",Production_Log!$D$3:$D$1000)))*Production_Log!$H$3:$H$1000) -> 0 | I36: =G36-H36 -> 0 | J36: =IF(G36=0,"-",H36/G36) -> -
B37: TUBE | C37: Samsol International Private Limited | D37: SAMSOL HAIR COLOR 43 DIA 20.5 MM | E37: 20.5 | F37: 5732 | G37: =IFERROR(INDEX(MRP!$F$3:$F$150,MATCH(F37,MRP!$D$3:$D$150,0)),0) -> 0 | H37: =SUMPRODUCT((Production_Log!$F$3:$F$1000=F37)*((LEFT(Production_Log!$B$3:$B$1000,5)="Print")+(LEFT(Production_Log!$B$3:$B$1000,5)="PLINE"))*(ISERROR(SEARCH("(Varnish)",Production_Log!$D$3:$D$1000)))*Production_Log!$H$3:$H$1000) -> 0 | I37: =G37-H37 -> 0 | J37: =IF(G37=0,"-",H37/G37) -> -
B38: TUBE | C38: Samsol International Private Limited | D38: SAMSOL HAIR COLOR 39 SMALL PURPLE | E38: 20.5 | F38: 6556 | G38: =IFERROR(INDEX(MRP!$F$3:$F$150,MATCH(F38,MRP!$D$3:$D$150,0)),0) -> 0 | H38: =SUMPRODUCT((Production_Log!$F$3:$F$1000=F38)*((LEFT(Production_Log!$B$3:$B$1000,5)="Print")+(LEFT(Production_Log!$B$3:$B$1000,5)="PLINE"))*(ISERROR(SEARCH("(Varnish)",Production_Log!$D$3:$D$1000)))*Production_Log!$H$3:$H$1000) -> 0 | I38: =G38-H38 -> 0 | J38: =IF(G38=0,"-",H38/G38) -> -
... B59: TUBE | C59: Adore | D59: ANVIL 45 | E59: 35 | F59: 6021 | G59: =IFERROR(INDEX(MRP!$F$3:$F$150,MATCH(F59,MRP!$D$3:$D$150,0)),0) -> 0 | H59: =SUMPRODUCT((Production_Log!$F$3:$F$1000=F59)*((LEFT(Production_Log!$B$3:$B$1000,5)="Print")+(LEFT(Production_Log!$B$3:$B$1000,5)="PLINE"))*(ISERROR(SEARCH("(Varnish)",Production_Log!$D$3:$D$1000)))*Production_Log!$H$3:$H$1000) -> 0 | I59: =G59-H59 -> 0 | J59: =IF(G59=0,"-",H59/G59) -> -
B60: PET | C60: Samsol International Private Limited | D60: BLACK SMALL BOTTLE 120ML | E60: 120 ml | F60: 8011 | G60: =IFERROR(INDEX(MRP!$F$3:$F$150,MATCH(F60,MRP!$D$3:$D$150,0)),0) -> 0 | H60: =SUMPRODUCT((Production_Log!$F$3:$F$1000=F60)*Production_Log!$H$3:$H$1000) -> 0 | I60: =G60-H60 -> 0 | J60: =IF(G60=0,"-",H60/G60) -> -
B61: PET | C61: Samsol International Private Limited | D61: WHITE SMALL BOTTLE 120ML | E61: 120 ml | F61: 8012 | G61: =IFERROR(INDEX(MRP!$F$3:$F$150,MATCH(F61,MRP!$D$3:$D$150,0)),0) -> 0 | H61: =SUMPRODUCT((Production_Log!$F$3:$F$1000=F61)*Production_Log!$H$3:$H$1000) -> 0 | I61: =G61-H61 -> 0 | J61: =IF(G61=0,"-",H61/G61) -> -
B62: PET | C62: Horizon Chem | D62: PET BOTTLE (150ML)TRANSPARENT BODY MIST | E62: 150 ml | F62: 8017 | G62: =IFERROR(INDEX(MRP!$F$3:$F$150,MATCH(F62,MRP!$D$3:$D$150,0)),0) -> 0 | H62: =SUMPRODUCT((Production_Log!$F$3:$F$1000=F62)*Production_Log!$H$3:$H$1000) -> 0 | I62: =G62-H62 -> 0 | J62: =IF(G62=0,"-",H62/G62) -> -
...

Sheet MRP
A1: OCTOBER 2026 Tube Required Orders | G1: Date: | H1: =TODAY() -> 46316
A2: Dia | B2: Customer | C2: Product Name | D2: Product ID | E2: Job Order # | F2: Required Qty | G2: Produced | H2: Remaining Balance | I2: Remarks
A3: 20.5 | B3: Mablay Beauty PVT LTD. | C3: VINCE HIS ONLY BEARD & MUSTACHE COLOR CREAM | D3: 6077 | E3: 6907 | F3: 22000 | G3: =INDEX(Tubex_Dashboard!$H$11:$H$100,MATCH(MRP!D3,Tubex_Dashboard!$F$11:$F$100,0)) -> 0 | H3: =F3-G3 -> 22000
A4: 25 | B4: Samsol International Private Limited | C4: TUBES COMMON RED | D4: 6470 | F4: 30000 | G4: =INDEX(Tubex_Dashboard!$H$11:$H$100,MATCH(MRP!D4,Tubex_Dashboard!$F$11:$F$100,0)) -> 0 | H4: =F4-G4 -> 30000 | I4: Order Not Approved
A5: 30 | B5: Mablay Beauty PVT LTD. | C5: VINCE NURTURAL | D5: 5814 | E5: 6901 & 6905 | F5: 50000 | G5: =INDEX(Tubex_Dashboard!$H$11:$H$100,MATCH(MRP!D5,Tubex_Dashboard!$F$11:$F$100,0)) -> 49742 | H5: =F5-G5 -> 258 | I5: Order Complete
A6: 30 | B6: Golden Pearl Cosmetics (PVT) LTD | C6: HELLO HAIR COLOR | D6: 6206 | E6: 6902 | F6: 389418 | G6: =INDEX(Tubex_Dashboard!$H$11:$H$100,MATCH(MRP!D6,Tubex_Dashboard!$F$11:$F$100,0)) -> 149188 | H6: =F6-G6 -> 240230
A7: 32 | B7: Hola Hair | C7: H.H 100GM | D7: 6515 | E7: 6904 | F7: 172336 | G7: =INDEX(Tubex_Dashboard!$H$11:$H$100,MATCH(MRP!D7,Tubex_Dashboard!$F$11:$F$100,0)) -> 58672 | H7: =F7-G7 -> 113664
E8: TOTAL: | F8: =SUM(F3:F7) -> 663754 | G8: =SUM(G3:G7) -> 257602 | H8: =SUMIF(H3:H7, ">0") -> 406152
A9: OCTOBER TUBES MATERIAL REQUIREMENT PLAN
A10: Item ID | B10: Category | C10: Item Name | D10: UOM | E10: Required Qty | F10: Current Stock (Store + WIP) | G10: Surplus / (Deficit) | H10: Current Stock Pieces Can Produce | I10: Status | J10: Product Name(s)
A11: 33 | B11: SLUG | C11: 12.5X4.5X4.8 | D11: kg | E11: =SUMPRODUCT((TableBOM[Item ID]=A11)*TableBOM[Per 1000 Units]*(1+TableBOM[Scrap %])*((SUMIF($D$3:$D$7,TableBOM[Product ID],$H$3:$H$7))>0)*(SUMIF($D$3:$D$7,TableBOM[Product ID],$H$3:$H$7))/1000) -> 0 | F11: =IFERROR(INDEX(TableInventory[Store Balance],MATCH(A11,TableInventory[Item ID],0)),0)+IFERROR(INDEX(TableInventory[WIP],MATCH(A11,TableInventory[Item ID],0)),0) -> 0 | G11: =F11-E11 -> 0 | H11: =IFERROR(IF(SUMPRODUCT((TableBOM[Item ID]=A11)*((SUMIF($D$3:$D$7,TableBOM[Product ID],$H$3:$H$7))>0)*(SUMIF($D$3:$D$7,TableBOM[Product ID],$H$3:$H$7))*TableBOM[Per 1000 Units]*(1+TableBOM[Scrap %]))=0,"-",ROUND(F11*1000*SUMPRODUCT((TableBOM[Item ID]=A11)*((SUMIF($D$3:$D$7,TableBOM[Product ID],$H$3:$H$7))>0)*(SUMIF($D$3:$D$7,TableBOM[Product ID],$H$3:$H$7)))/SUMPRODUCT((TableBOM[Item ID]=A11)*((SUMIF($D$3:$D$7,TableBOM[Product ID],$H$3:$H$7))>0)*(SUMIF($D$3:$D$7,TableBOM[Product ID],$H$3:$H$7))*TableBOM[Per 1000 Units]*(1+TableBOM[Scrap %])),0)),"-") -> - | I11: =IF(E11=0,"Not needed",IF(G11<0,"SHORTAGE",IF(G11<E11*0.1,"LOW","OK"))) -> Not needed | J11: =IF(LEN(IF((COUNTIFS(TableBOM[Product ID],$D$3,TableBOM[Item ID],$A11)>0)*($H$3>0),$C$3&", ","") & IF((COUNTIFS(TableBOM[Product ID],$D$4,TableBOM[Item ID],$A11)>0)*($H$4>0),$C$4&", ","") & IF((COUNTIFS(TableBOM[Product ID],$D$5,TableBOM[Item ID],$A11)>0)*($H$5>0),$C$5&", ","") & IF((COUNTIFS(TableBOM[Product ID],$D$6,TableBOM[Item ID],$A11)>0)*($H$6>0),$C$6&", ","") & IF((COUNTIFS(TableBOM[Product ID],$D$7,TableBOM[Item ID],$A11)>0)*($H$7>0),$C$7&", ",""))>1,LEFT(IF((COUNTIFS(TableBOM[Product ID],$D$3,TableBOM[Item ID],$A11)>0)*($H$3>0),$C$3&", ","") & IF((COUNTIFS(TableBOM[Product ID],$D$4,TableBOM[Item ID],$A11)>0)*($H$4>0),$C$4&", ","") & IF((COUNTIFS(TableBOM[Product ID],$D$5,TableBOM[Item ID],$A11)>0)*($H$5>0),$C$5&", ","") & IF((COUNTIFS(TableBOM[Product ID],$D$6,TableBOM[Item ID],$A11)>0)*($H$6>0),$C$6&", ","") & IF((COUNTIFS(TableBOM[Product ID],$D$7,TableBOM[Item ID],$A11)>0)*($H$7>0),$C$7&", ",""),LEN(IF((COUNTIFS(TableBOM[Product ID],$D$3,TableBOM[Item ID],$A11)>0)*($H$3>0),$C$3&", ","") & IF((COUNTIFS(TableBOM[Product ID],$D$4,TableBOM[Item ID],$A11)>0)*($H$4>0),$C$4&", ","") & IF((COUNTIFS(TableBOM[Product ID],$D$5,TableBOM[Item ID],$A11)>0)*($H$5>0),$C$5&", ","") & IF((COUNTIFS(TableBOM[Product ID],$D$6,TableBOM[Item ID],$A11)>0)*($H$6>0),$C$6&", ","") & IF((COUNTIFS(TableBOM[Product ID],$D$7,TableBOM[Item ID],$A11)>0)*($H$7>0),$C$7&", ",""))-2),"")
A12: 31 | B12: SLUG | C12: 13.5X4.2 | D12: kg | E12: =SUMPRODUCT((TableBOM[Item ID]=A12)*TableBOM[Per 1000 Units]*(1+TableBOM[Scrap %])*((SUMIF($D$3:$D$7,TableBOM[Product ID],$H$3:$H$7))>0)*(SUMIF($D$3:$D$7,TableBOM[Product ID],$H$3:$H$7))/1000) -> 0 | F12: =IFERROR(INDEX(TableInventory[Store Balance],MATCH(A12,TableInventory[Item ID],0)),0)+IFERROR(INDEX(TableInventory[WIP],MATCH(A12,TableInventory[Item ID],0)),0) -> 71.5 | G12: =F12-E12 -> 71.5 | H12: =IFERROR(IF(SUMPRODUCT((TableBOM[Item ID]=A12)*((SUMIF($D$3:$D$7,TableBOM[Product ID],$H$3:$H$7))>0)*(SUMIF($D$3:$D$7,TableBOM[Product ID],$H$3:$H$7))*TableBOM[Per 1000 Units]*(1+TableBOM[Scrap %]))=0,"-",ROUND(F12*1000*SUMPRODUCT((TableBOM[Item ID]=A12)*((SUMIF($D$3:$D$7,TableBOM[Product ID],$H$3:$H$7))>0)*(SUMIF($D$3:$D$7,TableBOM[Product ID],$H$3:$H$7)))/SUMPRODUCT((TableBOM[Item ID]=A12)*((SUMIF($D$3:$D$7,TableBOM[Product ID],$H$3:$H$7))>0)*(SUMIF($D$3:$D$7,TableBOM[Product ID],$H$3:$H$7))*TableBOM[Per 1000 Units]*(1+TableBOM[Scrap %])),0)),"-") -> - | I12: =IF(E12=0,"Not needed",IF(G12<0,"SHORTAGE",IF(G12<E12*0.1,"LOW","OK"))) -> Not needed | J12: =IF(LEN(IF((COUNTIFS(TableBOM[Product ID],$D$3,TableBOM[Item ID],$A12)>0)*($H$3>0),$C$3&", ","") & IF((COUNTIFS(TableBOM[Product ID],$D$4,TableBOM[Item ID],$A12)>0)*($H$4>0),$C$4&", ","") & IF((COUNTIFS(TableBOM[Product ID],$D$5,TableBOM[Item ID],$A12)>0)*($H$5>0),$C$5&", ","") & IF((COUNTIFS(TableBOM[Product ID],$D$6,TableBOM[Item ID],$A12)>0)*($H$6>0),$C$6&", ","") & IF((COUNTIFS(TableBOM[Product ID],$D$7,TableBOM[Item ID],$A12)>0)*($H$7>0),$C$7&", ",""))>1,LEFT(IF((COUNTIFS(TableBOM[Product ID],$D$3,TableBOM[Item ID],$A12)>0)*($H$3>0),$C$3&", ","") & IF((COUNTIFS(TableBOM[Product ID],$D$4,TableBOM[Item ID],$A12)>0)*($H$4>0),$C$4&", ","") & IF((COUNTIFS(TableBOM[Product ID],$D$5,TableBOM[Item ID],$A12)>0)*($H$5>0),$C$5&", ","") & IF((COUNTIFS(TableBOM[Product ID],$D$6,TableBOM[Item ID],$A12)>0)*($H$6>0),$C$6&", ","") & IF((COUNTIFS(TableBOM[Product ID],$D$7,TableBOM[Item ID],$A12)>0)*($H$7>0),$C$7&", ",""),LEN(IF((COUNTIFS(TableBOM[Product ID],$D$3,TableBOM[Item ID],$A12)>0)*($H$3>0),$C$3&", ","") & IF((COUNTIFS(TableBOM[Product ID],$D$4,TableBOM[Item ID],$A12)>0)*($H$4>0),$C$4&", ","") & IF((COUNTIFS(TableBOM[Product ID],$D$5,TableBOM[Item ID],$A12)>0)*($H$5>0),$C$5&", ","") & IF((COUNTIFS(TableBOM[Product ID],$D$6,TableBOM[Item ID],$A12)>0)*($H$6>0),$C$6&", ","") & IF((COUNTIFS(TableBOM[Product ID],$D$7,TableBOM[Item ID],$A12)>0)*($H$7>0),$C$7&", ",""))-2),"")
A13: 2799 | B13: SLUG | C13: 16x4.5 | D13: kg | E13: =SUMPRODUCT((TableBOM[Item ID]=A13)*TableBOM[Per 1000 Units]*(1+TableBOM[Scrap %])*((SUMIF($D$3:$D$7,TableBOM[Product ID],$H$3:$H$7))>0)*(SUMIF($D$3:$D$7,TableBOM[Product ID],$H$3:$H$7))/1000) -> 0 | F13: =IFERROR(INDEX(TableInventory[Store Balance],MATCH(A13,TableInventory[Item ID],0)),0)+IFERROR(INDEX(TableInventory[WIP],MATCH(A13,TableInventory[Item ID],0)),0) -> 88 | G13: =F13-E13 -> 88 | H13: =IFERROR(IF(SUMPRODUCT((TableBOM[Item ID]=A13)*((SUMIF($D$3:$D$7,TableBOM[Product ID],$H$3:$H$7))>0)*(SUMIF($D$3:$D$7,TableBOM[Product ID],$H$3:$H$7))*TableBOM[Per 1000 Units]*(1+TableBOM[Scrap %]))=0,"-",ROUND(F13*1000*SUMPRODUCT((TableBOM[Item ID]=A13)*((SUMIF($D$3:$D$7,TableBOM[Product ID],$H$3:$H$7))>0)*(SUMIF($D$3:$D$7,TableBOM[Product ID],$H$3:$H$7)))/SUMPRODUCT((TableBOM[Item ID]=A13)*((SUMIF($D$3:$D$7,TableBOM[Product ID],$H$3:$H$7))>0)*(SUMIF($D$3:$D$7,TableBOM[Product ID],$H$3:$H$7))*TableBOM[Per 1000 Units]*(1+TableBOM[Scrap %])),0)),"-") -> - | I13: =IF(E13=0,"Not needed",IF(G13<0,"SHORTAGE",IF(G13<E13*0.1,"LOW","OK"))) -> Not needed | J13: =IF(LEN(IF((COUNTIFS(TableBOM[Product ID],$D$3,TableBOM[Item ID],$A13)>0)*($H$3>0),$C$3&", ","") & IF((COUNTIFS(TableBOM[Product ID],$D$4,TableBOM[Item ID],$A13)>0)*($H$4>0),$C$4&", ","") & IF((COUNTIFS(TableBOM[Product ID],$D$5,TableBOM[Item ID],$A13)>0)*($H$5>0),$C$5&", ","") & IF((COUNTIFS(TableBOM[Product ID],$D$6,TableBOM[Item ID],$A13)>0)*($H$6>0),$C$6&", ","") & IF((COUNTIFS(TableBOM[Product ID],$D$7,TableBOM[Item ID],$A13)>0)*($H$7>0),$C$7&", ",""))>1,LEFT(IF((COUNTIFS(TableBOM[Product ID],$D$3,TableBOM[Item ID],$A13)>0)*($H$3>0),$C$3&", ","") & IF((COUNTIFS(TableBOM[Product ID],$D$4,TableBOM[Item ID],$A13)>0)*($H$4>0),$C$4&", ","") & IF((COUNTIFS(TableBOM[Product ID],$D$5,TableBOM[Item ID],$A13)>0)*($H$5>0),$C$5&", ","") & IF((COUNTIFS(TableBOM[Product ID],$D$6,TableBOM[Item ID],$A13)>0)*($H$6>0),$C$6&", ","") & IF((COUNTIFS(TableBOM[Product ID],$D$7,TableBOM[Item ID],$A13)>0)*($H$7>0),$C$7&", ",""),LEN(IF((COUNTIFS(TableBOM[Product ID],$D$3,TableBOM[Item ID],$A13)>0)*($H$3>0),$C$3&", ","") & IF((COUNTIFS(TableBOM[Product ID],$D$4,TableBOM[Item ID],$A13)>0)*($H$4>0),$C$4&", ","") & IF((COUNTIFS(TableBOM[Product ID],$D$5,TableBOM[Item ID],$A13)>0)*($H$5>0),$C$5&", ","") & IF((COUNTIFS(TableBOM[Product ID],$D$6,TableBOM[Item ID],$A13)>0)*($H$6>0),$C$6&", ","") & IF((COUNTIFS(TableBOM[Product ID],$D$7,TableBOM[Item ID],$A13)>0)*($H$7>0),$C$7&", ",""))-2),"")
A14: 25 | B14: SLUG | C14: 16X4.8 S/M | D14: kg | E14: =SUMPRODUCT((TableBOM[Item ID]=A14)*TableBOM[Per 1000 Units]*(1+TableBOM[Scrap %])*((SUMIF($D$3:$D$7,TableBOM[Product ID],$H$3:$H$7))>0)*(SUMIF($D$3:$D$7,TableBOM[Product ID],$H$3:$H$7))/1000) -> 0 | F14: =IFERROR(INDEX(TableInventory[Store Balance],MATCH(A14,TableInventory[Item ID],0)),0)+IFERROR(INDEX(TableInventory[WIP],MATCH(A14,TableInventory[Item ID],0)),0) -> 0 | G14: =F14-E14 -> 0 | H14: =IFERROR(IF(SUMPRODUCT((TableBOM[Item ID]=A14)*((SUMIF($D$3:$D$7,TableBOM[Product ID],$H$3:$H$7))>0)*(SUMIF($D$3:$D$7,TableBOM[Product ID],$H$3:$H$7))*TableBOM[Per 1000 Units]*(1+TableBOM[Scrap %]))=0,"-",ROUND(F14*1000*SUMPRODUCT((TableBOM[Item ID]=A14)*((SUMIF($D$3:$D$7,TableBOM[Product ID],$H$3:$H$7))>0)*(SUMIF($D$3:$D$7,TableBOM[Product ID],$H$3:$H$7)))/SUMPRODUCT((TableBOM[Item ID]=A14)*((SUMIF($D$3:$D$7,TableBOM[Product ID],$H$3:$H$7))>0)*(SUMIF($D$3:$D$7,TableBOM[Product ID],$H$3:$H$7))*TableBOM[Per 1000 Units]*(1+TableBOM[Scrap %])),0)),"-") -> - | I14: =IF(E14=0,"Not needed",IF(G14<0,"SHORTAGE",IF(G14<E14*0.1,"LOW","OK"))) -> Not needed | J14: =IF(LEN(IF((COUNTIFS(TableBOM[Product ID],$D$3,TableBOM[Item ID],$A14)>0)*($H$3>0),$C$3&", ","") & IF((COUNTIFS(TableBOM[Product ID],$D$4,TableBOM[Item ID],$A14)>0)*($H$4>0),$C$4&", ","") & IF((COUNTIFS(TableBOM[Product ID],$D$5,TableBOM[Item ID],$A14)>0)*($H$5>0),$C$5&", ","") & IF((COUNTIFS(TableBOM[Product ID],$D$6,TableBOM[Item ID],$A14)>0)*($H$6>0),$C$6&", ","") & IF((COUNTIFS(TableBOM[Product ID],$D$7,TableBOM[Item ID],$A14)>0)*($H$7>0),$C$7&", ",""))>1,LEFT(IF((COUNTIFS(TableBOM[Product ID],$D$3,TableBOM[Item ID],$A14)>0)*($H$3>0),$C$3&", ","") & IF((COUNTIFS(TableBOM[Product ID],$D$4,TableBOM[Item ID],$A14)>0)*($H$4>0),$C$4&", ","") & IF((COUNTIFS(TableBOM[Product ID],$D$5,TableBOM[Item ID],$A14)>0)*($H$5>0),$C$5&", ","") & IF((COUNTIFS(TableBOM[Product ID],$D$6,TableBOM[Item ID],$A14)>0)*($H$6>0),$C$6&", ","") & IF((COUNTIFS(TableBOM[Product ID],$D$7,TableBOM[Item ID],$A14)>0)*($H$7>0),$C$7&", ",""),LEN(IF((COUNTIFS(TableBOM[Product ID],$D$3,TableBOM[Item ID],$A14)>0)*($H$3>0),$C$3&", ","") & IF((COUNTIFS(TableBOM[Product ID],$D$4,TableBOM[Item ID],$A14)>0)*($H$4>0),$C$4&", ","") & IF((COUNTIFS(TableBOM[Product ID],$D$5,TableBOM[Item ID],$A14)>0)*($H$5>0),$C$5&", ","") & IF((COUNTIFS(TableBOM[Product ID],$D$6,TableBOM[Item ID],$A14)>0)*($H$6>0),$C$6&", ","") & IF((COUNTIFS(TableBOM[Product ID],$D$7,TableBOM[Item ID],$A14)>0)*($H$7>0),$C$7&", ",""))-2),"")
A15: 22 | B15: SLUG | C15: 19X4.2 | D15: kg | E15: =SUMPRODUCT((TableBOM[Item ID]=A15)*TableBOM[Per 1000 Units]*(1+TableBOM[Scrap %])*((SUMIF($D$3:$D$7,TableBOM[Product ID],$H$3:$H$7))>0)*(SUMIF($D$3:$D$7,TableBOM[Product ID],$H$3:$H$7))/1000) -> 0 | F15: =IFERROR(INDEX(TableInventory[Store Balance],MATCH(A15,TableInventory[Item ID],0)),0)+IFERROR(INDEX(TableInventory[WIP],MATCH(A15,TableInventory[Item ID],0)),0) -> 0 | G15: =F15-E15 -> 0 | H15: =IFERROR(IF(SUMPRODUCT((TableBOM[Item ID]=A15)*((SUMIF($D$3:$D$7,TableBOM[Product ID],$H$3:$H$7))>0)*(SUMIF($D$3:$D$7,TableBOM[Product ID],$H$3:$H$7))*TableBOM[Per 1000 Units]*(1+TableBOM[Scrap %]))=0,"-",ROUND(F15*1000*SUMPRODUCT((TableBOM[Item ID]=A15)*((SUMIF($D$3:$D$7,TableBOM[Product ID],$H$3:$H$7))>0)*(SUMIF($D$3:$D$7,TableBOM[Product ID],$H$3:$H$7)))/SUMPRODUCT((TableBOM[Item ID]=A15)*((SUMIF($D$3:$D$7,TableBOM[Product ID],$H$3:$H$7))>0)*(SUMIF($D$3:$D$7,TableBOM[Product ID],$H$3:$H$7))*TableBOM[Per 1000 Units]*(1+TableBOM[Scrap %])),0)),"-") -> - | I15: =IF(E15=0,"Not needed",IF(G15<0,"SHORTAGE",IF(G15<E15*0.1,"LOW","OK"))) -> Not needed | J15: =IF(LEN(IF((COUNTIFS(TableBOM[Product ID],$D$3,TableBOM[Item ID],$A15)>0)*($H$3>0),$C$3&", ","") & IF((COUNTIFS(TableBOM[Product ID],$D$4,TableBOM[Item ID],$A15)>0)*($H$4>0),$C$4&", ","") & IF((COUNTIFS(TableBOM[Product ID],$D$5,TableBOM[Item ID],$A15)>0)*($H$5>0),$C$5&", ","") & IF((COUNTIFS(TableBOM[Product ID],$D$6,TableBOM[Item ID],$A15)>0)*($H$6>0),$C$6&", ","") & IF((COUNTIFS(TableBOM[Product ID],$D$7,TableBOM[Item ID],$A15)>0)*($H$7>0),$C$7&", ",""))>1,LEFT(IF((COUNTIFS(TableBOM[Product ID],$D$3,TableBOM[Item ID],$A15)>0)*($H$3>0),$C$3&", ","") & IF((COUNTIFS(TableBOM[Product ID],$D$4,TableBOM[Item ID],$A15)>0)*($H$4>0),$C$4&", ","") & IF((COUNTIFS(TableBOM[Product ID],$D$5,TableBOM[Item ID],$A15)>0)*($H$5>0),$C$5&", ","") & IF((COUNTIFS(TableBOM[Product ID],$D$6,TableBOM[Item ID],$A15)>0)*($H$6>0),$C$6&", ","") & IF((COUNTIFS(TableBOM[Product ID],$D$7,TableBOM[Item ID],$A15)>0)*($H$7>0),$C$7&", ",""),LEN(IF((COUNTIFS(TableBOM[Product ID],$D$3,TableBOM[Item ID],$A15)>0)*($H$3>0),$C$3&", ","") & IF((COUNTIFS(TableBOM[Product ID],$D$4,TableBOM[Item ID],$A15)>0)*($H$4>0),$C$4&", ","") & IF((COUNTIFS(TableBOM[Product ID],$D$5,TableBOM[Item ID],$A15)>0)*($H$5>0),$C$5&", ","") & IF((COUNTIFS(TableBOM[Product ID],$D$6,TableBOM[Item ID],$A15)>0)*($H$6>0),$C$6&", ","") & IF((COUNTIFS(TableBOM[Product ID],$D$7,TableBOM[Item ID],$A15)>0)*($H$7>0),$C$7&", ",""))-2),"")
A16: 19 | B16: SLUG | C16: 19X4.5 S/M | D16: kg | E16: =SUMPRODUCT((TableBOM[Item ID]=A16)*TableBOM[Per 1000 Units]*(1+TableBOM[Scrap %])*((SUMIF($D$3:$D$7,TableBOM[Product ID],$H$3:$H$7))>0)*(SUMIF($D$3:$D$7,TableBOM[Product ID],$H$3:$H$7))/1000) -> 0 | F16: =IFERROR(INDEX(TableInventory[Store Balance],MATCH(A16,TableInventory[Item ID],0)),0)+IFERROR(INDEX(TableInventory[WIP],MATCH(A16,TableInventory[Item ID],0)),0) -> 425 | G16: =F16-E16 -> 425 | H16: =IFERROR(IF(SUMPRODUCT((TableBOM[Item ID]=A16)*((SUMIF($D$3:$D$7,TableBOM[Product ID],$H$3:$H$7))>0)*(SUMIF($D$3:$D$7,TableBOM[Product ID],$H$3:$H$7))*TableBOM[Per 1000 Units]*(1+TableBOM[Scrap %]))=0,"-",ROUND(F16*1000*SUMPRODUCT((TableBOM[Item ID]=A16)*((SUMIF($D$3:$D$7,TableBOM[Product ID],$H$3:$H$7))>0)*(SUMIF($D$3:$D$7,TableBOM[Product ID],$H$3:$H$7)))/SUMPRODUCT((TableBOM[Item ID]=A16)*((SUMIF($D$3:$D$7,TableBOM[Product ID],$H$3:$H$7))>0)*(SUMIF($D$3:$D$7,TableBOM[Product ID],$H$3:$H$7))*TableBOM[Per 1000 Units]*(1+TableBOM[Scrap %])),0)),"-") -> - | I16: =IF(E16=0,"Not needed",IF(G16<0,"SHORTAGE",IF(G16<E16*0.1,"LOW","OK"))) -> Not needed | J16: =IF(LEN(IF((COUNTIFS(TableBOM[Product ID],$D$3,TableBOM[Item ID],$A16)>0)*($H$3>0),$C$3&", ","") & IF((COUNTIFS(TableBOM[Product ID],$D$4,TableBOM[Item ID],$A16)>0)*($H$4>0),$C$4&", ","") & IF((COUNTIFS(TableBOM[Product ID],$D$5,TableBOM[Item ID],$A16)>0)*($H$5>0),$C$5&", ","") & IF((COUNTIFS(TableBOM[Product ID],$D$6,TableBOM[Item ID],$A16)>0)*($H$6>0),$C$6&", ","") & IF((COUNTIFS(TableBOM[Product ID],$D$7,TableBOM[Item ID],$A16)>0)*($H$7>0),$C$7&", ",""))>1,LEFT(IF((COUNTIFS(TableBOM[Product ID],$D$3,TableBOM[Item ID],$A16)>0)*($H$3>0),$C$3&", ","") & IF((COUNTIFS(TableBOM[Product ID],$D$4,TableBOM[Item ID],$A16)>0)*($H$4>0),$C$4&", ","") & IF((COUNTIFS(TableBOM[Product ID],$D$5,TableBOM[Item ID],$A16)>0)*($H$5>0),$C$5&", ","") & IF((COUNTIFS(TableBOM[Product ID],$D$6,TableBOM[Item ID],$A16)>0)*($H$6>0),$C$6&", ","") & IF((COUNTIFS(TableBOM[Product ID],$D$7,TableBOM[Item ID],$A16)>0)*($H$7>0),$C$7&", ",""),LEN(IF((COUNTIFS(TableBOM[Product ID],$D$3,TableBOM[Item ID],$A16)>0)*($H$3>0),$C$3&", ","") & IF((COUNTIFS(TableBOM[Product ID],$D$4,TableBOM[Item ID],$A16)>0)*($H$4>0),$C$4&", ","") & IF((COUNTIFS(TableBOM[Product ID],$D$5,TableBOM[Item ID],$A16)>0)*($H$5>0),$C$5&", ","") & IF((COUNTIFS(TableBOM[Product ID],$D$6,TableBOM[Item ID],$A16)>0)*($H$6>0),$C$6&", ","") & IF((COUNTIFS(TableBOM[Product ID],$D$7,TableBOM[Item ID],$A16)>0)*($H$7>0),$C$7&", ",""))-2),"")
A17: 4179 | B17: SLUG | C17: 20.5x4.5 | D17: kg | E17: =SUMPRODUCT((TableBOM[Item ID]=A17)*TableBOM[Per 1000 Units]*(1+TableBOM[Scrap %])*((SUMIF($D$3:$D$7,TableBOM[Product ID],$H$3:$H$7))>0)*(SUMIF($D$3:$D$7,TableBOM[Product ID],$H$3:$H$7))/1000) -> 95.2754 | F17: =IFERROR(INDEX(TableInventory[Store Balance],MATCH(A17,TableInventory[Item ID],0)),0)+IFERROR(INDEX(TableInventory[WIP],MATCH(A17,TableInventory[Item ID],0)),0) -> 132 | G17: =F17-E17 -> 36.7246 | H17: =IFERROR(IF(SUMPRODUCT((TableBOM[Item ID]=A17)*((SUMIF($D$3:$D$7,TableBOM[Product ID],$H$3:$H$7))>0)*(SUMIF($D$3:$D$7,TableBOM[Product ID],$H$3:$H$7))*TableBOM[Per 1000 Units]*(1+TableBOM[Scrap %]))=0,"-",ROUND(F17*1000*SUMPRODUCT((TableBOM[Item ID]=A17)*((SUMIF($D$3:$D$7,TableBOM[Product ID],$H$3:$H$7))>0)*(SUMIF($D$3:$D$7,TableBOM[Product ID],$H$3:$H$7)))/SUMPRODUCT((TableBOM[Item ID]=A17)*((SUMIF($D$3:$D$7,TableBOM[Product ID],$H$3:$H$7))>0)*(SUMIF($D$3:$D$7,TableBOM[Product ID],$H$3:$H$7))*TableBOM[Per 1000 Units]*(1+TableBOM[Scrap %])),0)),"-") -> 30480 | I17: =IF(E17=0,"Not needed",IF(G17<0,"SHORTAGE",IF(G17<E17*0.1,"LOW","OK"))) -> OK | J17: =IF(LEN(IF((COUNTIFS(TableBOM[Product ID],$D$3,TableBOM[Item ID],$A17)>0)*($H$3>0),$C$3&", ","") & IF((COUNTIFS(TableBOM[Product ID],$D$4,TableBOM[Item ID],$A17)>0)*($H$4>0),$C$4&", ","") & IF((COUNTIFS(TableBOM[Product ID],$D$5,TableBOM[Item ID],$A17)>0)*($H$5>0),$C$5&", ","") & IF((COUNTIFS(TableBOM[Product ID],$D$6,TableBOM[Item ID],$A17)>0)*($H$6>0),$C$6&", ","") & IF((COUNTIFS(TableBOM[Product ID],$D$7,TableBOM[Item ID],$A17)>0)*($H$7>0),$C$7&", ",""))>1,LEFT(IF((COUNTIFS(TableBOM[Product ID],$D$3,TableBOM[Item ID],$A17)>0)*($H$3>0),$C$3&", ","") & IF((COUNTIFS(TableBOM[Product ID],$D$4,TableBOM[Item ID],$A17)>0)*($H$4>0),$C$4&", ","") & IF((COUNTIFS(TableBOM[Product ID],$D$5,TableBOM[Item ID],$A17)>0)*($H$5>0),$C$5&", ","") & IF((COUNTIFS(TableBOM[Product ID],$D$6,TableBOM[Item ID],$A17)>0)*($H$6>0),$C$6&", ","") & IF((COUNTIFS(TableBOM[Product ID],$D$7,TableBOM[Item ID],$A17)>0)*($H$7>0),$C$7&", ",""),LEN(IF((COUNTIFS(TableBOM[Product ID],$D$3,TableBOM[Item ID],$A17)>0)*($H$3>0),$C$3&", ","") & IF((COUNTIFS(TableBOM[Product ID],$D$4,TableBOM[Item ID],$A17)>0)*($H$4>0),$C$4&", ","") & IF((COUNTIFS(TableBOM[Product ID],$D$5,TableBOM[Item ID],$A17)>0)*($H$5>0),$C$5&", ","") & IF((COUNTIFS(TableBOM[Product ID],$D$6,TableBOM[Item ID],$A17)>0)*($H$6>0),$C$6&", ","") & IF((COUNTIFS(TableBOM[Product ID],$D$7,TableBOM[Item ID],$A17)>0)*($H$7>0),$C$7&", ",""))-2),"") -> VINCE HIS ONLY BEARD & MUSTACHE COLOR CREAM
A18: 6 | B18: SLUG | C18: 25X4.5 S/M | D18: kg | E18: =SUMPRODUCT((TableBOM[Item ID]=A18)*TableBOM[Per 1000 Units]*(1+TableBOM[Scrap %])*((SUMIF($D$3:$D$7,TableBOM[Product ID],$H$3:$H$7))>0)*(SUMIF($D$3:$D$7,TableBOM[Product ID],$H$3:$H$7))/1000) -> 195.261 | F18: =IFERROR(INDEX(TableInventory[Store Balance],MATCH(A18,TableInventory[Item ID],0)),0)+IFERROR(INDEX(TableInventory[WIP],MATCH(A18,TableInventory[Item ID],0)),0) -> 103 | G18: =F18-E18 -> -92.261 | H18: =IFERROR(IF(SUMPRODUCT((TableBOM[Item ID]=A18)*((SUMIF($D$3:$D$7,TableBOM[Product ID],$H$3:$H$7))>0)*(SUMIF($D$3:$D$7,TableBOM[Product ID],$H$3:$H$7))*TableBOM[Per 1000 Units]*(1+TableBOM[Scrap %]))=0,"-",ROUND(F18*1000*SUMPRODUCT((TableBOM[Item ID]=A18)*((SUMIF($D$3:$D$7,TableBOM[Product ID],$H$3:$H$7))>0)*(SUMIF($D$3:$D$7,TableBOM[Product ID],$H$3:$H$7)))/SUMPRODUCT((TableBOM[Item ID]=A18)*((SUMIF($D$3:$D$7,TableBOM[Product ID],$H$3:$H$7))>0)*(SUMIF($D$3:$D$7,TableBOM[Product ID],$H$3:$H$7))*TableBOM[Per 1000 Units]*(1+TableBOM[Scrap %])),0)),"-") -> 15825 | I18: =IF(E18=0,"Not needed",IF(G18<0,"SHORTAGE",IF(G18<E18*0.1,"LOW","OK"))) -> SHORTAGE | J18: =IF(LEN(IF((COUNTIFS(TableBOM[Product ID],$D$3,TableBOM[Item ID],$A18)>0)*($H$3>0),$C$3&", ","") & IF((COUNTIFS(TableBOM[Product ID],$D$4,TableBOM[Item ID],$A18)>0)*($H$4>0),$C$4&", ","") & IF((COUNTIFS(TableBOM[Product ID],$D$5,TableBOM[Item ID],$A18)>0)*($H$5>0),$C$5&", ","") & IF((COUNTIFS(TableBOM[Product ID],$D$6,TableBOM[Item ID],$A18)>0)*($H$6>0),$C$6&", ","") & IF((COUNTIFS(TableBOM[Product ID],$D$7,TableBOM[Item ID],$A18)>0)*($H$7>0),$C$7&", ",""))>1,LEFT(IF((COUNTIFS(TableBOM[Product ID],$D$3,TableBOM[Item ID],$A18)>0)*($H$3>0),$C$3&", ","") & IF((COUNTIFS(TableBOM[Product ID],$D$4,TableBOM[Item ID],$A18)>0)*($H$4>0),$C$4&", ","") & IF((COUNTIFS(TableBOM[Product ID],$D$5,TableBOM[Item ID],$A18)>0)*($H$5>0),$C$5&", ","") & IF((COUNTIFS(TableBOM[Product ID],$D$6,TableBOM[Item ID],$A18)>0)*($H$6>0),$C$6&", ","") & IF((COUNTIFS(TableBOM[Product ID],$D$7,TableBOM[Item ID],$A18)>0)*($H$7>0),$C$7&", ",""),LEN(IF((COUNTIFS(TableBOM[Product ID],$D$3,TableBOM[Item ID],$A18)>0)*($H$3>0),$C$3&", ","") & IF((COUNTIFS(TableBOM[Product ID],$D$4,TableBOM[Item ID],$A18)>0)*($H$4>0),$C$4&", ","") & IF((COUNTIFS(TableBOM[Product ID],$D$5,TableBOM[Item ID],$A18)>0)*($H$5>0),$C$5&", ","") & IF((COUNTIFS(TableBOM[Product ID],$D$6,TableBOM[Item ID],$A18)>0)*($H$6>0),$C$6&", ","") & IF((COUNTIFS(TableBOM[Product ID],$D$7,TableBOM[Item ID],$A18)>0)*($H$7>0),$C$7&", ",""))-2),"") -> TUBES COMMON RED
A19: 10 | B19: SLUG | C19: 25X4.8 S/M | D19: kg | E19: =SUMPRODUCT((TableBOM[Item ID]=A19)*TableBOM[Per 1000 Units]*(1+TableBOM[Scrap %])*((SUMIF($D$3:$D$7,TableBOM[Product ID],$H$3:$H$7))>0)*(SUMIF($D$3:$D$7,TableBOM[Product ID],$H$3:$H$7))/1000) -> 0 | F19: =IFERROR(INDEX(TableInventory[Store Balance],MATCH(A19,TableInventory[Item ID],0)),0)+IFERROR(INDEX(TableInventory[WIP],MATCH(A19,TableInventory[Item ID],0)),0) -> 0 | G19: =F19-E19 -> 0 | H19: =IFERROR(IF(SUMPRODUCT((TableBOM[Item ID]=A19)*((SUMIF($D$3:$D$7,TableBOM[Product ID],$H$3:$H$7))>0)*(SUMIF($D$3:$D$7,TableBOM[Product ID],$H$3:$H$7))*TableBOM[Per 1000 Units]*(1+TableBOM[Scrap %]))=0,"-",ROUND(F19*1000*SUMPRODUCT((TableBOM[Item ID]=A19)*((SUMIF($D$3:$D$7,TableBOM[Product ID],$H$3:$H$7))>0)*(SUMIF($D$3:$D$7,TableBOM[Product ID],$H$3:$H$7)))/SUMPRODUCT((TableBOM[Item ID]=A19)*((SUMIF($D$3:$D$7,TableBOM[Product ID],$H$3:$H$7))>0)*(SUMIF($D$3:$D$7,TableBOM[Product ID],$H$3:$H$7))*TableBOM[Per 1000 Units]*(1+TableBOM[Scrap %])),0)),"-") -> - | I19: =IF(E19=0,"Not needed",IF(G19<0,"SHORTAGE",IF(G19<E19*0.1,"LOW","OK"))) -> Not needed | J19: =IF(LEN(IF((COUNTIFS(TableBOM[Product ID],$D$3,TableBOM[Item ID],$A19)>0)*($H$3>0),$C$3&", ","") & IF((COUNTIFS(TableBOM[Product ID],$D$4,TableBOM[Item ID],$A19)>0)*($H$4>0),$C$4&", ","") & IF((COUNTIFS(TableBOM[Product ID],$D$5,TableBOM[Item ID],$A19)>0)*($H$5>0),$C$5&", ","") & IF((COUNTIFS(TableBOM[Product ID],$D$6,TableBOM[Item ID],$A19)>0)*($H$6>0),$C$6&", ","") & IF((COUNTIFS(TableBOM[Product ID],$D$7,TableBOM[Item ID],$A19)>0)*($H$7>0),$C$7&", ",""))>1,LEFT(IF((COUNTIFS(TableBOM[Product ID],$D$3,TableBOM[Item ID],$A19)>0)*($H$3>0),$C$3&", ","") & IF((COUNTIFS(TableBOM[Product ID],$D$4,TableBOM[Item ID],$A19)>0)*($H$4>0),$C$4&", ","") & IF((COUNTIFS(TableBOM[Product ID],$D$5,TableBOM[Item ID],$A19)>0)*($H$5>0),$C$5&", ","") & IF((COUNTIFS(TableBOM[Product ID],$D$6,TableBOM[Item ID],$A19)>0)*($H$6>0),$C$6&", ","") & IF((COUNTIFS(TableBOM[Product ID],$D$7,TableBOM[Item ID],$A19)>0)*($H$7>0),$C$7&", ",""),LEN(IF((COUNTIFS(TableBOM[Product ID],$D$3,TableBOM[Item ID],$A19)>0)*($H$3>0),$C$3&", ","") & IF((COUNTIFS(TableBOM[Product ID],$D$4,TableBOM[Item ID],$A19)>0)*($H$4>0),$C$4&", ","") & IF((COUNTIFS(TableBOM[Product ID],$D$5,TableBOM[Item ID],$A19)>0)*($H$5>0),$C$5&", ","") & IF((COUNTIFS(TableBOM[Product ID],$D$6,TableBOM[Item ID],$A19)>0)*($H$6>0),$C$6&", ","") & IF((COUNTIFS(TableBOM[Product ID],$D$7,TableBOM[Item ID],$A19)>0)*($H$7>0),$C$7&", ",""))-2),"")
A20: 2 | B20: SLUG | C20: 30X4.3 | D20: kg | E20: =SUMPRODUCT((TableBOM[Item ID]=A20)*TableBOM[Per 1000 Units]*(1+TableBOM[Scrap %])*((SUMIF($D$3:$D$7,TableBOM[Product ID],$H$3:$H$7))>0)*(SUMIF($D$3:$D$7,TableBOM[Product ID],$H$3:$H$7))/1000) -> 0 | F20: =IFERROR(INDEX(TableInventory[Store Balance],MATCH(A20,TableInventory[Item ID],0)),0)+IFERROR(INDEX(TableInventory[WIP],MATCH(A20,TableInventory[Item ID],0)),0) -> 0 | G20: =F20-E20 -> 0 | H20: =IFERROR(IF(SUMPRODUCT((TableBOM[Item ID]=A20)*((SUMIF($D$3:$D$7,TableBOM[Product ID],$H$3:$H$7))>0)*(SUMIF($D$3:$D$7,TableBOM[Product ID],$H$3:$H$7))*TableBOM[Per 1000 Units]*(1+TableBOM[Scrap %]))=0,"-",ROUND(F20*1000*SUMPRODUCT((TableBOM[Item ID]=A20)*((SUMIF($D$3:$D$7,TableBOM[Product ID],$H$3:$H$7))>0)*(SUMIF($D$3:$D$7,TableBOM[Product ID],$H$3:$H$7)))/SUMPRODUCT((TableBOM[Item ID]=A20)*((SUMIF($D$3:$D$7,TableBOM[Product ID],$H$3:$H$7))>0)*(SUMIF($D$3:$D$7,TableBOM[Product ID],$H$3:$H$7))*TableBOM[Per 1000 Units]*(1+TableBOM[Scrap %])),0)),"-") -> - | I20: =IF(E20=0,"Not needed",IF(G20<0,"SHORTAGE",IF(G20<E20*0.1,"LOW","OK"))) -> Not needed | J20: =IF(LEN(IF((COUNTIFS(TableBOM[Product ID],$D$3,TableBOM[Item ID],$A20)>0)*($H$3>0),$C$3&", ","") & IF((COUNTIFS(TableBOM[Product ID],$D$4,TableBOM[Item ID],$A20)>0)*($H$4>0),$C$4&", ","") & IF((COUNTIFS(TableBOM[Product ID],$D$5,TableBOM[Item ID],$A20)>0)*($H$5>0),$C$5&", ","") & IF((COUNTIFS(TableBOM[Product ID],$D$6,TableBOM[Item ID],$A20)>0)*($H$6>0),$C$6&", ","") & IF((COUNTIFS(TableBOM[Product ID],$D$7,TableBOM[Item ID],$A20)>0)*($H$7>0),$C$7&", ",""))>1,LEFT(IF((COUNTIFS(TableBOM[Product ID],$D$3,TableBOM[Item ID],$A20)>0)*($H$3>0),$C$3&", ","") & IF((COUNTIFS(TableBOM[Product ID],$D$4,TableBOM[Item ID],$A20)>0)*($H$4>0),$C$4&", ","") & IF((COUNTIFS(TableBOM[Product ID],$D$5,TableBOM[Item ID],$A20)>0)*($H$5>0),$C$5&", ","") & IF((COUNTIFS(TableBOM[Product ID],$D$6,TableBOM[Item ID],$A20)>0)*($H$6>0),$C$6&", ","") & IF((COUNTIFS(TableBOM[Product ID],$D$7,TableBOM[Item ID],$A20)>0)*($H$7>0),$C$7&", ",""),LEN(IF((COUNTIFS(TableBOM[Product ID],$D$3,TableBOM[Item ID],$A20)>0)*($H$3>0),$C$3&", ","") & IF((COUNTIFS(TableBOM[Product ID],$D$4,TableBOM[Item ID],$A20)>0)*($H$4>0),$C$4&", ","") & IF((COUNTIFS(TableBOM[Product ID],$D$5,TableBOM[Item ID],$A20)>0)*($H$5>0),$C$5&", ","") & IF((COUNTIFS(TableBOM[Product ID],$D$6,TableBOM[Item ID],$A20)>0)*($H$6>0),$C$6&", ","") & IF((COUNTIFS(TableBOM[Product ID],$D$7,TableBOM[Item ID],$A20)>0)*($H$7>0),$C$7&", ",""))-2),"")
A21: 3597 | B21: SLUG | C21: SLUG 30X4.8 | D21: kg | E21: =SUMPRODUCT((TableBOM[Item ID]=A21)*TableBOM[Per 1000 Units]*(1+TableBOM[Scrap %])*((SUMIF($D$3:$D$7,TableBOM[Product ID],$H$3:$H$7))>0)*(SUMIF($D$3:$D$7,TableBOM[Product ID],$H$3:$H$7))/1000) -> 2116.2944 | F21: =IFERROR(INDEX(TableInventory[Store Balance],MATCH(A21,TableInventory[Item ID],0)),0)+IFERROR(INDEX(TableInventory[WIP],MATCH(A21,TableInventory[Item ID],0)),0) -> 85 | G21: =F21-E21 -> -2031.2944 | H21: =IFERROR(IF(SUMPRODUCT((TableBOM[Item ID]=A21)*((SUMIF($D$3:$D$7,TableBOM[Product ID],$H$3:$H$7))>0)*(SUMIF($D$3:$D$7,TableBOM[Product ID],$H$3:$H$7))*TableBOM[Per 1000 Units]*(1+TableBOM[Scrap %]))=0,"-",ROUND(F21*1000*SUMPRODUCT((TableBOM[Item ID]=A21)*((SUMIF($D$3:$D$7,TableBOM[Product ID],$H$3:$H$7))>0)*(SUMIF($D$3:$D$7,TableBOM[Product ID],$H$3:$H$7)))/SUMPRODUCT((TableBOM[Item ID]=A21)*((SUMIF($D$3:$D$7,TableBOM[Product ID],$H$3:$H$7))>0)*(SUMIF($D$3:$D$7,TableBOM[Product ID],$H$3:$H$7))*TableBOM[Per 1000 Units]*(1+TableBOM[Scrap %])),0)),"-") -> 9659 | I21: =IF(E21=0,"Not needed",IF(G21<0,"SHORTAGE",IF(G21<E21*0.1,"LOW","OK"))) -> SHORTAGE | J21: =IF(LEN(IF((COUNTIFS(TableBOM[Product ID],$D$3,TableBOM[Item ID],$A21)>0)*($H$3>0),$C$3&", ","") & IF((COUNTIFS(TableBOM[Product ID],$D$4,TableBOM[Item ID],$A21)>0)*($H$4>0),$C$4&", ","") & IF((COUNTIFS(TableBOM[Product ID],$D$5,TableBOM[Item ID],$A21)>0)*($H$5>0),$C$5&", ","") & IF((COUNTIFS(TableBOM[Product ID],$D$6,TableBOM[Item ID],$A21)>0)*($H$6>0),$C$6&", ","") & IF((COUNTIFS(TableBOM[Product ID],$D$7,TableBOM[Item ID],$A21)>0)*($H$7>0),$C$7&", ",""))>1,LEFT(IF((COUNTIFS(TableBOM[Product ID],$D$3,TableBOM[Item ID],$A21)>0)*($H$3>0),$C$3&", ","") & IF((COUNTIFS(TableBOM[Product ID],$D$4,TableBOM[Item ID],$A21)>0)*($H$4>0),$C$4&", ","") & IF((COUNTIFS(TableBOM[Product ID],$D$5,TableBOM[Item ID],$A21)>0)*($H$5>0),$C$5&", ","") & IF((COUNTIFS(TableBOM[Product ID],$D$6,TableBOM[Item ID],$A21)>0)*($H$6>0),$C$6&", ","") & IF((COUNTIFS(TableBOM[Product ID],$D$7,TableBOM[Item ID],$A21)>0)*($H$7>0),$C$7&", ",""),LEN(IF((COUNTIFS(TableBOM[Product ID],$D$3,TableBOM[Item ID],$A21)>0)*($H$3>0),$C$3&", ","") & IF((COUNTIFS(TableBOM[Product ID],$D$4,TableBOM[Item ID],$A21)>0)*($H$4>0),$C$4&", ","") & IF((COUNTIFS(TableBOM[Product ID],$D$5,TableBOM[Item ID],$A21)>0)*($H$5>0),$C$5&", ","") & IF((COUNTIFS(TableBOM[Product ID],$D$6,TableBOM[Item ID],$A21)>0)*($H$6>0),$C$6&", ","") & IF((COUNTIFS(TableBOM[Product ID],$D$7,TableBOM[Item ID],$A21)>0)*($H$7>0),$C$7&", ",""))-2),"") -> VINCE NURTURAL, HELLO HAIR COLOR
A22: 6961 | B22: SLUG | C22: 32X5.2 | D22: kg | E22: =SUMPRODUCT((TableBOM[Item ID]=A22)*TableBOM[Per 1000 Units]*(1+TableBOM[Scrap %])*((SUMIF($D$3:$D$7,TableBOM[Product ID],$H$3:$H$7))>0)*(SUMIF($D$3:$D$7,TableBOM[Product ID],$H$3:$H$7))/1000) -> 0 | F22: =IFERROR(INDEX(TableInventory[Store Balance],MATCH(A22,TableInventory[Item ID],0)),0)+IFERROR(INDEX(TableInventory[WIP],MATCH(A22,TableInventory[Item ID],0)),0) -> 0 | G22: =F22-E22 -> 0 | H22: =IFERROR(IF(SUMPRODUCT((TableBOM[Item ID]=A22)*((SUMIF($D$3:$D$7,TableBOM[Product ID],$H$3:$H$7))>0)*(SUMIF($D$3:$D$7,TableBOM[Product ID],$H$3:$H$7))*TableBOM[Per 1000 Units]*(1+TableBOM[Scrap %]))=0,"-",ROUND(F22*1000*SUMPRODUCT((TableBOM[Item ID]=A22)*((SUMIF($D$3:$D$7,TableBOM[Product ID],$H$3:$H$7))>0)*(SUMIF($D$3:$D$7,TableBOM[Product ID],$H$3:$H$7)))/SUMPRODUCT((TableBOM[Item ID]=A22)*((SUMIF($D$3:$D$7,TableBOM[Product ID],$H$3:$H$7))>0)*(SUMIF($D$3:$D$7,TableBOM[Product ID],$H$3:$H$7))*TableBOM[Per 1000 Units]*(1+TableBOM[Scrap %])),0)),"-") -> - | I22: =IF(E22=0,"Not needed",IF(G22<0,"SHORTAGE",IF(G22<E22*0.1,"LOW","OK"))) -> Not needed | J22: =IF(LEN(IF((COUNTIFS(TableBOM[Product ID],$D$3,TableBOM[Item ID],$A22)>0)*($H$3>0),$C$3&", ","") & IF((COUNTIFS(TableBOM[Product ID],$D$4,TableBOM[Item ID],$A22)>0)*($H$4>0),$C$4&", ","") & IF((COUNTIFS(TableBOM[Product ID],$D$5,TableBOM[Item ID],$A22)>0)*($H$5>0),$C$5&", ","") & IF((COUNTIFS(TableBOM[Product ID],$D$6,TableBOM[Item ID],$A22)>0)*($H$6>0),$C$6&", ","") & IF((COUNTIFS(TableBOM[Product ID],$D$7,TableBOM[Item ID],$A22)>0)*($H$7>0),$C$7&", ",""))>1,LEFT(IF((COUNTIFS(TableBOM[Product ID],$D$3,TableBOM[Item ID],$A22)>0)*($H$3>0),$C$3&", ","") & IF((COUNTIFS(TableBOM[Product ID],$D$4,TableBOM[Item ID],$A22)>0)*($H$4>0),$C$4&", ","") & IF((COUNTIFS(TableBOM[Product ID],$D$5,TableBOM[Item ID],$A22)>0)*($H$5>0),$C$5&", ","") & IF((COUNTIFS(TableBOM[Product ID],$D$6,TableBOM[Item ID],$A22)>0)*($H$6>0),$C$6&", ","") & IF((COUNTIFS(TableBOM[Product ID],$D$7,TableBOM[Item ID],$A22)>0)*($H$7>0),$C$7&", ",""),LEN(IF((COUNTIFS(TableBOM[Product ID],$D$3,TableBOM[Item ID],$A22)>0)*($H$3>0),$C$3&", ","") & IF((COUNTIFS(TableBOM[Product ID],$D$4,TableBOM[Item ID],$A22)>0)*($H$4>0),$C$4&", ","") & IF((COUNTIFS(TableBOM[Product ID],$D$5,TableBOM[Item ID],$A22)>0)*($H$5>0),$C$5&", ","") & IF((COUNTIFS(TableBOM[Product ID],$D$6,TableBOM[Item ID],$A22)>0)*($H$6>0),$C$6&", ","") & IF((COUNTIFS(TableBOM[Product ID],$D$7,TableBOM[Item ID],$A22)>0)*($H$7>0),$C$7&", ",""))-2),"")
... A91: 3043 | B91: PACKING | C91: PLASTIC DOORI | D91: ROLL | E91: =SUMPRODUCT((TableBOM[Item ID]=A91)*TableBOM[Per 1000 Units]*(1+TableBOM[Scrap %])*((SUMIF($D$3:$D$7,TableBOM[Product ID],$H$3:$H$7))>0)*(SUMIF($D$3:$D$7,TableBOM[Product ID],$H$3:$H$7))/1000) -> 0 | F91: =IFERROR(INDEX(TableInventory[Store Balance],MATCH(A91,TableInventory[Item ID],0)),0)+IFERROR(INDEX(TableInventory[WIP],MATCH(A91,TableInventory[Item ID],0)),0) -> 0 | G91: =F91-E91 -> 0 | H91: =IFERROR(IF(SUMPRODUCT((TableBOM[Item ID]=A91)*((SUMIF($D$3:$D$7,TableBOM[Product ID],$H$3:$H$7))>0)*(SUMIF($D$3:$D$7,TableBOM[Product ID],$H$3:$H$7))*TableBOM[Per 1000 Units]*(1+TableBOM[Scrap %]))=0,"-",ROUND(F91*1000*SUMPRODUCT((TableBOM[Item ID]=A91)*((SUMIF($D$3:$D$7,TableBOM[Product ID],$H$3:$H$7))>0)*(SUMIF($D$3:$D$7,TableBOM[Product ID],$H$3:$H$7)))/SUMPRODUCT((TableBOM[Item ID]=A91)*((SUMIF($D$3:$D$7,TableBOM[Product ID],$H$3:$H$7))>0)*(SUMIF($D$3:$D$7,TableBOM[Product ID],$H$3:$H$7))*TableBOM[Per 1000 Units]*(1+TableBOM[Scrap %])),0)),"-") -> - | I91: =IF(E91=0,"Not needed",IF(G91<0,"SHORTAGE",IF(G91<E91*0.1,"LOW","OK"))) -> Not needed | J91: =IF(LEN(IF((COUNTIFS(TableBOM[Product ID],$D$3,TableBOM[Item ID],$A91)>0)*($H$3>0),$C$3&", ","") & IF((COUNTIFS(TableBOM[Product ID],$D$4,TableBOM[Item ID],$A91)>0)*($H$4>0),$C$4&", ","") & IF((COUNTIFS(TableBOM[Product ID],$D$5,TableBOM[Item ID],$A91)>0)*($H$5>0),$C$5&", ","") & IF((COUNTIFS(TableBOM[Product ID],$D$6,TableBOM[Item ID],$A91)>0)*($H$6>0),$C$6&", ","") & IF((COUNTIFS(TableBOM[Product ID],$D$7,TableBOM[Item ID],$A91)>0)*($H$7>0),$C$7&", ",""))>1,LEFT(IF((COUNTIFS(TableBOM[Product ID],$D$3,TableBOM[Item ID],$A91)>0)*($H$3>0),$C$3&", ","") & IF((COUNTIFS(TableBOM[Product ID],$D$4,TableBOM[Item ID],$A91)>0)*($H$4>0),$C$4&", ","") & IF((COUNTIFS(TableBOM[Product ID],$D$5,TableBOM[Item ID],$A91)>0)*($H$5>0),$C$5&", ","") & IF((COUNTIFS(TableBOM[Product ID],$D$6,TableBOM[Item ID],$A91)>0)*($H$6>0),$C$6&", ","") & IF((COUNTIFS(TableBOM[Product ID],$D$7,TableBOM[Item ID],$A91)>0)*($H$7>0),$C$7&", ",""),LEN(IF((COUNTIFS(TableBOM[Product ID],$D$3,TableBOM[Item ID],$A91)>0)*($H$3>0),$C$3&", ","") & IF((COUNTIFS(TableBOM[Product ID],$D$4,TableBOM[Item ID],$A91)>0)*($H$4>0),$C$4&", ","") & IF((COUNTIFS(TableBOM[Product ID],$D$5,TableBOM[Item ID],$A91)>0)*($H$5>0),$C$5&", ","") & IF((COUNTIFS(TableBOM[Product ID],$D$6,TableBOM[Item ID],$A91)>0)*($H$6>0),$C$6&", ","") & IF((COUNTIFS(TableBOM[Product ID],$D$7,TableBOM[Item ID],$A91)>0)*($H$7>0),$C$7&", ",""))-2),"")
A94: OCTOBER 2026 PET Required Pet Orders | G94: Date: | H94: =TODAY() -> 46316
A95: Dia | B95: Customer | C95: Product Name | D95: Product ID | E95: Job Order # | F95: Required Qty | G95: Produced | H95: Remaining Balance | I95: Remarks
A96: 75 ml | B96: Alpha Labs PVT LTD | C96: PET BOTTLE (75ML) TRANSPARENT BODY MIST | D96: 8018 | E96: 352 | F96: 25000 | G96: =INDEX(Tubex_Dashboard!$H$11:$H$100,MATCH(MRP!D96,Tubex_Dashboard!$F$11:$F$100,0)) -> 0 | H96: =F96-G96 -> 25000
A97: 130 ml | B97: Mablay Beauty PVT LTD. | C97: PET BOTTLE 130ML WHITE | D97: 8015 | E97: 344 | F97: 9480 | G97: =INDEX(Tubex_Dashboard!$H$11:$H$100,MATCH(MRP!D97,Tubex_Dashboard!$F$11:$F$100,0)) -> 0 | H97: =F97-G97 -> 9480
A98: 130 ml | B98: Alpha Labs PVT LTD | C98: PET BOTTLE SMALL (130ML) TRANSPARENT | D98: 8019 | E98: 355 | F98: 5000 | G98: =INDEX(Tubex_Dashboard!$H$11:$H$100,MATCH(MRP!D98,Tubex_Dashboard!$F$11:$F$100,0)) -> 5000 | H98: =F98-G98 -> 0 | I98: Order Complete
A99: 130 ml | B99: Mablay Beauty PVT LTD. | C99: PET BOTTLE SMALL (130ML) TRANSPARENT | D99: 8010 | E99: 354 | F99: =30000-11500 -> 18500 | G99: =INDEX(Tubex_Dashboard!$H$11:$H$100,MATCH(MRP!D99,Tubex_Dashboard!$F$11:$F$100,0)) -> 18690 | H99: =F99-G99 -> -190 | I99: Order Complete
A100: 150 ml | B100: Alpha Labs PVT LTD | C100: PET BOTTLE (150ML)TRANSPARENT BODY MIST | D100: 8001 | E100: 341, 347, 348 & 353 | F100: 549967 | G100: =INDEX(Tubex_Dashboard!$H$11:$H$100,MATCH(MRP!D100,Tubex_Dashboard!$F$11:$F$100,0)) -> 108470 | H100: =F100-G100 -> 441497
A101: 200 ml | B101: Samsol International Private Limited | C101: PET BOTTLE LARGE (200 ML) YELLOW | D101: 8006 | E101: 351 | F101: 4280 | G101: =INDEX(Tubex_Dashboard!$H$11:$H$100,MATCH(MRP!D101,Tubex_Dashboard!$F$11:$F$100,0)) -> 0 | H101: =F101-G101 -> 4280
E102: TOTAL: | F102: =SUM(F96:F101) -> 612227 | G102: =SUM(G96:G101) -> 132160 | H102: =SUMIF(H96:H101, ">0") -> 480257
A103: OCTOBER PET MATERIAL REQUIREMENT PLAN
A104: Item ID | B104: Category | C104: Item Name | D104: UOM | E104: Required Qty | F104: Current Stock (Store + WIP) | G104: Surplus / (Deficit) | H104: Current Stock Pieces Can Produce | I104: Status | J104: Product Name(s)
A105: 2680 | B105: PET RESIN | C105: PET RESIN A-84 | D105: kg | E105: =SUMPRODUCT((TableBOM[Item ID]=A105)*TableBOM[Per 1000 Units]*(1+TableBOM[Scrap %])*((SUMIF($D$96:$D$101,TableBOM[Product ID],$H$96:$H$101))>0)*(SUMIF($D$96:$D$101,TableBOM[Product ID],$H$96:$H$101))/1000) -> 12105.696 | F105: =IFERROR(INDEX(TableInventory[Store Balance],MATCH(A105,TableInventory[Item ID],0)),0)+IFERROR(INDEX(TableInventory[WIP],MATCH(A105,TableInventory[Item ID],0)),0) -> 50 | G105: =F105-E105 -> -12055.696 | H105: =IFERROR(IF(SUMPRODUCT((TableBOM[Item ID]=A105)*((SUMIF($D$96:$D$101,TableBOM[Product ID],$H$96:$H$101))>0)*(SUMIF($D$96:$D$101,TableBOM[Product ID],$H$96:$H$101))*TableBOM[Per 1000 Units]*(1+TableBOM[Scrap %]))=0,"-",ROUND(F105*1000*SUMPRODUCT((TableBOM[Item ID]=A105)*((SUMIF($D$96:$D$101,TableBOM[Product ID],$H$96:$H$101))>0)*(SUMIF($D$96:$D$101,TableBOM[Product ID],$H$96:$H$101)))/SUMPRODUCT((TableBOM[Item ID]=A105)*((SUMIF($D$96:$D$101,TableBOM[Product ID],$H$96:$H$101))>0)*(SUMIF($D$96:$D$101,TableBOM[Product ID],$H$96:$H$101))*TableBOM[Per 1000 Units]*(1+TableBOM[Scrap %])),0)),"-") -> 1984 | I105: =IF(E105=0,"Not needed",IF(G105<0,"SHORTAGE",IF(G105<E105*0.1,"LOW","OK"))) -> SHORTAGE | J105: =IF(LEN(IF((COUNTIFS(TableBOM[Product ID],$D$96,TableBOM[Item ID],$A105)>0)*($H$96>0),"Alpha 75ml TRP, ","") & IF((COUNTIFS(TableBOM[Product ID],$D$97,TableBOM[Item ID],$A105)>0)*($H$97>0),"Mablay 130ml White, ","") & IF((COUNTIFS(TableBOM[Product ID],$D$98,TableBOM[Item ID],$A105)>0)*($H$98>0),"Alpha 130ml TRP, ","") & IF((COUNTIFS(TableBOM[Product ID],$D$99,TableBOM[Item ID],$A105)>0)*($H$99>0),"Mablay 130ml TRP, ","") & IF((COUNTIFS(TableBOM[Product ID],$D$100,TableBOM[Item ID],$A105)>0)*($H$100>0),"Alpha 150ml TRP, ","") & IF((COUNTIFS(TableBOM[Product ID],$D$101,TableBOM[Item ID],$A105)>0)*($H$101>0),"Samsol Yellow 200ml, ",""))>1,LEFT(IF((COUNTIFS(TableBOM[Product ID],$D$96,TableBOM[Item ID],$A105)>0)*($H$96>0),"Alpha 75ml TRP, ","") & IF((COUNTIFS(TableBOM[Product ID],$D$97,TableBOM[Item ID],$A105)>0)*($H$97>0),"Mablay 130ml White, ","") & IF((COUNTIFS(TableBOM[Product ID],$D$98,TableBOM[Item ID],$A105)>0)*($H$98>0),"Alpha 130ml TRP, ","") & IF((COUNTIFS(TableBOM[Product ID],$D$99,TableBOM[Item ID],$A105)>0)*($H$99>0),"Mablay 130ml TRP, ","") & IF((COUNTIFS(TableBOM[Product ID],$D$100,TableBOM[Item ID],$A105)>0)*($H$100>0),"Alpha 150ml TRP, ","") & IF((COUNTIFS(TableBOM[Product ID],$D$101,TableBOM[Item ID],$A105)>0)*($H$101>0),"Samsol Yellow 200ml, ",""),LEN(IF((COUNTIFS(TableBOM[Product ID],$D$96,TableBOM[Item ID],$A105)>0)*($H$96>0),"Alpha 75ml TRP, ","") & IF((COUNTIFS(TableBOM[Product ID],$D$97,TableBOM[Item ID],$A105)>0)*($H$97>0),"Mablay 130ml White, ","") & IF((COUNTIFS(TableBOM[Product ID],$D$98,TableBOM[Item ID],$A105)>0)*($H$98>0),"Alpha 130ml TRP, ","") & IF((COUNTIFS(TableBOM[Product ID],$D$99,TableBOM[Item ID],$A105)>0)*($H$99>0),"Mablay 130ml TRP, ","") & IF((COUNTIFS(TableBOM[Product ID],$D$100,TableBOM[Item ID],$A105)>0)*($H$100>0),"Alpha 150ml TRP, ","") & IF((COUNTIFS(TableBOM[Product ID],$D$101,TableBOM[Item ID],$A105)>0)*($H$101>0),"Samsol Yellow 200ml, ",""))-2),"") -> Alpha 75ml TRP, Mablay 130ml White, Alpha 150ml TRP, Samsol Yellow 200ml
