Workbook

Sheet Tubex_Dashboard
B2: TUBEX — July 2026 Month to Date Report
B3: Report Date (Yesterday's Production): | H3: =TODAY()-1 -> 46209
B5: TUBE — YESTERDAY | D5: TUBE — MTD | G5: TUBE — REJECT % | J5: Dispatch — MTD | M5: Press & Printing Downtime — MTD
B6: =SUMPRODUCT((Production_Log!$A$3:$A$8963=MAX(Production_Log!$A$3:$A$8963))*(LEFT(Production_Log!$B$3:$B$8963,5)="Print")*(ISERROR(SEARCH("(Varnish)",Production_Log!$D$3:$D$8963)))*Production_Log!$H$3:$H$8963) -> 21724 | D6: =SUMIF($B$11:$B$64,"TUBE",$H$11:$H$64) -> 83072 | G6: {=IFERROR(SUMPRODUCT((Production_Log!$F$3:$F$8963<>0)*(LEFT(Production_Log!$B$3:$B$8963,5)="Print")*(ISERROR(SEARCH("(Varnish)",Production_Log!$D$3:$D$8963)))*Production_Log!$I$3:$I$8963)/SUMPRODUCT((Production_Log!$F$3:$F$8963<>0)*(LEFT(Production_Log!$B$3:$B$8963,5)="Print")*(ISERROR(SEARCH("(Varnish)",Production_Log!$D$3:$D$8963)))*(Production_Log!$H$3:$H$8963+Production_Log!$I$3:$I$8963)),"-")} -> 0.022820308 | J6: =SUMIF($B$11:$B$64,"TUBE",$K$11:$K$64) -> 76160 | M6: Category | N6: Hours (MTD) | O6: % Share
B7: PET — YESTERDAY | D7: PET — MTD | G7: PET — REJECT % | J7: Dispatch — MTD | M7: =IFERROR(INDEX($S$9:$S$21,MATCH(LARGE($U$9:$U$21,1),$U$9:$U$21,0)),"") -> Operations | N7: =(IFERROR(INDEX($T$9:$T$21,MATCH(LARGE($U$9:$U$21,1),$U$9:$U$21,0)),""))/60 -> 14 | O7: =IFERROR(N7/$N$14,"") -> 0.42424242
B8: =SUMPRODUCT((Production_Log!$A$3:$A$8963=MAX(Production_Log!$A$3:$A$8963))*(Production_Log!$B$3:$B$8963="PF Machine")*Production_Log!$H$3:$H$8963) -> 5400 | D8: 5400 | G8: {=IFERROR(SUMPRODUCT((Production_Log!$B$3:$B$8963="PF Machine")*Production_Log!$I$3:$I$8963)/SUMPRODUCT((Production_Log!$B$3:$B$8963="PF Machine")*(Production_Log!$H$3:$H$8963+Production_Log!$I$3:$I$8963)),0)} -> 0.12903226 | J8: =SUMIF($B$11:$B$64,"PET",$K$11:$K$64) -> 13800 | M8: =IFERROR(INDEX($S$9:$S$21,MATCH(LARGE($U$9:$U$21,2),$U$9:$U$21,0)),"") -> Power Shutdown | N8: =IFERROR(INDEX($T$9:$T$21,MATCH(LARGE($U$9:$U$21,2),$U$9:$U$21,0)),"")/60 -> 11 | O8: =IFERROR(N8/$N$14,"") -> 0.33333333
B9: Summary of Production & Dispatch - MTD | M9: =IFERROR(INDEX($S$9:$S$21,MATCH(LARGE($U$9:$U$21,3),$U$9:$U$21,0)),"") -> Mechanical | N9: =IFERROR(INDEX($T$9:$T$21,MATCH(LARGE($U$9:$U$21,3),$U$9:$U$21,0)),"")/60 -> 8 | O9: =IFERROR(N9/$N$14,"") -> 0.24242424 | S9: Mechanical | T9: =SUMPRODUCT(((LEFT(Production_Log!$B$3:$B$8963,5)="Press")+(LEFT(Production_Log!$B$3:$B$8963,5)="Print"))*Production_Log!$K$3:$K$8963) -> 480 | U9: =T9+0.00001 -> 480.00001
B10: Type | C10: Customer | D10: Product Name | E10: Dia | F10: Prod ID | G10: Orders | H10: MTD Produced | I10: Remaining | J10: Compliance | K10: Dispatch | L10: Remarks | M10: =IFERROR(INDEX($S$9:$S$21,MATCH(LARGE($U$9:$U$21,4),$U$9:$U$21,0)),"") -> Workers Shortage | N10: =IFERROR(INDEX($T$9:$T$21,MATCH(LARGE($U$9:$U$21,4),$U$9:$U$21,0)),"")/60 -> 0 | O10: =IFERROR(N10/$N$14,"") -> 0 | S10: Electrical | T10: =SUMPRODUCT(((LEFT(Production_Log!$B$3:$B$8963,5)="Press")+(LEFT(Production_Log!$B$3:$B$8963,5)="Print"))*Production_Log!$L$3:$L$8963) -> 0 | U10: =T10+0.00002 -> 2e-05
B11: TUBE | C11: Brookes Pharma Private Limited | D11: ECZEMUS OINTMENT 0.03% 10G | E11: 16 | F11: 6561 | G11: =IFERROR(INDEX(MRP!$F$3:$F$8,MATCH(Tubex_Dashboard!F11,MRP!$D$3:$D$8,0)),0) -> 25000 | H11: =SUMPRODUCT((Production_Log!$F$3:$F$8963=F11)*(LEFT(Production_Log!$B$3:$B$8963,5)="Print")*(ISERROR(SEARCH("(Varnish)",Production_Log!$D$3:$D$8963)))*Production_Log!$H$3:$H$8963) -> 0 | I11: =G11-H11 -> 25000 | J11: =IF(G11=0,"-",H11/G11) -> 0 | L11: Hold (Caps Not Approved) | M11: =IFERROR(INDEX($S$9:$S$21,MATCH(LARGE($U$9:$U$21,5),$U$9:$U$21,0)),"") -> Gas Shutdown | N11: =IFERROR(INDEX($T$9:$T$21,MATCH(LARGE($U$9:$U$21,5),$U$9:$U$21,0)),"")/60 -> 0 | O11: =IFERROR(N11/$N$14,"") -> 0
B12: TUBE | C12: Samsol International Private Limited | D12: S 43 25MM | E12: 25 | F12: 3447 | G12: =IFERROR(INDEX(MRP!$F$3:$F$8,MATCH(Tubex_Dashboard!F12,MRP!$D$3:$D$8,0)),0) -> 78976 | H12: =SUMPRODUCT((Production_Log!$F$3:$F$8963=F12)*(LEFT(Production_Log!$B$3:$B$8963,5)="Print")*(ISERROR(SEARCH("(Varnish)",Production_Log!$D$3:$D$8963)))*Production_Log!$H$3:$H$8963) -> 10416 | I12: =G12-H12 -> 68560 | J12: =IF(G12=0,"-",H12/G12) -> 0.13188817 | L12: 100k Extra Planned | M12: =IFERROR(INDEX($S$9:$S$21,MATCH(LARGE($U$9:$U$21,6),$U$9:$U$21,0)),"") -> Changeover | N12: =IFERROR(INDEX($T$9:$T$21,MATCH(LARGE($U$9:$U$21,6),$U$9:$U$21,0)),"")/60 -> 0 | O12: =IFERROR(N12/$N$14,"") -> 0 | S12: Material Shortage | T12: =SUMPRODUCT(((LEFT(Production_Log!$B$3:$B$8963,5)="Press")+(LEFT(Production_Log!$B$3:$B$8963,5)="Print"))*Production_Log!$M$3:$M$8963) -> 0 | U12: =T12+0.00003 -> 3e-05
B13: TUBE | C13: Samsol International Private Limited | D13: S-45 | E13: 25 | F13: 5389 | G13: =IFERROR(INDEX(MRP!$F$3:$F$8,MATCH(Tubex_Dashboard!F13,MRP!$D$3:$D$8,0)),0) -> 100000 | H13: =SUMPRODUCT((Production_Log!$F$3:$F$8963=F13)*(LEFT(Production_Log!$B$3:$B$8963,5)="Print")*(ISERROR(SEARCH("(Varnish)",Production_Log!$D$3:$D$8963)))*Production_Log!$H$3:$H$8963) -> 0 | I13: =G13-H13 -> 100000 | J13: =IF(G13=0,"-",H13/G13) -> 0 | L13: 100k Extra Planned | M13: =IFERROR(INDEX($S$9:$S$21,MATCH(LARGE($U$9:$U$21,7),$U$9:$U$21,0)),"") -> Material Shortage | N13: =IFERROR(INDEX($T$9:$T$21,MATCH(LARGE($U$9:$U$21,7),$U$9:$U$21,0)),"")/60 -> 0 | O13: =IFERROR(N13/$N$14,"") -> 0 | S13: Changeover | T13: =SUMPRODUCT(((LEFT(Production_Log!$B$3:$B$8963,5)="Press")+(LEFT(Production_Log!$B$3:$B$8963,5)="Print"))*Production_Log!$N$3:$N$8963) -> 0 | U13: =T13+0.00004 -> 4e-05
B14: TUBE | C14: Golden Pearl Cosmetics (PVT) LTD | D14: HELLO HAIR COLOR | E14: 30 | F14: 6206 | G14: =IFERROR(INDEX(MRP!$F$3:$F$8,MATCH(Tubex_Dashboard!F14,MRP!$D$3:$D$8,0)),0) -> 174138 | H14: =SUMPRODUCT((Production_Log!$F$3:$F$8963=F14)*(LEFT(Production_Log!$B$3:$B$8963,5)="Print")*(ISERROR(SEARCH("(Varnish)",Production_Log!$D$3:$D$8963)))*Production_Log!$H$3:$H$8963) -> 72656 | I14: =G14-H14 -> 101482 | J14: =IF(G14=0,"-",H14/G14) -> 0.41723231 | K14: 76160 | M14: TOTAL | N14: =SUM($T$9:$T$21)/60 -> 33 | O14: 100% | S14: Operations | T14: =SUMPRODUCT(((LEFT(Production_Log!$B$3:$B$8963,5)="Press")+(LEFT(Production_Log!$B$3:$B$8963,5)="Print"))*Production_Log!$O$3:$O$8963) -> 840 | U14: =T14+0.00005 -> 840.00005
B15: TUBE | C15: Mablay Beauty PVT LTD. | D15: VINCE NURTURAL | E15: 30 | F15: 5814 | G15: =IFERROR(INDEX(MRP!$F$3:$F$8,MATCH(Tubex_Dashboard!F15,MRP!$D$3:$D$8,0)),0) -> 30000 | H15: =SUMPRODUCT((Production_Log!$F$3:$F$8963=F15)*(LEFT(Production_Log!$B$3:$B$8963,5)="Print")*(ISERROR(SEARCH("(Varnish)",Production_Log!$D$3:$D$8963)))*Production_Log!$H$3:$H$8963) -> 0 | I15: =G15-H15 -> 30000 | J15: =IF(G15=0,"-",H15/G15) -> 0
B16: TUBE | C16: Adore | D16: V- HC BROWN | E16: 35 | F16: 6530 | G16: =IFERROR(INDEX(MRP!$F$3:$F$8,MATCH(Tubex_Dashboard!F16,MRP!$D$3:$D$8,0)),0) -> 13300 | H16: =SUMPRODUCT((Production_Log!$F$3:$F$8963=F16)*(LEFT(Production_Log!$B$3:$B$8963,5)="Print")*(ISERROR(SEARCH("(Varnish)",Production_Log!$D$3:$D$8963)))*Production_Log!$H$3:$H$8963) -> 0 | I16: =G16-H16 -> 13300 | J16: =IF(G16=0,"-",H16/G16) -> 0 | L16: Hold | S16: Power Shutdown | T16: =SUMPRODUCT(((LEFT(Production_Log!$B$3:$B$8963,5)="Press")+(LEFT(Production_Log!$B$3:$B$8963,5)="Print"))*Production_Log!$P$3:$P$8963) -> 660 | U16: =T16+0.00006 -> 660.00006
D17: TOTAL | G17: =SUM(G11:G16) -> 421414 | H17: =SUM(H11:H16) -> 83072 | I17: =SUMIF(I11:I16,">"&0) -> 338342 | K17: =SUM(K11:K16) -> 76160
B18: PET | C18: Samsol International Private Limited | D18: PET BOTTLE SMALL (120ML) YELLOW | E18: 120 ml | F18: 8005 | G18: 19840 | H18: =SUMPRODUCT((Production_Log!$F$3:$F$8963=F18)*Production_Log!$H$3:$H$8963) -> 0 | I18: =G18-H18 -> 19840 | J18: =IF(G18=0,"-",H18/G18) -> 0 | S18: Gas Shutdown | T18: =SUMPRODUCT(((LEFT(Production_Log!$B$3:$B$8963,5)="Press")+(LEFT(Production_Log!$B$3:$B$8963,5)="Print"))*Production_Log!$Q$3:$Q$8963) -> 0 | U18: =T18+0.00007 -> 7e-05
B19: PET | C19: Mablay Beauty PVT LTD. | D19: PET BOTTLE 130ML WHITE | E19: 130 ml | F19: 8015 | G19: 15000 | H19: =SUMPRODUCT((Production_Log!$F$3:$F$8963=F19)*Production_Log!$H$3:$H$8963) -> 0 | I19: =G19-H19 -> 15000 | J19: =IF(G19=0,"-",H19/G19) -> 0 | S19: Workers Shortage | T19: =SUMPRODUCT(((LEFT(Production_Log!$B$3:$B$8963,5)="Press")+(LEFT(Production_Log!$B$3:$B$8963,5)="Print"))*Production_Log!$R$3:$R$8963) -> 0 | U19: =T19+0.00008 -> 8e-05
B20: PET | C20: Alpha Labs PVT LTD | D20: TRANSPARENT BOTTLE 150ML | E20: 150 ml | F20: 8001 | G20: 153167 | H20: =SUMPRODUCT((Production_Log!$F$3:$F$8963=F20)*Production_Log!$H$3:$H$8963) -> 0 | I20: =G20-H20 -> 153167 | J20: =IF(G20=0,"-",H20/G20) -> 0 | K20: 13800
B21: PET | C21: Samsol International Private Limited | D21: PET BOTTLE LARGE 200ML WHITE | E21: 200 ml | F21: 8007 | G21: 10000 | H21: =SUMPRODUCT((Production_Log!$F$3:$F$8963=F21)*Production_Log!$H$3:$H$8963) -> 0 | I21: =G21-H21 -> 10000 | J21: =IF(G21=0,"-",H21/G21) -> 0
B22: PET | C22: Samsol International Private Limited | D22: PET BOTTLE LARGE (200 ML) YELLOW | E22: 200 ml | F22: 8006 | G22: 42400 | H22: =SUMPRODUCT((Production_Log!$F$3:$F$8963=F22)*Production_Log!$H$3:$H$8963) -> 0 | I22: =G22-H22 -> 42400 | J22: =IF(G22=0,"-",H22/G22) -> 0
B23: PET | C23: Samsol International Private Limited | D23: BT-200ML MUSTARD OIL (TRANSPARENT) | E23: 200 ml | F23: 8014 | G23: 10000 | H23: =SUMPRODUCT((Production_Log!$F$3:$F$8963=F23)*Production_Log!$H$3:$H$8963) -> 0 | I23: =G23-H23 -> 10000 | J23: =IF(G23=0,"-",H23/G23) -> 0
D24: TOTAL | G24: =SUM(G18:G23) -> 250407 | H24: =SUM(H18:H23) -> 0 | I24: =SUMIF(I18:I23,">"&0) -> 250407 | K24: =SUM(K18:K23) -> 13800
B25: TUBE | C25: Bahadur | D25: BAHADUR TUBE 12.5MM | E25: 12.5 | F25: 9004 | G25: =IFERROR(INDEX(MRP!$F$3:$F$8,MATCH(Tubex_Dashboard!F25,MRP!$D$3:$D$8,0)),0) -> 0 | H25: =SUMPRODUCT((Production_Log!$F$3:$F$8963=F25)*(LEFT(Production_Log!$B$3:$B$8963,5)="Print")*(ISERROR(SEARCH("(Varnish)",Production_Log!$D$3:$D$8963)))*Production_Log!$H$3:$H$8963) -> 0 | I25: =G25-H25 -> 0 | J25: =IF(G25=0,"-",H25/G25) -> -
B26: TUBE | C26: Samsol International Private Limited | D26: S-45 DIA 19MM | E26: 19 | F26: 6624 | G26: =IFERROR(INDEX(MRP!$F$3:$F$8,MATCH(Tubex_Dashboard!F26,MRP!$D$3:$D$8,0)),0) -> 0 | H26: =SUMPRODUCT((Production_Log!$F$3:$F$8963=F26)*(LEFT(Production_Log!$B$3:$B$8963,5)="Print")*(ISERROR(SEARCH("(Varnish)",Production_Log!$D$3:$D$8963)))*Production_Log!$H$3:$H$8963) -> 0 | I26: =G26-H26 -> 0 | J26: =IF(G26=0,"-",H26/G26) -> -
B27: TUBE | C27: Samsol International Private Limited | D27: S-43 DIA 19MM | E27: 19 | F27: 6623 | G27: =IFERROR(INDEX(MRP!$F$3:$F$8,MATCH(Tubex_Dashboard!F27,MRP!$D$3:$D$8,0)),0) -> 0 | H27: =SUMPRODUCT((Production_Log!$F$3:$F$8963=F27)*(LEFT(Production_Log!$B$3:$B$8963,5)="Print")*(ISERROR(SEARCH("(Varnish)",Production_Log!$D$3:$D$8963)))*Production_Log!$H$3:$H$8963) -> 0 | I27: =G27-H27 -> 0 | J27: =IF(G27=0,"-",H27/G27) -> -
B28: TUBE | C28: Brookes Pharma Private Limited | D28: PHLOGIN GEL 20G | E28: 19 | F28: 6559 | G28: =IFERROR(INDEX(MRP!$F$3:$F$8,MATCH(Tubex_Dashboard!F28,MRP!$D$3:$D$8,0)),0) -> 0 | H28: =SUMPRODUCT((Production_Log!$F$3:$F$8963=F28)*(LEFT(Production_Log!$B$3:$B$8963,5)="Print")*(ISERROR(SEARCH("(Varnish)",Production_Log!$D$3:$D$8963)))*Production_Log!$H$3:$H$8963) -> 0 | I28: =G28-H28 -> 0 | J28: =IF(G28=0,"-",H28/G28) -> -
B29: TUBE | C29: Brookes Pharma Private Limited | D29: PYODINE GEL 20GM | E29: 19 | F29: 1085 | G29: =IFERROR(INDEX(MRP!$F$3:$F$8,MATCH(Tubex_Dashboard!F29,MRP!$D$3:$D$8,0)),0) -> 0 | H29: =SUMPRODUCT((Production_Log!$F$3:$F$8963=F29)*(LEFT(Production_Log!$B$3:$B$8963,5)="Print")*(ISERROR(SEARCH("(Varnish)",Production_Log!$D$3:$D$8963)))*Production_Log!$H$3:$H$8963) -> 0 | I29: =G29-H29 -> 0 | J29: =IF(G29=0,"-",H29/G29) -> -
B30: TUBE | C30: Brookes Pharma Private Limited | D30: CONTRATUBEX GEL 20G | E30: 19 | F30: 6560 | G30: =IFERROR(INDEX(MRP!$F$3:$F$8,MATCH(Tubex_Dashboard!F30,MRP!$D$3:$D$8,0)),0) -> 0 | H30: =SUMPRODUCT((Production_Log!$F$3:$F$8963=F30)*(LEFT(Production_Log!$B$3:$B$8963,5)="Print")*(ISERROR(SEARCH("(Varnish)",Production_Log!$D$3:$D$8963)))*Production_Log!$H$3:$H$8963) -> 0 | I30: =G30-H30 -> 0 | J30: =IF(G30=0,"-",H30/G30) -> -
B31: TUBE | C31: Samsol International Private Limited | D31: S-43 DIA 20.5 | E31: 20.5 | F31: 5699 | G31: =IFERROR(INDEX(MRP!$F$3:$F$8,MATCH(Tubex_Dashboard!F31,MRP!$D$3:$D$8,0)),0) -> 0 | H31: =SUMPRODUCT((Production_Log!$F$3:$F$8963=F31)*(LEFT(Production_Log!$B$3:$B$8963,5)="Print")*(ISERROR(SEARCH("(Varnish)",Production_Log!$D$3:$D$8963)))*Production_Log!$H$3:$H$8963) -> 0 | I31: =G31-H31 -> 0 | J31: =IF(G31=0,"-",H31/G31) -> -
B32: TUBE | C32: Mablay Beauty PVT LTD. | D32: VINCE HIS ONLY BEARD & MUSTACHE COLOR CREAM | E32: 20.5 | F32: 6077 | G32: =IFERROR(INDEX(MRP!$F$3:$F$8,MATCH(Tubex_Dashboard!F32,MRP!$D$3:$D$8,0)),0) -> 0 | H32: =SUMPRODUCT((Production_Log!$F$3:$F$8963=F32)*(LEFT(Production_Log!$B$3:$B$8963,5)="Print")*(ISERROR(SEARCH("(Varnish)",Production_Log!$D$3:$D$8963)))*Production_Log!$H$3:$H$8963) -> 0 | I32: =G32-H32 -> 0 | J32: =IF(G32=0,"-",H32/G32) -> -
B33: TUBE | C33: Samsol International Private Limited | D33: S-45 DIA 20.5 | E33: 20.5 | F33: 5698 | G33: =IFERROR(INDEX(MRP!$F$3:$F$8,MATCH(Tubex_Dashboard!F33,MRP!$D$3:$D$8,0)),0) -> 0 | H33: =SUMPRODUCT((Production_Log!$F$3:$F$8963=F33)*(LEFT(Production_Log!$B$3:$B$8963,5)="Print")*(ISERROR(SEARCH("(Varnish)",Production_Log!$D$3:$D$8963)))*Production_Log!$H$3:$H$8963) -> 0 | I33: =G33-H33 -> 0 | J33: =IF(G33=0,"-",H33/G33) -> - | S33: Gas Shutdown | T33: =SUMPRODUCT((MONTH(Production_Log!$A$3:$A$8963)=MONTH(TODAY()))*(YEAR(Production_Log!$A$3:$A$8963)=YEAR(TODAY()))*Production_Log!$Q$3:$Q$8963) -> 0 | U33: =T34+0.00006 -> 6e-05
B34: TUBE | C34: Samsol International Private Limited | D34: SAMSOL HAIR COLOR 45 DIA 20.5 MM | E34: 20.5 | F34: 5731 | G34: =IFERROR(INDEX(MRP!$F$3:$F$8,MATCH(Tubex_Dashboard!F34,MRP!$D$3:$D$8,0)),0) -> 0 | H34: =SUMPRODUCT((Production_Log!$F$3:$F$8963=F34)*(LEFT(Production_Log!$B$3:$B$8963,5)="Print")*(ISERROR(SEARCH("(Varnish)",Production_Log!$D$3:$D$8963)))*Production_Log!$H$3:$H$8963) -> 0 | I34: =G34-H34 -> 0 | J34: =IF(G34=0,"-",H34/G34) -> -
B35: TUBE | C35: Samsol International Private Limited | D35: SAMSOL HAIR COLOR 43 DIA 20.5 MM | E35: 20.5 | F35: 5732 | G35: =IFERROR(INDEX(MRP!$F$3:$F$8,MATCH(Tubex_Dashboard!F35,MRP!$D$3:$D$8,0)),0) -> 0 | H35: =SUMPRODUCT((Production_Log!$F$3:$F$8963=F35)*(LEFT(Production_Log!$B$3:$B$8963,5)="Print")*(ISERROR(SEARCH("(Varnish)",Production_Log!$D$3:$D$8963)))*Production_Log!$H$3:$H$8963) -> 0 | I35: =G35-H35 -> 0 | J35: =IF(G35=0,"-",H35/G35) -> -
B36: TUBE | C36: Samsol International Private Limited | D36: SAMSOL HAIR COLOR 39 SMALL PURPLE | E36: 20.5 | F36: 6556 | G36: =IFERROR(INDEX(MRP!$F$3:$F$8,MATCH(Tubex_Dashboard!F36,MRP!$D$3:$D$8,0)),0) -> 0 | H36: =SUMPRODUCT((Production_Log!$F$3:$F$8963=F36)*(LEFT(Production_Log!$B$3:$B$8963,5)="Print")*(ISERROR(SEARCH("(Varnish)",Production_Log!$D$3:$D$8963)))*Production_Log!$H$3:$H$8963) -> 0 | I36: =G36-H36 -> 0 | J36: =IF(G36=0,"-",H36/G36) -> -
B37: TUBE | C37: Samsol International Private Limited | D37: SAMSOL HAIR COLOR 41 SMALL PURPLE | E37: 20.5 | F37: 6557 | G37: =IFERROR(INDEX(MRP!$F$3:$F$8,MATCH(Tubex_Dashboard!F37,MRP!$D$3:$D$8,0)),0) -> 0 | H37: =SUMPRODUCT((Production_Log!$F$3:$F$8963=F37)*(LEFT(Production_Log!$B$3:$B$8963,5)="Print")*(ISERROR(SEARCH("(Varnish)",Production_Log!$D$3:$D$8963)))*Production_Log!$H$3:$H$8963) -> 0 | I37: =G37-H37 -> 0 | J37: =IF(G37=0,"-",H37/G37) -> -
B38: TUBE | C38: Samsol International Private Limited | D38: TUBES COMMON RED | E38: 25 | F38: 6470 | G38: =IFERROR(INDEX(MRP!$F$3:$F$8,MATCH(Tubex_Dashboard!F38,MRP!$D$3:$D$8,0)),0) -> 0 | H38: =SUMPRODUCT((Production_Log!$F$3:$F$8963=F38)*(LEFT(Production_Log!$B$3:$B$8963,5)="Print")*(ISERROR(SEARCH("(Varnish)",Production_Log!$D$3:$D$8963)))*Production_Log!$H$3:$H$8963) -> 0 | I38: =G38-H38 -> 0 | J38: =IF(G38=0,"-",H38/G38) -> -
B39: TUBE | C39: Samsol International Private Limited | D39: TUBE COMMON PURPLE | E39: 25 | F39: 6532 | G39: =IFERROR(INDEX(MRP!$F$3:$F$8,MATCH(Tubex_Dashboard!F39,MRP!$D$3:$D$8,0)),0) -> 0 | H39: =SUMPRODUCT((Production_Log!$F$3:$F$8963=F39)*(LEFT(Production_Log!$B$3:$B$8963,5)="Print")*(ISERROR(SEARCH("(Varnish)",Production_Log!$D$3:$D$8963)))*Production_Log!$H$3:$H$8963) -> 0 | I39: =G39-H39 -> 0 | J39: =IF(G39=0,"-",H39/G39) -> -
B40: TUBE | C40: Samsol International Private Limited | D40: TUBES | E40: 25 | F40: 3726 | G40: =IFERROR(INDEX(MRP!$F$3:$F$8,MATCH(Tubex_Dashboard!F40,MRP!$D$3:$D$8,0)),0) -> 0 | H40: =SUMPRODUCT((Production_Log!$F$3:$F$8963=F40)*(LEFT(Production_Log!$B$3:$B$8963,5)="Print")*(ISERROR(SEARCH("(Varnish)",Production_Log!$D$3:$D$8963)))*Production_Log!$H$3:$H$8963) -> 0 | I40: =G40-H40 -> 0 | J40: =IF(G40=0,"-",H40/G40) -> -
B41: TUBE | C41: Mablay Beauty PVT LTD. | D41: HIS ONLY HAIR COLOR CREAM 40GM | E41: 25 | F41: 6228 | G41: =IFERROR(INDEX(MRP!$F$3:$F$8,MATCH(Tubex_Dashboard!F41,MRP!$D$3:$D$8,0)),0) -> 0 | H41: =SUMPRODUCT((Production_Log!$F$3:$F$8963=F41)*(LEFT(Production_Log!$B$3:$B$8963,5)="Print")*(ISERROR(SEARCH("(Varnish)",Production_Log!$D$3:$D$8963)))*Production_Log!$H$3:$H$8963) -> 0 | I41: =G41-H41 -> 0 | J41: =IF(G41=0,"-",H41/G41) -> -
B42: TUBE | C42: DTM | D42: DTM DIA 25MM | E42: 25 | F42: 6338 | G42: =IFERROR(INDEX(MRP!$F$3:$F$8,MATCH(Tubex_Dashboard!F42,MRP!$D$3:$D$8,0)),0) -> 0 | H42: =SUMPRODUCT((Production_Log!$F$3:$F$8963=F42)*(LEFT(Production_Log!$B$3:$B$8963,5)="Print")*(ISERROR(SEARCH("(Varnish)",Production_Log!$D$3:$D$8963)))*Production_Log!$H$3:$H$8963) -> 0 | I42: =G42-H42 -> 0 | J42: =IF(G42=0,"-",H42/G42) -> -
...

Sheet MRP
A1: JULY 2026 Tube Required Orders | G1: Date: | H1: =TODAY() -> 46210
A2: Dia | B2: Customer | C2: Product Name | D2: Product ID | E2: Job Order # | F2: Required Qty | G2: Produced | H2: Remaining Balance | I2: Remarks
A3: 16 | B3: Brookes Pharma Private Limited | C3: ECZEMUS OINTMENT 0.03% 10G | D3: 6561 | E3: 6849 | F3: 25000 | G3: =INDEX(Tubex_Dashboard!$H$11:$H$56,MATCH(MRP!D3,Tubex_Dashboard!$F$11:$F$56,0)) -> 0 | H3: =F3-G3 -> 25000 | I3: CAPS Not Approved
A4: 25 | B4: Samsol International Private Limited | C4: S-45 | D4: 5389 | E4: 6892 | F4: 100000 | G4: =INDEX(Tubex_Dashboard!$H$11:$H$56,MATCH(MRP!D4,Tubex_Dashboard!$F$11:$F$56,0)) -> 0 | H4: =F4-G4 -> 100000 | I4: 100k Extra Planned
A5: 25 | B5: Samsol International Private Limited | C5: S 43 25MM | D5: 3447 | E5: 6891 | F5: 78976 | G5: =INDEX(Tubex_Dashboard!$H$11:$H$56,MATCH(MRP!D5,Tubex_Dashboard!$F$11:$F$56,0)) -> 10416 | H5: =F5-G5 -> 68560 | I5: 100k Extra Planned
A6: 30 | B6: Mablay Beauty PVT LTD. | C6: VINCE NURTURAL | D6: 5814 | E6: 6887 | F6: 30000 | G6: =INDEX(Tubex_Dashboard!$H$11:$H$56,MATCH(MRP!D6,Tubex_Dashboard!$F$11:$F$56,0)) -> 0 | H6: =F6-G6 -> 30000
A7: 30 | B7: Golden Pearl Cosmetics (PVT) LTD | C7: HELLO HAIR COLOR | D7: 6206 | E7: 6894 | F7: 174138 | G7: =INDEX(Tubex_Dashboard!$H$11:$H$100,MATCH(MRP!D7,Tubex_Dashboard!$F$11:$F$100,0)) -> 72656 | H7: =F7-G7 -> 101482
A8: 35 | B8: Adore | C8: V- HC BROWN | D8: 6530 | E8: 6884 | F8: 13300 | G8: =INDEX(Tubex_Dashboard!$H$11:$H$56,MATCH(MRP!D8,Tubex_Dashboard!$F$11:$F$56,0)) -> 0 | H8: =F8-G8 -> 13300 | I8: HOLD
E9: TOTAL: | F9: =SUM(F3:F8) -> 421414 | G9: =SUM(G3:G8) -> 83072 | H9: =SUMIF(H3:H8, ">0") -> 338342
A10: JULY TUBES MATERIAL REQUIREMENT PLAN
A11: Item ID | B11: Category | C11: Item Name | D11: UOM | E11: Required Qty | F11: Current Stock (Store + WIP) | G11: Surplus / (Deficit) | H11: Product Name(s) | I11: Status
A12: 33 | B12: SLUG | C12: 12.5X4.5X4.8 | D12: kg | E12: =SUMPRODUCT((TableBOM[Item ID]=A12)*TableBOM[Per 1000 Units]*(1+TableBOM[Scrap %])*SUMIF($D$3:$D$8,TableBOM[Product ID],$H$3:$H$8)/1000) -> 0 | F12: =IFERROR(INDEX(TableInventory[Store Balance],MATCH(A12,TableInventory[Item ID],0)),0)+IFERROR(INDEX(TableInventory[Work In Process],MATCH(A12,TableInventory[Item ID],0)),0) -> 0 | G12: =F12-E12 -> 0 | H12: =IF(LEN(IF((COUNTIFS(TableBOM[Product ID],$D$3,TableBOM[Item ID],$A12)>0)*($H$3>0),$C$3&", ","") & IF((COUNTIFS(TableBOM[Product ID],$D$4,TableBOM[Item ID],$A12)>0)*($H$4>0),$C$4&", ","") & IF((COUNTIFS(TableBOM[Product ID],$D$5,TableBOM[Item ID],$A12)>0)*($H$5>0),$C$5&", ","") & IF((COUNTIFS(TableBOM[Product ID],$D$6,TableBOM[Item ID],$A12)>0)*($H$6>0),$C$6&", ","") & IF((COUNTIFS(TableBOM[Product ID],$D$7,TableBOM[Item ID],$A12)>0)*($H$7>0),$C$7&", ","") & IF((COUNTIFS(TableBOM[Product ID],$D$8,TableBOM[Item ID],$A12)>0)*($H$8>0),$C$8&", ",""))>1,LEFT(IF((COUNTIFS(TableBOM[Product ID],$D$3,TableBOM[Item ID],$A12)>0)*($H$3>0),$C$3&", ","") & IF((COUNTIFS(TableBOM[Product ID],$D$4,TableBOM[Item ID],$A12)>0)*($H$4>0),$C$4&", ","") & IF((COUNTIFS(TableBOM[Product ID],$D$5,TableBOM[Item ID],$A12)>0)*($H$5>0),$C$5&", ","") & IF((COUNTIFS(TableBOM[Product ID],$D$6,TableBOM[Item ID],$A12)>0)*($H$6>0),$C$6&", ","") & IF((COUNTIFS(TableBOM[Product ID],$D$7,TableBOM[Item ID],$A12)>0)*($H$7>0),$C$7&", ","") & IF((COUNTIFS(TableBOM[Product ID],$D$8,TableBOM[Item ID],$A12)>0)*($H$8>0),$C$8&", ",""),LEN(IF((COUNTIFS(TableBOM[Product ID],$D$3,TableBOM[Item ID],$A12)>0)*($H$3>0),$C$3&", ","") & IF((COUNTIFS(TableBOM[Product ID],$D$4,TableBOM[Item ID],$A12)>0)*($H$4>0),$C$4&", ","") & IF((COUNTIFS(TableBOM[Product ID],$D$5,TableBOM[Item ID],$A12)>0)*($H$5>0),$C$5&", ","") & IF((COUNTIFS(TableBOM[Product ID],$D$6,TableBOM[Item ID],$A12)>0)*($H$6>0),$C$6&", ","") & IF((COUNTIFS(TableBOM[Product ID],$D$7,TableBOM[Item ID],$A12)>0)*($H$7>0),$C$7&", ","") & IF((COUNTIFS(TableBOM[Product ID],$D$8,TableBOM[Item ID],$A12)>0)*($H$8>0),$C$8&", ",""))-2),"") | I12: =IF(E12=0,"Not needed",IF(G12<0,"SHORTAGE",IF(G12<F12*0.1,"LOW","OK"))) -> Not needed
A13: 31 | B13: SLUG | C13: 13.5X4.2 | D13: kg | E13: =SUMPRODUCT((TableBOM[Item ID]=A13)*TableBOM[Per 1000 Units]*(1+TableBOM[Scrap %])*SUMIF($D$3:$D$8,TableBOM[Product ID],$H$3:$H$8)/1000) -> 0 | F13: =IFERROR(INDEX(TableInventory[Store Balance],MATCH(A13,TableInventory[Item ID],0)),0)+IFERROR(INDEX(TableInventory[Work In Process],MATCH(A13,TableInventory[Item ID],0)),0) -> 71.5 | G13: =F13-E13 -> 71.5 | H13: =IF(LEN(IF((COUNTIFS(TableBOM[Product ID],$D$3,TableBOM[Item ID],$A13)>0)*($H$3>0),$C$3&", ","") & IF((COUNTIFS(TableBOM[Product ID],$D$4,TableBOM[Item ID],$A13)>0)*($H$4>0),$C$4&", ","") & IF((COUNTIFS(TableBOM[Product ID],$D$5,TableBOM[Item ID],$A13)>0)*($H$5>0),$C$5&", ","") & IF((COUNTIFS(TableBOM[Product ID],$D$6,TableBOM[Item ID],$A13)>0)*($H$6>0),$C$6&", ","") & IF((COUNTIFS(TableBOM[Product ID],$D$7,TableBOM[Item ID],$A13)>0)*($H$7>0),$C$7&", ","") & IF((COUNTIFS(TableBOM[Product ID],$D$8,TableBOM[Item ID],$A13)>0)*($H$8>0),$C$8&", ",""))>1,LEFT(IF((COUNTIFS(TableBOM[Product ID],$D$3,TableBOM[Item ID],$A13)>0)*($H$3>0),$C$3&", ","") & IF((COUNTIFS(TableBOM[Product ID],$D$4,TableBOM[Item ID],$A13)>0)*($H$4>0),$C$4&", ","") & IF((COUNTIFS(TableBOM[Product ID],$D$5,TableBOM[Item ID],$A13)>0)*($H$5>0),$C$5&", ","") & IF((COUNTIFS(TableBOM[Product ID],$D$6,TableBOM[Item ID],$A13)>0)*($H$6>0),$C$6&", ","") & IF((COUNTIFS(TableBOM[Product ID],$D$7,TableBOM[Item ID],$A13)>0)*($H$7>0),$C$7&", ","") & IF((COUNTIFS(TableBOM[Product ID],$D$8,TableBOM[Item ID],$A13)>0)*($H$8>0),$C$8&", ",""),LEN(IF((COUNTIFS(TableBOM[Product ID],$D$3,TableBOM[Item ID],$A13)>0)*($H$3>0),$C$3&", ","") & IF((COUNTIFS(TableBOM[Product ID],$D$4,TableBOM[Item ID],$A13)>0)*($H$4>0),$C$4&", ","") & IF((COUNTIFS(TableBOM[Product ID],$D$5,TableBOM[Item ID],$A13)>0)*($H$5>0),$C$5&", ","") & IF((COUNTIFS(TableBOM[Product ID],$D$6,TableBOM[Item ID],$A13)>0)*($H$6>0),$C$6&", ","") & IF((COUNTIFS(TableBOM[Product ID],$D$7,TableBOM[Item ID],$A13)>0)*($H$7>0),$C$7&", ","") & IF((COUNTIFS(TableBOM[Product ID],$D$8,TableBOM[Item ID],$A13)>0)*($H$8>0),$C$8&", ",""))-2),"") | I13: =IF(E13=0,"Not needed",IF(G13<0,"SHORTAGE",IF(G13<F13*0.1,"LOW","OK"))) -> Not needed
A14: 2799 | B14: SLUG | C14: 16x4.5 | D14: kg | E14: =SUMPRODUCT((TableBOM[Item ID]=A14)*TableBOM[Per 1000 Units]*(1+TableBOM[Scrap %])*SUMIF($D$3:$D$8,TableBOM[Product ID],$H$3:$H$8)/1000) -> 69.269475 | F14: =IFERROR(INDEX(TableInventory[Store Balance],MATCH(A14,TableInventory[Item ID],0)),0)+IFERROR(INDEX(TableInventory[Work In Process],MATCH(A14,TableInventory[Item ID],0)),0) -> 88 | G14: =F14-E14 -> 18.730525 | H14: =IF(LEN(IF((COUNTIFS(TableBOM[Product ID],$D$3,TableBOM[Item ID],$A14)>0)*($H$3>0),$C$3&", ","") & IF((COUNTIFS(TableBOM[Product ID],$D$4,TableBOM[Item ID],$A14)>0)*($H$4>0),$C$4&", ","") & IF((COUNTIFS(TableBOM[Product ID],$D$5,TableBOM[Item ID],$A14)>0)*($H$5>0),$C$5&", ","") & IF((COUNTIFS(TableBOM[Product ID],$D$6,TableBOM[Item ID],$A14)>0)*($H$6>0),$C$6&", ","") & IF((COUNTIFS(TableBOM[Product ID],$D$7,TableBOM[Item ID],$A14)>0)*($H$7>0),$C$7&", ","") & IF((COUNTIFS(TableBOM[Product ID],$D$8,TableBOM[Item ID],$A14)>0)*($H$8>0),$C$8&", ",""))>1,LEFT(IF((COUNTIFS(TableBOM[Product ID],$D$3,TableBOM[Item ID],$A14)>0)*($H$3>0),$C$3&", ","") & IF((COUNTIFS(TableBOM[Product ID],$D$4,TableBOM[Item ID],$A14)>0)*($H$4>0),$C$4&", ","") & IF((COUNTIFS(TableBOM[Product ID],$D$5,TableBOM[Item ID],$A14)>0)*($H$5>0),$C$5&", ","") & IF((COUNTIFS(TableBOM[Product ID],$D$6,TableBOM[Item ID],$A14)>0)*($H$6>0),$C$6&", ","") & IF((COUNTIFS(TableBOM[Product ID],$D$7,TableBOM[Item ID],$A14)>0)*($H$7>0),$C$7&", ","") & IF((COUNTIFS(TableBOM[Product ID],$D$8,TableBOM[Item ID],$A14)>0)*($H$8>0),$C$8&", ",""),LEN(IF((COUNTIFS(TableBOM[Product ID],$D$3,TableBOM[Item ID],$A14)>0)*($H$3>0),$C$3&", ","") & IF((COUNTIFS(TableBOM[Product ID],$D$4,TableBOM[Item ID],$A14)>0)*($H$4>0),$C$4&", ","") & IF((COUNTIFS(TableBOM[Product ID],$D$5,TableBOM[Item ID],$A14)>0)*($H$5>0),$C$5&", ","") & IF((COUNTIFS(TableBOM[Product ID],$D$6,TableBOM[Item ID],$A14)>0)*($H$6>0),$C$6&", ","") & IF((COUNTIFS(TableBOM[Product ID],$D$7,TableBOM[Item ID],$A14)>0)*($H$7>0),$C$7&", ","") & IF((COUNTIFS(TableBOM[Product ID],$D$8,TableBOM[Item ID],$A14)>0)*($H$8>0),$C$8&", ",""))-2),"") -> ECZEMUS OINTMENT 0.03% 10G | I14: =IF(E14=0,"Not needed",IF(G14<0,"SHORTAGE",IF(G14<F14*0.1,"LOW","OK"))) -> OK
A15: 25 | B15: SLUG | C15: 16X4.8 S/M | D15: kg | E15: =SUMPRODUCT((TableBOM[Item ID]=A15)*TableBOM[Per 1000 Units]*(1+TableBOM[Scrap %])*SUMIF($D$3:$D$8,TableBOM[Product ID],$H$3:$H$8)/1000) -> 0 | F15: =IFERROR(INDEX(TableInventory[Store Balance],MATCH(A15,TableInventory[Item ID],0)),0)+IFERROR(INDEX(TableInventory[Work In Process],MATCH(A15,TableInventory[Item ID],0)),0) -> 0 | G15: =F15-E15 -> 0 | H15: =IF(LEN(IF((COUNTIFS(TableBOM[Product ID],$D$3,TableBOM[Item ID],$A15)>0)*($H$3>0),$C$3&", ","") & IF((COUNTIFS(TableBOM[Product ID],$D$4,TableBOM[Item ID],$A15)>0)*($H$4>0),$C$4&", ","") & IF((COUNTIFS(TableBOM[Product ID],$D$5,TableBOM[Item ID],$A15)>0)*($H$5>0),$C$5&", ","") & IF((COUNTIFS(TableBOM[Product ID],$D$6,TableBOM[Item ID],$A15)>0)*($H$6>0),$C$6&", ","") & IF((COUNTIFS(TableBOM[Product ID],$D$7,TableBOM[Item ID],$A15)>0)*($H$7>0),$C$7&", ","") & IF((COUNTIFS(TableBOM[Product ID],$D$8,TableBOM[Item ID],$A15)>0)*($H$8>0),$C$8&", ",""))>1,LEFT(IF((COUNTIFS(TableBOM[Product ID],$D$3,TableBOM[Item ID],$A15)>0)*($H$3>0),$C$3&", ","") & IF((COUNTIFS(TableBOM[Product ID],$D$4,TableBOM[Item ID],$A15)>0)*($H$4>0),$C$4&", ","") & IF((COUNTIFS(TableBOM[Product ID],$D$5,TableBOM[Item ID],$A15)>0)*($H$5>0),$C$5&", ","") & IF((COUNTIFS(TableBOM[Product ID],$D$6,TableBOM[Item ID],$A15)>0)*($H$6>0),$C$6&", ","") & IF((COUNTIFS(TableBOM[Product ID],$D$7,TableBOM[Item ID],$A15)>0)*($H$7>0),$C$7&", ","") & IF((COUNTIFS(TableBOM[Product ID],$D$8,TableBOM[Item ID],$A15)>0)*($H$8>0),$C$8&", ",""),LEN(IF((COUNTIFS(TableBOM[Product ID],$D$3,TableBOM[Item ID],$A15)>0)*($H$3>0),$C$3&", ","") & IF((COUNTIFS(TableBOM[Product ID],$D$4,TableBOM[Item ID],$A15)>0)*($H$4>0),$C$4&", ","") & IF((COUNTIFS(TableBOM[Product ID],$D$5,TableBOM[Item ID],$A15)>0)*($H$5>0),$C$5&", ","") & IF((COUNTIFS(TableBOM[Product ID],$D$6,TableBOM[Item ID],$A15)>0)*($H$6>0),$C$6&", ","") & IF((COUNTIFS(TableBOM[Product ID],$D$7,TableBOM[Item ID],$A15)>0)*($H$7>0),$C$7&", ","") & IF((COUNTIFS(TableBOM[Product ID],$D$8,TableBOM[Item ID],$A15)>0)*($H$8>0),$C$8&", ",""))-2),"") | I15: =IF(E15=0,"Not needed",IF(G15<0,"SHORTAGE",IF(G15<F15*0.1,"LOW","OK"))) -> Not needed
A16: 22 | B16: SLUG | C16: 19X4.2 | D16: kg | E16: =SUMPRODUCT((TableBOM[Item ID]=A16)*TableBOM[Per 1000 Units]*(1+TableBOM[Scrap %])*SUMIF($D$3:$D$8,TableBOM[Product ID],$H$3:$H$8)/1000) -> 0 | F16: =IFERROR(INDEX(TableInventory[Store Balance],MATCH(A16,TableInventory[Item ID],0)),0)+IFERROR(INDEX(TableInventory[Work In Process],MATCH(A16,TableInventory[Item ID],0)),0) -> 0 | G16: =F16-E16 -> 0 | H16: =IF(LEN(IF((COUNTIFS(TableBOM[Product ID],$D$3,TableBOM[Item ID],$A16)>0)*($H$3>0),$C$3&", ","") & IF((COUNTIFS(TableBOM[Product ID],$D$4,TableBOM[Item ID],$A16)>0)*($H$4>0),$C$4&", ","") & IF((COUNTIFS(TableBOM[Product ID],$D$5,TableBOM[Item ID],$A16)>0)*($H$5>0),$C$5&", ","") & IF((COUNTIFS(TableBOM[Product ID],$D$6,TableBOM[Item ID],$A16)>0)*($H$6>0),$C$6&", ","") & IF((COUNTIFS(TableBOM[Product ID],$D$7,TableBOM[Item ID],$A16)>0)*($H$7>0),$C$7&", ","") & IF((COUNTIFS(TableBOM[Product ID],$D$8,TableBOM[Item ID],$A16)>0)*($H$8>0),$C$8&", ",""))>1,LEFT(IF((COUNTIFS(TableBOM[Product ID],$D$3,TableBOM[Item ID],$A16)>0)*($H$3>0),$C$3&", ","") & IF((COUNTIFS(TableBOM[Product ID],$D$4,TableBOM[Item ID],$A16)>0)*($H$4>0),$C$4&", ","") & IF((COUNTIFS(TableBOM[Product ID],$D$5,TableBOM[Item ID],$A16)>0)*($H$5>0),$C$5&", ","") & IF((COUNTIFS(TableBOM[Product ID],$D$6,TableBOM[Item ID],$A16)>0)*($H$6>0),$C$6&", ","") & IF((COUNTIFS(TableBOM[Product ID],$D$7,TableBOM[Item ID],$A16)>0)*($H$7>0),$C$7&", ","") & IF((COUNTIFS(TableBOM[Product ID],$D$8,TableBOM[Item ID],$A16)>0)*($H$8>0),$C$8&", ",""),LEN(IF((COUNTIFS(TableBOM[Product ID],$D$3,TableBOM[Item ID],$A16)>0)*($H$3>0),$C$3&", ","") & IF((COUNTIFS(TableBOM[Product ID],$D$4,TableBOM[Item ID],$A16)>0)*($H$4>0),$C$4&", ","") & IF((COUNTIFS(TableBOM[Product ID],$D$5,TableBOM[Item ID],$A16)>0)*($H$5>0),$C$5&", ","") & IF((COUNTIFS(TableBOM[Product ID],$D$6,TableBOM[Item ID],$A16)>0)*($H$6>0),$C$6&", ","") & IF((COUNTIFS(TableBOM[Product ID],$D$7,TableBOM[Item ID],$A16)>0)*($H$7>0),$C$7&", ","") & IF((COUNTIFS(TableBOM[Product ID],$D$8,TableBOM[Item ID],$A16)>0)*($H$8>0),$C$8&", ",""))-2),"") | I16: =IF(E16=0,"Not needed",IF(G16<0,"SHORTAGE",IF(G16<F16*0.1,"LOW","OK"))) -> Not needed
A17: 19 | B17: SLUG | C17: 19X4.5 S/M | D17: kg | E17: =SUMPRODUCT((TableBOM[Item ID]=A17)*TableBOM[Per 1000 Units]*(1+TableBOM[Scrap %])*SUMIF($D$3:$D$8,TableBOM[Product ID],$H$3:$H$8)/1000) -> 0 | F17: =IFERROR(INDEX(TableInventory[Store Balance],MATCH(A17,TableInventory[Item ID],0)),0)+IFERROR(INDEX(TableInventory[Work In Process],MATCH(A17,TableInventory[Item ID],0)),0) -> 425 | G17: =F17-E17 -> 425 | H17: =IF(LEN(IF((COUNTIFS(TableBOM[Product ID],$D$3,TableBOM[Item ID],$A17)>0)*($H$3>0),$C$3&", ","") & IF((COUNTIFS(TableBOM[Product ID],$D$4,TableBOM[Item ID],$A17)>0)*($H$4>0),$C$4&", ","") & IF((COUNTIFS(TableBOM[Product ID],$D$5,TableBOM[Item ID],$A17)>0)*($H$5>0),$C$5&", ","") & IF((COUNTIFS(TableBOM[Product ID],$D$6,TableBOM[Item ID],$A17)>0)*($H$6>0),$C$6&", ","") & IF((COUNTIFS(TableBOM[Product ID],$D$7,TableBOM[Item ID],$A17)>0)*($H$7>0),$C$7&", ","") & IF((COUNTIFS(TableBOM[Product ID],$D$8,TableBOM[Item ID],$A17)>0)*($H$8>0),$C$8&", ",""))>1,LEFT(IF((COUNTIFS(TableBOM[Product ID],$D$3,TableBOM[Item ID],$A17)>0)*($H$3>0),$C$3&", ","") & IF((COUNTIFS(TableBOM[Product ID],$D$4,TableBOM[Item ID],$A17)>0)*($H$4>0),$C$4&", ","") & IF((COUNTIFS(TableBOM[Product ID],$D$5,TableBOM[Item ID],$A17)>0)*($H$5>0),$C$5&", ","") & IF((COUNTIFS(TableBOM[Product ID],$D$6,TableBOM[Item ID],$A17)>0)*($H$6>0),$C$6&", ","") & IF((COUNTIFS(TableBOM[Product ID],$D$7,TableBOM[Item ID],$A17)>0)*($H$7>0),$C$7&", ","") & IF((COUNTIFS(TableBOM[Product ID],$D$8,TableBOM[Item ID],$A17)>0)*($H$8>0),$C$8&", ",""),LEN(IF((COUNTIFS(TableBOM[Product ID],$D$3,TableBOM[Item ID],$A17)>0)*($H$3>0),$C$3&", ","") & IF((COUNTIFS(TableBOM[Product ID],$D$4,TableBOM[Item ID],$A17)>0)*($H$4>0),$C$4&", ","") & IF((COUNTIFS(TableBOM[Product ID],$D$5,TableBOM[Item ID],$A17)>0)*($H$5>0),$C$5&", ","") & IF((COUNTIFS(TableBOM[Product ID],$D$6,TableBOM[Item ID],$A17)>0)*($H$6>0),$C$6&", ","") & IF((COUNTIFS(TableBOM[Product ID],$D$7,TableBOM[Item ID],$A17)>0)*($H$7>0),$C$7&", ","") & IF((COUNTIFS(TableBOM[Product ID],$D$8,TableBOM[Item ID],$A17)>0)*($H$8>0),$C$8&", ",""))-2),"") | I17: =IF(E17=0,"Not needed",IF(G17<0,"SHORTAGE",IF(G17<F17*0.1,"LOW","OK"))) -> Not needed
A18: 4179 | B18: SLUG | C18: 20.5x4.5 | D18: kg | E18: =SUMPRODUCT((TableBOM[Item ID]=A18)*TableBOM[Per 1000 Units]*(1+TableBOM[Scrap %])*SUMIF($D$3:$D$8,TableBOM[Product ID],$H$3:$H$8)/1000) -> 0 | F18: =IFERROR(INDEX(TableInventory[Store Balance],MATCH(A18,TableInventory[Item ID],0)),0)+IFERROR(INDEX(TableInventory[Work In Process],MATCH(A18,TableInventory[Item ID],0)),0) -> 132 | G18: =F18-E18 -> 132 | H18: =IF(LEN(IF((COUNTIFS(TableBOM[Product ID],$D$3,TableBOM[Item ID],$A18)>0)*($H$3>0),$C$3&", ","") & IF((COUNTIFS(TableBOM[Product ID],$D$4,TableBOM[Item ID],$A18)>0)*($H$4>0),$C$4&", ","") & IF((COUNTIFS(TableBOM[Product ID],$D$5,TableBOM[Item ID],$A18)>0)*($H$5>0),$C$5&", ","") & IF((COUNTIFS(TableBOM[Product ID],$D$6,TableBOM[Item ID],$A18)>0)*($H$6>0),$C$6&", ","") & IF((COUNTIFS(TableBOM[Product ID],$D$7,TableBOM[Item ID],$A18)>0)*($H$7>0),$C$7&", ","") & IF((COUNTIFS(TableBOM[Product ID],$D$8,TableBOM[Item ID],$A18)>0)*($H$8>0),$C$8&", ",""))>1,LEFT(IF((COUNTIFS(TableBOM[Product ID],$D$3,TableBOM[Item ID],$A18)>0)*($H$3>0),$C$3&", ","") & IF((COUNTIFS(TableBOM[Product ID],$D$4,TableBOM[Item ID],$A18)>0)*($H$4>0),$C$4&", ","") & IF((COUNTIFS(TableBOM[Product ID],$D$5,TableBOM[Item ID],$A18)>0)*($H$5>0),$C$5&", ","") & IF((COUNTIFS(TableBOM[Product ID],$D$6,TableBOM[Item ID],$A18)>0)*($H$6>0),$C$6&", ","") & IF((COUNTIFS(TableBOM[Product ID],$D$7,TableBOM[Item ID],$A18)>0)*($H$7>0),$C$7&", ","") & IF((COUNTIFS(TableBOM[Product ID],$D$8,TableBOM[Item ID],$A18)>0)*($H$8>0),$C$8&", ",""),LEN(IF((COUNTIFS(TableBOM[Product ID],$D$3,TableBOM[Item ID],$A18)>0)*($H$3>0),$C$3&", ","") & IF((COUNTIFS(TableBOM[Product ID],$D$4,TableBOM[Item ID],$A18)>0)*($H$4>0),$C$4&", ","") & IF((COUNTIFS(TableBOM[Product ID],$D$5,TableBOM[Item ID],$A18)>0)*($H$5>0),$C$5&", ","") & IF((COUNTIFS(TableBOM[Product ID],$D$6,TableBOM[Item ID],$A18)>0)*($H$6>0),$C$6&", ","") & IF((COUNTIFS(TableBOM[Product ID],$D$7,TableBOM[Item ID],$A18)>0)*($H$7>0),$C$7&", ","") & IF((COUNTIFS(TableBOM[Product ID],$D$8,TableBOM[Item ID],$A18)>0)*($H$8>0),$C$8&", ",""))-2),"") | I18: =IF(E18=0,"Not needed",IF(G18<0,"SHORTAGE",IF(G18<F18*0.1,"LOW","OK"))) -> Not needed
A19: 6 | B19: SLUG | C19: 25X4.5 S/M | D19: kg | E19: =SUMPRODUCT((TableBOM[Item ID]=A19)*TableBOM[Per 1000 Units]*(1+TableBOM[Scrap %])*SUMIF($D$3:$D$8,TableBOM[Product ID],$H$3:$H$8)/1000) -> 1097.1065 | F19: =IFERROR(INDEX(TableInventory[Store Balance],MATCH(A19,TableInventory[Item ID],0)),0)+IFERROR(INDEX(TableInventory[Work In Process],MATCH(A19,TableInventory[Item ID],0)),0) -> 325 | G19: =F19-E19 -> -772.10647 | H19: =IF(LEN(IF((COUNTIFS(TableBOM[Product ID],$D$3,TableBOM[Item ID],$A19)>0)*($H$3>0),$C$3&", ","") & IF((COUNTIFS(TableBOM[Product ID],$D$4,TableBOM[Item ID],$A19)>0)*($H$4>0),$C$4&", ","") & IF((COUNTIFS(TableBOM[Product ID],$D$5,TableBOM[Item ID],$A19)>0)*($H$5>0),$C$5&", ","") & IF((COUNTIFS(TableBOM[Product ID],$D$6,TableBOM[Item ID],$A19)>0)*($H$6>0),$C$6&", ","") & IF((COUNTIFS(TableBOM[Product ID],$D$7,TableBOM[Item ID],$A19)>0)*($H$7>0),$C$7&", ","") & IF((COUNTIFS(TableBOM[Product ID],$D$8,TableBOM[Item ID],$A19)>0)*($H$8>0),$C$8&", ",""))>1,LEFT(IF((COUNTIFS(TableBOM[Product ID],$D$3,TableBOM[Item ID],$A19)>0)*($H$3>0),$C$3&", ","") & IF((COUNTIFS(TableBOM[Product ID],$D$4,TableBOM[Item ID],$A19)>0)*($H$4>0),$C$4&", ","") & IF((COUNTIFS(TableBOM[Product ID],$D$5,TableBOM[Item ID],$A19)>0)*($H$5>0),$C$5&", ","") & IF((COUNTIFS(TableBOM[Product ID],$D$6,TableBOM[Item ID],$A19)>0)*($H$6>0),$C$6&", ","") & IF((COUNTIFS(TableBOM[Product ID],$D$7,TableBOM[Item ID],$A19)>0)*($H$7>0),$C$7&", ","") & IF((COUNTIFS(TableBOM[Product ID],$D$8,TableBOM[Item ID],$A19)>0)*($H$8>0),$C$8&", ",""),LEN(IF((COUNTIFS(TableBOM[Product ID],$D$3,TableBOM[Item ID],$A19)>0)*($H$3>0),$C$3&", ","") & IF((COUNTIFS(TableBOM[Product ID],$D$4,TableBOM[Item ID],$A19)>0)*($H$4>0),$C$4&", ","") & IF((COUNTIFS(TableBOM[Product ID],$D$5,TableBOM[Item ID],$A19)>0)*($H$5>0),$C$5&", ","") & IF((COUNTIFS(TableBOM[Product ID],$D$6,TableBOM[Item ID],$A19)>0)*($H$6>0),$C$6&", ","") & IF((COUNTIFS(TableBOM[Product ID],$D$7,TableBOM[Item ID],$A19)>0)*($H$7>0),$C$7&", ","") & IF((COUNTIFS(TableBOM[Product ID],$D$8,TableBOM[Item ID],$A19)>0)*($H$8>0),$C$8&", ",""))-2),"") -> S-45, S 43 25MM | I19: =IF(E19=0,"Not needed",IF(G19<0,"SHORTAGE",IF(G19<F19*0.1,"LOW","OK"))) -> SHORTAGE
A20: 10 | B20: SLUG | C20: 25X4.8 S/M | D20: kg | E20: =SUMPRODUCT((TableBOM[Item ID]=A20)*TableBOM[Per 1000 Units]*(1+TableBOM[Scrap %])*SUMIF($D$3:$D$8,TableBOM[Product ID],$H$3:$H$8)/1000) -> 0 | F20: =IFERROR(INDEX(TableInventory[Store Balance],MATCH(A20,TableInventory[Item ID],0)),0)+IFERROR(INDEX(TableInventory[Work In Process],MATCH(A20,TableInventory[Item ID],0)),0) -> 0 | G20: =F20-E20 -> 0 | H20: =IF(LEN(IF((COUNTIFS(TableBOM[Product ID],$D$3,TableBOM[Item ID],$A20)>0)*($H$3>0),$C$3&", ","") & IF((COUNTIFS(TableBOM[Product ID],$D$4,TableBOM[Item ID],$A20)>0)*($H$4>0),$C$4&", ","") & IF((COUNTIFS(TableBOM[Product ID],$D$5,TableBOM[Item ID],$A20)>0)*($H$5>0),$C$5&", ","") & IF((COUNTIFS(TableBOM[Product ID],$D$6,TableBOM[Item ID],$A20)>0)*($H$6>0),$C$6&", ","") & IF((COUNTIFS(TableBOM[Product ID],$D$7,TableBOM[Item ID],$A20)>0)*($H$7>0),$C$7&", ","") & IF((COUNTIFS(TableBOM[Product ID],$D$8,TableBOM[Item ID],$A20)>0)*($H$8>0),$C$8&", ",""))>1,LEFT(IF((COUNTIFS(TableBOM[Product ID],$D$3,TableBOM[Item ID],$A20)>0)*($H$3>0),$C$3&", ","") & IF((COUNTIFS(TableBOM[Product ID],$D$4,TableBOM[Item ID],$A20)>0)*($H$4>0),$C$4&", ","") & IF((COUNTIFS(TableBOM[Product ID],$D$5,TableBOM[Item ID],$A20)>0)*($H$5>0),$C$5&", ","") & IF((COUNTIFS(TableBOM[Product ID],$D$6,TableBOM[Item ID],$A20)>0)*($H$6>0),$C$6&", ","") & IF((COUNTIFS(TableBOM[Product ID],$D$7,TableBOM[Item ID],$A20)>0)*($H$7>0),$C$7&", ","") & IF((COUNTIFS(TableBOM[Product ID],$D$8,TableBOM[Item ID],$A20)>0)*($H$8>0),$C$8&", ",""),LEN(IF((COUNTIFS(TableBOM[Product ID],$D$3,TableBOM[Item ID],$A20)>0)*($H$3>0),$C$3&", ","") & IF((COUNTIFS(TableBOM[Product ID],$D$4,TableBOM[Item ID],$A20)>0)*($H$4>0),$C$4&", ","") & IF((COUNTIFS(TableBOM[Product ID],$D$5,TableBOM[Item ID],$A20)>0)*($H$5>0),$C$5&", ","") & IF((COUNTIFS(TableBOM[Product ID],$D$6,TableBOM[Item ID],$A20)>0)*($H$6>0),$C$6&", ","") & IF((COUNTIFS(TableBOM[Product ID],$D$7,TableBOM[Item ID],$A20)>0)*($H$7>0),$C$7&", ","") & IF((COUNTIFS(TableBOM[Product ID],$D$8,TableBOM[Item ID],$A20)>0)*($H$8>0),$C$8&", ",""))-2),"") | I20: =IF(E20=0,"Not needed",IF(G20<0,"SHORTAGE",IF(G20<F20*0.1,"LOW","OK"))) -> Not needed
A21: 2 | B21: SLUG | C21: 30X4.3 | D21: kg | E21: =SUMPRODUCT((TableBOM[Item ID]=A21)*TableBOM[Per 1000 Units]*(1+TableBOM[Scrap %])*SUMIF($D$3:$D$8,TableBOM[Product ID],$H$3:$H$8)/1000) -> 0 | F21: =IFERROR(INDEX(TableInventory[Store Balance],MATCH(A21,TableInventory[Item ID],0)),0)+IFERROR(INDEX(TableInventory[Work In Process],MATCH(A21,TableInventory[Item ID],0)),0) -> 0 | G21: =F21-E21 -> 0 | H21: =IF(LEN(IF((COUNTIFS(TableBOM[Product ID],$D$3,TableBOM[Item ID],$A21)>0)*($H$3>0),$C$3&", ","") & IF((COUNTIFS(TableBOM[Product ID],$D$4,TableBOM[Item ID],$A21)>0)*($H$4>0),$C$4&", ","") & IF((COUNTIFS(TableBOM[Product ID],$D$5,TableBOM[Item ID],$A21)>0)*($H$5>0),$C$5&", ","") & IF((COUNTIFS(TableBOM[Product ID],$D$6,TableBOM[Item ID],$A21)>0)*($H$6>0),$C$6&", ","") & IF((COUNTIFS(TableBOM[Product ID],$D$7,TableBOM[Item ID],$A21)>0)*($H$7>0),$C$7&", ","") & IF((COUNTIFS(TableBOM[Product ID],$D$8,TableBOM[Item ID],$A21)>0)*($H$8>0),$C$8&", ",""))>1,LEFT(IF((COUNTIFS(TableBOM[Product ID],$D$3,TableBOM[Item ID],$A21)>0)*($H$3>0),$C$3&", ","") & IF((COUNTIFS(TableBOM[Product ID],$D$4,TableBOM[Item ID],$A21)>0)*($H$4>0),$C$4&", ","") & IF((COUNTIFS(TableBOM[Product ID],$D$5,TableBOM[Item ID],$A21)>0)*($H$5>0),$C$5&", ","") & IF((COUNTIFS(TableBOM[Product ID],$D$6,TableBOM[Item ID],$A21)>0)*($H$6>0),$C$6&", ","") & IF((COUNTIFS(TableBOM[Product ID],$D$7,TableBOM[Item ID],$A21)>0)*($H$7>0),$C$7&", ","") & IF((COUNTIFS(TableBOM[Product ID],$D$8,TableBOM[Item ID],$A21)>0)*($H$8>0),$C$8&", ",""),LEN(IF((COUNTIFS(TableBOM[Product ID],$D$3,TableBOM[Item ID],$A21)>0)*($H$3>0),$C$3&", ","") & IF((COUNTIFS(TableBOM[Product ID],$D$4,TableBOM[Item ID],$A21)>0)*($H$4>0),$C$4&", ","") & IF((COUNTIFS(TableBOM[Product ID],$D$5,TableBOM[Item ID],$A21)>0)*($H$5>0),$C$5&", ","") & IF((COUNTIFS(TableBOM[Product ID],$D$6,TableBOM[Item ID],$A21)>0)*($H$6>0),$C$6&", ","") & IF((COUNTIFS(TableBOM[Product ID],$D$7,TableBOM[Item ID],$A21)>0)*($H$7>0),$C$7&", ","") & IF((COUNTIFS(TableBOM[Product ID],$D$8,TableBOM[Item ID],$A21)>0)*($H$8>0),$C$8&", ",""))-2),"") | I21: =IF(E21=0,"Not needed",IF(G21<0,"SHORTAGE",IF(G21<F21*0.1,"LOW","OK"))) -> Not needed
A22: 406 | B22: SLUG | C22: 30X4.5 S/M | D22: kg | E22: =SUMPRODUCT((TableBOM[Item ID]=A22)*TableBOM[Per 1000 Units]*(1+TableBOM[Scrap %])*SUMIF($D$3:$D$8,TableBOM[Product ID],$H$3:$H$8)/1000) -> 1157.0416 | F22: =IFERROR(INDEX(TableInventory[Store Balance],MATCH(A22,TableInventory[Item ID],0)),0)+IFERROR(INDEX(TableInventory[Work In Process],MATCH(A22,TableInventory[Item ID],0)),0) -> 298 | G22: =F22-E22 -> -859.0416 | H22: =IF(LEN(IF((COUNTIFS(TableBOM[Product ID],$D$3,TableBOM[Item ID],$A22)>0)*($H$3>0),$C$3&", ","") & IF((COUNTIFS(TableBOM[Product ID],$D$4,TableBOM[Item ID],$A22)>0)*($H$4>0),$C$4&", ","") & IF((COUNTIFS(TableBOM[Product ID],$D$5,TableBOM[Item ID],$A22)>0)*($H$5>0),$C$5&", ","") & IF((COUNTIFS(TableBOM[Product ID],$D$6,TableBOM[Item ID],$A22)>0)*($H$6>0),$C$6&", ","") & IF((COUNTIFS(TableBOM[Product ID],$D$7,TableBOM[Item ID],$A22)>0)*($H$7>0),$C$7&", ","") & IF((COUNTIFS(TableBOM[Product ID],$D$8,TableBOM[Item ID],$A22)>0)*($H$8>0),$C$8&", ",""))>1,LEFT(IF((COUNTIFS(TableBOM[Product ID],$D$3,TableBOM[Item ID],$A22)>0)*($H$3>0),$C$3&", ","") & IF((COUNTIFS(TableBOM[Product ID],$D$4,TableBOM[Item ID],$A22)>0)*($H$4>0),$C$4&", ","") & IF((COUNTIFS(TableBOM[Product ID],$D$5,TableBOM[Item ID],$A22)>0)*($H$5>0),$C$5&", ","") & IF((COUNTIFS(TableBOM[Product ID],$D$6,TableBOM[Item ID],$A22)>0)*($H$6>0),$C$6&", ","") & IF((COUNTIFS(TableBOM[Product ID],$D$7,TableBOM[Item ID],$A22)>0)*($H$7>0),$C$7&", ","") & IF((COUNTIFS(TableBOM[Product ID],$D$8,TableBOM[Item ID],$A22)>0)*($H$8>0),$C$8&", ",""),LEN(IF((COUNTIFS(TableBOM[Product ID],$D$3,TableBOM[Item ID],$A22)>0)*($H$3>0),$C$3&", ","") & IF((COUNTIFS(TableBOM[Product ID],$D$4,TableBOM[Item ID],$A22)>0)*($H$4>0),$C$4&", ","") & IF((COUNTIFS(TableBOM[Product ID],$D$5,TableBOM[Item ID],$A22)>0)*($H$5>0),$C$5&", ","") & IF((COUNTIFS(TableBOM[Product ID],$D$6,TableBOM[Item ID],$A22)>0)*($H$6>0),$C$6&", ","") & IF((COUNTIFS(TableBOM[Product ID],$D$7,TableBOM[Item ID],$A22)>0)*($H$7>0),$C$7&", ","") & IF((COUNTIFS(TableBOM[Product ID],$D$8,TableBOM[Item ID],$A22)>0)*($H$8>0),$C$8&", ",""))-2),"") -> VINCE NURTURAL, HELLO HAIR COLOR | I22: =IF(E22=0,"Not needed",IF(G22<0,"SHORTAGE",IF(G22<F22*0.1,"LOW","OK"))) -> SHORTAGE
A23: 6961 | B23: SLUG | C23: 32X5.2 | D23: kg | E23: =SUMPRODUCT((TableBOM[Item ID]=A23)*TableBOM[Per 1000 Units]*(1+TableBOM[Scrap %])*SUMIF($D$3:$D$8,TableBOM[Product ID],$H$3:$H$8)/1000) -> 0 | F23: =IFERROR(INDEX(TableInventory[Store Balance],MATCH(A23,TableInventory[Item ID],0)),0)+IFERROR(INDEX(TableInventory[Work In Process],MATCH(A23,TableInventory[Item ID],0)),0) -> 0 | G23: =F23-E23 -> 0 | H23: =IF(LEN(IF((COUNTIFS(TableBOM[Product ID],$D$3,TableBOM[Item ID],$A23)>0)*($H$3>0),$C$3&", ","") & IF((COUNTIFS(TableBOM[Product ID],$D$4,TableBOM[Item ID],$A23)>0)*($H$4>0),$C$4&", ","") & IF((COUNTIFS(TableBOM[Product ID],$D$5,TableBOM[Item ID],$A23)>0)*($H$5>0),$C$5&", ","") & IF((COUNTIFS(TableBOM[Product ID],$D$6,TableBOM[Item ID],$A23)>0)*($H$6>0),$C$6&", ","") & IF((COUNTIFS(TableBOM[Product ID],$D$7,TableBOM[Item ID],$A23)>0)*($H$7>0),$C$7&", ","") & IF((COUNTIFS(TableBOM[Product ID],$D$8,TableBOM[Item ID],$A23)>0)*($H$8>0),$C$8&", ",""))>1,LEFT(IF((COUNTIFS(TableBOM[Product ID],$D$3,TableBOM[Item ID],$A23)>0)*($H$3>0),$C$3&", ","") & IF((COUNTIFS(TableBOM[Product ID],$D$4,TableBOM[Item ID],$A23)>0)*($H$4>0),$C$4&", ","") & IF((COUNTIFS(TableBOM[Product ID],$D$5,TableBOM[Item ID],$A23)>0)*($H$5>0),$C$5&", ","") & IF((COUNTIFS(TableBOM[Product ID],$D$6,TableBOM[Item ID],$A23)>0)*($H$6>0),$C$6&", ","") & IF((COUNTIFS(TableBOM[Product ID],$D$7,TableBOM[Item ID],$A23)>0)*($H$7>0),$C$7&", ","") & IF((COUNTIFS(TableBOM[Product ID],$D$8,TableBOM[Item ID],$A23)>0)*($H$8>0),$C$8&", ",""),LEN(IF((COUNTIFS(TableBOM[Product ID],$D$3,TableBOM[Item ID],$A23)>0)*($H$3>0),$C$3&", ","") & IF((COUNTIFS(TableBOM[Product ID],$D$4,TableBOM[Item ID],$A23)>0)*($H$4>0),$C$4&", ","") & IF((COUNTIFS(TableBOM[Product ID],$D$5,TableBOM[Item ID],$A23)>0)*($H$5>0),$C$5&", ","") & IF((COUNTIFS(TableBOM[Product ID],$D$6,TableBOM[Item ID],$A23)>0)*($H$6>0),$C$6&", ","") & IF((COUNTIFS(TableBOM[Product ID],$D$7,TableBOM[Item ID],$A23)>0)*($H$7>0),$C$7&", ","") & IF((COUNTIFS(TableBOM[Product ID],$D$8,TableBOM[Item ID],$A23)>0)*($H$8>0),$C$8&", ",""))-2),"") | I23: =IF(E23=0,"Not needed",IF(G23<0,"SHORTAGE",IF(G23<F23*0.1,"LOW","OK"))) -> Not needed
A24: 3935 | B24: SLUG | C24: 32x5.0 | D24: kg | E24: =SUMPRODUCT((TableBOM[Item ID]=A24)*TableBOM[Per 1000 Units]*(1+TableBOM[Scrap %])*SUMIF($D$3:$D$8,TableBOM[Product ID],$H$3:$H$8)/1000) -> 0 | F24: =IFERROR(INDEX(TableInventory[Store Balance],MATCH(A24,TableInventory[Item ID],0)),0)+IFERROR(INDEX(TableInventory[Work In Process],MATCH(A24,TableInventory[Item ID],0)),0) -> 444 | G24: =F24-E24 -> 444 | H24: =IF(LEN(IF((COUNTIFS(TableBOM[Product ID],$D$3,TableBOM[Item ID],$A24)>0)*($H$3>0),$C$3&", ","") & IF((COUNTIFS(TableBOM[Product ID],$D$4,TableBOM[Item ID],$A24)>0)*($H$4>0),$C$4&", ","") & IF((COUNTIFS(TableBOM[Product ID],$D$5,TableBOM[Item ID],$A24)>0)*($H$5>0),$C$5&", ","") & IF((COUNTIFS(TableBOM[Product ID],$D$6,TableBOM[Item ID],$A24)>0)*($H$6>0),$C$6&", ","") & IF((COUNTIFS(TableBOM[Product ID],$D$7,TableBOM[Item ID],$A24)>0)*($H$7>0),$C$7&", ","") & IF((COUNTIFS(TableBOM[Product ID],$D$8,TableBOM[Item ID],$A24)>0)*($H$8>0),$C$8&", ",""))>1,LEFT(IF((COUNTIFS(TableBOM[Product ID],$D$3,TableBOM[Item ID],$A24)>0)*($H$3>0),$C$3&", ","") & IF((COUNTIFS(TableBOM[Product ID],$D$4,TableBOM[Item ID],$A24)>0)*($H$4>0),$C$4&", ","") & IF((COUNTIFS(TableBOM[Product ID],$D$5,TableBOM[Item ID],$A24)>0)*($H$5>0),$C$5&", ","") & IF((COUNTIFS(TableBOM[Product ID],$D$6,TableBOM[Item ID],$A24)>0)*($H$6>0),$C$6&", ","") & IF((COUNTIFS(TableBOM[Product ID],$D$7,TableBOM[Item ID],$A24)>0)*($H$7>0),$C$7&", ","") & IF((COUNTIFS(TableBOM[Product ID],$D$8,TableBOM[Item ID],$A24)>0)*($H$8>0),$C$8&", ",""),LEN(IF((COUNTIFS(TableBOM[Product ID],$D$3,TableBOM[Item ID],$A24)>0)*($H$3>0),$C$3&", ","") & IF((COUNTIFS(TableBOM[Product ID],$D$4,TableBOM[Item ID],$A24)>0)*($H$4>0),$C$4&", ","") & IF((COUNTIFS(TableBOM[Product ID],$D$5,TableBOM[Item ID],$A24)>0)*($H$5>0),$C$5&", ","") & IF((COUNTIFS(TableBOM[Product ID],$D$6,TableBOM[Item ID],$A24)>0)*($H$6>0),$C$6&", ","") & IF((COUNTIFS(TableBOM[Product ID],$D$7,TableBOM[Item ID],$A24)>0)*($H$7>0),$C$7&", ","") & IF((COUNTIFS(TableBOM[Product ID],$D$8,TableBOM[Item ID],$A24)>0)*($H$8>0),$C$8&", ",""))-2),"") | I24: =IF(E24=0,"Not needed",IF(G24<0,"SHORTAGE",IF(G24<F24*0.1,"LOW","OK"))) -> Not needed
A25: 3503 | B25: SLUG | C25: 35X5.0 | D25: kg | E25: =SUMPRODUCT((TableBOM[Item ID]=A25)*TableBOM[Per 1000 Units]*(1+TableBOM[Scrap %])*SUMIF($D$3:$D$8,TableBOM[Product ID],$H$3:$H$8)/1000) -> 187.5566 | F25: =IFERROR(INDEX(TableInventory[Store Balance],MATCH(A25,TableInventory[Item ID],0)),0)+IFERROR(INDEX(TableInventory[Work In Process],MATCH(A25,TableInventory[Item ID],0)),0) -> 328 | G25: =F25-E25 -> 140.4434 | H25: =IF(LEN(IF((COUNTIFS(TableBOM[Product ID],$D$3,TableBOM[Item ID],$A25)>0)*($H$3>0),$C$3&", ","") & IF((COUNTIFS(TableBOM[Product ID],$D$4,TableBOM[Item ID],$A25)>0)*($H$4>0),$C$4&", ","") & IF((COUNTIFS(TableBOM[Product ID],$D$5,TableBOM[Item ID],$A25)>0)*($H$5>0),$C$5&", ","") & IF((COUNTIFS(TableBOM[Product ID],$D$6,TableBOM[Item ID],$A25)>0)*($H$6>0),$C$6&", ","") & IF((COUNTIFS(TableBOM[Product ID],$D$7,TableBOM[Item ID],$A25)>0)*($H$7>0),$C$7&", ","") & IF((COUNTIFS(TableBOM[Product ID],$D$8,TableBOM[Item ID],$A25)>0)*($H$8>0),$C$8&", ",""))>1,LEFT(IF((COUNTIFS(TableBOM[Product ID],$D$3,TableBOM[Item ID],$A25)>0)*($H$3>0),$C$3&", ","") & IF((COUNTIFS(TableBOM[Product ID],$D$4,TableBOM[Item ID],$A25)>0)*($H$4>0),$C$4&", ","") & IF((COUNTIFS(TableBOM[Product ID],$D$5,TableBOM[Item ID],$A25)>0)*($H$5>0),$C$5&", ","") & IF((COUNTIFS(TableBOM[Product ID],$D$6,TableBOM[Item ID],$A25)>0)*($H$6>0),$C$6&", ","") & IF((COUNTIFS(TableBOM[Product ID],$D$7,TableBOM[Item ID],$A25)>0)*($H$7>0),$C$7&", ","") & IF((COUNTIFS(TableBOM[Product ID],$D$8,TableBOM[Item ID],$A25)>0)*($H$8>0),$C$8&", ",""),LEN(IF((COUNTIFS(TableBOM[Product ID],$D$3,TableBOM[Item ID],$A25)>0)*($H$3>0),$C$3&", ","") & IF((COUNTIFS(TableBOM[Product ID],$D$4,TableBOM[Item ID],$A25)>0)*($H$4>0),$C$4&", ","") & IF((COUNTIFS(TableBOM[Product ID],$D$5,TableBOM[Item ID],$A25)>0)*($H$5>0),$C$5&", ","") & IF((COUNTIFS(TableBOM[Product ID],$D$6,TableBOM[Item ID],$A25)>0)*($H$6>0),$C$6&", ","") & IF((COUNTIFS(TableBOM[Product ID],$D$7,TableBOM[Item ID],$A25)>0)*($H$7>0),$C$7&", ","") & IF((COUNTIFS(TableBOM[Product ID],$D$8,TableBOM[Item ID],$A25)>0)*($H$8>0),$C$8&", ",""))-2),"") -> V- HC BROWN | I25: HOLD
A26: 184 | B26: LACQUER | C26: LACQUER IMP 49989 | D26: kg | E26: =SUMPRODUCT((TableBOM[Item ID]=A26)*TableBOM[Per 1000 Units]*(1+TableBOM[Scrap %])*SUMIF($D$3:$D$8,TableBOM[Product ID],$H$3:$H$8)/1000) -> 0 | F26: =IFERROR(INDEX(TableInventory[Store Balance],MATCH(A26,TableInventory[Item ID],0)),0)+IFERROR(INDEX(TableInventory[Work In Process],MATCH(A26,TableInventory[Item ID],0)),0) -> 0 | G26: =F26-E26 -> 0 | H26: =IF(LEN(IF((COUNTIFS(TableBOM[Product ID],$D$3,TableBOM[Item ID],$A26)>0)*($H$3>0),$C$3&", ","") & IF((COUNTIFS(TableBOM[Product ID],$D$4,TableBOM[Item ID],$A26)>0)*($H$4>0),$C$4&", ","") & IF((COUNTIFS(TableBOM[Product ID],$D$5,TableBOM[Item ID],$A26)>0)*($H$5>0),$C$5&", ","") & IF((COUNTIFS(TableBOM[Product ID],$D$6,TableBOM[Item ID],$A26)>0)*($H$6>0),$C$6&", ","") & IF((COUNTIFS(TableBOM[Product ID],$D$7,TableBOM[Item ID],$A26)>0)*($H$7>0),$C$7&", ","") & IF((COUNTIFS(TableBOM[Product ID],$D$8,TableBOM[Item ID],$A26)>0)*($H$8>0),$C$8&", ",""))>1,LEFT(IF((COUNTIFS(TableBOM[Product ID],$D$3,TableBOM[Item ID],$A26)>0)*($H$3>0),$C$3&", ","") & IF((COUNTIFS(TableBOM[Product ID],$D$4,TableBOM[Item ID],$A26)>0)*($H$4>0),$C$4&", ","") & IF((COUNTIFS(TableBOM[Product ID],$D$5,TableBOM[Item ID],$A26)>0)*($H$5>0),$C$5&", ","") & IF((COUNTIFS(TableBOM[Product ID],$D$6,TableBOM[Item ID],$A26)>0)*($H$6>0),$C$6&", ","") & IF((COUNTIFS(TableBOM[Product ID],$D$7,TableBOM[Item ID],$A26)>0)*($H$7>0),$C$7&", ","") & IF((COUNTIFS(TableBOM[Product ID],$D$8,TableBOM[Item ID],$A26)>0)*($H$8>0),$C$8&", ",""),LEN(IF((COUNTIFS(TableBOM[Product ID],$D$3,TableBOM[Item ID],$A26)>0)*($H$3>0),$C$3&", ","") & IF((COUNTIFS(TableBOM[Product ID],$D$4,TableBOM[Item ID],$A26)>0)*($H$4>0),$C$4&", ","") & IF((COUNTIFS(TableBOM[Product ID],$D$5,TableBOM[Item ID],$A26)>0)*($H$5>0),$C$5&", ","") & IF((COUNTIFS(TableBOM[Product ID],$D$6,TableBOM[Item ID],$A26)>0)*($H$6>0),$C$6&", ","") & IF((COUNTIFS(TableBOM[Product ID],$D$7,TableBOM[Item ID],$A26)>0)*($H$7>0),$C$7&", ","") & IF((COUNTIFS(TableBOM[Product ID],$D$8,TableBOM[Item ID],$A26)>0)*($H$8>0),$C$8&", ",""))-2),"") | I26: =IF(E26=0,"Not needed",IF(G26<0,"SHORTAGE",IF(G26<F26*0.1,"LOW","OK"))) -> Not needed
A27: 185 | B27: LACQUER | C27: EPOXY LACQUER (1500) | D27: L | E27: =SUMPRODUCT((TableBOM[Item ID]=A27)*TableBOM[Per 1000 Units]*(1+TableBOM[Scrap %])*SUMIF($D$3:$D$8,TableBOM[Product ID],$H$3:$H$8)/1000) -> 64.977959 | F27: =IFERROR(INDEX(TableInventory[Store Balance],MATCH(A27,TableInventory[Item ID],0)),0)+IFERROR(INDEX(TableInventory[Work In Process],MATCH(A27,TableInventory[Item ID],0)),0) -> 50 | G27: =F27-E27 -> -14.977959 | H27: =IF(LEN(IF((COUNTIFS(TableBOM[Product ID],$D$3,TableBOM[Item ID],$A27)>0)*($H$3>0),$C$3&", ","") & IF((COUNTIFS(TableBOM[Product ID],$D$4,TableBOM[Item ID],$A27)>0)*($H$4>0),$C$4&", ","") & IF((COUNTIFS(TableBOM[Product ID],$D$5,TableBOM[Item ID],$A27)>0)*($H$5>0),$C$5&", ","") & IF((COUNTIFS(TableBOM[Product ID],$D$6,TableBOM[Item ID],$A27)>0)*($H$6>0),$C$6&", ","") & IF((COUNTIFS(TableBOM[Product ID],$D$7,TableBOM[Item ID],$A27)>0)*($H$7>0),$C$7&", ","") & IF((COUNTIFS(TableBOM[Product ID],$D$8,TableBOM[Item ID],$A27)>0)*($H$8>0),$C$8&", ",""))>1,LEFT(IF((COUNTIFS(TableBOM[Product ID],$D$3,TableBOM[Item ID],$A27)>0)*($H$3>0),$C$3&", ","") & IF((COUNTIFS(TableBOM[Product ID],$D$4,TableBOM[Item ID],$A27)>0)*($H$4>0),$C$4&", ","") & IF((COUNTIFS(TableBOM[Product ID],$D$5,TableBOM[Item ID],$A27)>0)*($H$5>0),$C$5&", ","") & IF((COUNTIFS(TableBOM[Product ID],$D$6,TableBOM[Item ID],$A27)>0)*($H$6>0),$C$6&", ","") & IF((COUNTIFS(TableBOM[Product ID],$D$7,TableBOM[Item ID],$A27)>0)*($H$7>0),$C$7&", ","") & IF((COUNTIFS(TableBOM[Product ID],$D$8,TableBOM[Item ID],$A27)>0)*($H$8>0),$C$8&", ",""),LEN(IF((COUNTIFS(TableBOM[Product ID],$D$3,TableBOM[Item ID],$A27)>0)*($H$3>0),$C$3&", ","") & IF((COUNTIFS(TableBOM[Product ID],$D$4,TableBOM[Item ID],$A27)>0)*($H$4>0),$C$4&", ","") & IF((COUNTIFS(TableBOM[Product ID],$D$5,TableBOM[Item ID],$A27)>0)*($H$5>0),$C$5&", ","") & IF((COUNTIFS(TableBOM[Product ID],$D$6,TableBOM[Item ID],$A27)>0)*($H$6>0),$C$6&", ","") & IF((COUNTIFS(TableBOM[Product ID],$D$7,TableBOM[Item ID],$A27)>0)*($H$7>0),$C$7&", ","") & IF((COUNTIFS(TableBOM[Product ID],$D$8,TableBOM[Item ID],$A27)>0)*($H$8>0),$C$8&", ",""))-2),"") -> ECZEMUS OINTMENT 0.03% 10G, S-45, S 43 25MM | I27: =IF(E27=0,"Not needed",IF(G27<0,"SHORTAGE",IF(G27<F27*0.1,"LOW","OK"))) -> SHORTAGE
A28: 188 | B28: LACQUER | C28: LACQUER RHENANIA (ACTEGA COLL 299) | D28: kg | E28: =SUMPRODUCT((TableBOM[Item ID]=A28)*TableBOM[Per 1000 Units]*(1+TableBOM[Scrap %])*SUMIF($D$3:$D$8,TableBOM[Product ID],$H$3:$H$8)/1000) -> 0 | F28: =IFERROR(INDEX(TableInventory[Store Balance],MATCH(A28,TableInventory[Item ID],0)),0)+IFERROR(INDEX(TableInventory[Work In Process],MATCH(A28,TableInventory[Item ID],0)),0) -> 91 | G28: =F28-E28 -> 91 | H28: =IF(LEN(IF((COUNTIFS(TableBOM[Product ID],$D$3,TableBOM[Item ID],$A28)>0)*($H$3>0),$C$3&", ","") & IF((COUNTIFS(TableBOM[Product ID],$D$4,TableBOM[Item ID],$A28)>0)*($H$4>0),$C$4&", ","") & IF((COUNTIFS(TableBOM[Product ID],$D$5,TableBOM[Item ID],$A28)>0)*($H$5>0),$C$5&", ","") & IF((COUNTIFS(TableBOM[Product ID],$D$6,TableBOM[Item ID],$A28)>0)*($H$6>0),$C$6&", ","") & IF((COUNTIFS(TableBOM[Product ID],$D$7,TableBOM[Item ID],$A28)>0)*($H$7>0),$C$7&", ","") & IF((COUNTIFS(TableBOM[Product ID],$D$8,TableBOM[Item ID],$A28)>0)*($H$8>0),$C$8&", ",""))>1,LEFT(IF((COUNTIFS(TableBOM[Product ID],$D$3,TableBOM[Item ID],$A28)>0)*($H$3>0),$C$3&", ","") & IF((COUNTIFS(TableBOM[Product ID],$D$4,TableBOM[Item ID],$A28)>0)*($H$4>0),$C$4&", ","") & IF((COUNTIFS(TableBOM[Product ID],$D$5,TableBOM[Item ID],$A28)>0)*($H$5>0),$C$5&", ","") & IF((COUNTIFS(TableBOM[Product ID],$D$6,TableBOM[Item ID],$A28)>0)*($H$6>0),$C$6&", ","") & IF((COUNTIFS(TableBOM[Product ID],$D$7,TableBOM[Item ID],$A28)>0)*($H$7>0),$C$7&", ","") & IF((COUNTIFS(TableBOM[Product ID],$D$8,TableBOM[Item ID],$A28)>0)*($H$8>0),$C$8&", ",""),LEN(IF((COUNTIFS(TableBOM[Product ID],$D$3,TableBOM[Item ID],$A28)>0)*($H$3>0),$C$3&", ","") & IF((COUNTIFS(TableBOM[Product ID],$D$4,TableBOM[Item ID],$A28)>0)*($H$4>0),$C$4&", ","") & IF((COUNTIFS(TableBOM[Product ID],$D$5,TableBOM[Item ID],$A28)>0)*($H$5>0),$C$5&", ","") & IF((COUNTIFS(TableBOM[Product ID],$D$6,TableBOM[Item ID],$A28)>0)*($H$6>0),$C$6&", ","") & IF((COUNTIFS(TableBOM[Product ID],$D$7,TableBOM[Item ID],$A28)>0)*($H$7>0),$C$7&", ","") & IF((COUNTIFS(TableBOM[Product ID],$D$8,TableBOM[Item ID],$A28)>0)*($H$8>0),$C$8&", ",""))-2),"") | I28: =IF(E28=0,"Not needed",IF(G28<0,"SHORTAGE",IF(G28<F28*0.1,"LOW","OK"))) -> Not needed
A29: 1065 | B29: LACQUER | C29: PIGMENTED LACQUER 57300 | D29: kg | E29: =SUMPRODUCT((TableBOM[Item ID]=A29)*TableBOM[Per 1000 Units]*(1+TableBOM[Scrap %])*SUMIF($D$3:$D$8,TableBOM[Product ID],$H$3:$H$8)/1000) -> 0 | F29: =IFERROR(INDEX(TableInventory[Store Balance],MATCH(A29,TableInventory[Item ID],0)),0)+IFERROR(INDEX(TableInventory[Work In Process],MATCH(A29,TableInventory[Item ID],0)),0) -> 0 | G29: =F29-E29 -> 0 | H29: =IF(LEN(IF((COUNTIFS(TableBOM[Product ID],$D$3,TableBOM[Item ID],$A29)>0)*($H$3>0),$C$3&", ","") & IF((COUNTIFS(TableBOM[Product ID],$D$4,TableBOM[Item ID],$A29)>0)*($H$4>0),$C$4&", ","") & IF((COUNTIFS(TableBOM[Product ID],$D$5,TableBOM[Item ID],$A29)>0)*($H$5>0),$C$5&", ","") & IF((COUNTIFS(TableBOM[Product ID],$D$6,TableBOM[Item ID],$A29)>0)*($H$6>0),$C$6&", ","") & IF((COUNTIFS(TableBOM[Product ID],$D$7,TableBOM[Item ID],$A29)>0)*($H$7>0),$C$7&", ","") & IF((COUNTIFS(TableBOM[Product ID],$D$8,TableBOM[Item ID],$A29)>0)*($H$8>0),$C$8&", ",""))>1,LEFT(IF((COUNTIFS(TableBOM[Product ID],$D$3,TableBOM[Item ID],$A29)>0)*($H$3>0),$C$3&", ","") & IF((COUNTIFS(TableBOM[Product ID],$D$4,TableBOM[Item ID],$A29)>0)*($H$4>0),$C$4&", ","") & IF((COUNTIFS(TableBOM[Product ID],$D$5,TableBOM[Item ID],$A29)>0)*($H$5>0),$C$5&", ","") & IF((COUNTIFS(TableBOM[Product ID],$D$6,TableBOM[Item ID],$A29)>0)*($H$6>0),$C$6&", ","") & IF((COUNTIFS(TableBOM[Product ID],$D$7,TableBOM[Item ID],$A29)>0)*($H$7>0),$C$7&", ","") & IF((COUNTIFS(TableBOM[Product ID],$D$8,TableBOM[Item ID],$A29)>0)*($H$8>0),$C$8&", ",""),LEN(IF((COUNTIFS(TableBOM[Product ID],$D$3,TableBOM[Item ID],$A29)>0)*($H$3>0),$C$3&", ","") & IF((COUNTIFS(TableBOM[Product ID],$D$4,TableBOM[Item ID],$A29)>0)*($H$4>0),$C$4&", ","") & IF((COUNTIFS(TableBOM[Product ID],$D$5,TableBOM[Item ID],$A29)>0)*($H$5>0),$C$5&", ","") & IF((COUNTIFS(TableBOM[Product ID],$D$6,TableBOM[Item ID],$A29)>0)*($H$6>0),$C$6&", ","") & IF((COUNTIFS(TableBOM[Product ID],$D$7,TableBOM[Item ID],$A29)>0)*($H$7>0),$C$7&", ","") & IF((COUNTIFS(TableBOM[Product ID],$D$8,TableBOM[Item ID],$A29)>0)*($H$8>0),$C$8&", ",""))-2),"") | I29: =IF(E29=0,"Not needed",IF(G29<0,"SHORTAGE",IF(G29<F29*0.1,"LOW","OK"))) -> Not needed
